Workbook

Sheet 1ºT-12ª-EG-A-PAUTA
A1: INSTITUTO TÉCNICO PRIVADO DE SAÚDE JOMORAIS
B7: PAUTA DE APROVEITAMENTO ESCOLAR
C8: ÁREA DE FORMAÇÃO: SAÚDE
K9: 12ª CLASSE | O9: CURSO: ENFERMAGEM GERAL | AE9: PERÍODO: VESPERTINO
B10: O Director do Instituto | AE10: 1º TRIMESTRE | AL10: MF: | AM10: =SUM(AM12,AM11) -> 42 | AO10: 46003
B11: ________________________________________ | K11: TURMA: | M11: A | AL11: M | AM11: =COUNTIF(AS17:AS58,"M") -> 8
B12: GABRIEL PRÓSPERO MABIALA | AD12: ANO LECTIVO: 2025/2026 | AL12: F | AM12: =COUNTIF(AS17:AS58,"F") -> 34
B13: DATA______/______/2025
B14: Nº | C14: Nº PROC | D14: NOME | E14: DISCIPLINA A REPETIR | F14: S. Colect. | I14: S. Mental | L14: Epidemiol. | O14: F.A.E | R14: Urgência | U14: Nutrição | X14: AEPMC | AA14: T. Enfer. | AD14: A.E.S.M | AG14: P.T | AJ14: A.E.S.Ç | AM14: Gestão | AP14: OBS | AQ14: MÉDIA | AR14: Idade | AS14: Género | AT14: DADOS ESTATÍSTICOS
F15: FALTAS | H15: MT1º | I15: FALTAS | K15: MT1º | L15: FALTAS | N15: MT1º | O15: FALTAS | Q15: MT1º | R15: FALTAS | T15: MT1º | U15: FALTAS | W15: MT1º | X15: FALTAS | Z15: MT1º | AA15: FALTAS | AC15: MT1º | AD15: FALTAS | AF15: MT1º | AG15: FALTAS | AI15: MT1º | AJ15: FALTAS | AL15: MT1º | AM15: FALTAS | AO15: MT1º | AT15: MATRICULADOS | AV15: APROVADO/A | AX15: REPROVADO/A | AZ15: Desistido/a
F16: J | G16: I | I16: J | J16: I | L16: J | M16: I | O16: J | P16: I | R16: J | S16: I | U16: J | V16: I | X16: J | Y16: I | AA16: J | AB16: I | AD16: J | AE16: I | AG16: J | AH16: I | AJ16: J | AK16: I | AM16: J | AN16: I | AT16: M | AU16: F | AV16: M | AW16: F | AX16: M | AY16: F | AZ16: M | BA16: F
B17: 1 | C17: 2582 | D17: Alberto Filipe Massiala | H17: =SUM('12EG -A- S.COLECT.'!K10) -> 14.666667 | K17: =SUM('12EG -A- S. MENTAL'!K10) -> 7.6666667 | N17: =SUM('12EG -A- EPIDEMIOL.'!K10) -> 11 | Q17: =SUM('12EG-A- F.A.E'!K10) -> 1.6666667 | T17: =SUM('12EG -A- URGÊNCIA'!K10) -> 6.6666667 | W17: =SUM('12EG -A- N.D'!K10) -> 8.8333333 | Z17: =SUM('12EG -A- A.E.P.M.C'!K10) -> 9.3333333 | AC17: =SUM('12EG -A- TEC. ENFER'!K10) -> 3.6666667 | AF17: =SUM('12EG -A- A.E.S.M'!K10) -> 12 | AI17: =SUM('12EG -A- PROJ. TEC'!K10) -> 0 | AL17: =SUM('12EG -A- A.E.S.Ç'!K10) -> 12.666667 | AO17: =SUM('12EG -A- GESTÃO ENF.'!K10) -> 2.6666667 | AP17: N/TRANSITA | AQ17: =AVERAGE(H17:AO17) -> 7.5694444 | AR17: 17 | AS17: M | AT17: =COUNTIF(AS17:AS58,"M") -> 8 | AU17: =COUNTIF(AS17:AS58,"F") -> 34 | AV17: =COUNTIFS(AP17:AP58,"TRANSITA",AS17:AS58,"M") -> 1 | AW17: =COUNTIFS(AP17:AP58,"TRANSITA",AS17:AS58,"F") -> 18 | AX17: =COUNTIFS(AP17:AP58,"N/TRANSITA",AS17:AS58,"M") -> 7 | AY17: =COUNTIFS(AP17:AP58,"N/TRANSITA",AS17:AS58,"F") -> 16 | AZ17: =COUNTIFS(AP17:AP58,"Desistido",AS17:AS58,"M") -> 0 | BA17: =COUNTIFS(AP17:AP58,"Desistida",AS17:AS58,"F") -> 0
B18: 2 | C18: 2150 | D18: Aldina Marta Mavungo Cumbo | H18: =SUM('12EG -A- S.COLECT.'!K11) -> 19.666667 | K18: =SUM('12EG -A- S. MENTAL'!K11) -> 16 | N18: =SUM('12EG -A- EPIDEMIOL.'!K11) -> 13.666667 | Q18: =SUM('12EG-A- F.A.E'!K11) -> 10 | T18: =SUM('12EG -A- URGÊNCIA'!K11) -> 11.666667 | W18: =SUM('12EG -A- N.D'!K11) -> 15.333333 | Z18: =SUM('12EG -A- A.E.P.M.C'!K11) -> 14.833333 | AC18: =SUM('12EG -A- TEC. ENFER'!K11) -> 11 | AF18: =SUM('12EG -A- A.E.S.M'!K11) -> 12 | AI18: =SUM('12EG -A- PROJ. TEC'!K11) -> 15.333333 | AL18: =SUM('12EG -A- A.E.S.Ç'!K11) -> 16.666667 | AO18: =SUM('12EG -A- GESTÃO ENF.'!K11) -> 5.1666667 | AP18: N/TRANSITA | AQ18: =AVERAGE(H18:AO18) -> 13.444444 | AR18: 17 | AS18: F | AT18: =SUM(AT17:AU17) -> 42 | AV18: =SUM(AV17:AW17) -> 19 | AX18: =SUM(AX17:AY17) -> 23 | AZ18: =SUM(AZ17:BA17) -> 0
B19: 3 | C19: 1791 | D19: Alice Malonda Lubota Macaia | H19: =SUM('12EG -A- S.COLECT.'!K12) -> 18.5 | K19: =SUM('12EG -A- S. MENTAL'!K12) -> 15 | N19: =SUM('12EG -A- EPIDEMIOL.'!K12) -> 5.3333333 | Q19: =SUM('12EG-A- F.A.E'!K12) -> 12 | T19: =SUM('12EG -A- URGÊNCIA'!K12) -> 11 | W19: =SUM('12EG -A- N.D'!K12) -> 14.833333 | Z19: =SUM('12EG -A- A.E.P.M.C'!K12) -> 13.833333 | AC19: =SUM('12EG -A- TEC. ENFER'!K12) -> 11.5 | AF19: =SUM('12EG -A- A.E.S.M'!K12) -> 12 | AI19: =SUM('12EG -A- PROJ. TEC'!K12) -> 17.333333 | AL19: =SUM('12EG -A- A.E.S.Ç'!K12) -> 17.666667 | AO19: =SUM('12EG -A- GESTÃO ENF.'!K12) -> 5.5 | AP19: N/TRANSITA | AQ19: =AVERAGE(H19:AO19) -> 12.875 | AR19: 17 | AS19: F
B20: 4 | C20: 2623 | D20: Angelina Kambo Macosso | H20: =SUM('12EG -A- S.COLECT.'!K13) -> 19 | K20: =SUM('12EG -A- S. MENTAL'!K13) -> 14.5 | N20: =SUM('12EG -A- EPIDEMIOL.'!K13) -> 16 | Q20: =SUM('12EG-A- F.A.E'!K13) -> 12.666667 | T20: =SUM('12EG -A- URGÊNCIA'!K13) -> 13.5 | W20: =SUM('12EG -A- N.D'!K13) -> 17 | Z20: =SUM('12EG -A- A.E.P.M.C'!K13) -> 18 | AC20: =SUM('12EG -A- TEC. ENFER'!K13) -> 12.866667 | AF20: =SUM('12EG -A- A.E.S.M'!K13) -> 12 | AI20: =SUM('12EG -A- PROJ. TEC'!K13) -> 17.666667 | AL20: =SUM('12EG -A- A.E.S.Ç'!K13) -> 17.833333 | AO20: =SUM('12EG -A- GESTÃO ENF.'!K13) -> 10.5 | AP20: TRANSITA | AQ20: =AVERAGE(H20:AO20) -> 15.127778 | AR20: 17 | AS20: F
B21: 5 | C21: 1818 | D21: Belma Da C. Ngaca Bernardo | H21: =SUM('12EG -A- S.COLECT.'!K14) -> 19.666667 | K21: =SUM('12EG -A- S. MENTAL'!K14) -> 16.333333 | N21: =SUM('12EG -A- EPIDEMIOL.'!K14) -> 17.333333 | Q21: =SUM('12EG-A- F.A.E'!K14) -> 12 | T21: =SUM('12EG -A- URGÊNCIA'!K14) -> 16 | W21: =SUM('12EG -A- N.D'!K14) -> 18.833333 | Z21: =SUM('12EG -A- A.E.P.M.C'!K14) -> 19 | AC21: =SUM('12EG -A- TEC. ENFER'!K14) -> 16.2 | AF21: =SUM('12EG -A- A.E.S.M'!K14) -> 12 | AI21: =SUM('12EG -A- PROJ. TEC'!K14) -> 19.333333 | AL21: =SUM('12EG -A- A.E.S.Ç'!K14) -> 17.833333 | AO21: =SUM('12EG -A- GESTÃO ENF.'!K14) -> 12.666667 | AP21: TRANSITA | AQ21: =AVERAGE(H21:AO21) -> 16.433333 | AR21: 18 | AS21: F
B22: 6 | C22: 1974 | D22: Carolina Teresa Joana Chingui | H22: =SUM('12EG -A- S.COLECT.'!K15) -> 14.5 | K22: =SUM('12EG -A- S. MENTAL'!K15) -> 14.333333 | N22: =SUM('12EG -A- EPIDEMIOL.'!K15) -> 14.666667 | Q22: =SUM('12EG-A- F.A.E'!K15) -> 2.6666667 | T22: =SUM('12EG -A- URGÊNCIA'!K15) -> 8.6666667 | W22: =SUM('12EG -A- N.D'!K15) -> 0 | Z22: =SUM('12EG -A- A.E.P.M.C'!K15) -> 0 | AC22: =SUM('12EG -A- TEC. ENFER'!K15) -> 11.2 | AF22: =SUM('12EG -A- A.E.S.M'!K15) -> 12 | AI22: =SUM('12EG -A- PROJ. TEC'!K15) -> 9.3333333 | AL22: =SUM('12EG -A- A.E.S.Ç'!K15) -> 15.333333 | AO22: =SUM('12EG -A- GESTÃO ENF.'!K15) -> 9.3333333 | AP22: N/TRANSITA | AQ22: =AVERAGE(H22:AO22) -> 9.3361111 | AR22: 17 | AS22: F
B23: 7 | C23: 2051 | D23: Celma Cecília Macaia Gomes | H23: =SUM('12EG -A- S.COLECT.'!K16) -> 18.666667 | K23: =SUM('12EG -A- S. MENTAL'!K16) -> 14.5 | N23: =SUM('12EG -A- EPIDEMIOL.'!K16) -> 16.666667 | Q23: =SUM('12EG-A- F.A.E'!K16) -> 12.666667 | T23: =SUM('12EG -A- URGÊNCIA'!K16) -> 13.833333 | W23: =SUM('12EG -A- N.D'!K16) -> 18.5 | Z23: =SUM('12EG -A- A.E.P.M.C'!K16) -> 16 | AC23: =SUM('12EG -A- TEC. ENFER'!K16) -> 13.6 | AF23: =SUM('12EG -A- A.E.S.M'!K16) -> 12 | AI23: =SUM('12EG -A- PROJ. TEC'!K16) -> 18.333333 | AL23: =SUM('12EG -A- A.E.S.Ç'!K16) -> 17.5 | AO23: =SUM('12EG -A- GESTÃO ENF.'!K16) -> 15.166667 | AP23: TRANSITA | AQ23: =AVERAGE(H23:AO23) -> 15.619444 | AR23: 17 | AS23: F
B24: 8 | C24: 2230 | D24: Dádiva Ermelinda Gabriel Barros | H24: =SUM('12EG -A- S.COLECT.'!K17) -> 14.833333 | K24: =SUM('12EG -A- S. MENTAL'!K17) -> 12 | N24: =SUM('12EG -A- EPIDEMIOL.'!K17) -> 9.3333333 | Q24: =SUM('12EG-A- F.A.E'!K17) -> 11 | T24: =SUM('12EG -A- URGÊNCIA'!K17) -> 11.333333 | W24: =SUM('12EG -A- N.D'!K17) -> 12.833333 | Z24: =SUM('12EG -A- A.E.P.M.C'!K17) -> 11.5 | AC24: =SUM('12EG -A- TEC. ENFER'!K17) -> 9.3333333 | AF24: =SUM('12EG -A- A.E.S.M'!K17) -> 12 | AI24: =SUM('12EG -A- PROJ. TEC'!K17) -> 16 | AL24: =SUM('12EG -A- A.E.S.Ç'!K17) -> 14 | AO24: =SUM('12EG -A- GESTÃO ENF.'!K17) -> 9 | AP24: N/TRANSITA | AQ24: =AVERAGE(H24:AO24) -> 11.930556 | AR24: 18 | AS24: F
B25: 9 | C25: 1774 | D25: Daniel Quendo João | H25: =SUM('12EG -A- S.COLECT.'!K18) -> 18.333333 | K25: =SUM('12EG -A- S. MENTAL'!K18) -> 7.3333333 | N25: =SUM('12EG -A- EPIDEMIOL.'!K18) -> 10 | Q25: =SUM('12EG-A- F.A.E'!K18) -> 2 | T25: =SUM('12EG -A- URGÊNCIA'!K18) -> 0 | W25: =SUM('12EG -A- N.D'!K18) -> 0 | Z25: =SUM('12EG -A- A.E.P.M.C'!K18) -> 0 | AC25: =SUM('12EG -A- TEC. ENFER'!K18) -> 2 | AF25: =SUM('12EG -A- A.E.S.M'!K18) -> 0 | AI25: =SUM('12EG -A- PROJ. TEC'!K18) -> 0 | AL25: =SUM('12EG -A- A.E.S.Ç'!K18) -> 6.6666667 | AO25: =SUM('12EG -A- GESTÃO ENF.'!K18) -> 2.5 | AP25: N/TRANSITA | AQ25: =AVERAGE(H25:AO25) -> 4.0694444 | AR25: 18 | AS25: M
B26: 10 | C26: 4446 | D26: Dina De Lourdes Massala | H26: =SUM('12EG -A- S.COLECT.'!K19) -> 19.333333 | K26: =SUM('12EG -A- S. MENTAL'!K19) -> 14.833333 | N26: =SUM('12EG -A- EPIDEMIOL.'!K19) -> 13 | Q26: =SUM('12EG-A- F.A.E'!K19) -> 11 | T26: =SUM('12EG -A- URGÊNCIA'!K19) -> 11.166667 | W26: =SUM('12EG -A- N.D'!K19) -> 17 | Z26: =SUM('12EG -A- A.E.P.M.C'!K19) -> 13.833333 | AC26: =SUM('12EG -A- TEC. ENFER'!K19) -> 13.666667 | AF26: =SUM('12EG -A- A.E.S.M'!K19) -> 16 | AI26: =SUM('12EG -A- PROJ. TEC'!K19) -> 16.666667 | AL26: =SUM('12EG -A- A.E.S.Ç'!K19) -> 12.833333 | AO26: =SUM('12EG -A- GESTÃO ENF.'!K19) -> 13.833333 | AP26: TRANSITA | AQ26: =AVERAGE(H26:AO26) -> 14.430556 | AR26: 16 | AS26: F
B27: 11 | C27: 1992 | D27: Esperança C. Bumba Mabiala | H27: =SUM('12EG -A- S.COLECT.'!K20) -> 18.666667 | K27: =SUM('12EG -A- S. MENTAL'!K20) -> 14 | N27: =SUM('12EG -A- EPIDEMIOL.'!K20) -> 17.333333 | Q27: =SUM('12EG-A- F.A.E'!K20) -> 10.333333 | T27: =SUM('12EG -A- URGÊNCIA'!K20) -> 15.833333 | W27: =SUM('12EG -A- N.D'!K20) -> 17.5 | Z27: =SUM('12EG -A- A.E.P.M.C'!K20) -> 18.333333 | AC27: =SUM('12EG -A- TEC. ENFER'!K20) -> 14.833333 | AF27: =SUM('12EG -A- A.E.S.M'!K20) -> 12 | AI27: =SUM('12EG -A- PROJ. TEC'!K20) -> 17 | AL27: =SUM('12EG -A- A.E.S.Ç'!K20) -> 17.5 | AO27: =SUM('12EG -A- GESTÃO ENF.'!K20) -> 14.666667 | AP27: TRANSITA | AQ27: =AVERAGE(H27:AO27) -> 15.666667 | AR27: 18 | AS27: F
B28: 12 | C28: 2053 | D28: Esperança Lando Liumba | H28: =SUM('12EG -A- S.COLECT.'!K21) -> 15.333333 | K28: =SUM('12EG -A- S. MENTAL'!K21) -> 15.333333 | N28: =SUM('12EG -A- EPIDEMIOL.'!K21) -> 17 | Q28: =SUM('12EG-A- F.A.E'!K21) -> 10.333333 | T28: =SUM('12EG -A- URGÊNCIA'!K21) -> 16.5 | W28: =SUM('12EG -A- N.D'!K21) -> 18.166667 | Z28: =SUM('12EG -A- A.E.P.M.C'!K21) -> 17.833333 | AC28: =SUM('12EG -A- TEC. ENFER'!K21) -> 14.166667 | AF28: =SUM('12EG -A- A.E.S.M'!K21) -> 12 | AI28: =SUM('12EG -A- PROJ. TEC'!K21) -> 15.333333 | AL28: =SUM('12EG -A- A.E.S.Ç'!K21) -> 17 | AO28: =SUM('12EG -A- GESTÃO ENF.'!K21) -> 12.333333 | AP28: TRANSITA | AQ28: =AVERAGE(H28:AO28) -> 15.111111 | AR28: 17 | AS28: F
B29: 13 | C29: 2039 | D29: Ester Mavungo Fuca | H29: =SUM('12EG -A- S.COLECT.'!K22) -> 18.166667 | K29: =SUM('12EG -A- S. MENTAL'!K22) -> 11.5 | N29: =SUM('12EG -A- EPIDEMIOL.'!K22) -> 13.333333 | Q29: =SUM('12EG-A- F.A.E'!K22) -> 8.3333333 | T29: =SUM('12EG -A- URGÊNCIA'!K22) -> 13 | W29: =SUM('12EG -A- N.D'!K22) -> 16 | Z29: =SUM('12EG -A- A.E.P.M.C'!K22) -> 12.5 | AC29: =SUM('12EG -A- TEC. ENFER'!K22) -> 10.666667 | AF29: =SUM('12EG -A- A.E.S.M'!K22) -> 12 | AI29: =SUM('12EG -A- PROJ. TEC'!K22) -> 15.666667 | AL29: =SUM('12EG -A- A.E.S.Ç'!K22) -> 17 | AO29: =SUM('12EG -A- GESTÃO ENF.'!K22) -> 12.666667 | AP29: N/TRANSITA | AQ29: =AVERAGE(H29:AO29) -> 13.402778 | AR29: 17 | AS29: F | AU29: MÁXIMA | AV29: =MAX(AQ17:AQ58) -> 16.433333
B30: 14 | C30: 1942 | D30: Eufemia Maria Goma Ventena | H30: =SUM('12EG -A- S.COLECT.'!K23) -> 18.666667 | K30: =SUM('12EG -A- S. MENTAL'!K23) -> 13.833333 | N30: =SUM('12EG -A- EPIDEMIOL.'!K23) -> 13.666667 | Q30: =SUM('12EG-A- F.A.E'!K23) -> 10 | T30: =SUM('12EG -A- URGÊNCIA'!K23) -> 14.666667 | W30: =SUM('12EG -A- N.D'!K23) -> 17.833333 | Z30: =SUM('12EG -A- A.E.P.M.C'!K23) -> 16.666667 | AC30: =SUM('12EG -A- TEC. ENFER'!K23) -> 10.833333 | AF30: =SUM('12EG -A- A.E.S.M'!K23) -> 12 | AI30: =SUM('12EG -A- PROJ. TEC'!K23) -> 16 | AL30: =SUM('12EG -A- A.E.S.Ç'!K23) -> 16.5 | AO30: =SUM('12EG -A- GESTÃO ENF.'!K23) -> 11.666667 | AP30: TRANSITA | AQ30: =AVERAGE(H30:AO30) -> 14.361111 | AR30: 18 | AS30: F
B31: 15 | C31: 2612 | D31: Eulália Buanga Bembe Alfredo | H31: =SUM('12EG -A- S.COLECT.'!K24) -> 18.666667 | K31: =SUM('12EG -A- S. MENTAL'!K24) -> 15 | N31: =SUM('12EG -A- EPIDEMIOL.'!K24) -> 16.666667 | Q31: =SUM('12EG-A- F.A.E'!K24) -> 11 | T31: =SUM('12EG -A- URGÊNCIA'!K24) -> 13.166667 | W31: =SUM('12EG -A- N.D'!K24) -> 18.166667 | Z31: =SUM('12EG -A- A.E.P.M.C'!K24) -> 15.166667 | AC31: =SUM('12EG -A- TEC. ENFER'!K24) -> 15.333333 | AF31: =SUM('12EG -A- A.E.S.M'!K24) -> 12 | AI31: =SUM('12EG -A- PROJ. TEC'!K24) -> 18.666667 | AL31: =SUM('12EG -A- A.E.S.Ç'!K24) -> 18.166667 | AO31: =SUM('12EG -A- GESTÃO ENF.'!K24) -> 9.1666667 | AP31: N/TRANSITA | AQ31: =AVERAGE(H31:AO31) -> 15.097222 | AR31: 17 | AS31: F | AU31: NOME DO/A ALUNO/A | AX31: Madalena Simba Pemba Miguel
B32: 16 | C32: 2041 | D32: Eva De Araújo Mambo | H32: =SUM('12EG -A- S.COLECT.'!K25) -> 17 | K32: =SUM('12EG -A- S. MENTAL'!K25) -> 13.666667 | N32: =SUM('12EG -A- EPIDEMIOL.'!K25) -> 11.666667 | Q32: =SUM('12EG-A- F.A.E'!K25) -> 10.666667 | T32: =SUM('12EG -A- URGÊNCIA'!K25) -> 17.333333 | W32: =SUM('12EG -A- N.D'!K25) -> 14.333333 | Z32: =SUM('12EG -A- A.E.P.M.C'!K25) -> 13.833333 | AC32: =SUM('12EG -A- TEC. ENFER'!K25) -> 10.7 | AF32: =SUM('12EG -A- A.E.S.M'!K25) -> 12 | AI32: =SUM('12EG -A- PROJ. TEC'!K25) -> 16.666667 | AL32: =SUM('12EG -A- A.E.S.Ç'!K25) -> 16.5 | AO32: =SUM('12EG -A- GESTÃO ENF.'!K25) -> 12 | AP32: TRANSITA | AQ32: =AVERAGE(H32:AO32) -> 13.863889 | AR32: 18 | AS32: F | AU32: IDADE: | AV32: 17
B33: 17 | C33: 2596 | D33: Fátima B. Puila Cassombe | H33: =SUM('12EG -A- S.COLECT.'!K26) -> 19.333333 | K33: =SUM('12EG -A- S. MENTAL'!K26) -> 15.333333 | N33: =SUM('12EG -A- EPIDEMIOL.'!K26) -> 12.333333 | Q33: =SUM('12EG-A- F.A.E'!K26) -> 12.666667 | T33: =SUM('12EG -A- URGÊNCIA'!K26) -> 16.166667 | W33: =SUM('12EG -A- N.D'!K26) -> 15.5 | Z33: =SUM('12EG -A- A.E.P.M.C'!K26) -> 17.333333 | AC33: =SUM('12EG -A- TEC. ENFER'!K26) -> 11.333333 | AF33: =SUM('12EG -A- A.E.S.M'!K26) -> 12 | AI33: =SUM('12EG -A- PROJ. TEC'!K26) -> 19 | AL33: =SUM('12EG -A- A.E.S.Ç'!K26) -> 18 | AO33: =SUM('12EG -A- GESTÃO ENF.'!K26) -> 13.5 | AP33: TRANSITA | AQ33: =AVERAGE(H33:AO33) -> 15.208333 | AR33: 17 | AS33: F
B34: 18 | C34: 2082 | D34: Filomena Lelo Tembo Chibuango | H34: =SUM('12EG -A- S.COLECT.'!K27) -> 18.333333 | K34: =SUM('12EG -A- S. MENTAL'!K27) -> 14.166667 | N34: =SUM('12EG -A- EPIDEMIOL.'!K27) -> 11.666667 | Q34: =SUM('12EG-A- F.A.E'!K27) -> 10.666667 | T34: =SUM('12EG -A- URGÊNCIA'!K27) -> 13.333333 | W34: =SUM('12EG -A- N.D'!K27) -> 17.166667 | Z34: =SUM('12EG -A- A.E.P.M.C'!K27) -> 14.333333 | AC34: =SUM('12EG -A- TEC. ENFER'!K27) -> 12.266667 | AF34: =SUM('12EG -A- A.E.S.M'!K27) -> 12 | AI34: =SUM('12EG -A- PROJ. TEC'!K27) -> 15.333333 | AL34: =SUM('12EG -A- A.E.S.Ç'!K27) -> 17.333333 | AO34: =SUM('12EG -A- GESTÃO ENF.'!K27) -> 13.666667 | AP34: TRANSITA | AQ34: =AVERAGE(H34:AO34) -> 14.188889 | AR34: 17 | AS34: F
B35: 19 | C35: 1936 | D35: Helena Da C. Bumba Bilendo | H35: =SUM('12EG -A- S.COLECT.'!K28) -> 16.333333 | K35: =SUM('12EG -A- S. MENTAL'!K28) -> 14.333333 | N35: =SUM('12EG -A- EPIDEMIOL.'!K28) -> 11.666667 | Q35: =SUM('12EG-A- F.A.E'!K28) -> 12.666667 | T35: =SUM('12EG -A- URGÊNCIA'!K28) -> 9 | W35: =SUM('12EG -A- N.D'!K28) -> 17.333333 | Z35: =SUM('12EG -A- A.E.P.M.C'!K28) -> 17 | AC35: =SUM('12EG -A- TEC. ENFER'!K28) -> 11.5 | AF35: =SUM('12EG -A- A.E.S.M'!K28) -> 12 | AI35: =SUM('12EG -A- PROJ. TEC'!K28) -> 14.666667 | AL35: =SUM('12EG -A- A.E.S.Ç'!K28) -> 16.166667 | AO35: =SUM('12EG -A- GESTÃO ENF.'!K28) -> 10.833333 | AP35: N/TRANSITA | AQ35: =AVERAGE(H35:AO35) -> 13.625 | AR35: 18 | AS35: F
B36: 20 | C36: 2107 | D36: Helena Nzuzi Lembe Gimbi | H36: =SUM('12EG -A- S.COLECT.'!K29) -> 19 | K36: =SUM('12EG -A- S. MENTAL'!K29) -> 14.666667 | N36: =SUM('12EG -A- EPIDEMIOL.'!K29) -> 15.333333 | Q36: =SUM('12EG-A- F.A.E'!K29) -> 0 | T36: =SUM('12EG -A- URGÊNCIA'!K29) -> 13 | W36: =SUM('12EG -A- N.D'!K29) -> 16.833333 | Z36: =SUM('12EG -A- A.E.P.M.C'!K29) -> 18 | AC36: =SUM('12EG -A- TEC. ENFER'!K29) -> 12.866667 | AF36: =SUM('12EG -A- A.E.S.M'!K29) -> 12 | AI36: =SUM('12EG -A- PROJ. TEC'!K29) -> 17 | AL36: =SUM('12EG -A- A.E.S.Ç'!K29) -> 16.833333 | AO36: =SUM('12EG -A- GESTÃO ENF.'!K29) -> 9.8333333 | AP36: N/TRANSITA | AQ36: =AVERAGE(H36:AO36) -> 13.780556 | AR36: 17 | AS36: F
B37: 21 | C37: 2477 | D37: Helena Pemba António Brás | H37: =SUM('12EG -A- S.COLECT.'!K30) -> 14.166667 | K37: =SUM('12EG -A- S. MENTAL'!K30) -> 15 | N37: =SUM('12EG -A- EPIDEMIOL.'!K30) -> 17.333333 | Q37: =SUM('12EG-A- F.A.E'!K30) -> 11 | T37: =SUM('12EG -A- URGÊNCIA'!K30) -> 11.333333 | W37: =SUM('12EG -A- N.D'!K30) -> 17.833333 | Z37: =SUM('12EG -A- A.E.P.M.C'!K30) -> 17.166667 | AC37: =SUM('12EG -A- TEC. ENFER'!K30) -> 14.366667 | AF37: =SUM('12EG -A- A.E.S.M'!K30) -> 12 | AI37: =SUM('12EG -A- PROJ. TEC'!K30) -> 17.666667 | AL37: =SUM('12EG -A- A.E.S.Ç'!K30) -> 17.166667 | AO37: =SUM('12EG -A- GESTÃO ENF.'!K30) -> 11.166667 | AP37: TRANSITA | AQ37: =AVERAGE(H37:AO37) -> 14.683333 | AR37: 17 | AS37: F
B38: 22 | C38: 1928 | D38: Isabel Mariana Miala | H38: =SUM('12EG -A- S.COLECT.'!K31) -> 15.666667 | K38: =SUM('12EG -A- S. MENTAL'!K31) -> 13.333333 | N38: =SUM('12EG -A- EPIDEMIOL.'!K31) -> 14 | Q38: =SUM('12EG-A- F.A.E'!K31) -> 10 | T38: =SUM('12EG -A- URGÊNCIA'!K31) -> 12.5 | W38: =SUM('12EG -A- N.D'!K31) -> 13.5 | Z38: =SUM('12EG -A- A.E.P.M.C'!K31) -> 15.166667 | AC38: =SUM('12EG -A- TEC. ENFER'!K31) -> 11.833333 | AF38: =SUM('12EG -A- A.E.S.M'!K31) -> 12 | AI38: =SUM('12EG -A- PROJ. TEC'!K31) -> 0 | AL38: =SUM('12EG -A- A.E.S.Ç'!K31) -> 17.333333 | AO38: =SUM('12EG -A- GESTÃO ENF.'!K31) -> 3.8333333 | AP38: N/TRANSITA | AQ38: =AVERAGE(H38:AO38) -> 11.597222 | AR38: 18 | AS38: F
B39: 23 | C39: 2313 | D39: Isabel Nhongo Luambo Estevão | H39: =SUM('12EG -A- S.COLECT.'!K32) -> 12.666667 | K39: =SUM('12EG -A- S. MENTAL'!K32) -> 13.666667 | N39: =SUM('12EG -A- EPIDEMIOL.'!K32) -> 17.333333 | Q39: =SUM('12EG-A- F.A.E'!K32) -> 12.666667 | T39: =SUM('12EG -A- URGÊNCIA'!K32) -> 17.833333 | W39: =SUM('12EG -A- N.D'!K32) -> 16.666667 | Z39: =SUM('12EG -A- A.E.P.M.C'!K32) -> 16.333333 | AC39: =SUM('12EG -A- TEC. ENFER'!K32) -> 11.7 | AF39: =SUM('12EG -A- A.E.S.M'!K32) -> 12 | AI39: =SUM('12EG -A- PROJ. TEC'!K32) -> 13 | AL39: =SUM('12EG -A- A.E.S.Ç'!K32) -> 15.166667 | AO39: =SUM('12EG -A- GESTÃO ENF.'!K32) -> 15.333333 | AP39: TRANSITA | AQ39: =AVERAGE(H39:AO39) -> 14.530556 | AR39: 17 | AS39: M
B40: 24 | C40: 2525 | D40: Jerónimo Yombe Vemba | H40: =SUM('12EG -A- S.COLECT.'!K33) -> 19.666667 | K40: =SUM('12EG -A- S. MENTAL'!K33) -> 8.8333333 | N40: =SUM('12EG -A- EPIDEMIOL.'!K33) -> 10.666667 | Q40: =SUM('12EG-A- F.A.E'!K33) -> 3 | T40: =SUM('12EG -A- URGÊNCIA'!K33) -> 6.6666667 | W40: =SUM('12EG -A- N.D'!K33) -> 11.166667 | Z40: =SUM('12EG -A- A.E.P.M.C'!K33) -> 9.5 | AC40: =SUM('12EG -A- TEC. ENFER'!K33) -> 7.7 | AF40: =SUM('12EG -A- A.E.S.M'!K33) -> 12 | AI40: =SUM('12EG -A- PROJ. TEC'!K33) -> 0 | AL40: =SUM('12EG -A- A.E.S.Ç'!K33) -> 12 | AO40: =SUM('12EG -A- GESTÃO ENF.'!K33) -> 7 | AP40: N/TRANSITA | AQ40: =AVERAGE(H40:AO40) -> 9.0166667 | AR40: 17 | AS40: M
B41: 25 | C41: 2163 | D41: Joana Dadiva Ndembe Bueia | H41: =SUM('12EG -A- S.COLECT.'!K34) -> 14 | K41: =SUM('12EG -A- S. MENTAL'!K34) -> 16.666667 | N41: =SUM('12EG -A- EPIDEMIOL.'!K34) -> 17.333333 | Q41: =SUM('12EG-A- F.A.E'!K34) -> 11 | T41: =SUM('12EG -A- URGÊNCIA'!K34) -> 16.333333 | W41: =SUM('12EG -A- N.D'!K34) -> 18.833333 | Z41: =SUM('12EG -A- A.E.P.M.C'!K34) -> 17.333333 | AC41: =SUM('12EG -A- TEC. ENFER'!K34) -> 14.666667 | AF41: =SUM('12EG -A- A.E.S.M'!K34) -> 12 | AI41: =SUM('12EG -A- PROJ. TEC'!K34) -> 19.333333 | AL41: =SUM('12EG -A- A.E.S.Ç'!K34) -> 17.5 | AO41: =SUM('12EG -A- GESTÃO ENF.'!K34) -> 15.333333 | AP41: TRANSITA | AQ41: =AVERAGE(H41:AO41) -> 15.861111 | AR41: 17 | AS41: F
B42: 26 | C42: 2042 | D42: João Sidónio António | H42: =SUM('12EG -A- S.COLECT.'!K35) -> 16.166667 | K42: =SUM('12EG -A- S. MENTAL'!K35) -> 12.666667 | N42: =SUM('12EG -A- EPIDEMIOL.'!K35) -> 14.666667 | Q42: =SUM('12EG-A- F.A.E'!K35) -> 4.6666667 | T42: =SUM('12EG -A- URGÊNCIA'!K35) -> 5.6666667 | W42: =SUM('12EG -A- N.D'!K35) -> 9.6666667 | Z42: =SUM('12EG -A- A.E.P.M.C'!K35) -> 13.666667 | AC42: =SUM('12EG -A- TEC. ENFER'!K35) -> 10 | AF42: =SUM('12EG -A- A.E.S.M'!K35) -> 12 | AI42: =SUM('12EG -A- PROJ. TEC'!K35) -> 9.3333333 | AL42: =SUM('12EG -A- A.E.S.Ç'!K35) -> 13.5 | AO42: =SUM('12EG -A- GESTÃO ENF.'!K35) -> 7 | AP42: N/TRANSITA | AQ42: =AVERAGE(H42:AO42) -> 10.75 | AR42: 18 | AS42: M
B43: 27 | C43: 1975 | D43: Jocelma Badila Da Costa | H43: =SUM('12EG -A- S.COLECT.'!K36) -> 15 | K43: =SUM('12EG -A- S. MENTAL'!K36) -> 17 | N43: =SUM('12EG -A- EPIDEMIOL.'!K36) -> 13.666667 | Q43: =SUM('12EG-A- F.A.E'!K36) -> 3.6666667 | T43: =SUM('12EG -A- URGÊNCIA'!K36) -> 10 | W43: =SUM('12EG -A- N.D'!K36) -> 18 | Z43: =SUM('12EG -A- A.E.P.M.C'!K36) -> 14.333333 | AC43: =SUM('12EG -A- TEC. ENFER'!K36) -> 10 | AF43: =SUM('12EG -A- A.E.S.M'!K36) -> 12 | AI43: =SUM('12EG -A- PROJ. TEC'!K36) -> 16 | AL43: =SUM('12EG -A- A.E.S.Ç'!K36) -> 15.5 | AO43: =SUM('12EG -A- GESTÃO ENF.'!K36) -> 5.8333333 | AP43: N/TRANSITA | AQ43: =AVERAGE(H43:AO43) -> 12.583333 | AR43: 17 | AS43: F
B44: 28 | C44: 1915 | D44: José Francisco Malonda Kibodo | H44: =SUM('12EG -A- S.COLECT.'!K37) -> 15.666667 | K44: =SUM('12EG -A- S. MENTAL'!K37) -> 15 | N44: =SUM('12EG -A- EPIDEMIOL.'!K37) -> 15.666667 | Q44: =SUM('12EG-A- F.A.E'!K37) -> 10.666667 | T44: =SUM('12EG -A- URGÊNCIA'!K37) -> 10.333333 | W44: =SUM('12EG -A- N.D'!K37) -> 14.333333 | Z44: =SUM('12EG -A- A.E.P.M.C'!K37) -> 14 | AC44: =SUM('12EG -A- TEC. ENFER'!K37) -> 6.8333333 | AF44: =SUM('12EG -A- A.E.S.M'!K37) -> 12 | AI44: =SUM('12EG -A- PROJ. TEC'!K37) -> 13.666667 | AL44: =SUM('12EG -A- A.E.S.Ç'!K37) -> 17 | AO44: =SUM('12EG -A- GESTÃO ENF.'!K37) -> 8.6666667 | AP44: N/TRANSITA | AQ44: =AVERAGE(H44:AO44) -> 12.819444 | AR44: 17 | AS44: M
... B58: 42 | C58: 2096 | D58: Zulmira Buanga António | H58: =SUM('12EG -A- S.COLECT.'!K51) -> 12 | K58: =SUM('12EG -A- S. MENTAL'!K51) -> 15.166667 | N58: =SUM('12EG -A- EPIDEMIOL.'!K51) -> 11 | Q58: =SUM('12EG-A- F.A.E'!K51) -> 11.666667 | T58: =SUM('12EG -A- URGÊNCIA'!K51) -> 12 | W58: =SUM('12EG -A- N.D'!K51) -> 10.5 | Z58: =SUM('12EG -A- A.E.P.M.C'!K51) -> 13.166667 | AC58: =SUM('12EG -A- TEC. ENFER'!K51) -> 11.366667 | AF58: =SUM('12EG -A- A.E.S.M'!K51) -> 12 | AI58: =SUM('12EG -A- PROJ. TEC'!K51) -> 13.333333 | AL58: =SUM('12EG -A- A.E.S.Ç'!K51) -> 16.833333 | AO58: =SUM('12EG -A- GESTÃO ENF.'!K51) -> 11 | AP58: TRANSITA | AQ58: =AVERAGE(H58:AO58) -> 12.502778 | AR58: 17 | AS58: F
...

Sheet 2ºT-12ª-EG-A-PAUTA
A1: INSTITUTO TÉCNICO PRIVADO DE SAÚDE JOMORAIS
B7: PAUTA DE APROVEITAMENTO ESCOLAR
C8: ÁREA DE FORMAÇÃO: SAÚDE
K9: 12ª CLASSE | O9: CURSO: ENFERMAGEM GERAL | AE9: PERÍODO: VESPERTINO
B10: O Director do Instituto | AE10: 2º TRIMESTRE | AL10: MF: | AM10: =SUM(AM12,AM11) -> 42 | AO10: 46118
B11: ________________________________________ | K11: TURMA: | M11: A | AL11: M | AM11: =COUNTIF(AS17:AS58,"M") -> 8
B12: GABRIEL PRÓSPERO MABIALA | AD12: ANO LECTIVO: 2025/2026 | AL12: F | AM12: =COUNTIF(AS17:AS58,"F") -> 34
B13: DATA______/______/2026
B14: Nº | C14: Nº PROC | D14: NOME | E14: DISCIPLINA A REPETIR | F14: S. Colect. | I14: S. Mental | L14: Epidemiol. | O14: F.A.E | R14: Urgência | U14: Nutrição | X14: AEPMC | AA14: T. Enfer. | AD14: A.E.S.M | AG14: P.T | AJ14: A.E.S.Ç | AM14: Gestão | AP14: OBS | AQ14: MÉDIA | AR14: Idade | AS14: Género | AT14: DADOS ESTATÍSTICOS
F15: FALTAS | H15: MT2º | I15: FALTAS | K15: MT2º | L15: FALTAS | N15: MT2º | O15: FALTAS | Q15: MT2º | R15: FALTAS | T15: MT2º | U15: FALTAS | W15: MT2º | X15: FALTAS | Z15: MT2º | AA15: FALTAS | AC15: MT2º | AD15: FALTAS | AF15: MT2º | AG15: FALTAS | AI15: MT2º | AJ15: FALTAS | AL15: MT2º | AM15: FALTAS | AO15: MT2º | AT15: MATRICULADOS | AV15: APROVADO/A | AX15: REPROVADO/A | AZ15: Desistido/a
F16: J | G16: I | I16: J | J16: I | L16: J | M16: I | O16: J | P16: I | R16: J | S16: I | U16: J | V16: I | X16: J | Y16: I | AA16: J | AB16: I | AD16: J | AE16: I | AG16: J | AH16: I | AJ16: J | AK16: I | AM16: J | AN16: I | AT16: M | AU16: F | AV16: M | AW16: F | AX16: M | AY16: F | AZ16: M | BA16: F
B17: 1 | C17: 2582 | D17: Alberto Filipe Massiala | H17: =SUM('12EG -A- S.COLECT.'!R10) -> 14 | K17: =SUM('12EG -A- S. MENTAL'!R10) -> 9.1666667 | N17: =SUM('12EG -A- EPIDEMIOL.'!R10) -> 16 | Q17: =SUM('12EG-A- F.A.E'!R10) -> 2.5 | T17: =SUM('12EG -A- URGÊNCIA'!R10) -> 3.6666667 | W17: =SUM('12EG -A- N.D'!R10) -> 11.833333 | Z17: =SUM('12EG -A- A.E.P.M.C'!R10) -> 10.333333 | AC17: =SUM('12EG -A- TEC. ENFER'!R10) -> 9.8333333 | AF17: =SUM('12EG -A- A.E.S.M'!R10) -> 9.3333333 | AI17: =SUM('12EG -A- PROJ. TEC'!R10) -> 0 | AL17: =SUM('12EG -A- A.E.S.Ç'!R10) -> 8.5 | AO17: =SUM('12EG -A- GESTÃO ENF.'!R10) -> 2.8333333 | AP17: N/TRANSITA | AQ17: =AVERAGE(H17:AO17) -> 8.1666667 | AR17: 17 | AS17: M | AT17: =COUNTIF(AS17:AS58,"M") -> 8 | AU17: =COUNTIF(AS17:AS58,"F") -> 34 | AV17: =COUNTIFS(AP17:AP58,"TRANSITA",AS17:AS58,"M") -> 1 | AW17: =COUNTIFS(AP17:AP58,"TRANSITA",AS17:AS58,"F") -> 11 | AX17: =COUNTIFS(AP17:AP58,"N/TRANSITA",AS17:AS58,"M") -> 7 | AY17: =COUNTIFS(AP17:AP58,"N/TRANSITA",AS17:AS58,"F") -> 23 | AZ17: =COUNTIFS(AP17:AP58,"Desistido",AS17:AS58,"M") -> 0 | BA17: =COUNTIFS(AP17:AP58,"Desistida",AS17:AS58,"F") -> 0
B18: 2 | C18: 2150 | D18: Aldina Marta Mavungo Cumbo | H18: =SUM('12EG -A- S.COLECT.'!R11) -> 14 | K18: =SUM('12EG -A- S. MENTAL'!R11) -> 12.166667 | N18: =SUM('12EG -A- EPIDEMIOL.'!R11) -> 4.3333333 | Q18: =SUM('12EG-A- F.A.E'!R11) -> 10 | T18: =SUM('12EG -A- URGÊNCIA'!R11) -> 11 | W18: =SUM('12EG -A- N.D'!R11) -> 16.333333 | Z18: =SUM('12EG -A- A.E.P.M.C'!R11) -> 18.166667 | AC18: =SUM('12EG -A- TEC. ENFER'!R11) -> 14.433333 | AF18: =SUM('12EG -A- A.E.S.M'!R11) -> 15 | AI18: =SUM('12EG -A- PROJ. TEC'!R11) -> 16.666667 | AL18: =SUM('12EG -A- A.E.S.Ç'!R11) -> 10.666667 | AO18: =SUM('12EG -A- GESTÃO ENF.'!R11) -> 10.833333 | AP18: N/TRANSITA | AQ18: =AVERAGE(H18:AO18) -> 12.8 | AR18: 17 | AS18: F | AT18: =SUM(AT17:AU17) -> 42 | AV18: =SUM(AV17:AW17) -> 12 | AX18: =SUM(AX17:AY17) -> 30 | AZ18: =SUM(AZ17:BA17) -> 0
B19: 3 | C19: 1791 | D19: Alice Malonda Lubota Macaia | H19: =SUM('12EG -A- S.COLECT.'!R12) -> 14 | K19: =SUM('12EG -A- S. MENTAL'!R12) -> 15.833333 | N19: =SUM('12EG -A- EPIDEMIOL.'!R12) -> 15 | Q19: =SUM('12EG-A- F.A.E'!R12) -> 8.3333333 | T19: =SUM('12EG -A- URGÊNCIA'!R12) -> 11 | W19: =SUM('12EG -A- N.D'!R12) -> 16.833333 | Z19: =SUM('12EG -A- A.E.P.M.C'!R12) -> 17.833333 | AC19: =SUM('12EG -A- TEC. ENFER'!R12) -> 13.1 | AF19: =SUM('12EG -A- A.E.S.M'!R12) -> 9.3333333 | AI19: =SUM('12EG -A- PROJ. TEC'!R12) -> 17 | AL19: =SUM('12EG -A- A.E.S.Ç'!R12) -> 13.333333 | AO19: =SUM('12EG -A- GESTÃO ENF.'!R12) -> 11.5 | AP19: N/TRANSITA | AQ19: =AVERAGE(H19:AO19) -> 13.591667 | AR19: 17 | AS19: F
B20: 4 | C20: 2623 | D20: Angelina Kambo Macosso | H20: =SUM('12EG -A- S.COLECT.'!R13) -> 14 | K20: =SUM('12EG -A- S. MENTAL'!R13) -> 14.833333 | N20: =SUM('12EG -A- EPIDEMIOL.'!R13) -> 10.333333 | Q20: =SUM('12EG-A- F.A.E'!R13) -> 11.333333 | T20: =SUM('12EG -A- URGÊNCIA'!R13) -> 11 | W20: =SUM('12EG -A- N.D'!R13) -> 17.333333 | Z20: =SUM('12EG -A- A.E.P.M.C'!R13) -> 17.833333 | AC20: =SUM('12EG -A- TEC. ENFER'!R13) -> 12 | AF20: =SUM('12EG -A- A.E.S.M'!R13) -> 15.666667 | AI20: =SUM('12EG -A- PROJ. TEC'!R13) -> 16.666667 | AL20: =SUM('12EG -A- A.E.S.Ç'!R13) -> 14 | AO20: =SUM('12EG -A- GESTÃO ENF.'!R13) -> 11.166667 | AP20: TRANSITA | AQ20: =AVERAGE(H20:AO20) -> 13.847222 | AR20: 17 | AS20: F
B21: 5 | C21: 1818 | D21: Belma Da C. Ngaca Bernardo | H21: =SUM('12EG -A- S.COLECT.'!R14) -> 14 | K21: =SUM('12EG -A- S. MENTAL'!R14) -> 20 | N21: =SUM('12EG -A- EPIDEMIOL.'!R14) -> 17.333333 | Q21: =SUM('12EG-A- F.A.E'!R14) -> 12.666667 | T21: =SUM('12EG -A- URGÊNCIA'!R14) -> 18.666667 | W21: =SUM('12EG -A- N.D'!R14) -> 18.5 | Z21: =SUM('12EG -A- A.E.P.M.C'!R14) -> 19.666667 | AC21: =SUM('12EG -A- TEC. ENFER'!R14) -> 17.5 | AF21: =SUM('12EG -A- A.E.S.M'!R14) -> 14.833333 | AI21: =SUM('12EG -A- PROJ. TEC'!R14) -> 17.666667 | AL21: =SUM('12EG -A- A.E.S.Ç'!R14) -> 14.333333 | AO21: =SUM('12EG -A- GESTÃO ENF.'!R14) -> 13.5 | AP21: TRANSITA | AQ21: =AVERAGE(H21:AO21) -> 16.555556 | AR21: 18 | AS21: F
B22: 6 | C22: 1974 | D22: Carolina Teresa Joana Chingui | H22: =SUM('12EG -A- S.COLECT.'!R15) -> 14 | K22: =SUM('12EG -A- S. MENTAL'!R15) -> 13.333333 | N22: =SUM('12EG -A- EPIDEMIOL.'!R15) -> 12.666667 | Q22: =SUM('12EG-A- F.A.E'!R15) -> 10.333333 | T22: =SUM('12EG -A- URGÊNCIA'!R15) -> 10.666667 | W22: =SUM('12EG -A- N.D'!R15) -> 14.166667 | Z22: =SUM('12EG -A- A.E.P.M.C'!R15) -> 14.166667 | AC22: =SUM('12EG -A- TEC. ENFER'!R15) -> 14.5 | AF22: =SUM('12EG -A- A.E.S.M'!R15) -> 14.333333 | AI22: =SUM('12EG -A- PROJ. TEC'!R15) -> 16 | AL22: =SUM('12EG -A- A.E.S.Ç'!R15) -> 12.333333 | AO22: =SUM('12EG -A- GESTÃO ENF.'!R15) -> 8.1666667 | AP22: N/TRANSITA | AQ22: =AVERAGE(H22:AO22) -> 12.888889 | AR22: 17 | AS22: F
B23: 7 | C23: 2051 | D23: Celma Cecília Macaia Gomes | H23: =SUM('12EG -A- S.COLECT.'!R16) -> 14 | K23: =SUM('12EG -A- S. MENTAL'!R16) -> 15.166667 | N23: =SUM('12EG -A- EPIDEMIOL.'!R16) -> 11.333333 | Q23: =SUM('12EG-A- F.A.E'!R16) -> 10.666667 | T23: =SUM('12EG -A- URGÊNCIA'!R16) -> 13.333333 | W23: =SUM('12EG -A- N.D'!R16) -> 16.333333 | Z23: =SUM('12EG -A- A.E.P.M.C'!R16) -> 18.5 | AC23: =SUM('12EG -A- TEC. ENFER'!R16) -> 13.833333 | AF23: =SUM('12EG -A- A.E.S.M'!R16) -> 14.833333 | AI23: =SUM('12EG -A- PROJ. TEC'!R16) -> 18.333333 | AL23: =SUM('12EG -A- A.E.S.Ç'!R16) -> 13.666667 | AO23: =SUM('12EG -A- GESTÃO ENF.'!R16) -> 11.666667 | AP23: TRANSITA | AQ23: =AVERAGE(H23:AO23) -> 14.305556 | AR23: 17 | AS23: F
B24: 8 | C24: 2230 | D24: Dádiva Ermelinda Gabriel Barros | H24: =SUM('12EG -A- S.COLECT.'!R17) -> 14 | K24: =SUM('12EG -A- S. MENTAL'!R17) -> 12 | N24: =SUM('12EG -A- EPIDEMIOL.'!R17) -> 10.333333 | Q24: =SUM('12EG-A- F.A.E'!R17) -> 6.6666667 | T24: =SUM('12EG -A- URGÊNCIA'!R17) -> 10.833333 | W24: =SUM('12EG -A- N.D'!R17) -> 12.5 | Z24: =SUM('12EG -A- A.E.P.M.C'!R17) -> 16.333333 | AC24: =SUM('12EG -A- TEC. ENFER'!R17) -> 9.6666667 | AF24: =SUM('12EG -A- A.E.S.M'!R17) -> 9.3333333 | AI24: =SUM('12EG -A- PROJ. TEC'!R17) -> 15.666667 | AL24: =SUM('12EG -A- A.E.S.Ç'!R17) -> 13.166667 | AO24: =SUM('12EG -A- GESTÃO ENF.'!R17) -> 9.8333333 | AP24: N/TRANSITA | AQ24: =AVERAGE(H24:AO24) -> 11.694444 | AR24: 18 | AS24: F
B25: 9 | C25: 1774 | D25: Daniel Quendo João | H25: =SUM('12EG -A- S.COLECT.'!R18) -> 14 | K25: =SUM('12EG -A- S. MENTAL'!R18) -> 8.3333333 | N25: =SUM('12EG -A- EPIDEMIOL.'!R18) -> 14.333333 | Q25: =SUM('12EG-A- F.A.E'!R18) -> 1 | T25: =SUM('12EG -A- URGÊNCIA'!R18) -> 0 | W25: =SUM('12EG -A- N.D'!R18) -> 11.833333 | Z25: =SUM('12EG -A- A.E.P.M.C'!R18) -> 8.8333333 | AC25: =SUM('12EG -A- TEC. ENFER'!R18) -> 6.25 | AF25: =SUM('12EG -A- A.E.S.M'!R18) -> 14 | AI25: =SUM('12EG -A- PROJ. TEC'!R18) -> 0 | AL25: =SUM('12EG -A- A.E.S.Ç'!R18) -> 9.6666667 | AO25: =SUM('12EG -A- GESTÃO ENF.'!R18) -> 2.8333333 | AP25: N/TRANSITA | AQ25: =AVERAGE(H25:AO25) -> 7.5902778 | AR25: 18 | AS25: M
B26: 10 | C26: 4446 | D26: Dina De Lourdes Massala | H26: =SUM('12EG -A- S.COLECT.'!R19) -> 14 | K26: =SUM('12EG -A- S. MENTAL'!R19) -> 12.666667 | N26: =SUM('12EG -A- EPIDEMIOL.'!R19) -> 13.333333 | Q26: =SUM('12EG-A- F.A.E'!R19) -> 10.666667 | T26: =SUM('12EG -A- URGÊNCIA'!R19) -> 14.333333 | W26: =SUM('12EG -A- N.D'!R19) -> 15.666667 | Z26: =SUM('12EG -A- A.E.P.M.C'!R19) -> 16.833333 | AC26: =SUM('12EG -A- TEC. ENFER'!R19) -> 12.333333 | AF26: =SUM('12EG -A- A.E.S.M'!R19) -> 13.5 | AI26: =SUM('12EG -A- PROJ. TEC'!R19) -> 17 | AL26: =SUM('12EG -A- A.E.S.Ç'!R19) -> 11.666667 | AO26: =SUM('12EG -A- GESTÃO ENF.'!R19) -> 11 | AP26: TRANSITA | AQ26: =AVERAGE(H26:AO26) -> 13.583333 | AR26: 16 | AS26: F
B27: 11 | C27: 1992 | D27: Esperança C. Bumba Mabiala | H27: =SUM('12EG -A- S.COLECT.'!R20) -> 14 | K27: =SUM('12EG -A- S. MENTAL'!R20) -> 17.333333 | N27: =SUM('12EG -A- EPIDEMIOL.'!R20) -> 12.666667 | Q27: =SUM('12EG-A- F.A.E'!R20) -> 10.666667 | T27: =SUM('12EG -A- URGÊNCIA'!R20) -> 12.166667 | W27: =SUM('12EG -A- N.D'!R20) -> 17.166667 | Z27: =SUM('12EG -A- A.E.P.M.C'!R20) -> 17.666667 | AC27: =SUM('12EG -A- TEC. ENFER'!R20) -> 12.566667 | AF27: =SUM('12EG -A- A.E.S.M'!R20) -> 14.5 | AI27: =SUM('12EG -A- PROJ. TEC'!R20) -> 16.666667 | AL27: =SUM('12EG -A- A.E.S.Ç'!R20) -> 15 | AO27: =SUM('12EG -A- GESTÃO ENF.'!R20) -> 17.5 | AP27: TRANSITA | AQ27: =AVERAGE(H27:AO27) -> 14.825 | AR27: 18 | AS27: F
B28: 12 | C28: 2053 | D28: Esperança Lando Liumba | H28: =SUM('12EG -A- S.COLECT.'!R21) -> 14 | K28: =SUM('12EG -A- S. MENTAL'!R21) -> 14.5 | N28: =SUM('12EG -A- EPIDEMIOL.'!R21) -> 15.333333 | Q28: =SUM('12EG-A- F.A.E'!R21) -> 10.666667 | T28: =SUM('12EG -A- URGÊNCIA'!R21) -> 12.666667 | W28: =SUM('12EG -A- N.D'!R21) -> 16.833333 | Z28: =SUM('12EG -A- A.E.P.M.C'!R21) -> 17.833333 | AC28: =SUM('12EG -A- TEC. ENFER'!R21) -> 16.666667 | AF28: =SUM('12EG -A- A.E.S.M'!R21) -> 15.666667 | AI28: =SUM('12EG -A- PROJ. TEC'!R21) -> 16 | AL28: =SUM('12EG -A- A.E.S.Ç'!R21) -> 14.5 | AO28: =SUM('12EG -A- GESTÃO ENF.'!R21) -> 15.833333 | AP28: TRANSITA | AQ28: =AVERAGE(H28:AO28) -> 15.041667 | AR28: 17 | AS28: F
B29: 13 | C29: 2039 | D29: Ester Mavungo Fuca | H29: =SUM('12EG -A- S.COLECT.'!R22) -> 14 | K29: =SUM('12EG -A- S. MENTAL'!R22) -> 14.166667 | N29: =SUM('12EG -A- EPIDEMIOL.'!R22) -> 12.333333 | Q29: =SUM('12EG-A- F.A.E'!R22) -> 7.15 | T29: =SUM('12EG -A- URGÊNCIA'!R22) -> 11.666667 | W29: =SUM('12EG -A- N.D'!R22) -> 17.666667 | Z29: =SUM('12EG -A- A.E.P.M.C'!R22) -> 17.5 | AC29: =SUM('12EG -A- TEC. ENFER'!R22) -> 14.533333 | AF29: =SUM('12EG -A- A.E.S.M'!R22) -> 14.666667 | AI29: =SUM('12EG -A- PROJ. TEC'!R22) -> 15.333333 | AL29: =SUM('12EG -A- A.E.S.Ç'!R22) -> 11.333333 | AO29: =SUM('12EG -A- GESTÃO ENF.'!R22) -> 11.166667 | AP29: N/TRANSITA | AQ29: =AVERAGE(H29:AO29) -> 13.459722 | AR29: 17 | AS29: F | AU29: MÁXIMA | AV29: =MAX(AQ17:AQ58) -> 16.555556
B30: 14 | C30: 1942 | D30: Eufemia Maria Goma Ventena | H30: =SUM('12EG -A- S.COLECT.'!R23) -> 14 | K30: =SUM('12EG -A- S. MENTAL'!R23) -> 14.666667 | N30: =SUM('12EG -A- EPIDEMIOL.'!R23) -> 11.666667 | Q30: =SUM('12EG-A- F.A.E'!R23) -> 8.6666667 | T30: =SUM('12EG -A- URGÊNCIA'!R23) -> 10.166667 | W30: =SUM('12EG -A- N.D'!R23) -> 14.666667 | Z30: =SUM('12EG -A- A.E.P.M.C'!R23) -> 18.5 | AC30: =SUM('12EG -A- TEC. ENFER'!R23) -> 12.166667 | AF30: =SUM('12EG -A- A.E.S.M'!R23) -> 15.333333 | AI30: =SUM('12EG -A- PROJ. TEC'!R23) -> 17.666667 | AL30: =SUM('12EG -A- A.E.S.Ç'!R23) -> 13.333333 | AO30: =SUM('12EG -A- GESTÃO ENF.'!R23) -> 16.166667 | AP30: N/TRANSITA | AQ30: =AVERAGE(H30:AO30) -> 13.916667 | AR30: 18 | AS30: F
B31: 15 | C31: 2612 | D31: Eulália Buanga Bembe Alfredo | H31: =SUM('12EG -A- S.COLECT.'!R24) -> 14 | K31: =SUM('12EG -A- S. MENTAL'!R24) -> 15.833333 | N31: =SUM('12EG -A- EPIDEMIOL.'!R24) -> 4 | Q31: =SUM('12EG-A- F.A.E'!R24) -> 11.666667 | T31: =SUM('12EG -A- URGÊNCIA'!R24) -> 11 | W31: =SUM('12EG -A- N.D'!R24) -> 17.166667 | Z31: =SUM('12EG -A- A.E.P.M.C'!R24) -> 19.666667 | AC31: =SUM('12EG -A- TEC. ENFER'!R24) -> 14.566667 | AF31: =SUM('12EG -A- A.E.S.M'!R24) -> 15.833333 | AI31: =SUM('12EG -A- PROJ. TEC'!R24) -> 17.333333 | AL31: =SUM('12EG -A- A.E.S.Ç'!R24) -> 13 | AO31: =SUM('12EG -A- GESTÃO ENF.'!R24) -> 14.5 | AP31: N/TRANSITA | AQ31: =AVERAGE(H31:AO31) -> 14.047222 | AR31: 17 | AS31: F | AU31: NOME DO/A ALUNO/A | AX31: Madalena Simba Pemba Miguel
B32: 16 | C32: 2041 | D32: Eva De Araújo Mambo | H32: =SUM('12EG -A- S.COLECT.'!R25) -> 14 | K32: =SUM('12EG -A- S. MENTAL'!R25) -> 13.833333 | N32: =SUM('12EG -A- EPIDEMIOL.'!R25) -> 12.333333 | Q32: =SUM('12EG-A- F.A.E'!R25) -> 8.3333333 | T32: =SUM('12EG -A- URGÊNCIA'!R25) -> 13 | W32: =SUM('12EG -A- N.D'!R25) -> 13.666667 | Z32: =SUM('12EG -A- A.E.P.M.C'!R25) -> 17.333333 | AC32: =SUM('12EG -A- TEC. ENFER'!R25) -> 13 | AF32: =SUM('12EG -A- A.E.S.M'!R25) -> 14.666667 | AI32: =SUM('12EG -A- PROJ. TEC'!R25) -> 17.333333 | AL32: =SUM('12EG -A- A.E.S.Ç'!R25) -> 12.666667 | AO32: =SUM('12EG -A- GESTÃO ENF.'!R25) -> 12 | AP32: N/TRANSITA | AQ32: =AVERAGE(H32:AO32) -> 13.513889 | AR32: 18 | AS32: F | AU32: IDADE: | AV32: 17
B33: 17 | C33: 2596 | D33: Fátima B. Puila Cassombe | H33: =SUM('12EG -A- S.COLECT.'!R26) -> 14 | K33: =SUM('12EG -A- S. MENTAL'!R26) -> 14.666667 | N33: =SUM('12EG -A- EPIDEMIOL.'!R26) -> 8 | Q33: =SUM('12EG-A- F.A.E'!R26) -> 10 | T33: =SUM('12EG -A- URGÊNCIA'!R26) -> 14.333333 | W33: =SUM('12EG -A- N.D'!R26) -> 15.833333 | Z33: =SUM('12EG -A- A.E.P.M.C'!R26) -> 18.333333 | AC33: =SUM('12EG -A- TEC. ENFER'!R26) -> 13.866667 | AF33: =SUM('12EG -A- A.E.S.M'!R26) -> 14.5 | AI33: =SUM('12EG -A- PROJ. TEC'!R26) -> 17.333333 | AL33: =SUM('12EG -A- A.E.S.Ç'!R26) -> 13.333333 | AO33: =SUM('12EG -A- GESTÃO ENF.'!R26) -> 11.166667 | AP33: N/TRANSITA | AQ33: =AVERAGE(H33:AO33) -> 13.780556 | AR33: 17 | AS33: F
B34: 18 | C34: 2082 | D34: Filomena Lelo Tembo Chibuango | H34: =SUM('12EG -A- S.COLECT.'!R27) -> 14 | K34: =SUM('12EG -A- S. MENTAL'!R27) -> 18.833333 | N34: =SUM('12EG -A- EPIDEMIOL.'!R27) -> 13.666667 | Q34: =SUM('12EG-A- F.A.E'!R27) -> 8.6666667 | T34: =SUM('12EG -A- URGÊNCIA'!R27) -> 11.666667 | W34: =SUM('12EG -A- N.D'!R27) -> 13.833333 | Z34: =SUM('12EG -A- A.E.P.M.C'!R27) -> 16.833333 | AC34: =SUM('12EG -A- TEC. ENFER'!R27) -> 15.166667 | AF34: =SUM('12EG -A- A.E.S.M'!R27) -> 14.666667 | AI34: =SUM('12EG -A- PROJ. TEC'!R27) -> 17.666667 | AL34: =SUM('12EG -A- A.E.S.Ç'!R27) -> 13 | AO34: =SUM('12EG -A- GESTÃO ENF.'!R27) -> 12.166667 | AP34: N/TRANSITA | AQ34: =AVERAGE(H34:AO34) -> 14.180556 | AR34: 17 | AS34: F
B35: 19 | C35: 1936 | D35: Helena Da C. Bumba Bilendo | H35: =SUM('12EG -A- S.COLECT.'!R28) -> 14 | K35: =SUM('12EG -A- S. MENTAL'!R28) -> 15 | N35: =SUM('12EG -A- EPIDEMIOL.'!R28) -> 16 | Q35: =SUM('12EG-A- F.A.E'!R28) -> 10 | T35: =SUM('12EG -A- URGÊNCIA'!R28) -> 9.5 | W35: =SUM('12EG -A- N.D'!R28) -> 16 | Z35: =SUM('12EG -A- A.E.P.M.C'!R28) -> 17.833333 | AC35: =SUM('12EG -A- TEC. ENFER'!R28) -> 10.666667 | AF35: =SUM('12EG -A- A.E.S.M'!R28) -> 15.166667 | AI35: =SUM('12EG -A- PROJ. TEC'!R28) -> 15.666667 | AL35: =SUM('12EG -A- A.E.S.Ç'!R28) -> 14.333333 | AO35: =SUM('12EG -A- GESTÃO ENF.'!R28) -> 10.833333 | AP35: N/TRANSITA | AQ35: =AVERAGE(H35:AO35) -> 13.75 | AR35: 18 | AS35: F
B36: 20 | C36: 2107 | D36: Helena Nzuzi Lembe Gimbi | H36: =SUM('12EG -A- S.COLECT.'!R29) -> 14 | K36: =SUM('12EG -A- S. MENTAL'!R29) -> 10 | N36: =SUM('12EG -A- EPIDEMIOL.'!R29) -> 13 | Q36: =SUM('12EG-A- F.A.E'!R29) -> 0 | T36: =SUM('12EG -A- URGÊNCIA'!R29) -> 9.3333333 | W36: =SUM('12EG -A- N.D'!R29) -> 11 | Z36: =SUM('12EG -A- A.E.P.M.C'!R29) -> 13.333333 | AC36: =SUM('12EG -A- TEC. ENFER'!R29) -> 8.8333333 | AF36: =SUM('12EG -A- A.E.S.M'!R29) -> 9.3333333 | AI36: =SUM('12EG -A- PROJ. TEC'!R29) -> 5.6666667 | AL36: =SUM('12EG -A- A.E.S.Ç'!R29) -> 0 | AO36: =SUM('12EG -A- GESTÃO ENF.'!R29) -> 9.6666667 | AP36: N/TRANSITA | AQ36: =AVERAGE(H36:AO36) -> 8.6805556 | AR36: 17 | AS36: F
B37: 21 | C37: 2477 | D37: Helena Pemba António Brás | H37: =SUM('12EG -A- S.COLECT.'!R30) -> 14 | K37: =SUM('12EG -A- S. MENTAL'!R30) -> 16.166667 | N37: =SUM('12EG -A- EPIDEMIOL.'!R30) -> 12.666667 | Q37: =SUM('12EG-A- F.A.E'!R30) -> 10 | T37: =SUM('12EG -A- URGÊNCIA'!R30) -> 10.166667 | W37: =SUM('12EG -A- N.D'!R30) -> 15.833333 | Z37: =SUM('12EG -A- A.E.P.M.C'!R30) -> 19.166667 | AC37: =SUM('12EG -A- TEC. ENFER'!R30) -> 14.066667 | AF37: =SUM('12EG -A- A.E.S.M'!R30) -> 16 | AI37: =SUM('12EG -A- PROJ. TEC'!R30) -> 17.333333 | AL37: =SUM('12EG -A- A.E.S.Ç'!R30) -> 14.333333 | AO37: =SUM('12EG -A- GESTÃO ENF.'!R30) -> 15.666667 | AP37: TRANSITA | AQ37: =AVERAGE(H37:AO37) -> 14.616667 | AR37: 17 | AS37: F
B38: 22 | C38: 1928 | D38: Isabel Mariana Miala | H38: =SUM('12EG -A- S.COLECT.'!R31) -> 14 | K38: =SUM('12EG -A- S. MENTAL'!R31) -> 13.333333 | N38: =SUM('12EG -A- EPIDEMIOL.'!R31) -> 8.6666667 | Q38: =SUM('12EG-A- F.A.E'!R31) -> 10.666667 | T38: =SUM('12EG -A- URGÊNCIA'!R31) -> 11.666667 | W38: =SUM('12EG -A- N.D'!R31) -> 13.666667 | Z38: =SUM('12EG -A- A.E.P.M.C'!R31) -> 12.666667 | AC38: =SUM('12EG -A- TEC. ENFER'!R31) -> 13 | AF38: =SUM('12EG -A- A.E.S.M'!R31) -> 14 | AI38: =SUM('12EG -A- PROJ. TEC'!R31) -> 17 | AL38: =SUM('12EG -A- A.E.S.Ç'!R31) -> 12.666667 | AO38: =SUM('12EG -A- GESTÃO ENF.'!R31) -> 5.8333333 | AP38: N/TRANSITA | AQ38: =AVERAGE(H38:AO38) -> 12.263889 | AR38: 18 | AS38: F
B39: 23 | C39: 2313 | D39: Isabel Nhongo Luambo Estevão | H39: =SUM('12EG -A- S.COLECT.'!R32) -> 14 | K39: =SUM('12EG -A- S. MENTAL'!R32) -> 12.5 | N39: =SUM('12EG -A- EPIDEMIOL.'!R32) -> 13 | Q39: =SUM('12EG-A- F.A.E'!R32) -> 10.5 | T39: =SUM('12EG -A- URGÊNCIA'!R32) -> 11.333333 | W39: =SUM('12EG -A- N.D'!R32) -> 16.5 | Z39: =SUM('12EG -A- A.E.P.M.C'!R32) -> 18 | AC39: =SUM('12EG -A- TEC. ENFER'!R32) -> 13.266667 | AF39: =SUM('12EG -A- A.E.S.M'!R32) -> 13.5 | AI39: =SUM('12EG -A- PROJ. TEC'!R32) -> 17.666667 | AL39: =SUM('12EG -A- A.E.S.Ç'!R32) -> 15.5 | AO39: =SUM('12EG -A- GESTÃO ENF.'!R32) -> 12.5 | AP39: TRANSITA | AQ39: =AVERAGE(H39:AO39) -> 14.022222 | AR39: 17 | AS39: M
B40: 24 | C40: 2525 | D40: Jerónimo Yombe Vemba | H40: =SUM('12EG -A- S.COLECT.'!R33) -> 14 | K40: =SUM('12EG -A- S. MENTAL'!R33) -> 9 | N40: =SUM('12EG -A- EPIDEMIOL.'!R33) -> 17.333333 | Q40: =SUM('12EG-A- F.A.E'!R33) -> 4 | T40: =SUM('12EG -A- URGÊNCIA'!R33) -> 3 | W40: =SUM('12EG -A- N.D'!R33) -> 8.8333333 | Z40: =SUM('12EG -A- A.E.P.M.C'!R33) -> 10 | AC40: =SUM('12EG -A- TEC. ENFER'!R33) -> 9 | AF40: =SUM('12EG -A- A.E.S.M'!R33) -> 14 | AI40: =SUM('12EG -A- PROJ. TEC'!R33) -> 9.3333333 | AL40: =SUM('12EG -A- A.E.S.Ç'!R33) -> 10 | AO40: =SUM('12EG -A- GESTÃO ENF.'!R33) -> 1.8333333 | AP40: N/TRANSITA | AQ40: =AVERAGE(H40:AO40) -> 9.1944444 | AR40: 17 | AS40: M
B41: 25 | C41: 2163 | D41: Joana Dadiva Ndembe Bueia | H41: =SUM('12EG -A- S.COLECT.'!R34) -> 14 | K41: =SUM('12EG -A- S. MENTAL'!R34) -> 17 | N41: =SUM('12EG -A- EPIDEMIOL.'!R34) -> 9.3333333 | Q41: =SUM('12EG-A- F.A.E'!R34) -> 13.333333 | T41: =SUM('12EG -A- URGÊNCIA'!R34) -> 18.666667 | W41: =SUM('12EG -A- N.D'!R34) -> 18.833333 | Z41: =SUM('12EG -A- A.E.P.M.C'!R34) -> 19.5 | AC41: =SUM('12EG -A- TEC. ENFER'!R34) -> 14.166667 | AF41: =SUM('12EG -A- A.E.S.M'!R34) -> 14.666667 | AI41: =SUM('12EG -A- PROJ. TEC'!R34) -> 18 | AL41: =SUM('12EG -A- A.E.S.Ç'!R34) -> 15.333333 | AO41: =SUM('12EG -A- GESTÃO ENF.'!R34) -> 11.833333 | AP41: TRANSITA | AQ41: =AVERAGE(H41:AO41) -> 15.388889 | AR41: 17 | AS41: F
B42: 26 | C42: 2042 | D42: João Sidónio António | H42: =SUM('12EG -A- S.COLECT.'!R35) -> 14 | K42: =SUM('12EG -A- S. MENTAL'!R35) -> 15 | N42: =SUM('12EG -A- EPIDEMIOL.'!R35) -> 13 | Q42: =SUM('12EG-A- F.A.E'!R35) -> 8.3333333 | T42: =SUM('12EG -A- URGÊNCIA'!R35) -> 4.6666667 | W42: =SUM('12EG -A- N.D'!R35) -> 13 | Z42: =SUM('12EG -A- A.E.P.M.C'!R35) -> 12.5 | AC42: =SUM('12EG -A- TEC. ENFER'!R35) -> 7.3333333 | AF42: =SUM('12EG -A- A.E.S.M'!R35) -> 14.166667 | AI42: =SUM('12EG -A- PROJ. TEC'!R35) -> 10.333333 | AL42: =SUM('12EG -A- A.E.S.Ç'!R35) -> 11.666667 | AO42: =SUM('12EG -A- GESTÃO ENF.'!R35) -> 9.3333333 | AP42: N/TRANSITA | AQ42: =AVERAGE(H42:AO42) -> 11.111111 | AR42: 18 | AS42: M
B43: 27 | C43: 1975 | D43: Jocelma Badila Da Costa | H43: =SUM('12EG -A- S.COLECT.'!R36) -> 14 | K43: =SUM('12EG -A- S. MENTAL'!R36) -> 12.166667 | N43: =SUM('12EG -A- EPIDEMIOL.'!R36) -> 5 | Q43: =SUM('12EG-A- F.A.E'!R36) -> 8.3333333 | T43: =SUM('12EG -A- URGÊNCIA'!R36) -> 11.333333 | W43: =SUM('12EG -A- N.D'!R36) -> 15.333333 | Z43: =SUM('12EG -A- A.E.P.M.C'!R36) -> 18.333333 | AC43: =SUM('12EG -A- TEC. ENFER'!R36) -> 10.166667 | AF43: =SUM('12EG -A- A.E.S.M'!R36) -> 15.333333 | AI43: =SUM('12EG -A- PROJ. TEC'!R36) -> 16.666667 | AL43: =SUM('12EG -A- A.E.S.Ç'!R36) -> 10 | AO43: =SUM('12EG -A- GESTÃO ENF.'!R36) -> 7.3333333 | AP43: N/TRANSITA | AQ43: =AVERAGE(H43:AO43) -> 12 | AR43: 17 | AS43: F
B44: 28 | C44: 1915 | D44: José Francisco Malonda Kibodo | H44: =SUM('12EG -A- S.COLECT.'!R37) -> 14 | K44: =SUM('12EG -A- S. MENTAL'!R37) -> 13.5 | N44: =SUM('12EG -A- EPIDEMIOL.'!R37) -> 6.6666667 | Q44: =SUM('12EG-A- F.A.E'!R37) -> 10 | T44: =SUM('12EG -A- URGÊNCIA'!R37) -> 7 | W44: =SUM('12EG -A- N.D'!R37) -> 15.5 | Z44: =SUM('12EG -A- A.E.P.M.C'!R37) -> 15 | AC44: =SUM('12EG -A- TEC. ENFER'!R37) -> 11.3 | AF44: =SUM('12EG -A- A.E.S.M'!R37) -> 15.666667 | AI44: =SUM('12EG -A- PROJ. TEC'!R37) -> 18.333333 | AL44: =SUM('12EG -A- A.E.S.Ç'!R37) -> 9.6666667 | AO44: =SUM('12EG -A- GESTÃO ENF.'!R37) -> 12.333333 | AP44: N/TRANSITA | AQ44: =AVERAGE(H44:AO44) -> 12.413889 | AR44: 17 | AS44: M
... B58: 42 | C58: 2096 | D58: Zulmira Buanga António | H58: =SUM('12EG -A- S.COLECT.'!R51) -> 14 | K58: =SUM('12EG -A- S. MENTAL'!R51) -> 15 | N58: =SUM('12EG -A- EPIDEMIOL.'!R51) -> 10.666667 | Q58: =SUM('12EG-A- F.A.E'!R51) -> 8.3333333 | T58: =SUM('12EG -A- URGÊNCIA'!R51) -> 8.3333333 | W58: =SUM('12EG -A- N.D'!R51) -> 14.5 | Z58: =SUM('12EG -A- A.E.P.M.C'!R51) -> 11.666667 | AC58: =SUM('12EG -A- TEC. ENFER'!R51) -> 12.333333 | AF58: =SUM('12EG -A- A.E.S.M'!R51) -> 12.666667 | AI58: =SUM('12EG -A- PROJ. TEC'!R51) -> 15.666667 | AL58: =SUM('12EG -A- A.E.S.Ç'!R51) -> 13 | AO58: =SUM('12EG -A- GESTÃO ENF.'!R51) -> 10.666667 | AP58: N/TRANSITA | AQ58: =AVERAGE(H58:AO58) -> 12.236111 | AR58: 17 | AS58: F
...

Sheet 12EG -A- S.COLECT.
A1: INSTITUTO TÉCNICO PRIVADO DE SAÚDE JOMORAIS
B4: Classe: 12ª | L4: Disciplina: Saúde Colectiva | Y4: Ano Lectivo: 2025/2026
B6: Turno: Vespertino | L6: Turma: A | Y6: Curso:ENFERMAGEM GERAL
B7: MINI-PAUTA - SAÚDE
B8: Nº | C8: Nome do (a) Aluno (a) | D8: FALTAS | F8: Avaliações/I Trimestre | L8: OBS | M8: Avaliações/II Trimestre | S8: OBS | T8: Avaliações/III Trimestre | Z8: MFD | AA8: 40% MFD | AB8: EXAME ESCRITO | AC8: 60% NEE | AD8: MF | AE8: OBS
D9: J | E9: I | F9: MAC | G9: NPP | H9: NPR1 | I9: NPT | J9: NPR2 | K9: MT1 | M9: MAC | N9: NPP | O9: NPR1 | P9: NPT | Q9: NPR2 | R9: MT2 | T9: MAC | U9: NPP | V9: NPR1 | W9: NPT | X9: NPR2 | Y9: MT3
B10: 1 | C10: Alberto Filipe Massiala | F10: 13 | G10: 20 | I10: 11 | K10: =AVERAGE(F10,MAX(G10:H10),MAX(I10:J10)) -> 14.666667 | L10: =IF(K10>=10,"TRANSITA","N/TRANSITA") -> TRANSITA | M10: 14 | N10: 14 | P10: 14 | R10: =AVERAGE(M10,MAX(N10:O10),MAX(P10:Q10)) -> 14 | S10: =IF(R10>=10,"TRANSITA","N/TRANSITA") -> TRANSITA | W10: =AVERAGE(T10:U10) -> #DIV/0! | Y10: =AVERAGE(T10,MAX(U10:V10),MAX(W10:X10)) -> #DIV/0! | Z10: =SUM(K10,R10,Y10)/3 -> #DIV/0! | AA10: =Z10*0.4 -> #DIV/0! | AC10: =AB10*0.6 -> 0 | AD10: =AVERAGE(AA10+AC10) -> #DIV/0! | AE10: =IF(AD10>=10,"APROVADO/A","REPROVADO/A") -> #DIV/0!
B11: 2 | C11: Aldina Marta Mavungo Cumbo | F11: 19 | G11: 20 | I11: 20 | K11: =AVERAGE(F11,MAX(G11:H11),MAX(I11:J11)) -> 19.666667 | L11: =IF(K11>=10,"TRANSITA","N/TRANSITA") -> TRANSITA | M11: 14 | N11: 14 | P11: 14 | R11: =AVERAGE(M11,MAX(N11:O11),MAX(P11:Q11)) -> 14 | S11: =IF(R11>=10,"TRANSITA","N/TRANSITA") -> TRANSITA | W11: =AVERAGE(T11:U11) -> #DIV/0! | Y11: =AVERAGE(T11,MAX(U11:V11),MAX(W11:X11)) -> #DIV/0! | Z11: =SUM(K11,R11,Y11)/3 -> #DIV/0! | AA11: =Z11*0.4 -> #DIV/0! | AC11: =AB11*0.6 -> 0 | AD11: =AVERAGE(AA11+AC11) -> #DIV/0! | AE11: =IF(AD11>=10,"APROVADO/A","REPROVADO/A") -> #DIV/0!
B12: 3 | C12: Alice Malonda Lubota Macaia | F12: 18 | G12: 20 | I12: 17.5 | K12: =AVERAGE(F12,MAX(G12:H12),MAX(I12:J12)) -> 18.5 | L12: =IF(K12>=10,"TRANSITA","N/TRANSITA") -> TRANSITA | M12: 14 | N12: 14 | P12: 14 | R12: =AVERAGE(M12,MAX(N12:O12),MAX(P12:Q12)) -> 14 | S12: =IF(R12>=10,"TRANSITA","N/TRANSITA") -> TRANSITA | W12: =AVERAGE(T12:U12) -> #DIV/0! | Y12: =AVERAGE(T12,MAX(U12:V12),MAX(W12:X12)) -> #DIV/0! | Z12: =SUM(K12,R12,Y12)/3 -> #DIV/0! | AA12: =Z12*0.4 -> #DIV/0! | AC12: =AB12*0.6 -> 0 | AD12: =AVERAGE(AA12+AC12) -> #DIV/0! | AE12: =IF(AD12>=10,"APROVADO/A","REPROVADO/A") -> #DIV/0!
B13: 4 | C13: Angelina Kambo Macosso | F13: 17 | G13: 20 | I13: 20 | K13: =AVERAGE(F13,MAX(G13:H13),MAX(I13:J13)) -> 19 | L13: =IF(K13>=10,"TRANSITA","N/TRANSITA") -> TRANSITA | M13: 14 | N13: 14 | P13: 14 | R13: =AVERAGE(M13,MAX(N13:O13),MAX(P13:Q13)) -> 14 | S13: =IF(R13>=10,"TRANSITA","N/TRANSITA") -> TRANSITA | W13: =AVERAGE(T13:U13) -> #DIV/0! | Y13: =AVERAGE(T13,MAX(U13:V13),MAX(W13:X13)) -> #DIV/0! | Z13: =SUM(K13,R13,Y13)/3 -> #DIV/0! | AA13: =Z13*0.4 -> #DIV/0! | AC13: =AB13*0.6 -> 0 | AD13: =AVERAGE(AA13+AC13) -> #DIV/0! | AE13: =IF(AD13>=10,"APROVADO/A","REPROVADO/A") -> #DIV/0!
B14: 5 | C14: Belma Da C. Ngaca Bernardo | F14: 19 | G14: 20 | I14: 20 | K14: =AVERAGE(F14,MAX(G14:H14),MAX(I14:J14)) -> 19.666667 | L14: =IF(K14>=10,"TRANSITA","N/TRANSITA") -> TRANSITA | M14: 14 | N14: 14 | P14: 14 | R14: =AVERAGE(M14,MAX(N14:O14),MAX(P14:Q14)) -> 14 | S14: =IF(R14>=10,"TRANSITA","N/TRANSITA") -> TRANSITA | W14: =AVERAGE(T14:U14) -> #DIV/0! | Y14: =AVERAGE(T14,MAX(U14:V14),MAX(W14:X14)) -> #DIV/0! | Z14: =SUM(K14,R14,Y14)/3 -> #DIV/0! | AA14: =Z14*0.4 -> #DIV/0! | AC14: =AB14*0.6 -> 0 | AD14: =AVERAGE(AA14+AC14) -> #DIV/0! | AE14: =IF(AD14>=10,"APROVADO/A","REPROVADO/A") -> #DIV/0!
B15: 6 | C15: Carolina Teresa Joana Chingui | F15: 16 | G15: 15 | I15: 12.5 | K15: =AVERAGE(F15,MAX(G15:H15),MAX(I15:J15)) -> 14.5 | L15: =IF(K15>=10,"TRANSITA","N/TRANSITA") -> TRANSITA | M15: 14 | N15: 14 | P15: 14 | R15: =AVERAGE(M15,MAX(N15:O15),MAX(P15:Q15)) -> 14 | S15: =IF(R15>=10,"TRANSITA","N/TRANSITA") -> TRANSITA | W15: =AVERAGE(T15:U15) -> #DIV/0! | Y15: =AVERAGE(T15,MAX(U15:V15),MAX(W15:X15)) -> #DIV/0! | Z15: =SUM(K15,R15,Y15)/3 -> #DIV/0! | AA15: =Z15*0.4 -> #DIV/0! | AC15: =AB15*0.6 -> 0 | AD15: =AVERAGE(AA15+AC15) -> #DIV/0! | AE15: =IF(AD15>=10,"APROVADO/A","REPROVADO/A") -> #DIV/0!
B16: 7 | C16: Celma Cecília Macaia Gomes | F16: 16 | G16: 20 | I16: 20 | K16: =AVERAGE(F16,MAX(G16:H16),MAX(I16:J16)) -> 18.666667 | L16: =IF(K16>=10,"TRANSITA","N/TRANSITA") -> TRANSITA | M16: 14 | N16: 14 | P16: 14 | R16: =AVERAGE(M16,MAX(N16:O16),MAX(P16:Q16)) -> 14 | S16: =IF(R16>=10,"TRANSITA","N/TRANSITA") -> TRANSITA | W16: =AVERAGE(T16:U16) -> #DIV/0! | Y16: =AVERAGE(T16,MAX(U16:V16),MAX(W16:X16)) -> #DIV/0! | Z16: =SUM(K16,R16,Y16)/3 -> #DIV/0! | AA16: =Z16*0.4 -> #DIV/0! | AC16: =AB16*0.6 -> 0 | AD16: =AVERAGE(AA16+AC16) -> #DIV/0! | AE16: =IF(AD16>=10,"APROVADO/A","REPROVADO/A") -> #DIV/0!
B17: 8 | C17: Dádiva Ermelinda Gabriel Barros | F17: 16 | G17: 17.5 | I17: 11 | K17: =AVERAGE(F17,MAX(G17:H17),MAX(I17:J17)) -> 14.833333 | L17: =IF(K17>=10,"TRANSITA","N/TRANSITA") -> TRANSITA | M17: 14 | N17: 14 | P17: 14 | R17: =AVERAGE(M17,MAX(N17:O17),MAX(P17:Q17)) -> 14 | S17: =IF(R17>=10,"TRANSITA","N/TRANSITA") -> TRANSITA | W17: =AVERAGE(T17:U17) -> #DIV/0! | Y17: =AVERAGE(T17,MAX(U17:V17),MAX(W17:X17)) -> #DIV/0! | Z17: =SUM(K17,R17,Y17)/3 -> #DIV/0! | AA17: =Z17*0.4 -> #DIV/0! | AC17: =AB17*0.6 -> 0 | AD17: =AVERAGE(AA17+AC17) -> #DIV/0! | AE17: =IF(AD17>=10,"APROVADO/A","REPROVADO/A") -> #DIV/0!
B18: 9 | C18: Daniel Quendo João | F18: 17 | G18: 20 | I18: 18 | K18: =AVERAGE(F18,MAX(G18:H18),MAX(I18:J18)) -> 18.333333 | L18: =IF(K18>=10,"TRANSITA","N/TRANSITA") -> TRANSITA | M18: 14 | N18: 14 | P18: 14 | R18: =AVERAGE(M18,MAX(N18:O18),MAX(P18:Q18)) -> 14 | S18: =IF(R18>=10,"TRANSITA","N/TRANSITA") -> TRANSITA | W18: =AVERAGE(T18:U18) -> #DIV/0! | Y18: =AVERAGE(T18,MAX(U18:V18),MAX(W18:X18)) -> #DIV/0! | Z18: =SUM(K18,R18,Y18)/3 -> #DIV/0! | AA18: =Z18*0.4 -> #DIV/0! | AC18: =AB18*0.6 -> 0 | AD18: =AVERAGE(AA18+AC18) -> #DIV/0! | AE18: =IF(AD18>=10,"APROVADO/A","REPROVADO/A") -> #DIV/0!
B19: 10 | C19: Dina De Lourdes Massala | F19: 18 | G19: 20 | I19: 20 | K19: =AVERAGE(F19,MAX(G19:H19),MAX(I19:J19)) -> 19.333333 | L19: =IF(K19>=10,"TRANSITA","N/TRANSITA") -> TRANSITA | M19: 14 | N19: 14 | P19: 14 | R19: =AVERAGE(M19,MAX(N19:O19),MAX(P19:Q19)) -> 14 | S19: =IF(R19>=10,"TRANSITA","N/TRANSITA") -> TRANSITA | W19: =AVERAGE(T19:U19) -> #DIV/0! | Y19: =AVERAGE(T19,MAX(U19:V19),MAX(W19:X19)) -> #DIV/0! | Z19: =SUM(K19,R19,Y19)/3 -> #DIV/0! | AA19: =Z19*0.4 -> #DIV/0! | AC19: =AB19*0.6 -> 0 | AD19: =AVERAGE(AA19+AC19) -> #DIV/0! | AE19: =IF(AD19>=10,"APROVADO/A","REPROVADO/A") -> #DIV/0!
B20: 11 | C20: Esperança C. Bumba Mabiala | F20: 18 | G20: 20 | I20: 18 | K20: =AVERAGE(F20,MAX(G20:H20),MAX(I20:J20)) -> 18.666667 | L20: =IF(K20>=10,"TRANSITA","N/TRANSITA") -> TRANSITA | M20: 14 | N20: 14 | P20: 14 | R20: =AVERAGE(M20,MAX(N20:O20),MAX(P20:Q20)) -> 14 | S20: =IF(R20>=10,"TRANSITA","N/TRANSITA") -> TRANSITA | W20: =AVERAGE(T20:U20) -> #DIV/0! | Y20: =AVERAGE(T20,MAX(U20:V20),MAX(W20:X20)) -> #DIV/0! | Z20: =SUM(K20,R20,Y20)/3 -> #DIV/0! | AA20: =Z20*0.4 -> #DIV/0! | AC20: =AB20*0.6 -> 0 | AD20: =AVERAGE(AA20+AC20) -> #DIV/0! | AE20: =IF(AD20>=10,"APROVADO/A","REPROVADO/A") -> #DIV/0!
B21: 12 | C21: Esperança Lando Liumba | F21: 15 | G21: 20 | I21: 11 | K21: =AVERAGE(F21,MAX(G21:H21),MAX(I21:J21)) -> 15.333333 | L21: =IF(K21>=10,"TRANSITA","N/TRANSITA") -> TRANSITA | M21: 14 | N21: 14 | P21: 14 | R21: =AVERAGE(M21,MAX(N21:O21),MAX(P21:Q21)) -> 14 | S21: =IF(R21>=10,"TRANSITA","N/TRANSITA") -> TRANSITA | W21: =AVERAGE(T21:U21) -> #DIV/0! | Y21: =AVERAGE(T21,MAX(U21:V21),MAX(W21:X21)) -> #DIV/0! | Z21: =SUM(K21,R21,Y21)/3 -> #DIV/0! | AA21: =Z21*0.4 -> #DIV/0! | AC21: =AB21*0.6 -> 0 | AD21: =AVERAGE(AA21+AC21) -> #DIV/0! | AE21: =IF(AD21>=10,"APROVADO/A","REPROVADO/A") -> #DIV/0!
... B40: 31 | C40: Lídia Pedro Puna | F40: 17 | G40: 20 | I40: 10.5 | K40: =AVERAGE(F40,MAX(G40:H40),MAX(I40:J40)) -> 15.833333 | L40: =IF(K40>=10,"TRANSITA","N/TRANSITA") -> TRANSITA | M40: 14 | N40: 14 | P40: 14 | R40: =AVERAGE(M40,MAX(N40:O40),MAX(P40:Q40)) -> 14 | S40: =IF(R40>=10,"TRANSITA","N/TRANSITA") -> TRANSITA | W40: =AVERAGE(T40:U40) -> #DIV/0! | Y40: =AVERAGE(T40,MAX(U40:V40),MAX(W40:X40)) -> #DIV/0! | Z40: =SUM(K40,R40,Y40)/3 -> #DIV/0! | AA40: =Z40*0.4 -> #DIV/0! | AC40: =AB40*0.6 -> 0 | AD40: =AVERAGE(AA40+AC40) -> #DIV/0! | AE40: =IF(AD40>=10,"APROVADO/A","REPROVADO/A") -> #DIV/0!
B41: 32 | C41: Lúcia Dicuela Bangala Muanda | F41: 15 | G41: 20 | I41: 15 | K41: =AVERAGE(F41,MAX(G41:H41),MAX(I41:J41)) -> 16.666667 | L41: =IF(K41>=10,"TRANSITA","N/TRANSITA") -> TRANSITA | M41: 14 | N41: 14 | P41: 14 | R41: =AVERAGE(M41,MAX(N41:O41),MAX(P41:Q41)) -> 14 | S41: =IF(R41>=10,"TRANSITA","N/TRANSITA") -> TRANSITA | W41: =AVERAGE(T41:U41) -> #DIV/0! | Y41: =AVERAGE(T41,MAX(U41:V41),MAX(W41:X41)) -> #DIV/0! | Z41: =SUM(K41,R41,Y41)/3 -> #DIV/0! | AA41: =Z41*0.4 -> #DIV/0! | AC41: =AB41*0.6 -> 0 | AD41: =AVERAGE(AA41+AC41) -> #DIV/0!
B42: 33 | C42: Manuela Lopes Moio Capita | F42: 17 | G42: 20 | I42: 20 | K42: =AVERAGE(F42,MAX(G42:H42),MAX(I42:J42)) -> 19 | L42: =IF(K42>=10,"TRANSITA","N/TRANSITA") -> TRANSITA | M42: 14 | N42: 14 | P42: 14 | R42: =AVERAGE(M42,MAX(N42:O42),MAX(P42:Q42)) -> 14 | S42: =IF(R42>=10,"TRANSITA","N/TRANSITA") -> TRANSITA | W42: =AVERAGE(T42:U42) -> #DIV/0! | Y42: =AVERAGE(T42,MAX(U42:V42),MAX(W42:X42)) -> #DIV/0! | Z42: =SUM(K42,R42,Y42)/3 -> #DIV/0! | AA42: =Z42*0.4 -> #DIV/0! | AC42: =AB42*0.6 -> 0 | AD42: =AVERAGE(AA42+AC42) -> #DIV/0! | AE42: =IF(AD42>=10,"APROVADO/A","REPROVADO/A") -> #DIV/0!
B43: 34 | C43: Maria Da Conceição Buca Yoba | F43: 18 | G43: 20 | I43: 18.5 | K43: =AVERAGE(F43,MAX(G43:H43),MAX(I43:J43)) -> 18.833333 | L43: =IF(K43>=10,"TRANSITA","N/TRANSITA") -> TRANSITA | M43: 14 | N43: 14 | P43: 14 | R43: =AVERAGE(M43,MAX(N43:O43),MAX(P43:Q43)) -> 14 | S43: =IF(R43>=10,"TRANSITA","N/TRANSITA") -> TRANSITA | W43: =AVERAGE(T43:U43) -> #DIV/0! | Y43: =AVERAGE(T43,MAX(U43:V43),MAX(W43:X43)) -> #DIV/0! | Z43: =SUM(K43,R43,Y43)/3 -> #DIV/0! | AA43: =Z43*0.4 -> #DIV/0! | AC43: =AB43*0.6 -> 0 | AD43: =AVERAGE(AA43+AC43) -> #DIV/0! | AE43: =IF(AD43>=10,"APROVADO/A","REPROVADO/A") -> #DIV/0!
B44: 35 | C44: Maria Rosa Brás | F44: 16 | G44: 17.5 | I44: 20 | K44: =AVERAGE(F44,MAX(G44:H44),MAX(I44:J44)) -> 17.833333 | L44: =IF(K44>=10,"TRANSITA","N/TRANSITA") -> TRANSITA | M44: 14 | N44: 14 | P44: 14 | R44: =AVERAGE(M44,MAX(N44:O44),MAX(P44:Q44)) -> 14 | S44: =IF(R44>=10,"TRANSITA","N/TRANSITA") -> TRANSITA | W44: =AVERAGE(T44:U44) -> #DIV/0! | Y44: =AVERAGE(T44,MAX(U44:V44),MAX(W44:X44)) -> #DIV/0! | Z44: =SUM(K44,R44,Y44)/3 -> #DIV/0! | AA44: =Z44*0.4 -> #DIV/0! | AC44: =AB44*0.6 -> 0 | AD44: =AVERAGE(AA44+AC44) -> #DIV/0! | AE44: =IF(AD44>=10,"APROVADO/A","REPROVADO/A") -> #DIV/0!
B45: 36 | C45: Marta Gabriel Muela | F45: 13 | G45: 13.5 | I45: 15 | K45: =AVERAGE(F45,MAX(G45:H45),MAX(I45:J45)) -> 13.833333 | L45: =IF(K45>=10,"TRANSITA","N/TRANSITA") -> TRANSITA | M45: 14 | N45: 14 | P45: 14 | R45: =AVERAGE(M45,MAX(N45:O45),MAX(P45:Q45)) -> 14 | S45: =IF(R45>=10,"TRANSITA","N/TRANSITA") -> TRANSITA | W45: =AVERAGE(T45:U45) -> #DIV/0! | Y45: =AVERAGE(T45,MAX(U45:V45),MAX(W45:X45)) -> #DIV/0! | Z45: =SUM(K45,R45,Y45)/3 -> #DIV/0! | AA45: =Z45*0.4 -> #DIV/0! | AC45: =AB45*0.6 -> 0 | AD45: =AVERAGE(AA45+AC45) -> #DIV/0! | AE45: =IF(AD45>=10,"APROVADO/A","REPROVADO/A") -> #DIV/0!
B46: 37 | C46: Martina Cumba Muendo Nvemba | F46: 18 | G46: 20 | I46: 20 | K46: =AVERAGE(F46,MAX(G46:H46),MAX(I46:J46)) -> 19.333333 | L46: =IF(K46>=10,"TRANSITA","N/TRANSITA") -> TRANSITA | M46: 14 | N46: 14 | P46: 14 | R46: =AVERAGE(M46,MAX(N46:O46),MAX(P46:Q46)) -> 14 | S46: =IF(R46>=10,"TRANSITA","N/TRANSITA") -> TRANSITA | W46: =AVERAGE(T46:U46) -> #DIV/0! | Y46: =AVERAGE(T46,MAX(U46:V46),MAX(W46:X46)) -> #DIV/0! | Z46: =SUM(K46,R46,Y46)/3 -> #DIV/0! | AA46: =Z46*0.4 -> #DIV/0! | AC46: =AB46*0.6 -> 0 | AD46: =AVERAGE(AA46+AC46) -> #DIV/0! | AE46: =IF(AD46>=10,"APROVADO/A","REPROVADO/A") -> #DIV/0!
B47: 38 | C47: Raimundo Luís Gime Bussaco | F47: 19 | G47: 20 | I47: 20 | K47: =AVERAGE(F47,MAX(G47:H47),MAX(I47:J47)) -> 19.666667 | L47: =IF(K47>=10,"TRANSITA","N/TRANSITA") -> TRANSITA | M47: 14 | N47: 14 | P47: 14 | R47: =AVERAGE(M47,MAX(N47:O47),MAX(P47:Q47)) -> 14 | S47: =IF(R47>=10,"TRANSITA","N/TRANSITA") -> TRANSITA | W47: =AVERAGE(T47:U47) -> #DIV/0! | Y47: =AVERAGE(T47,MAX(U47:V47),MAX(W47:X47)) -> #DIV/0! | Z47: =SUM(K47,R47,Y47)/3 -> #DIV/0! | AA47: =Z47*0.4 -> #DIV/0! | AC47: =AB47*0.6 -> 0 | AD47: =AVERAGE(AA47+AC47) -> #DIV/0! | AE47: =IF(AD47>=10,"APROVADO/A","REPROVADO/A") -> #DIV/0!
B48: 39 | C48: Rosária Domingas Mangovo | F48: 17 | G48: 20 | I48: 10 | K48: =AVERAGE(F48,MAX(G48:H48),MAX(I48:J48)) -> 15.666667 | L48: =IF(K48>=10,"TRANSITA","N/TRANSITA") -> TRANSITA | M48: 14 | N48: 14 | P48: 14 | R48: =AVERAGE(M48,MAX(N48:O48),MAX(P48:Q48)) -> 14 | S48: =IF(R48>=10,"TRANSITA","N/TRANSITA") -> TRANSITA | W48: =AVERAGE(T48:U48) -> #DIV/0! | Y48: =AVERAGE(T48,MAX(U48:V48),MAX(W48:X48)) -> #DIV/0! | Z48: =SUM(K48,R48,Y48)/3 -> #DIV/0! | AA48: =Z48*0.4 -> #DIV/0! | AC48: =AB48*0.6 -> 0 | AD48: =AVERAGE(AA48+AC48) -> #DIV/0! | AE48: =IF(AD48>=10,"APROVADO/A","REPROVADO/A") -> #DIV/0!
B49: 40 | C49: Silvia Amada Castelão Morais | D49: 0 | F49: 15 | G49: 13 | I49: 17 | K49: =AVERAGE(F49,MAX(G49:H49),MAX(I49:J49)) -> 15 | L49: =IF(K49>=10,"TRANSITA","N/TRANSITA") -> TRANSITA | M49: 14 | N49: 14 | P49: 14 | R49: =AVERAGE(M49,MAX(N49:O49),MAX(P49:Q49)) -> 14 | S49: =IF(R49>=10,"TRANSITA","N/TRANSITA") -> TRANSITA | W49: =AVERAGE(T49:U49) -> #DIV/0! | Y49: =AVERAGE(T49,MAX(U49:V49),MAX(W49:X49)) -> #DIV/0! | Z49: =SUM(K49,R49,Y49)/3 -> #DIV/0! | AA49: =Z49*0.4 -> #DIV/0! | AC49: =AB49*0.6 -> 0 | AD49: =AVERAGE(AA49+AC49) -> #DIV/0! | AE49: =IF(AD49>=10,"APROVADO/A","REPROVADO/A") -> #DIV/0!
