Workbook

Sheet 1ºT-11ª-A-PAUTA
A1: INSTITUTO TÉCNICO PRIVADO DE SAÚDE JOMORAIS
B7: PAUTA DE APROVEITAMENTO ESCOLAR
C8: ÁREA DE FORMAÇÃO: SAÚDE
H9: 11ª CLASSE | M9: CURSO: ANÁLISES CLÍNICAS | AE9: PERÍODO: VESPERTINO
B10: O Director do Instituto | AE10: 1º TRIMESTRE | AL10: MF: | AM10: =SUM(AM12,AM11) -> 44
B11: ________________________________________ | H11: TURMA: | J11: A | AL11: M | AM11: =COUNTIF(AS17:AS60,"M") -> 11 | AP11: 46003
B12: GABRIEL PRÓSPERO MABIALA | AD12: ANO LECTIVO: 2025/2026 | AL12: F | AM12: =COUNTIF(AS17:AS60,"F") -> 33
B13: DATA______/______/2025
B14: Nº | C14: Nº PROC | D14: NOME | E14: DISCIPLINA A REPETIR | F14: L. Port. | I14: Mat. | L14: Biol. | O14: Inglês | R14: Qca Org. | U14: Microbiol. | X14: Hemat. | AA14: Imunol. | AD14: Urinol. | AG14: Parasitol. | AJ14: Ed. Física | AM14: A.F.H | AP14: OBS | AQ14: MÉDIA | AR14: Idade | AS14: Género | AT14: DADOS ESTATÍSTICOS
F15: FALTAS | H15: MT1º | I15: FALTAS | K15: MT1º | L15: FALTAS | N15: MT1º | O15: FALTAS | Q15: MT1º | R15: FALTAS | T15: MT1º | U15: FALTAS | W15: MT1º | X15: FALTAS | Z15: MT1º | AA15: FALTAS | AC15: MT1º | AD15: FALTAS | AF15: MT1º | AG15: FALTAS | AI15: MT1º | AJ15: FALTAS | AL15: MT1º | AM15: FALTAS | AO15: MT1º | AT15: MATRICULADOS | AV15: TRANSITA | AX15: N/TRANSITA | AZ15: Desistido/a
F16: J | G16: I | I16: J | J16: I | L16: J | M16: I | O16: J | P16: I | R16: J | S16: I | U16: J | V16: I | X16: J | Y16: I | AA16: J | AB16: I | AD16: J | AE16: I | AG16: J | AH16: I | AJ16: J | AK16: I | AM16: J | AN16: I | AT16: M | AU16: F | AV16: M | AW16: F | AX16: M | AY16: F | AZ16: M | BA16: F
B17: 1 | C17: 4121 | D17: Abrão Gomes | H17: =SUM('11CL-AC-A-L PORT'!J9) -> 13.333333 | K17: =SUM('11CL-AC-A-MAT'!J9) -> 10.333333 | N17: =SUM('11CL-AC-A-BIOL'!J9) -> 12.666667 | Q17: =SUM('11CL-AC-A-INGLES'!J9) -> 13.333333 | T17: =SUM('11CL-AC-A-QCA ORG.'!J9) -> 11.333333 | W17: =SUM('11CL-AC-A-MICROBIOL'!J9) -> 12.166667 | Z17: =SUM('11CL-AC-A-HEMAT I'!J9) -> 11.333333 | AC17: =SUM('11CL-AC-A-IMUNOL.'!J9) -> 16.166667 | AF17: =SUM('11CL-AC-A-URINOL.'!J9) -> 12.166667 | AI17: =SUM('11CL-AC-A-PRASITOL.'!J9) -> 10.666667 | AL17: =SUM('11CL-AC-A-ED. FIS'!J9) -> 14 | AO17: =SUM('11CL-AC-A-AFH'!J9) -> 13.666667 | AP17: N/TRANSITA | AQ17: =AVERAGE(H17:AO17) -> 12.597222 | AR17: 17 | AS17: M | AT17: =COUNTIF(AS17:AS60,"M") -> 11 | AU17: =COUNTIF(AS17:AS60,"F") -> 33 | AV17: =COUNTIFS(AP17:AP60,"Transita",AS17:AS60,"M") -> 4 | AW17: =COUNTIFS(AP17:AP60,"Transita",AS17:AS60,"F") -> 5 | AX17: =COUNTIFS(AP17:AP60,"N/Transita",AS17:AS60,"M") -> 7 | AY17: =COUNTIFS(AP17:AP60,"N/Transita",AS17:AS60,"F") -> 27 | AZ17: =COUNTIFS(AP17:AP60,"DESISTIDO",AS17:AS60,"M") -> 0 | BA17: =COUNTIFS(AP17:AP60,"DESISTIDA",AS17:AS60,"F") -> 1
B18: 2 | C18: 2862 | D18: Agostinho Mbaki Baza | H18: =SUM('11CL-AC-A-L PORT'!J10) -> 15.166667 | K18: =SUM('11CL-AC-A-MAT'!J10) -> 19.333333 | N18: =SUM('11CL-AC-A-BIOL'!J10) -> 16.333333 | Q18: =SUM('11CL-AC-A-INGLES'!J10) -> 19 | T18: =SUM('11CL-AC-A-QCA ORG.'!J10) -> 17.333333 | W18: =SUM('11CL-AC-A-MICROBIOL'!J10) -> 14 | Z18: =SUM('11CL-AC-A-HEMAT I'!J10) -> 16.5 | AC18: =SUM('11CL-AC-A-IMUNOL.'!J10) -> 18.333333 | AF18: =SUM('11CL-AC-A-URINOL.'!J10) -> 16.5 | AI18: =SUM('11CL-AC-A-PRASITOL.'!J10) -> 17.333333 | AL18: =SUM('11CL-AC-A-ED. FIS'!J10) -> 13 | AO18: =SUM('11CL-AC-A-AFH'!J10) -> 15.666667 | AP18: TRANSITA | AQ18: =AVERAGE(H18:AO18) -> 16.541667 | AR18: 16 | AS18: M | AT18: =SUM(AT17:AU17) -> 44 | AV18: =SUM(AV16:AW17) -> 9 | AX18: =SUM(AX16:AY17) -> 34 | AZ18: =SUM(AZ16:BA17) -> 1
B19: 3 | C19: 3183 | D19: Albertina Vumbi Bazunga | H19: =SUM('11CL-AC-A-L PORT'!J11) -> 9.6666667 | K19: =SUM('11CL-AC-A-MAT'!J11) -> 11.666667 | N19: =SUM('11CL-AC-A-BIOL'!J11) -> 11.333333 | Q19: =SUM('11CL-AC-A-INGLES'!J11) -> 15.333333 | T19: =SUM('11CL-AC-A-QCA ORG.'!J11) -> 12.333333 | W19: =SUM('11CL-AC-A-MICROBIOL'!J11) -> 14.166667 | Z19: =SUM('11CL-AC-A-HEMAT I'!J11) -> 14 | AC19: =SUM('11CL-AC-A-IMUNOL.'!J11) -> 14.916667 | AF19: =SUM('11CL-AC-A-URINOL.'!J11) -> 13.5 | AI19: =SUM('11CL-AC-A-PRASITOL.'!J11) -> 13 | AL19: =SUM('11CL-AC-A-ED. FIS'!J11) -> 12 | AO19: =SUM('11CL-AC-A-AFH'!J11) -> 11.166667 | AP19: N/TRANSITA | AQ19: =AVERAGE(H19:AO19) -> 12.756944 | AR19: 17 | AS19: F
B20: 4 | C20: 2921 | D20: Alberto Mambo Simba | H20: =SUM('11CL-AC-A-L PORT'!J12) -> 14 | K20: =SUM('11CL-AC-A-MAT'!J12) -> 15.333333 | N20: =SUM('11CL-AC-A-BIOL'!J12) -> 15.666667 | Q20: =SUM('11CL-AC-A-INGLES'!J12) -> 16 | T20: =SUM('11CL-AC-A-QCA ORG.'!J12) -> 15.166667 | W20: =SUM('11CL-AC-A-MICROBIOL'!J12) -> 13.833333 | Z20: =SUM('11CL-AC-A-HEMAT I'!J12) -> 14.666667 | AC20: =SUM('11CL-AC-A-IMUNOL.'!J12) -> 17.416667 | AF20: =SUM('11CL-AC-A-URINOL.'!J12) -> 16.666667 | AI20: =SUM('11CL-AC-A-PRASITOL.'!J12) -> 14 | AL20: =SUM('11CL-AC-A-ED. FIS'!J12) -> 15 | AO20: =SUM('11CL-AC-A-AFH'!J12) -> 13.333333 | AP20: TRANSITA | AQ20: =AVERAGE(H20:AO20) -> 15.090278 | AR20: 17 | AS20: M
B21: 5 | C21: 3551 | D21: Alda Catarina Mamata Balou | H21: =SUM('11CL-AC-A-L PORT'!J13) -> 12.333333 | K21: =SUM('11CL-AC-A-MAT'!J13) -> 10 | N21: =SUM('11CL-AC-A-BIOL'!J13) -> 10 | Q21: =SUM('11CL-AC-A-INGLES'!J13) -> 12.333333 | T21: =SUM('11CL-AC-A-QCA ORG.'!J13) -> 5 | W21: =SUM('11CL-AC-A-MICROBIOL'!J13) -> 11.833333 | Z21: =SUM('11CL-AC-A-HEMAT I'!J13) -> 10.666667 | AC21: =SUM('11CL-AC-A-IMUNOL.'!J13) -> 13 | AF21: =SUM('11CL-AC-A-URINOL.'!J13) -> 13.666667 | AI21: =SUM('11CL-AC-A-PRASITOL.'!J13) -> 11.166667 | AL21: =SUM('11CL-AC-A-ED. FIS'!J13) -> 10 | AO21: =SUM('11CL-AC-A-AFH'!J13) -> 10 | AP21: N/TRANSITA | AQ21: =AVERAGE(H21:AO21) -> 10.833333 | AR21: 16 | AS21: F
B22: 6 | C22: 3070 | D22: Alice Bitumba Mavungo | H22: =SUM('11CL-AC-A-L PORT'!J14) -> 9.8333333 | K22: =SUM('11CL-AC-A-MAT'!J14) -> 10.666667 | N22: =SUM('11CL-AC-A-BIOL'!J14) -> 10.333333 | Q22: =SUM('11CL-AC-A-INGLES'!J14) -> 13 | T22: =SUM('11CL-AC-A-QCA ORG.'!J14) -> 10.166667 | W22: =SUM('11CL-AC-A-MICROBIOL'!J14) -> 13.833333 | Z22: =SUM('11CL-AC-A-HEMAT I'!J14) -> 12 | AC22: =SUM('11CL-AC-A-IMUNOL.'!J14) -> 15.166667 | AF22: =SUM('11CL-AC-A-URINOL.'!J14) -> 14.25 | AI22: =SUM('11CL-AC-A-PRASITOL.'!J14) -> 10.666667 | AL22: =SUM('11CL-AC-A-ED. FIS'!J14) -> 13 | AO22: =SUM('11CL-AC-A-AFH'!J14) -> 8.5 | AP22: N/TRANSITA | AQ22: =AVERAGE(H22:AO22) -> 11.784722 | AR22: 17 | AS22: F
B23: 7 | C23: 2939 | D23: Amélia Chibamba Chiama | H23: =SUM('11CL-AC-A-L PORT'!J15) -> 10.833333 | K23: =SUM('11CL-AC-A-MAT'!J15) -> 10 | N23: =SUM('11CL-AC-A-BIOL'!J15) -> 13.666667 | Q23: =SUM('11CL-AC-A-INGLES'!J15) -> 13 | T23: =SUM('11CL-AC-A-QCA ORG.'!J15) -> 15.666667 | W23: =SUM('11CL-AC-A-MICROBIOL'!J15) -> 15.166667 | Z23: =SUM('11CL-AC-A-HEMAT I'!J15) -> 10.833333 | AC23: =SUM('11CL-AC-A-IMUNOL.'!J15) -> 14 | AF23: =SUM('11CL-AC-A-URINOL.'!J15) -> 15.5 | AI23: =SUM('11CL-AC-A-PRASITOL.'!J15) -> 12.666667 | AL23: =SUM('11CL-AC-A-ED. FIS'!J15) -> 14 | AO23: =SUM('11CL-AC-A-AFH'!J15) -> 12.833333 | AP23: N/TRANSITA | AQ23: =AVERAGE(H23:AO23) -> 13.180556 | AR23: 14 | AS23: F | AU23: MÁXIMA | AV23: =MAX(AQ17:AQ60) -> 17.451389
B24: 8 | C24: 2833 | D24: Ana De Jesus Custódio Sambo | H24: =SUM('11CL-AC-A-L PORT'!J16) -> 13.166667 | K24: =SUM('11CL-AC-A-MAT'!J16) -> 11.666667 | N24: =SUM('11CL-AC-A-BIOL'!J16) -> 10 | Q24: =SUM('11CL-AC-A-INGLES'!J16) -> 18 | T24: =SUM('11CL-AC-A-QCA ORG.'!J16) -> 17.333333 | W24: =SUM('11CL-AC-A-MICROBIOL'!J16) -> 12.5 | Z24: =SUM('11CL-AC-A-HEMAT I'!J16) -> 12.666667 | AC24: =SUM('11CL-AC-A-IMUNOL.'!J16) -> 13.833333 | AF24: =SUM('11CL-AC-A-URINOL.'!J16) -> 13.666667 | AI24: =SUM('11CL-AC-A-PRASITOL.'!J16) -> 9.6666667 | AL24: =SUM('11CL-AC-A-ED. FIS'!J16) -> 12 | AO24: =SUM('11CL-AC-A-AFH'!J16) -> 10.666667 | AP24: N/TRANSITA | AQ24: =AVERAGE(H24:AO24) -> 12.930556 | AR24: 16 | AS24: F
B25: 9 | C25: 3750 | D25: Ana Soca Deca Luba | H25: =SUM('11CL-AC-A-L PORT'!J17) -> 10.5 | K25: =SUM('11CL-AC-A-MAT'!J17) -> 4.3333333 | N25: =SUM('11CL-AC-A-BIOL'!J17) -> 7.6666667 | Q25: =SUM('11CL-AC-A-INGLES'!J17) -> 14.666667 | T25: =SUM('11CL-AC-A-QCA ORG.'!J17) -> 5.8333333 | W25: =SUM('11CL-AC-A-MICROBIOL'!J17) -> 12.166667 | Z25: =SUM('11CL-AC-A-HEMAT I'!J17) -> 9.6666667 | AC25: =SUM('11CL-AC-A-IMUNOL.'!J17) -> 13.666667 | AF25: =SUM('11CL-AC-A-URINOL.'!J17) -> 4 | AI25: =SUM('11CL-AC-A-PRASITOL.'!J17) -> 11.5 | AL25: =SUM('11CL-AC-A-ED. FIS'!J17) -> 14 | AO25: =SUM('11CL-AC-A-AFH'!J17) -> 10.666667 | AP25: N/TRANSITA | AQ25: =AVERAGE(H25:AO25) -> 9.8888889 | AR25: 17 | AS25: F | AU25: NOME DO/A ALUNO/A | AX25: Joana Bundo Fernandes
B26: 10 | C26: 3013 | D26: Angelina Buanga Poba | H26: =SUM('11CL-AC-A-L PORT'!J18) -> 12.333333 | K26: =SUM('11CL-AC-A-MAT'!J18) -> 5.6666667 | N26: =SUM('11CL-AC-A-BIOL'!J18) -> 8.3333333 | Q26: =SUM('11CL-AC-A-INGLES'!J18) -> 15.333333 | T26: =SUM('11CL-AC-A-QCA ORG.'!J18) -> 2.6666667 | W26: =SUM('11CL-AC-A-MICROBIOL'!J18) -> 11.5 | Z26: =SUM('11CL-AC-A-HEMAT I'!J18) -> 15.333333 | AC26: =SUM('11CL-AC-A-IMUNOL.'!J18) -> 12.333333 | AF26: =SUM('11CL-AC-A-URINOL.'!J18) -> 12.666667 | AI26: =SUM('11CL-AC-A-PRASITOL.'!J18) -> 10.166667 | AL26: =SUM('11CL-AC-A-ED. FIS'!J18) -> 12 | AO26: =SUM('11CL-AC-A-AFH'!J18) -> 12.5 | AP26: N/TRANSITA | AQ26: =AVERAGE(H26:AO26) -> 10.902778 | AR26: 16 | AS26: M | AU26: IDADE: | AV26: 16
B27: 11 | C27: 3036 | D27: Antoaneta Menga Futi Gime | H27: =SUM('11CL-AC-A-L PORT'!J19) -> 12.333333 | K27: =SUM('11CL-AC-A-MAT'!J19) -> 10.333333 | N27: =SUM('11CL-AC-A-BIOL'!J19) -> 14.666667 | Q27: =SUM('11CL-AC-A-INGLES'!J19) -> 16.333333 | T27: =SUM('11CL-AC-A-QCA ORG.'!J19) -> 12 | W27: =SUM('11CL-AC-A-MICROBIOL'!J19) -> 15 | Z27: =SUM('11CL-AC-A-HEMAT I'!J19) -> 13 | AC27: =SUM('11CL-AC-A-IMUNOL.'!J19) -> 15.083333 | AF27: =SUM('11CL-AC-A-URINOL.'!J19) -> 15.666667 | AI27: =SUM('11CL-AC-A-PRASITOL.'!J19) -> 12.333333 | AL27: =SUM('11CL-AC-A-ED. FIS'!J19) -> 13.333333 | AO27: =SUM('11CL-AC-A-AFH'!J19) -> 9.3333333 | AP27: N/TRANSITA | AQ27: =AVERAGE(H27:AO27) -> 13.284722 | AR27: 17 | AS27: F
B28: 12 | C28: 4217 | D28: Arinalda De Canatividade Prata Bungo | H28: =SUM('11CL-AC-A-L PORT'!J20) -> 13.833333 | K28: =SUM('11CL-AC-A-MAT'!J20) -> 16.333333 | N28: =SUM('11CL-AC-A-BIOL'!J20) -> 15.666667 | Q28: =SUM('11CL-AC-A-INGLES'!J20) -> 16.666667 | T28: =SUM('11CL-AC-A-QCA ORG.'!J20) -> 14 | W28: =SUM('11CL-AC-A-MICROBIOL'!J20) -> 15.333333 | Z28: =SUM('11CL-AC-A-HEMAT I'!J20) -> 15 | AC28: =SUM('11CL-AC-A-IMUNOL.'!J20) -> 17.416667 | AF28: =SUM('11CL-AC-A-URINOL.'!J20) -> 16.333333 | AI28: =SUM('11CL-AC-A-PRASITOL.'!J20) -> 13.5 | AL28: =SUM('11CL-AC-A-ED. FIS'!J20) -> 13 | AO28: =SUM('11CL-AC-A-AFH'!J20) -> 13.166667 | AP28: TRANSITA | AQ28: =AVERAGE(H28:AO28) -> 15.020833 | AR28: 17 | AS28: F
B29: 13 | C29: 3063 | D29: Basílio Araújo Simba Mabiala | H29: =SUM('11CL-AC-A-L PORT'!J21) -> 14.166667 | K29: =SUM('11CL-AC-A-MAT'!J21) -> 17 | N29: =SUM('11CL-AC-A-BIOL'!J21) -> 0 | Q29: =SUM('11CL-AC-A-INGLES'!J21) -> 16.333333 | T29: =SUM('11CL-AC-A-QCA ORG.'!J21) -> 15 | W29: =SUM('11CL-AC-A-MICROBIOL'!J21) -> 16.5 | Z29: =SUM('11CL-AC-A-HEMAT I'!J21) -> 14.166667 | AC29: =SUM('11CL-AC-A-IMUNOL.'!J21) -> 16 | AF29: =SUM('11CL-AC-A-URINOL.'!J21) -> 14.833333 | AI29: =SUM('11CL-AC-A-PRASITOL.'!J21) -> 15.333333 | AL29: =SUM('11CL-AC-A-ED. FIS'!J21) -> 16 | AO29: =SUM('11CL-AC-A-AFH'!J21) -> 15.333333 | AP29: N/TRANSITA | AQ29: =AVERAGE(H29:AO29) -> 14.222222 | AR29: 17 | AS29: M
B30: 14 | C30: 3606 | D30: Carlota Mbungo Conde | H30: =SUM('11CL-AC-A-L PORT'!J22) -> 9.8333333 | K30: =SUM('11CL-AC-A-MAT'!J22) -> 5 | N30: =SUM('11CL-AC-A-BIOL'!J22) -> 10 | Q30: =SUM('11CL-AC-A-INGLES'!J22) -> 10 | T30: =SUM('11CL-AC-A-QCA ORG.'!J22) -> 2.1666667 | W30: =SUM('11CL-AC-A-MICROBIOL'!J22) -> 12.5 | Z30: =SUM('11CL-AC-A-HEMAT I'!J22) -> 11.333333 | AC30: =SUM('11CL-AC-A-IMUNOL.'!J22) -> 11.833333 | AF30: =SUM('11CL-AC-A-URINOL.'!J22) -> 12 | AI30: =SUM('11CL-AC-A-PRASITOL.'!J22) -> 9 | AL30: =SUM('11CL-AC-A-ED. FIS'!J22) -> 11 | AO30: =SUM('11CL-AC-A-AFH'!J22) -> 9.6666667 | AP30: N/TRANSITA | AQ30: =AVERAGE(H30:AO30) -> 9.5277778 | AR30: 17 | AS30: F
B31: 15 | C31: 2798 | D31: Catarina Luemba Makuama | H31: =SUM('11CL-AC-A-L PORT'!J23) -> 10.166667 | K31: =SUM('11CL-AC-A-MAT'!J23) -> 4.6666667 | N31: =SUM('11CL-AC-A-BIOL'!J23) -> 6 | Q31: =SUM('11CL-AC-A-INGLES'!J23) -> 9.6666667 | T31: =SUM('11CL-AC-A-QCA ORG.'!J23) -> 7.6666667 | W31: =SUM('11CL-AC-A-MICROBIOL'!J23) -> 12.666667 | Z31: =SUM('11CL-AC-A-HEMAT I'!J23) -> 9.8333333 | AC31: =SUM('11CL-AC-A-IMUNOL.'!J23) -> 11.5 | AF31: =SUM('11CL-AC-A-URINOL.'!J23) -> 8.5 | AI31: =SUM('11CL-AC-A-PRASITOL.'!J23) -> 4.6666667 | AL31: =SUM('11CL-AC-A-ED. FIS'!J23) -> 13.333333 | AO31: =SUM('11CL-AC-A-AFH'!J23) -> 6 | AP31: N/TRANSITA | AQ31: =AVERAGE(H31:AO31) -> 8.7222222 | AR31: 17 | AS31: M
B32: 16 | C32: 4210 | D32: Cristina Conde Sassi | H32: =SUM('11CL-AC-A-L PORT'!J24) -> 10.833333 | K32: =SUM('11CL-AC-A-MAT'!J24) -> 12 | N32: =SUM('11CL-AC-A-BIOL'!J24) -> 12 | Q32: =SUM('11CL-AC-A-INGLES'!J24) -> 13.666667 | T32: =SUM('11CL-AC-A-QCA ORG.'!J24) -> 8.3333333 | W32: =SUM('11CL-AC-A-MICROBIOL'!J24) -> 12 | Z32: =SUM('11CL-AC-A-HEMAT I'!J24) -> 12.166667 | AC32: =SUM('11CL-AC-A-IMUNOL.'!J24) -> 11.833333 | AF32: =SUM('11CL-AC-A-URINOL.'!J24) -> 12.75 | AI32: =SUM('11CL-AC-A-PRASITOL.'!J24) -> 11 | AL32: =SUM('11CL-AC-A-ED. FIS'!J24) -> 12 | AO32: =SUM('11CL-AC-A-AFH'!J24) -> 8.6666667 | AP32: N/TRANSITA | AQ32: =AVERAGE(H32:AO32) -> 11.4375 | AR32: 14 | AS32: F
B33: 17 | C33: 3422 | D33: Dorcas Milando Dembi | H33: =SUM('11CL-AC-A-L PORT'!J25) -> 12.566667 | K33: =SUM('11CL-AC-A-MAT'!J25) -> 10.333333 | N33: =SUM('11CL-AC-A-BIOL'!J25) -> 11.666667 | Q33: =SUM('11CL-AC-A-INGLES'!J25) -> 16 | T33: =SUM('11CL-AC-A-QCA ORG.'!J25) -> 15.666667 | W33: =SUM('11CL-AC-A-MICROBIOL'!J25) -> 14.333333 | Z33: =SUM('11CL-AC-A-HEMAT I'!J25) -> 11.666667 | AC33: =SUM('11CL-AC-A-IMUNOL.'!J25) -> 13.166667 | AF33: =SUM('11CL-AC-A-URINOL.'!J25) -> 11.166667 | AI33: =SUM('11CL-AC-A-PRASITOL.'!J25) -> 12.833333 | AL33: =SUM('11CL-AC-A-ED. FIS'!J25) -> 14 | AO33: =SUM('11CL-AC-A-AFH'!J25) -> 9.3333333 | AP33: N/TRANSITA | AQ33: =AVERAGE(H33:AO33) -> 12.727778 | AR33: 17 | AS33: F
B34: 18 | C34: 3300 | D34: Elisa Zuzi Bumba Da Silva | H34: =SUM('11CL-AC-A-L PORT'!J26) -> 13.5 | K34: =SUM('11CL-AC-A-MAT'!J26) -> 6.3333333 | N34: =SUM('11CL-AC-A-BIOL'!J26) -> 13.333333 | Q34: =SUM('11CL-AC-A-INGLES'!J26) -> 18.333333 | T34: =SUM('11CL-AC-A-QCA ORG.'!J26) -> 12.5 | W34: =SUM('11CL-AC-A-MICROBIOL'!J26) -> 13.5 | Z34: =SUM('11CL-AC-A-HEMAT I'!J26) -> 11.833333 | AC34: =SUM('11CL-AC-A-IMUNOL.'!J26) -> 12 | AF34: =SUM('11CL-AC-A-URINOL.'!J26) -> 15.666667 | AI34: =SUM('11CL-AC-A-PRASITOL.'!J26) -> 12.166667 | AL34: =SUM('11CL-AC-A-ED. FIS'!J26) -> 14 | AO34: =SUM('11CL-AC-A-AFH'!J26) -> 12.5 | AP34: N/TRANSITA | AQ34: =AVERAGE(H34:AO34) -> 12.972222 | AR34: 17 | AS34: F
B35: 19 | C35: 2224 | D35: Felicidade Muanda Bititi | H35: =SUM('11CL-AC-A-L PORT'!J27) -> 0 | K35: =SUM('11CL-AC-A-MAT'!J27) -> 0 | N35: =SUM('11CL-AC-A-BIOL'!J27) -> 0 | Q35: =SUM('11CL-AC-A-INGLES'!J27) -> 0 | T35: =SUM('11CL-AC-A-QCA ORG.'!J27) -> 0 | W35: =SUM('11CL-AC-A-MICROBIOL'!J27) -> 0 | Z35: =SUM('11CL-AC-A-HEMAT I'!J27) -> 0 | AC35: =SUM('11CL-AC-A-IMUNOL.'!J27) -> 0 | AF35: =SUM('11CL-AC-A-URINOL.'!J27) -> 0 | AI35: =SUM('11CL-AC-A-PRASITOL.'!J27) -> 0 | AL35: =SUM('11CL-AC-A-ED. FIS'!J27) -> 0 | AO35: =SUM('11CL-AC-A-AFH'!J27) -> 11.333333 | AP35: DESISTIDA | AQ35: =AVERAGE(H35:AO35) -> 0.94444444 | AR35: 17 | AS35: F
B36: 20 | C36: 4097 | D36: Fernanda Pedro Tavares | H36: =SUM('11CL-AC-A-L PORT'!J28) -> 12.166667 | K36: =SUM('11CL-AC-A-MAT'!J28) -> 9 | N36: =SUM('11CL-AC-A-BIOL'!J28) -> 12.333333 | Q36: =SUM('11CL-AC-A-INGLES'!J28) -> 15.666667 | T36: =SUM('11CL-AC-A-QCA ORG.'!J28) -> 6 | W36: =SUM('11CL-AC-A-MICROBIOL'!J28) -> 13.833333 | Z36: =SUM('11CL-AC-A-HEMAT I'!J28) -> 7.3333333 | AC36: =SUM('11CL-AC-A-IMUNOL.'!J28) -> 11.833333 | AF36: =SUM('11CL-AC-A-URINOL.'!J28) -> 7.75 | AI36: =SUM('11CL-AC-A-PRASITOL.'!J28) -> 8.3333333 | AL36: =SUM('11CL-AC-A-ED. FIS'!J28) -> 11 | AO36: =SUM('11CL-AC-A-AFH'!J28) -> 8.6666667 | AP36: N/TRANSITA | AQ36: =AVERAGE(H36:AO36) -> 10.326389 | AR36: 17 | AS36: F
B37: 21 | C37: 2806 | D37: Gertrudes Buanga Zuzi | H37: =SUM('11CL-AC-A-L PORT'!J29) -> 10.666667 | K37: =SUM('11CL-AC-A-MAT'!J29) -> 5.6666667 | N37: =SUM('11CL-AC-A-BIOL'!J29) -> 8 | Q37: =SUM('11CL-AC-A-INGLES'!J29) -> 10 | T37: =SUM('11CL-AC-A-QCA ORG.'!J29) -> 4.5 | W37: =SUM('11CL-AC-A-MICROBIOL'!J29) -> 11.833333 | Z37: =SUM('11CL-AC-A-HEMAT I'!J29) -> 10 | AC37: =SUM('11CL-AC-A-IMUNOL.'!J29) -> 9.3333333 | AF37: =SUM('11CL-AC-A-URINOL.'!J29) -> 14.5 | AI37: =SUM('11CL-AC-A-PRASITOL.'!J29) -> 10.833333 | AL37: =SUM('11CL-AC-A-ED. FIS'!J29) -> 0 | AO37: =SUM('11CL-AC-A-AFH'!J29) -> 10 | AP37: N/TRANSITA | AQ37: =AVERAGE(H37:AO37) -> 8.7777778 | AR37: 18 | AS37: M
B38: 22 | C38: 2923 | D38: Helena Kalembela Miguel | H38: =SUM('11CL-AC-A-L PORT'!J30) -> 13 | K38: =SUM('11CL-AC-A-MAT'!J30) -> 15.666667 | N38: =SUM('11CL-AC-A-BIOL'!J30) -> 11 | Q38: =SUM('11CL-AC-A-INGLES'!J30) -> 14 | T38: =SUM('11CL-AC-A-QCA ORG.'!J30) -> 14.333333 | W38: =SUM('11CL-AC-A-MICROBIOL'!J30) -> 13.333333 | Z38: =SUM('11CL-AC-A-HEMAT I'!J30) -> 13 | AC38: =SUM('11CL-AC-A-IMUNOL.'!J30) -> 16.5 | AF38: =SUM('11CL-AC-A-URINOL.'!J30) -> 15.333333 | AI38: =SUM('11CL-AC-A-PRASITOL.'!J30) -> 11.666667 | AL38: =SUM('11CL-AC-A-ED. FIS'!J30) -> 11 | AO38: =SUM('11CL-AC-A-AFH'!J30) -> 6.5 | AP38: N/TRANSITA | AQ38: =AVERAGE(H38:AO38) -> 12.944444 | AR38: 16 | AS38: F
... B60: 44 | C60: 3628 | D60: Teresa Gertrudes Luzia Tati | H60: =SUM('11CL-AC-A-L PORT'!J52) -> 11.566667 | K60: =SUM('11CL-AC-A-MAT'!J52) -> 6.3333333 | N60: =SUM('11CL-AC-A-BIOL'!J52) -> 10 | Q60: =SUM('11CL-AC-A-INGLES'!J52) -> 13 | T60: =SUM('11CL-AC-A-QCA ORG.'!J52) -> 14 | W60: =SUM('11CL-AC-A-MICROBIOL'!J52) -> 12.833333 | Z60: =SUM('11CL-AC-A-HEMAT I'!J52) -> 9.8333333 | AC60: =SUM('11CL-AC-A-IMUNOL.'!J52) -> 15.333333 | AF60: =SUM('11CL-AC-A-URINOL.'!J52) -> 10.333333 | AI60: =SUM('11CL-AC-A-PRASITOL.'!J52) -> 8.5 | AL60: =SUM('11CL-AC-A-ED. FIS'!J52) -> 11 | AO60: =SUM('11CL-AC-A-AFH'!J52) -> 10 | AP60: N/TRANSITA | AQ60: =AVERAGE(H60:AO60) -> 11.061111 | AR60: 16 | AS60: F
B61: DATA DO CONSELHO DE TURMA______/______/2025
B64: A Directora de Turma | AA64: O Sibdirector Pedagógico
B65: _____________________________________
B66: RUTH DEMBI QUIFOCO ZEMBO | AA66: ALBERTO SASSA TATI

Sheet 2ºT-11ª-A-PAUTA
A1: INSTITUTO TÉCNICO PRIVADO DE SAÚDE JOMORAIS
B7: PAUTA DE APROVEITAMENTO ESCOLAR
C8: ÁREA DE FORMAÇÃO: SAÚDE
H9: 11ª CLASSE | M9: CURSO: ANÁLISES CLÍNICAS | AE9: PERÍODO: VESPERTINO
B10: O Director do Instituto | AE10: 2º TRIMESTRE | AL10: MF: | AM10: =SUM(AM12,AM11) -> 44
B11: ________________________________________ | H11: TURMA: | J11: A | AL11: M | AM11: =COUNTIF(AS17:AS60,"M") -> 11 | AP11: 46118
B12: GABRIEL PRÓSPERO MABIALA | AD12: ANO LECTIVO: 2025/2026 | AL12: F | AM12: =COUNTIF(AS17:AS60,"F") -> 33
B13: DATA______/______/2026
B14: Nº | C14: Nº PROC | D14: NOME | E14: DISCIPLINA A REPETIR | F14: L. Port. | I14: Mat. | L14: Biol. | O14: Inglês | R14: Qca Org. | U14: Microbiol. | X14: Hemat. | AA14: Imunol. | AD14: Urinol. | AG14: Parasitol. | AJ14: Ed. Física | AM14: A.F.H | AP14: OBS | AQ14: MÉDIA | AR14: Idade | AS14: Género | AT14: DADOS ESTATÍSTICOS
F15: FALTAS | H15: MT2º | I15: FALTAS | K15: MT2º | L15: FALTAS | N15: MT2º | O15: FALTAS | Q15: MT2º | R15: FALTAS | T15: MT2º | U15: FALTAS | W15: MT2º | X15: FALTAS | Z15: MT2º | AA15: FALTAS | AC15: MT2º | AD15: FALTAS | AF15: MT2º | AG15: FALTAS | AI15: MT2º | AJ15: FALTAS | AL15: MT2º | AM15: FALTAS | AO15: MT2º | AT15: MATRICULADOS | AV15: TRANSITA | AX15: N/TRANSITA | AZ15: Desistido/a
F16: J | G16: I | I16: J | J16: I | L16: J | M16: I | O16: J | P16: I | R16: J | S16: I | U16: J | V16: I | X16: J | Y16: I | AA16: J | AB16: I | AD16: J | AE16: I | AG16: J | AH16: I | AJ16: J | AK16: I | AM16: J | AN16: I | AT16: M | AU16: F | AV16: M | AW16: F | AX16: M | AY16: F | AZ16: M | BA16: F
B17: 1 | C17: 4121 | D17: Abrão Gomes | H17: =SUM('11CL-AC-A-L PORT'!Q9) -> 11 | K17: =SUM('11CL-AC-A-MAT'!Q9) -> 16.666667 | N17: =SUM('11CL-AC-A-BIOL'!Q9) -> 11.333333 | Q17: =SUM('11CL-AC-A-INGLES'!Q9) -> 13 | T17: =SUM('11CL-AC-A-QCA ORG.'!Q9) -> 10.666667 | W17: =SUM('11CL-AC-A-MICROBIOL'!Q9) -> 13.5 | Z17: =SUM('11CL-AC-A-HEMAT I'!Q9) -> 13.666667 | AC17: =SUM('11CL-AC-A-IMUNOL.'!Q9) -> 16.666667 | AF17: =SUM('11CL-AC-A-URINOL.'!Q9) -> 12.833333 | AI17: =SUM('11CL-AC-A-PRASITOL.'!Q9) -> 13.333333 | AL17: =SUM('11CL-AC-A-ED. FIS'!Q9) -> 15.333333 | AO17: =SUM('11CL-AC-A-AFH'!Q9) -> 13.666667 | AP17: TRANSITA | AQ17: =AVERAGE(H17:AO17) -> 13.472222 | AR17: 17 | AS17: M | AT17: =COUNTIF(AS17:AS60,"M") -> 11 | AU17: =COUNTIF(AS17:AS60,"F") -> 33 | AV17: =COUNTIFS(AP17:AP60,"Transita",AS17:AS60,"M") -> 5 | AW17: =COUNTIFS(AP17:AP60,"Transita",AS17:AS60,"F") -> 14 | AX17: =COUNTIFS(AP17:AP60,"N/Transita",AS17:AS60,"M") -> 6 | AY17: =COUNTIFS(AP17:AP60,"N/Transita",AS17:AS60,"F") -> 17 | AZ17: =COUNTIFS(AP17:AP60,"DESISTIDO",AS17:AS60,"M") -> 0 | BA17: =COUNTIFS(AP17:AP60,"DESISTIDA",AS17:AS60,"F") -> 2
B18: 2 | C18: 2862 | D18: Agostinho Mbaki Baza | H18: =SUM('11CL-AC-A-L PORT'!Q10) -> 15 | K18: =SUM('11CL-AC-A-MAT'!Q10) -> 19.666667 | N18: =SUM('11CL-AC-A-BIOL'!Q10) -> 14.333333 | Q18: =SUM('11CL-AC-A-INGLES'!Q10) -> 20 | T18: =SUM('11CL-AC-A-QCA ORG.'!Q10) -> 18 | W18: =SUM('11CL-AC-A-MICROBIOL'!Q10) -> 14 | Z18: =SUM('11CL-AC-A-HEMAT I'!Q10) -> 18.5 | AC18: =SUM('11CL-AC-A-IMUNOL.'!Q10) -> 18.666667 | AF18: =SUM('11CL-AC-A-URINOL.'!Q10) -> 16.166667 | AI18: =SUM('11CL-AC-A-PRASITOL.'!Q10) -> 18.333333 | AL18: =SUM('11CL-AC-A-ED. FIS'!Q10) -> 14 | AO18: =SUM('11CL-AC-A-AFH'!Q10) -> 12.666667 | AP18: TRANSITA | AQ18: =AVERAGE(H18:AO18) -> 16.611111 | AR18: 16 | AS18: M | AT18: =SUM(AT17:AU17) -> 44 | AV18: =SUM(AV16:AW17) -> 19 | AX18: =SUM(AX16:AY17) -> 23 | AZ18: =SUM(AZ16:BA17) -> 2
B19: 3 | C19: 3183 | D19: Albertina Vumbi Bazunga | H19: =SUM('11CL-AC-A-L PORT'!Q11) -> 11.333333 | K19: =SUM('11CL-AC-A-MAT'!Q11) -> 16.333333 | N19: =SUM('11CL-AC-A-BIOL'!Q11) -> 13.666667 | Q19: =SUM('11CL-AC-A-INGLES'!Q11) -> 17.333333 | T19: =SUM('11CL-AC-A-QCA ORG.'!Q11) -> 9.6666667 | W19: =SUM('11CL-AC-A-MICROBIOL'!Q11) -> 14.5 | Z19: =SUM('11CL-AC-A-HEMAT I'!Q11) -> 12.333333 | AC19: =SUM('11CL-AC-A-IMUNOL.'!Q11) -> 13.833333 | AF19: =SUM('11CL-AC-A-URINOL.'!Q11) -> 11.333333 | AI19: =SUM('11CL-AC-A-PRASITOL.'!Q11) -> 14.833333 | AL19: =SUM('11CL-AC-A-ED. FIS'!Q11) -> 8.6666667 | AO19: =SUM('11CL-AC-A-AFH'!Q11) -> 11 | AP19: N/TRANSITA | AQ19: =AVERAGE(H19:AO19) -> 12.902778 | AR19: 17 | AS19: F
B20: 4 | C20: 2921 | D20: Alberto Mambo Simba | H20: =SUM('11CL-AC-A-L PORT'!Q12) -> 15.166667 | K20: =SUM('11CL-AC-A-MAT'!Q12) -> 19.666667 | N20: =SUM('11CL-AC-A-BIOL'!Q12) -> 15.333333 | Q20: =SUM('11CL-AC-A-INGLES'!Q12) -> 17.666667 | T20: =SUM('11CL-AC-A-QCA ORG.'!Q12) -> 13.666667 | W20: =SUM('11CL-AC-A-MICROBIOL'!Q12) -> 14.166667 | Z20: =SUM('11CL-AC-A-HEMAT I'!Q12) -> 16.333333 | AC20: =SUM('11CL-AC-A-IMUNOL.'!Q12) -> 16 | AF20: =SUM('11CL-AC-A-URINOL.'!Q12) -> 12.666667 | AI20: =SUM('11CL-AC-A-PRASITOL.'!Q12) -> 17.166667 | AL20: =SUM('11CL-AC-A-ED. FIS'!Q12) -> 15 | AO20: =SUM('11CL-AC-A-AFH'!Q12) -> 16.333333 | AP20: TRANSITA | AQ20: =AVERAGE(H20:AO20) -> 15.763889 | AR20: 17 | AS20: M
B21: 5 | C21: 3551 | D21: Alda Catarina Mamata Balou | H21: =SUM('11CL-AC-A-L PORT'!Q13) -> 12 | K21: =SUM('11CL-AC-A-MAT'!Q13) -> 8.6666667 | N21: =SUM('11CL-AC-A-BIOL'!Q13) -> 10.333333 | Q21: =SUM('11CL-AC-A-INGLES'!Q13) -> 16.333333 | T21: =SUM('11CL-AC-A-QCA ORG.'!Q13) -> 10.666667 | W21: =SUM('11CL-AC-A-MICROBIOL'!Q13) -> 12.666667 | Z21: =SUM('11CL-AC-A-HEMAT I'!Q13) -> 12.833333 | AC21: =SUM('11CL-AC-A-IMUNOL.'!Q13) -> 13.333333 | AF21: =SUM('11CL-AC-A-URINOL.'!Q13) -> 10 | AI21: =SUM('11CL-AC-A-PRASITOL.'!Q13) -> 16.833333 | AL21: =SUM('11CL-AC-A-ED. FIS'!Q13) -> 10 | AO21: =SUM('11CL-AC-A-AFH'!Q13) -> 11 | AP21: N/TRANSITA | AQ21: =AVERAGE(H21:AO21) -> 12.055556 | AR21: 16 | AS21: F
B22: 6 | C22: 3070 | D22: Alice Bitumba Mavungo | H22: =SUM('11CL-AC-A-L PORT'!Q14) -> 10.333333 | K22: =SUM('11CL-AC-A-MAT'!Q14) -> 13.666667 | N22: =SUM('11CL-AC-A-BIOL'!Q14) -> 11 | Q22: =SUM('11CL-AC-A-INGLES'!Q14) -> 16.666667 | T22: =SUM('11CL-AC-A-QCA ORG.'!Q14) -> 9.3333333 | W22: =SUM('11CL-AC-A-MICROBIOL'!Q14) -> 13.666667 | Z22: =SUM('11CL-AC-A-HEMAT I'!Q14) -> 11.833333 | AC22: =SUM('11CL-AC-A-IMUNOL.'!Q14) -> 16.333333 | AF22: =SUM('11CL-AC-A-URINOL.'!Q14) -> 12.166667 | AI22: =SUM('11CL-AC-A-PRASITOL.'!Q14) -> 15.833333 | AL22: =SUM('11CL-AC-A-ED. FIS'!Q14) -> 15 | AO22: =SUM('11CL-AC-A-AFH'!Q14) -> 10.333333 | AP22: N/TRANSITA | AQ22: =AVERAGE(H22:AO22) -> 13.013889 | AR22: 17 | AS22: F
B23: 7 | C23: 2939 | D23: Amélia Chibamba Chiama | H23: =SUM('11CL-AC-A-L PORT'!Q15) -> 10.5 | K23: =SUM('11CL-AC-A-MAT'!Q15) -> 13.666667 | N23: =SUM('11CL-AC-A-BIOL'!Q15) -> 14.666667 | Q23: =SUM('11CL-AC-A-INGLES'!Q15) -> 18.666667 | T23: =SUM('11CL-AC-A-QCA ORG.'!Q15) -> 16.666667 | W23: =SUM('11CL-AC-A-MICROBIOL'!Q15) -> 14.166667 | Z23: =SUM('11CL-AC-A-HEMAT I'!Q15) -> 13.333333 | AC23: =SUM('11CL-AC-A-IMUNOL.'!Q15) -> 12.666667 | AF23: =SUM('11CL-AC-A-URINOL.'!Q15) -> 12.166667 | AI23: =SUM('11CL-AC-A-PRASITOL.'!Q15) -> 17 | AL23: =SUM('11CL-AC-A-ED. FIS'!Q15) -> 16.333333 | AO23: =SUM('11CL-AC-A-AFH'!Q15) -> 12 | AP23: TRANSITA | AQ23: =AVERAGE(H23:AO23) -> 14.319444 | AR23: 14 | AS23: F | AU23: MÁXIMA | AV23: =MAX(AQ17:AQ60) -> 16.958333
B24: 8 | C24: 2833 | D24: Ana De Jesus Custódio Sambo | H24: =SUM('11CL-AC-A-L PORT'!Q16) -> 11.833333 | K24: =SUM('11CL-AC-A-MAT'!Q16) -> 13 | N24: =SUM('11CL-AC-A-BIOL'!Q16) -> 12 | Q24: =SUM('11CL-AC-A-INGLES'!Q16) -> 16 | T24: =SUM('11CL-AC-A-QCA ORG.'!Q16) -> 11.333333 | W24: =SUM('11CL-AC-A-MICROBIOL'!Q16) -> 11 | Z24: =SUM('11CL-AC-A-HEMAT I'!Q16) -> 14.166667 | AC24: =SUM('11CL-AC-A-IMUNOL.'!Q16) -> 15.333333 | AF24: =SUM('11CL-AC-A-URINOL.'!Q16) -> 11.166667 | AI24: =SUM('11CL-AC-A-PRASITOL.'!Q16) -> 16.333333 | AL24: =SUM('11CL-AC-A-ED. FIS'!Q16) -> 14 | AO24: =SUM('11CL-AC-A-AFH'!Q16) -> 10 | AP24: TRANSITA | AQ24: =AVERAGE(H24:AO24) -> 13.013889 | AR24: 16 | AS24: F
B25: 9 | C25: 3750 | D25: Ana Soca Deca Luba | H25: =SUM('11CL-AC-A-L PORT'!Q17) -> 9 | K25: =SUM('11CL-AC-A-MAT'!Q17) -> 10.666667 | N25: =SUM('11CL-AC-A-BIOL'!Q17) -> 9.3333333 | Q25: =SUM('11CL-AC-A-INGLES'!Q17) -> 13 | T25: =SUM('11CL-AC-A-QCA ORG.'!Q17) -> 6.6666667 | W25: =SUM('11CL-AC-A-MICROBIOL'!Q17) -> 10.166667 | Z25: =SUM('11CL-AC-A-HEMAT I'!Q17) -> 9.8333333 | AC25: =SUM('11CL-AC-A-IMUNOL.'!Q17) -> 10.833333 | AF25: =SUM('11CL-AC-A-URINOL.'!Q17) -> 10.666667 | AI25: =SUM('11CL-AC-A-PRASITOL.'!Q17) -> 16.333333 | AL25: =SUM('11CL-AC-A-ED. FIS'!Q17) -> 14 | AO25: =SUM('11CL-AC-A-AFH'!Q17) -> 9.3333333 | AP25: N/TRANSITA | AQ25: =AVERAGE(H25:AO25) -> 10.819444 | AR25: 17 | AS25: F | AU25: NOME DO/A ALUNO/A | AX25: Joana Bundo Fernandes
B26: 10 | C26: 3013 | D26: Angelina Buanga Poba | H26: =SUM('11CL-AC-A-L PORT'!Q18) -> 11.333333 | K26: =SUM('11CL-AC-A-MAT'!Q18) -> 14.666667 | N26: =SUM('11CL-AC-A-BIOL'!Q18) -> 13 | Q26: =SUM('11CL-AC-A-INGLES'!Q18) -> 13.333333 | T26: =SUM('11CL-AC-A-QCA ORG.'!Q18) -> 10 | W26: =SUM('11CL-AC-A-MICROBIOL'!Q18) -> 12.333333 | Z26: =SUM('11CL-AC-A-HEMAT I'!Q18) -> 10.833333 | AC26: =SUM('11CL-AC-A-IMUNOL.'!Q18) -> 11.333333 | AF26: =SUM('11CL-AC-A-URINOL.'!Q18) -> 11.666667 | AI26: =SUM('11CL-AC-A-PRASITOL.'!Q18) -> 16.5 | AL26: =SUM('11CL-AC-A-ED. FIS'!Q18) -> 7 | AO26: =SUM('11CL-AC-A-AFH'!Q18) -> 10 | AP26: N/TRANSITA | AQ26: =AVERAGE(H26:AO26) -> 11.833333 | AR26: 16 | AS26: M | AU26: IDADE: | AV26: 16
B27: 11 | C27: 3036 | D27: Antoaneta Menga Futi Gime | H27: =SUM('11CL-AC-A-L PORT'!Q19) -> 12.5 | K27: =SUM('11CL-AC-A-MAT'!Q19) -> 17.333333 | N27: =SUM('11CL-AC-A-BIOL'!Q19) -> 16 | Q27: =SUM('11CL-AC-A-INGLES'!Q19) -> 18.333333 | T27: =SUM('11CL-AC-A-QCA ORG.'!Q19) -> 13.333333 | W27: =SUM('11CL-AC-A-MICROBIOL'!Q19) -> 12.666667 | Z27: =SUM('11CL-AC-A-HEMAT I'!Q19) -> 14.333333 | AC27: =SUM('11CL-AC-A-IMUNOL.'!Q19) -> 18.333333 | AF27: =SUM('11CL-AC-A-URINOL.'!Q19) -> 10.333333 | AI27: =SUM('11CL-AC-A-PRASITOL.'!Q19) -> 15.833333 | AL27: =SUM('11CL-AC-A-ED. FIS'!Q19) -> 16 | AO27: =SUM('11CL-AC-A-AFH'!Q19) -> 12 | AP27: TRANSITA | AQ27: =AVERAGE(H27:AO27) -> 14.75 | AR27: 17 | AS27: F
B28: 12 | C28: 4217 | D28: Arinalda De Canatividade Prata Bungo | H28: =SUM('11CL-AC-A-L PORT'!Q20) -> 13.166667 | K28: =SUM('11CL-AC-A-MAT'!Q20) -> 19.333333 | N28: =SUM('11CL-AC-A-BIOL'!Q20) -> 13 | Q28: =SUM('11CL-AC-A-INGLES'!Q20) -> 14.666667 | T28: =SUM('11CL-AC-A-QCA ORG.'!Q20) -> 14.333333 | W28: =SUM('11CL-AC-A-MICROBIOL'!Q20) -> 14.5 | Z28: =SUM('11CL-AC-A-HEMAT I'!Q20) -> 13.5 | AC28: =SUM('11CL-AC-A-IMUNOL.'!Q20) -> 16.833333 | AF28: =SUM('11CL-AC-A-URINOL.'!Q20) -> 12 | AI28: =SUM('11CL-AC-A-PRASITOL.'!Q20) -> 16.5 | AL28: =SUM('11CL-AC-A-ED. FIS'!Q20) -> 14 | AO28: =SUM('11CL-AC-A-AFH'!Q20) -> 15.666667 | AP28: TRANSITA | AQ28: =AVERAGE(H28:AO28) -> 14.791667 | AR28: 17 | AS28: F
B29: 13 | C29: 3063 | D29: Basílio Araújo Simba Mabiala | H29: =SUM('11CL-AC-A-L PORT'!Q21) -> 14.5 | K29: =SUM('11CL-AC-A-MAT'!Q21) -> 19.333333 | N29: =SUM('11CL-AC-A-BIOL'!Q21) -> 0 | Q29: =SUM('11CL-AC-A-INGLES'!Q21) -> 18 | T29: =SUM('11CL-AC-A-QCA ORG.'!Q21) -> 17 | W29: =SUM('11CL-AC-A-MICROBIOL'!Q21) -> 13.666667 | Z29: =SUM('11CL-AC-A-HEMAT I'!Q21) -> 11 | AC29: =SUM('11CL-AC-A-IMUNOL.'!Q21) -> 18.333333 | AF29: =SUM('11CL-AC-A-URINOL.'!Q21) -> 12.166667 | AI29: =SUM('11CL-AC-A-PRASITOL.'!Q21) -> 17.166667 | AL29: =SUM('11CL-AC-A-ED. FIS'!Q21) -> 16 | AO29: =SUM('11CL-AC-A-AFH'!Q21) -> 12.666667 | AP29: N/TRANSITA | AQ29: =AVERAGE(H29:AO29) -> 14.152778 | AR29: 17 | AS29: M
B30: 14 | C30: 3606 | D30: Carlota Mbungo Conde | H30: =SUM('11CL-AC-A-L PORT'!Q22) -> 8.8333333 | K30: =SUM('11CL-AC-A-MAT'!Q22) -> 12 | N30: =SUM('11CL-AC-A-BIOL'!Q22) -> 10 | Q30: =SUM('11CL-AC-A-INGLES'!Q22) -> 16.666667 | T30: =SUM('11CL-AC-A-QCA ORG.'!Q22) -> 8 | W30: =SUM('11CL-AC-A-MICROBIOL'!Q22) -> 12.833333 | Z30: =SUM('11CL-AC-A-HEMAT I'!Q22) -> 11.166667 | AC30: =SUM('11CL-AC-A-IMUNOL.'!Q22) -> 8.3333333 | AF30: =SUM('11CL-AC-A-URINOL.'!Q22) -> 10 | AI30: =SUM('11CL-AC-A-PRASITOL.'!Q22) -> 13 | AL30: =SUM('11CL-AC-A-ED. FIS'!Q22) -> 15 | AO30: =SUM('11CL-AC-A-AFH'!Q22) -> 10 | AP30: N/TRANSITA | AQ30: =AVERAGE(H30:AO30) -> 11.319444 | AR30: 17 | AS30: F
B31: 15 | C31: 2798 | D31: Catarina Luemba Makuama | H31: =SUM('11CL-AC-A-L PORT'!Q23) -> 8.6666667 | K31: =SUM('11CL-AC-A-MAT'!Q23) -> 14 | N31: =SUM('11CL-AC-A-BIOL'!Q23) -> 11 | Q31: =SUM('11CL-AC-A-INGLES'!Q23) -> 15.666667 | T31: =SUM('11CL-AC-A-QCA ORG.'!Q23) -> 6.6666667 | W31: =SUM('11CL-AC-A-MICROBIOL'!Q23) -> 11.833333 | Z31: =SUM('11CL-AC-A-HEMAT I'!Q23) -> 10.5 | AC31: =SUM('11CL-AC-A-IMUNOL.'!Q23) -> 11 | AF31: =SUM('11CL-AC-A-URINOL.'!Q23) -> 8 | AI31: =SUM('11CL-AC-A-PRASITOL.'!Q23) -> 13.833333 | AL31: =SUM('11CL-AC-A-ED. FIS'!Q23) -> 15 | AO31: =SUM('11CL-AC-A-AFH'!Q23) -> 9.3333333 | AP31: N/TRANSITA | AQ31: =AVERAGE(H31:AO31) -> 11.291667 | AR31: 17 | AS31: M
B32: 16 | C32: 4210 | D32: Cristina Conde Sassi | H32: =SUM('11CL-AC-A-L PORT'!Q24) -> 8.1666667 | K32: =SUM('11CL-AC-A-MAT'!Q24) -> 14.666667 | N32: =SUM('11CL-AC-A-BIOL'!Q24) -> 12.333333 | Q32: =SUM('11CL-AC-A-INGLES'!Q24) -> 16.333333 | T32: =SUM('11CL-AC-A-QCA ORG.'!Q24) -> 8.6666667 | W32: =SUM('11CL-AC-A-MICROBIOL'!Q24) -> 12.666667 | Z32: =SUM('11CL-AC-A-HEMAT I'!Q24) -> 11 | AC32: =SUM('11CL-AC-A-IMUNOL.'!Q24) -> 11.5 | AF32: =SUM('11CL-AC-A-URINOL.'!Q24) -> 12.666667 | AI32: =SUM('11CL-AC-A-PRASITOL.'!Q24) -> 15.166667 | AL32: =SUM('11CL-AC-A-ED. FIS'!Q24) -> 7.6666667 | AO32: =SUM('11CL-AC-A-AFH'!Q24) -> 11 | AP32: N/TRANSITA | AQ32: =AVERAGE(H32:AO32) -> 11.819444 | AR32: 14 | AS32: F
B33: 17 | C33: 3422 | D33: Dorcas Milando Dembi | H33: =SUM('11CL-AC-A-L PORT'!Q25) -> 12.666667 | K33: =SUM('11CL-AC-A-MAT'!Q25) -> 14 | N33: =SUM('11CL-AC-A-BIOL'!Q25) -> 13 | Q33: =SUM('11CL-AC-A-INGLES'!Q25) -> 14.333333 | T33: =SUM('11CL-AC-A-QCA ORG.'!Q25) -> 16.666667 | W33: =SUM('11CL-AC-A-MICROBIOL'!Q25) -> 11.833333 | Z33: =SUM('11CL-AC-A-HEMAT I'!Q25) -> 13.166667 | AC33: =SUM('11CL-AC-A-IMUNOL.'!Q25) -> 10.666667 | AF33: =SUM('11CL-AC-A-URINOL.'!Q25) -> 14.666667 | AI33: =SUM('11CL-AC-A-PRASITOL.'!Q25) -> 16.166667 | AL33: =SUM('11CL-AC-A-ED. FIS'!Q25) -> 15 | AO33: =SUM('11CL-AC-A-AFH'!Q25) -> 12.333333 | AP33: TRANSITA | AQ33: =AVERAGE(H33:AO33) -> 13.708333 | AR33: 17 | AS33: F
B34: 18 | C34: 3300 | D34: Elisa Zuzi Bumba Da Silva | H34: =SUM('11CL-AC-A-L PORT'!Q26) -> 12.666667 | K34: =SUM('11CL-AC-A-MAT'!Q26) -> 14.333333 | N34: =SUM('11CL-AC-A-BIOL'!Q26) -> 13.666667 | Q34: =SUM('11CL-AC-A-INGLES'!Q26) -> 17 | T34: =SUM('11CL-AC-A-QCA ORG.'!Q26) -> 10 | W34: =SUM('11CL-AC-A-MICROBIOL'!Q26) -> 13 | Z34: =SUM('11CL-AC-A-HEMAT I'!Q26) -> 11 | AC34: =SUM('11CL-AC-A-IMUNOL.'!Q26) -> 15.166667 | AF34: =SUM('11CL-AC-A-URINOL.'!Q26) -> 12.833333 | AI34: =SUM('11CL-AC-A-PRASITOL.'!Q26) -> 16.666667 | AL34: =SUM('11CL-AC-A-ED. FIS'!Q26) -> 15 | AO34: =SUM('11CL-AC-A-AFH'!Q26) -> 11 | AP34: TRANSITA | AQ34: =AVERAGE(H34:AO34) -> 13.527778 | AR34: 17 | AS34: F
B35: 19 | C35: 2224 | D35: Felicidade Muanda Bititi | H35: =SUM('11CL-AC-A-L PORT'!Q27) -> 0 | K35: =SUM('11CL-AC-A-MAT'!Q27) -> 0 | N35: =SUM('11CL-AC-A-BIOL'!Q27) -> 0 | Q35: =SUM('11CL-AC-A-INGLES'!Q27) -> 0 | T35: =SUM('11CL-AC-A-QCA ORG.'!Q27) -> 0 | W35: =SUM('11CL-AC-A-MICROBIOL'!Q27) -> 0 | Z35: =SUM('11CL-AC-A-HEMAT I'!Q27) -> 0 | AC35: =SUM('11CL-AC-A-IMUNOL.'!Q27) -> 0 | AF35: =SUM('11CL-AC-A-URINOL.'!Q27) -> 0 | AI35: =SUM('11CL-AC-A-PRASITOL.'!Q27) -> 0 | AL35: =SUM('11CL-AC-A-ED. FIS'!Q27) -> 0 | AO35: =SUM('11CL-AC-A-AFH'!Q27) -> 10 | AP35: DESISTIDA | AQ35: =AVERAGE(H35:AO35) -> 0.83333333 | AR35: 17 | AS35: F
B36: 20 | C36: 4097 | D36: Fernanda Pedro Tavares | H36: =SUM('11CL-AC-A-L PORT'!Q28) -> 0 | K36: =SUM('11CL-AC-A-MAT'!Q28) -> 0 | N36: =SUM('11CL-AC-A-BIOL'!Q28) -> 0 | Q36: =SUM('11CL-AC-A-INGLES'!Q28) -> 0 | T36: =SUM('11CL-AC-A-QCA ORG.'!Q28) -> 0 | W36: =SUM('11CL-AC-A-MICROBIOL'!Q28) -> 0 | Z36: =SUM('11CL-AC-A-HEMAT I'!Q28) -> 0 | AC36: =SUM('11CL-AC-A-IMUNOL.'!Q28) -> 0 | AF36: =SUM('11CL-AC-A-URINOL.'!Q28) -> 0 | AI36: =SUM('11CL-AC-A-PRASITOL.'!Q28) -> 0 | AL36: =SUM('11CL-AC-A-ED. FIS'!Q28) -> 14 | AO36: =SUM('11CL-AC-A-AFH'!Q28) -> 0 | AP36: DESISTIDA | AQ36: =AVERAGE(H36:AO36) -> 1.1666667 | AR36: 17 | AS36: F
B37: 21 | C37: 2806 | D37: Gertrudes Buanga Zuzi | H37: =SUM('11CL-AC-A-L PORT'!Q29) -> 9 | K37: =SUM('11CL-AC-A-MAT'!Q29) -> 16.666667 | N37: =SUM('11CL-AC-A-BIOL'!Q29) -> 8.3333333 | Q37: =SUM('11CL-AC-A-INGLES'!Q29) -> 9 | T37: =SUM('11CL-AC-A-QCA ORG.'!Q29) -> 6.6666667 | W37: =SUM('11CL-AC-A-MICROBIOL'!Q29) -> 11.166667 | Z37: =SUM('11CL-AC-A-HEMAT I'!Q29) -> 5.8333333 | AC37: =SUM('11CL-AC-A-IMUNOL.'!Q29) -> 12.166667 | AF37: =SUM('11CL-AC-A-URINOL.'!Q29) -> 9.5 | AI37: =SUM('11CL-AC-A-PRASITOL.'!Q29) -> 12.5 | AL37: =SUM('11CL-AC-A-ED. FIS'!Q29) -> 8.3333333 | AO37: =SUM('11CL-AC-A-AFH'!Q29) -> 4.5 | AP37: N/TRANSITA | AQ37: =AVERAGE(H37:AO37) -> 9.4722222 | AR37: 18 | AS37: M
B38: 22 | C38: 2923 | D38: Helena Kalembela Miguel | H38: =SUM('11CL-AC-A-L PORT'!Q30) -> 10.166667 | K38: =SUM('11CL-AC-A-MAT'!Q30) -> 18 | N38: =SUM('11CL-AC-A-BIOL'!Q30) -> 12.333333 | Q38: =SUM('11CL-AC-A-INGLES'!Q30) -> 16.666667 | T38: =SUM('11CL-AC-A-QCA ORG.'!Q30) -> 11.333333 | W38: =SUM('11CL-AC-A-MICROBIOL'!Q30) -> 14.166667 | Z38: =SUM('11CL-AC-A-HEMAT I'!Q30) -> 12.666667 | AC38: =SUM('11CL-AC-A-IMUNOL.'!Q30) -> 16.833333 | AF38: =SUM('11CL-AC-A-URINOL.'!Q30) -> 14 | AI38: =SUM('11CL-AC-A-PRASITOL.'!Q30) -> 15.166667 | AL38: =SUM('11CL-AC-A-ED. FIS'!Q30) -> 15 | AO38: =SUM('11CL-AC-A-AFH'!Q30) -> 10 | AP38: TRANSITA | AQ38: =AVERAGE(H38:AO38) -> 13.861111 | AR38: 16 | AS38: F
... B60: 44 | C60: 3628 | D60: Teresa Gertrudes Luzia Tati | H60: =SUM('11CL-AC-A-L PORT'!Q52) -> 11 | K60: =SUM('11CL-AC-A-MAT'!Q52) -> 13.333333 | N60: =SUM('11CL-AC-A-BIOL'!Q52) -> 11 | Q60: =SUM('11CL-AC-A-INGLES'!Q52) -> 15.333333 | T60: =SUM('11CL-AC-A-QCA ORG.'!Q52) -> 15.333333 | W60: =SUM('11CL-AC-A-MICROBIOL'!Q52) -> 12 | Z60: =SUM('11CL-AC-A-HEMAT I'!Q52) -> 12.833333 | AC60: =SUM('11CL-AC-A-IMUNOL.'!Q52) -> 9.6666667 | AF60: =SUM('11CL-AC-A-URINOL.'!Q52) -> 14.5 | AI60: =SUM('11CL-AC-A-PRASITOL.'!Q52) -> 16.333333 | AL60: =SUM('11CL-AC-A-ED. FIS'!Q52) -> 14 | AO60: =SUM('11CL-AC-A-AFH'!Q52) -> 10.333333 | AP60: N/TRANSITA | AQ60: =AVERAGE(H60:AO60) -> 12.972222 | AR60: 16 | AS60: F
B61: DATA DO CONSELHO DE TURMA______/______/2026
B64: A Directora de Turma | AA64: O Sibdirector Pedagógico
B65: _____________________________________
B66: RUTH DEMBI QUIFOCO ZEMBO | AA66: ALBERTO SASSA TATI

Sheet 11CL-AC-A-L PORT
A1: INSTITUTO TÉCNICO PRIVADO DE SAÚDE JOMORAIS
I3: DATA: 12/12/2025
B4: Classe: 11ª | I4: Disciplina: Língua Portuguesa | V4: Ano Lectivo:2025/2026
B5: Período: Vespertino | E5: Turma: A | V5: Curso: ANÁLISES CLÍNICAS
B6: MINI-PAUTA - TÉCNICO DE SAÚDE
B7: Nº | C7: Nome do (a) Aluno (a) | D7: FALTAS | E7: Avaliações/I Trimestre | K7: OBS | L7: Avaliações/II Trimestre | R7: OBS | S7: Avaliações/IIITrimestre | Y7: MFD | Z7: OBS | AA7: M | AB7: F | AC7: TRANSITA | AD7: N/TRANSITA | AE7: E.E.F
D8: J/I | E8: MAC | F8: NPP | G8: NPR1 | H8: NPT | I8: NPR2 | J8: MT1 | L8: MAC | M8: NPP | N8: NPR1 | O8: NPT | P8: NPR2 | Q8: MT2 | S8: MAC | T8: NPP | U8: NPR1 | V8: NPT | W8: NPR2 | X8: MT3 | AA8: =COUNTIF(Z9:Z58,"M") -> 0 | AB8: =COUNTIF(Z9:Z58,"F") -> 0 | AC8: =COUNTIF(Z9:Z58,"TRANSITA") -> 1 | AD8: =COUNTIF(Z9:Z58,"N/TRANSITA") -> 43 | AE8: =COUNTIF(Z9:Z58,"E.E.F") -> 0
B9: 1 | C9: Abrão Gomes | E9: 12 | F9: 13 | H9: 15 | J9: =AVERAGE(E9,MAX(F9:G9),MAX(H9:I9)) -> 13.333333 | K9: =IF(J9>=10,"TRANSITA","N/TRANSITA") -> TRANSITA | L9: 13 | M9: 12 | O9: 8 | Q9: =AVERAGE(L9,MAX(M9:N9),MAX(O9:P9)) -> 11 | R9: =IF(Q9>=10,"TRANSITA","N/TRANSITA") -> TRANSITA | X9: =AVERAGE(S9,MAX(T9:U9),MAX(V9:W9)) -> 0 | Y9: =SUM(J9,Q9,X9)/3 -> 8.1111111 | Z9: =IF(Y9>=10,"TRANSITA","N/TRANSITA") -> N/TRANSITA
B10: 2 | C10: Agostinho Mbaki Baza | E10: 14 | F10: 17 | H10: 14.5 | J10: =AVERAGE(E10,MAX(F10:G10),MAX(H10:I10)) -> 15.166667 | K10: =IF(J10>=10,"TRANSITA","N/TRANSITA") -> TRANSITA | L10: 14 | M10: 18 | O10: 13 | Q10: =AVERAGE(L10,MAX(M10:N10),MAX(O10:P10)) -> 15 | R10: =IF(Q10>=10,"TRANSITA","N/TRANSITA") -> TRANSITA | X10: =AVERAGE(S10,MAX(T10:U10),MAX(V10:W10)) -> 0 | Y10: =SUM(J10,Q10,X10)/3 -> 10.055556 | Z10: =IF(Y10>=10,"TRANSITA","N/TRANSITA") -> TRANSITA | AA10: =SUM(AA8:AB9) -> 0
B11: 3 | C11: Albertina Vumbi Bazunga | E11: 10 | F11: 13 | H11: 6 | J11: =AVERAGE(E11,MAX(F11:G11),MAX(H11:I11)) -> 9.6666667 | K11: =IF(J11>=10,"TRANSITA","N/TRANSITA") -> N/TRANSITA | L11: 13 | M11: 12.5 | O11: 8.5 | Q11: =AVERAGE(L11,MAX(M11:N11),MAX(O11:P11)) -> 11.333333 | R11: =IF(Q11>=10,"TRANSITA","N/TRANSITA") -> TRANSITA | X11: =AVERAGE(S11,MAX(T11:U11),MAX(V11:W11)) -> 0 | Y11: =SUM(J11,Q11,X11)/3 -> 7 | Z11: =IF(Y11>=10,"TRANSITA","N/TRANSITA") -> N/TRANSITA
B12: 4 | C12: Alberto Mambo Simba | E12: 15 | F12: 14 | H12: 13 | J12: =AVERAGE(E12,MAX(F12:G12),MAX(H12:I12)) -> 14 | K12: =IF(J12>=10,"TRANSITA","N/TRANSITA") -> TRANSITA | L12: 15 | M12: 17.5 | O12: 13 | Q12: =AVERAGE(L12,MAX(M12:N12),MAX(O12:P12)) -> 15.166667 | R12: =IF(Q12>=10,"TRANSITA","N/TRANSITA") -> TRANSITA | X12: =AVERAGE(S12,MAX(T12:U12),MAX(V12:W12)) -> 0 | Y12: =SUM(J12,Q12,X12)/3 -> 9.7222222 | Z12: =IF(Y12>=10,"TRANSITA","N/TRANSITA") -> N/TRANSITA
B13: 5 | C13: Alda Catarina Mamata Balou | E13: 12 | F13: 13 | H13: 12 | J13: =AVERAGE(E13,MAX(F13:G13),MAX(H13:I13)) -> 12.333333 | K13: =IF(J13>=10,"TRANSITA","N/TRANSITA") -> TRANSITA | L13: 12 | M13: 14.5 | O13: 9.5 | Q13: =AVERAGE(L13,MAX(M13:N13),MAX(O13:P13)) -> 12 | R13: =IF(Q13>=10,"TRANSITA","N/TRANSITA") -> TRANSITA | X13: =AVERAGE(S13,MAX(T13:U13),MAX(V13:W13)) -> 0 | Y13: =SUM(J13,Q13,X13)/3 -> 8.1111111 | Z13: =IF(Y13>=10,"TRANSITA","N/TRANSITA") -> N/TRANSITA
B14: 6 | C14: Alice Bitumba Mavungo | E14: 10 | F14: 6 | H14: 13.5 | J14: =AVERAGE(E14,MAX(F14:G14),MAX(H14:I14)) -> 9.8333333 | K14: =IF(J14>=10,"TRANSITA","N/TRANSITA") -> N/TRANSITA | L14: 11 | M14: 10 | O14: 10 | Q14: =AVERAGE(L14,MAX(M14:N14),MAX(O14:P14)) -> 10.333333 | R14: =IF(Q14>=10,"TRANSITA","N/TRANSITA") -> TRANSITA | X14: =AVERAGE(S14,MAX(T14:U14),MAX(V14:W14)) -> 0 | Y14: =SUM(J14,Q14,X14)/3 -> 6.7222222 | Z14: =IF(Y14>=10,"TRANSITA","N/TRANSITA") -> N/TRANSITA
B15: 7 | C15: Amélia Chibamba Chiama | E15: 10 | F15: 10 | H15: 12.5 | J15: =AVERAGE(E15,MAX(F15:G15),MAX(H15:I15)) -> 10.833333 | K15: =IF(J15>=10,"TRANSITA","N/TRANSITA") -> TRANSITA | L15: 11 | M15: 11 | O15: 9.5 | Q15: =AVERAGE(L15,MAX(M15:N15),MAX(O15:P15)) -> 10.5 | R15: =IF(Q15>=10,"TRANSITA","N/TRANSITA") -> TRANSITA | X15: =AVERAGE(S15,MAX(T15:U15),MAX(V15:W15)) -> 0 | Y15: =SUM(J15,Q15,X15)/3 -> 7.1111111 | Z15: =IF(Y15>=10,"TRANSITA","N/TRANSITA") -> N/TRANSITA
B16: 8 | C16: Ana De Jesus Custódio Sambo | E16: 12 | F16: 14 | H16: 13.5 | J16: =AVERAGE(E16,MAX(F16:G16),MAX(H16:I16)) -> 13.166667 | K16: =IF(J16>=10,"TRANSITA","N/TRANSITA") -> TRANSITA | L16: 13 | M16: 11.5 | O16: 11 | Q16: =AVERAGE(L16,MAX(M16:N16),MAX(O16:P16)) -> 11.833333 | R16: =IF(Q16>=10,"TRANSITA","N/TRANSITA") -> TRANSITA | X16: =AVERAGE(S16,MAX(T16:U16),MAX(V16:W16)) -> 0 | Y16: =SUM(J16,Q16,X16)/3 -> 8.3333333 | Z16: =IF(Y16>=10,"TRANSITA","N/TRANSITA") -> N/TRANSITA
B17: 9 | C17: Ana Soca Deca Luba | E17: 10 | F17: 11 | H17: 10.5 | J17: =AVERAGE(E17,MAX(F17:G17),MAX(H17:I17)) -> 10.5 | K17: =IF(J17>=10,"TRANSITA","N/TRANSITA") -> TRANSITA | L17: 10 | M17: 9.5 | O17: 7.5 | Q17: =AVERAGE(L17,MAX(M17:N17),MAX(O17:P17)) -> 9 | R17: =IF(Q17>=10,"TRANSITA","N/TRANSITA") -> N/TRANSITA | X17: =AVERAGE(S17,MAX(T17:U17),MAX(V17:W17)) -> 0 | Y17: =SUM(J17,Q17,X17)/3 -> 6.5 | Z17: =IF(Y17>=10,"TRANSITA","N/TRANSITA") -> N/TRANSITA
B18: 10 | C18: Angelina Buanga Poba | E18: 11 | F18: 13 | H18: 13 | J18: =AVERAGE(E18,MAX(F18:G18),MAX(H18:I18)) -> 12.333333 | K18: =IF(J18>=10,"TRANSITA","N/TRANSITA") -> TRANSITA | L18: 12 | M18: 13 | O18: 9 | Q18: =AVERAGE(L18,MAX(M18:N18),MAX(O18:P18)) -> 11.333333 | R18: =IF(Q18>=10,"TRANSITA","N/TRANSITA") -> TRANSITA | X18: =AVERAGE(S18,MAX(T18:U18),MAX(V18:W18)) -> 0 | Y18: =SUM(J18,Q18,X18)/3 -> 7.8888889 | Z18: =IF(Y18>=10,"TRANSITA","N/TRANSITA") -> N/TRANSITA
B19: 11 | C19: Antoaneta Menga Futi Gime | E19: 11 | F19: 12 | H19: 14 | J19: =AVERAGE(E19,MAX(F19:G19),MAX(H19:I19)) -> 12.333333 | K19: =IF(J19>=10,"TRANSITA","N/TRANSITA") -> TRANSITA | L19: 13 | M19: 15 | O19: 9.5 | Q19: =AVERAGE(L19,MAX(M19:N19),MAX(O19:P19)) -> 12.5 | R19: =IF(Q19>=10,"TRANSITA","N/TRANSITA") -> TRANSITA | X19: =AVERAGE(S19,MAX(T19:U19),MAX(V19:W19)) -> 0 | Y19: =SUM(J19,Q19,X19)/3 -> 8.2777778 | Z19: =IF(Y19>=10,"TRANSITA","N/TRANSITA") -> N/TRANSITA
B20: 12 | C20: Arinalda De Canatividade Prata Bungo | E20: 13 | F20: 14 | H20: 14.5 | J20: =AVERAGE(E20,MAX(F20:G20),MAX(H20:I20)) -> 13.833333 | K20: =IF(J20>=10,"TRANSITA","N/TRANSITA") -> TRANSITA | L20: 13 | M20: 17 | O20: 9.5 | Q20: =AVERAGE(L20,MAX(M20:N20),MAX(O20:P20)) -> 13.166667 | R20: =IF(Q20>=10,"TRANSITA","N/TRANSITA") -> TRANSITA | X20: =AVERAGE(S20,MAX(T20:U20),MAX(V20:W20)) -> 0 | Y20: =SUM(J20,Q20,X20)/3 -> 9 | Z20: =IF(Y20>=10,"TRANSITA","N/TRANSITA") -> N/TRANSITA
B21: 13 | C21: Basílio Araújo Simba Mabiala | E21: 14 | F21: 14 | H21: 14.5 | J21: =AVERAGE(E21,MAX(F21:G21),MAX(H21:I21)) -> 14.166667 | K21: =IF(J21>=10,"TRANSITA","N/TRANSITA") -> TRANSITA | L21: 14 | M21: 17.5 | O21: 12 | Q21: =AVERAGE(L21,MAX(M21:N21),MAX(O21:P21)) -> 14.5 | R21: =IF(Q21>=10,"TRANSITA","N/TRANSITA") -> TRANSITA | X21: =AVERAGE(S21,MAX(T21:U21),MAX(V21:W21)) -> 0 | Y21: =SUM(J21,Q21,X21)/3 -> 9.5555556 | Z21: =IF(Y21>=10,"TRANSITA","N/TRANSITA") -> N/TRANSITA
B22: 14 | C22: Carlota Mbungo Conde | E22: 11 | F22: 8 | H22: 10.5 | J22: =AVERAGE(E22,MAX(F22:G22),MAX(H22:I22)) -> 9.8333333 | K22: =IF(J22>=10,"TRANSITA","N/TRANSITA") -> N/TRANSITA | L22: 11 | M22: 8.5 | O22: 7 | Q22: =AVERAGE(L22,MAX(M22:N22),MAX(O22:P22)) -> 8.8333333 | R22: =IF(Q22>=10,"TRANSITA","N/TRANSITA") -> N/TRANSITA | X22: =AVERAGE(S22,MAX(T22:U22),MAX(V22:W22)) -> 0 | Y22: =SUM(J22,Q22,X22)/3 -> 6.2222222 | Z22: =IF(Y22>=10,"TRANSITA","N/TRANSITA") -> N/TRANSITA
... B26: 18 | C26: Elisa Zuzi Bumba Da Silva | E26: 12 | F26: 16 | H26: 12.5 | J26: =AVERAGE(E26,MAX(F26:G26),MAX(H26:I26)) -> 13.5 | K26: =IF(J26>=10,"TRANSITA","N/TRANSITA") -> TRANSITA | L26: 13 | M26: 16 | O26: 9 | Q26: =AVERAGE(L26,MAX(M26:N26),MAX(O26:P26)) -> 12.666667 | R26: =IF(Q26>=10,"TRANSITA","N/TRANSITA") -> TRANSITA | X26: =AVERAGE(S26,MAX(T26:U26),MAX(V26:W26)) -> 0 | Y26: =SUM(J26,Q26,X26)/3 -> 8.7222222 | Z26: =IF(Y26>=10,"TRANSITA","N/TRANSITA") -> N/TRANSITA
B27: 19 | C27: Felicidade Muanda Bititi | J27: =AVERAGE(E27,MAX(F27:G27),MAX(H27:I27)) -> 0 | K27: =IF(J27>=10,"TRANSITA","N/TRANSITA") -> N/TRANSITA | Q27: =AVERAGE(L27,MAX(M27:N27),MAX(O27:P27)) -> 0 | R27: =IF(Q27>=10,"TRANSITA","N/TRANSITA") -> N/TRANSITA | X27: =AVERAGE(S27,MAX(T27:U27),MAX(V27:W27)) -> 0 | Y27: =SUM(J27,Q27,X27)/3 -> 0 | Z27: =IF(Y27>=10,"TRANSITA","N/TRANSITA") -> N/TRANSITA
B28: 20 | C28: Fernanda Pedro Tavares | E28: 12 | F28: 12 | H28: 12.5 | J28: =AVERAGE(E28,MAX(F28:G28),MAX(H28:I28)) -> 12.166667 | K28: =IF(J28>=10,"TRANSITA","N/TRANSITA") -> TRANSITA | Q28: =AVERAGE(L28,MAX(M28:N28),MAX(O28:P28)) -> 0 | R28: =IF(Q28>=10,"TRANSITA","N/TRANSITA") -> N/TRANSITA | X28: =AVERAGE(S28,MAX(T28:U28),MAX(V28:W28)) -> 0 | Y28: =SUM(J28,Q28,X28)/3 -> 4.0555556 | Z28: =IF(Y28>=10,"TRANSITA","N/TRANSITA") -> N/TRANSITA
B29: 21 | C29: Gertrudes Buanga Zuzi | E29: 11 | F29: 10 | H29: 11 | J29: =AVERAGE(E29,MAX(F29:G29),MAX(H29:I29)) -> 10.666667 | K29: =IF(J29>=10,"TRANSITA","N/TRANSITA") -> TRANSITA | L29: 11 | M29: 12 | O29: 4 | Q29: =AVERAGE(L29,MAX(M29:N29),MAX(O29:P29)) -> 9 | R29: =IF(Q29>=10,"TRANSITA","N/TRANSITA") -> N/TRANSITA | X29: =AVERAGE(S29,MAX(T29:U29),MAX(V29:W29)) -> 0 | Y29: =SUM(J29,Q29,X29)/3 -> 6.5555556 | Z29: =IF(Y29>=10,"TRANSITA","N/TRANSITA") -> N/TRANSITA
B30: 22 | C30: Helena Kalembela Miguel | E30: 12 | F30: 14 | H30: 13 | J30: =AVERAGE(E30,MAX(F30:G30),MAX(H30:I30)) -> 13 | K30: =IF(J30>=10,"TRANSITA","N/TRANSITA") -> TRANSITA | L30: 11 | M30: 9 | O30: 10.5 | Q30: =AVERAGE(L30,MAX(M30:N30),MAX(O30:P30)) -> 10.166667 | R30: =IF(Q30>=10,"TRANSITA","N/TRANSITA") -> TRANSITA | X30: =AVERAGE(S30,MAX(T30:U30),MAX(V30:W30)) -> 0 | Y30: =SUM(J30,Q30,X30)/3 -> 7.7222222 | Z30: =IF(Y30>=10,"TRANSITA","N/TRANSITA") -> N/TRANSITA
B31: 23 | C31: Helena Maravilha Zinga Sumbo | E31: 11 | F31: 14 | H31: 13.5 | J31: =AVERAGE(E31,MAX(F31:G31),MAX(H31:I31)) -> 12.833333 | K31: =IF(J31>=10,"TRANSITA","N/TRANSITA") -> TRANSITA | L31: 12 | M31: 15.5 | O31: 11 | Q31: =AVERAGE(L31,MAX(M31:N31),MAX(O31:P31)) -> 12.833333 | R31: =IF(Q31>=10,"TRANSITA","N/TRANSITA") -> TRANSITA | X31: =AVERAGE(S31,MAX(T31:U31),MAX(V31:W31)) -> 0 | Y31: =SUM(J31,Q31,X31)/3 -> 8.5555556 | Z31: =IF(Y31>=10,"TRANSITA","N/TRANSITA") -> N/TRANSITA
B32: 24 | C32: Inês Filomena Muanda Baiona | E32: 8 | F32: 0 | H32: 11.5 | J32: =AVERAGE(E32,MAX(F32:G32),MAX(H32:I32)) -> 6.5 | K32: =IF(J32>=10,"TRANSITA","N/TRANSITA") -> N/TRANSITA | L32: 9 | M32: 10 | O32: 7 | Q32: =AVERAGE(L32,MAX(M32:N32),MAX(O32:P32)) -> 8.6666667 | R32: =IF(Q32>=10,"TRANSITA","N/TRANSITA") -> N/TRANSITA | X32: =AVERAGE(S32,MAX(T32:U32),MAX(V32:W32)) -> 0 | Y32: =SUM(J32,Q32,X32)/3 -> 5.0555556 | Z32: =IF(Y32>=10,"TRANSITA","N/TRANSITA") -> N/TRANSITA
B33: 25 | C33: Isabel Ndaia Muanda | E33: 10 | F33: 11 | H33: 10 | J33: =AVERAGE(E33,MAX(F33:G33),MAX(H33:I33)) -> 10.333333 | K33: =IF(J33>=10,"TRANSITA","N/TRANSITA") -> TRANSITA | L33: 10 | M33: 9.5 | O33: 8 | Q33: =AVERAGE(L33,MAX(M33:N33),MAX(O33:P33)) -> 9.1666667 | R33: =IF(Q33>=10,"TRANSITA","N/TRANSITA") -> N/TRANSITA | X33: =AVERAGE(S33,MAX(T33:U33),MAX(V33:W33)) -> 0 | Y33: =SUM(J33,Q33,X33)/3 -> 6.5 | Z33: =IF(Y33>=10,"TRANSITA","N/TRANSITA") -> N/TRANSITA
B34: 26 | C34: Janete Malonda Cunha | E34: 13 | F34: 12 | H34: 15 | J34: =AVERAGE(E34,MAX(F34:G34),MAX(H34:I34)) -> 13.333333 | K34: =IF(J34>=10,"TRANSITA","N/TRANSITA") -> TRANSITA | L34: 13 | M34: 17 | O34: 10 | Q34: =AVERAGE(L34,MAX(M34:N34),MAX(O34:P34)) -> 13.333333 | R34: =IF(Q34>=10,"TRANSITA","N/TRANSITA") -> TRANSITA | X34: =AVERAGE(S34,MAX(T34:U34),MAX(V34:W34)) -> 0 | Y34: =SUM(J34,Q34,X34)/3 -> 8.8888889 | Z34: =IF(Y34>=10,"TRANSITA","N/TRANSITA") -> N/TRANSITA
B35: 27 | C35: Joana Albertina Mango | E35: 11 | F35: 14 | H35: 11.7 | J35: =AVERAGE(E35,MAX(F35:G35),MAX(H35:I35)) -> 12.233333 | K35: =IF(J35>=10,"TRANSITA","N/TRANSITA") -> TRANSITA | L35: 10 | M35: 9 | O35: 8 | Q35: =AVERAGE(L35,MAX(M35:N35),MAX(O35:P35)) -> 9 | R35: =IF(Q35>=10,"TRANSITA","N/TRANSITA") -> N/TRANSITA | X35: =AVERAGE(S35,MAX(T35:U35),MAX(V35:W35)) -> 0 | Y35: =SUM(J35,Q35,X35)/3 -> 7.0777778 | Z35: =IF(Y35>=10,"TRANSITA","N/TRANSITA") -> N/TRANSITA
B36: 28 | C36: Joana Laura Futi Muana | E36: 10 | F36: 12 | H36: 8.5 | J36: =AVERAGE(E36,MAX(F36:G36),MAX(H36:I36)) -> 10.166667 | K36: =IF(J36>=10,"TRANSITA","N/TRANSITA") -> TRANSITA | L36: 11 | M36: 8 | O36: 11.5 | Q36: =AVERAGE(L36,MAX(M36:N36),MAX(O36:P36)) -> 10.166667 | R36: =IF(Q36>=10,"TRANSITA","N/TRANSITA") -> TRANSITA | X36: =AVERAGE(S36,MAX(T36:U36),MAX(V36:W36)) -> 0 | Y36: =SUM(J36,Q36,X36)/3 -> 6.7777778 | Z36: =IF(Y36>=10,"TRANSITA","N/TRANSITA") -> N/TRANSITA
B37: 29 | C37: Josefina Massanga Vumbi Goma | E37: 13 | F37: 16 | H37: 13.7 | J37: =AVERAGE(E37,MAX(F37:G37),MAX(H37:I37)) -> 14.233333 | K37: =IF(J37>=10,"TRANSITA","N/TRANSITA") -> TRANSITA | L37: 14 | M37: 17 | O37: 12 | Q37: =AVERAGE(L37,MAX(M37:N37),MAX(O37:P37)) -> 14.333333 | R37: =IF(Q37>=10,"TRANSITA","N/TRANSITA") -> TRANSITA | X37: =AVERAGE(S37,MAX(T37:U37),MAX(V37:W37)) -> 0 | Y37: =SUM(J37,Q37,X37)/3 -> 9.5222222 | Z37: =IF(Y37>=10,"TRANSITA","N/TRANSITA") -> N/TRANSITA
B38: 30 | C38: Jurema Bernadete Nsunda | E38: 12 | F38: 15 | H38: 14.5 | J38: =AVERAGE(E38,MAX(F38:G38),MAX(H38:I38)) -> 13.833333 | K38: =IF(J38>=10,"TRANSITA","N/TRANSITA") -> TRANSITA | L38: 13 | M38: 16.5 | O38: 10.5 | Q38: =AVERAGE(L38,MAX(M38:N38),MAX(O38:P38)) -> 13.333333 | R38: =IF(Q38>=10,"TRANSITA","N/TRANSITA") -> TRANSITA | X38: =AVERAGE(S38,MAX(T38:U38),MAX(V38:W38)) -> 0 | Y38: =SUM(J38,Q38,X38)/3 -> 9.0555556 | Z38: =IF(Y38>=10,"TRANSITA","N/TRANSITA") -> N/TRANSITA
B39: 31 | C39: Madalena Lando António | E39: 11 | F39: 11 | H39: 11 | J39: =AVERAGE(E39,MAX(F39:G39),MAX(H39:I39)) -> 11 | K39: =IF(J39>=10,"TRANSITA","N/TRANSITA") -> TRANSITA | L39: 12 | M39: 14 | O39: 8.5 | Q39: =AVERAGE(L39,MAX(M39:N39),MAX(O39:P39)) -> 11.5 | R39: =IF(Q39>=10,"TRANSITA","N/TRANSITA") -> TRANSITA | X39: =AVERAGE(S39,MAX(T39:U39),MAX(V39:W39)) -> 0 | Y39: =SUM(J39,Q39,X39)/3 -> 7.5 | Z39: =IF(Y39>=10,"TRANSITA","N/TRANSITA") -> N/TRANSITA
B40: 32 | C40: Marcos Nduli Sechie Gouveia | E40: 14 | F40: 15 | H40: 16.5 | J40: =AVERAGE(E40,MAX(F40:G40),MAX(H40:I40)) -> 15.166667 | K40: =IF(J40>=10,"TRANSITA","N/TRANSITA") -> TRANSITA | L40: 14 | M40: 17.5 | O40: 12 | Q40: =AVERAGE(L40,MAX(M40:N40),MAX(O40:P40)) -> 14.5 | R40: =IF(Q40>=10,"TRANSITA","N/TRANSITA") -> TRANSITA | X40: =AVERAGE(S40,MAX(T40:U40),MAX(V40:W40)) -> 0 | Y40: =SUM(J40,Q40,X40)/3 -> 9.8888889 | Z40: =IF(Y40>=10,"TRANSITA","N/TRANSITA") -> N/TRANSITA
... B52: 44 | C52: Teresa Gertrudes Luzia Tati | E52: 10 | F52: 12 | H52: 12.7 | J52: =AVERAGE(E52,MAX(F52:G52),MAX(H52:I52)) -> 11.566667 | K52: =IF(J52>=10,"TRANSITA","N/TRANSITA") -> TRANSITA | L52: 12 | M52: 12 | O52: 9 | Q52: =AVERAGE(L52,MAX(M52:N52),MAX(O52:P52)) -> 11 | R52: =IF(Q52>=10,"TRANSITA","N/TRANSITA") -> TRANSITA | X52: =AVERAGE(S52,MAX(T52:U52),MAX(V52:W52)) -> 0 | Y52: =SUM(J52,Q52,X52)/3 -> 7.5222222 | Z52: =IF(Y52>=10,"TRANSITA","N/TRANSITA") -> N/TRANSITA
A55: O (A) Professor (a) | S55: O Subdirector Pedagógico
A56: _______________________________ | S56: ___________________________
S57: ALBERTO SASSA TATI

Sheet 11CL-AC-A-MAT
A1: INSTITUTO TÉCNICO PRIVADO DE SAÚDE JOMORAIS
I3: DATA: 12/12/2025
B4: Classe: 11ª | I4: Disciplina: Matemática | V4: Ano Lectivo:2025/2026
B5: Período: Vespertino | E5: Turma: A | V5: Curso: ANÁLISES CLÍNICAS
B6: MINI-PAUTA - TÉCNICO DE SAÚDE
B7: Nº | C7: Nome do (a) Aluno (a) | D7: FALTAS | E7: Avaliações/I Trimestre | K7: OBS | L7: Avaliações/II Trimestre | R7: OBS | S7: Avaliações/IIITrimestre | Y7: MFD | Z7: OBS | AA7: M | AB7: F | AC7: TRANSITA | AD7: N/TRANSITA | AE7: E.E.F
D8: J/I | E8: MAC | F8: NPP | G8: NPR1 | H8: NPT | I8: NPR2 | J8: MT1 | L8: MAC | M8: NPP | N8: NPR1 | O8: NPT | P8: NPR2 | Q8: MT2 | S8: MAC | T8: NPP | U8: NPR1 | V8: NPT | W8: NPR2 | X8: MT3 | AA8: =COUNTIF(Z9:Z58,"M") -> 0 | AB8: =COUNTIF(Z9:Z58,"F") -> 0 | AC8: =COUNTIF(Z9:Z58,"TRANSITA") -> 12 | AD8: =COUNTIF(Z9:Z58,"N/TRANSITA") -> 32 | AE8: =COUNTIF(Z9:Z58,"E.E.F") -> 0
B9: 1 | C9: Abrão Gomes | E9: 11 | F9: 16 | H9: 4 | J9: =AVERAGE(E9,MAX(F9:G9),MAX(H9:I9)) -> 10.333333 | K9: =IF(J9>=10,"TRANSITA","N/TRANSITA") -> TRANSITA | L9: 20 | M9: 20 | O9: 10 | Q9: =AVERAGE(L9,MAX(M9:N9),MAX(O9:P9)) -> 16.666667 | R9: =IF(Q9>=10,"TRANSITA","N/TRANSITA") -> TRANSITA | X9: =AVERAGE(S9,MAX(T9:U9),MAX(V9:W9)) -> 0 | Y9: =SUM(J9,Q9,X9)/3 -> 9 | Z9: =IF(Y9>=10,"TRANSITA","N/TRANSITA") -> N/TRANSITA
B10: 2 | C10: Agostinho Mbaki Baza | E10: 18 | F10: 20 | H10: 20 | J10: =AVERAGE(E10,MAX(F10:G10),MAX(H10:I10)) -> 19.333333 | K10: =IF(J10>=10,"TRANSITA","N/TRANSITA") -> TRANSITA | L10: 20 | M10: 20 | O10: 19 | Q10: =AVERAGE(L10,MAX(M10:N10),MAX(O10:P10)) -> 19.666667 | R10: =IF(Q10>=10,"TRANSITA","N/TRANSITA") -> TRANSITA | X10: =AVERAGE(S10,MAX(T10:U10),MAX(V10:W10)) -> 0 | Y10: =SUM(J10,Q10,X10)/3 -> 13 | Z10: =IF(Y10>=10,"TRANSITA","N/TRANSITA") -> TRANSITA | AA10: =SUM(AA8:AB9) -> 0
B11: 3 | C11: Albertina Vumbi Bazunga | E11: 11 | F11: 19 | H11: 5 | J11: =AVERAGE(E11,MAX(F11:G11),MAX(H11:I11)) -> 11.666667 | K11: =IF(J11>=10,"TRANSITA","N/TRANSITA") -> TRANSITA | L11: 20 | M11: 20 | O11: 9 | Q11: =AVERAGE(L11,MAX(M11:N11),MAX(O11:P11)) -> 16.333333 | R11: =IF(Q11>=10,"TRANSITA","N/TRANSITA") -> TRANSITA | X11: =AVERAGE(S11,MAX(T11:U11),MAX(V11:W11)) -> 0 | Y11: =SUM(J11,Q11,X11)/3 -> 9.3333333 | Z11: =IF(Y11>=10,"TRANSITA","N/TRANSITA") -> N/TRANSITA
B12: 4 | C12: Alberto Mambo Simba | E12: 14 | F12: 20 | H12: 12 | J12: =AVERAGE(E12,MAX(F12:G12),MAX(H12:I12)) -> 15.333333 | K12: =IF(J12>=10,"TRANSITA","N/TRANSITA") -> TRANSITA | L12: 20 | M12: 20 | O12: 19 | Q12: =AVERAGE(L12,MAX(M12:N12),MAX(O12:P12)) -> 19.666667 | R12: =IF(Q12>=10,"TRANSITA","N/TRANSITA") -> TRANSITA | X12: =AVERAGE(S12,MAX(T12:U12),MAX(V12:W12)) -> 0 | Y12: =SUM(J12,Q12,X12)/3 -> 11.666667 | Z12: =IF(Y12>=10,"TRANSITA","N/TRANSITA") -> TRANSITA
B13: 5 | C13: Alda Catarina Mamata Balou | E13: 10 | F13: 11 | H13: 9 | J13: =AVERAGE(E13,MAX(F13:G13),MAX(H13:I13)) -> 10 | K13: =IF(J13>=10,"TRANSITA","N/TRANSITA") -> TRANSITA | L13: 20 | M13: 2 | O13: 4 | Q13: =AVERAGE(L13,MAX(M13:N13),MAX(O13:P13)) -> 8.6666667 | R13: =IF(Q13>=10,"TRANSITA","N/TRANSITA") -> N/TRANSITA | X13: =AVERAGE(S13,MAX(T13:U13),MAX(V13:W13)) -> 0 | Y13: =SUM(J13,Q13,X13)/3 -> 6.2222222 | Z13: =IF(Y13>=10,"TRANSITA","N/TRANSITA") -> N/TRANSITA
B14: 6 | C14: Alice Bitumba Mavungo | E14: 6 | F14: 16 | H14: 10 | J14: =AVERAGE(E14,MAX(F14:G14),MAX(H14:I14)) -> 10.666667 | K14: =IF(J14>=10,"TRANSITA","N/TRANSITA") -> TRANSITA | L14: 10 | M14: 20 | O14: 11 | Q14: =AVERAGE(L14,MAX(M14:N14),MAX(O14:P14)) -> 13.666667 | R14: =IF(Q14>=10,"TRANSITA","N/TRANSITA") -> TRANSITA | X14: =AVERAGE(S14,MAX(T14:U14),MAX(V14:W14)) -> 0 | Y14: =SUM(J14,Q14,X14)/3 -> 8.1111111 | Z14: =IF(Y14>=10,"TRANSITA","N/TRANSITA") -> N/TRANSITA
B15: 7 | C15: Amélia Chibamba Chiama | E15: 11 | F15: 12 | H15: 7 | J15: =AVERAGE(E15,MAX(F15:G15),MAX(H15:I15)) -> 10 | K15: =IF(J15>=10,"TRANSITA","N/TRANSITA") -> TRANSITA | L15: 11 | M15: 17 | O15: 13 | Q15: =AVERAGE(L15,MAX(M15:N15),MAX(O15:P15)) -> 13.666667 | R15: =IF(Q15>=10,"TRANSITA","N/TRANSITA") -> TRANSITA | X15: =AVERAGE(S15,MAX(T15:U15),MAX(V15:W15)) -> 0 | Y15: =SUM(J15,Q15,X15)/3 -> 7.8888889 | Z15: =IF(Y15>=10,"TRANSITA","N/TRANSITA") -> N/TRANSITA
B16: 8 | C16: Ana De Jesus Custódio Sambo | E16: 12 | F16: 18 | H16: 5 | J16: =AVERAGE(E16,MAX(F16:G16),MAX(H16:I16)) -> 11.666667 | K16: =IF(J16>=10,"TRANSITA","N/TRANSITA") -> TRANSITA | L16: 10 | M16: 20 | O16: 9 | Q16: =AVERAGE(L16,MAX(M16:N16),MAX(O16:P16)) -> 13 | R16: =IF(Q16>=10,"TRANSITA","N/TRANSITA") -> TRANSITA | X16: =AVERAGE(S16,MAX(T16:U16),MAX(V16:W16)) -> 0 | Y16: =SUM(J16,Q16,X16)/3 -> 8.2222222 | Z16: =IF(Y16>=10,"TRANSITA","N/TRANSITA") -> N/TRANSITA
B17: 9 | C17: Ana Soca Deca Luba | E17: 5 | F17: 8 | H17: 0 | J17: =AVERAGE(E17,MAX(F17:G17),MAX(H17:I17)) -> 4.3333333 | K17: =IF(J17>=10,"TRANSITA","N/TRANSITA") -> N/TRANSITA | L17: 10 | M17: 20 | O17: 2 | Q17: =AVERAGE(L17,MAX(M17:N17),MAX(O17:P17)) -> 10.666667 | R17: =IF(Q17>=10,"TRANSITA","N/TRANSITA") -> TRANSITA | X17: =AVERAGE(S17,MAX(T17:U17),MAX(V17:W17)) -> 0 | Y17: =SUM(J17,Q17,X17)/3 -> 5 | Z17: =IF(Y17>=10,"TRANSITA","N/TRANSITA") -> N/TRANSITA
B18: 10 | C18: Angelina Buanga Poba | E18: 7 | F18: 6 | H18: 4 | J18: =AVERAGE(E18,MAX(F18:G18),MAX(H18:I18)) -> 5.6666667 | K18: =IF(J18>=10,"TRANSITA","N/TRANSITA") -> N/TRANSITA | L18: 20 | M18: 20 | O18: 4 | Q18: =AVERAGE(L18,MAX(M18:N18),MAX(O18:P18)) -> 14.666667 | R18: =IF(Q18>=10,"TRANSITA","N/TRANSITA") -> TRANSITA | X18: =AVERAGE(S18,MAX(T18:U18),MAX(V18:W18)) -> 0 | Y18: =SUM(J18,Q18,X18)/3 -> 6.7777778 | Z18: =IF(Y18>=10,"TRANSITA","N/TRANSITA") -> N/TRANSITA
B19: 11 | C19: Antoaneta Menga Futi Gime | E19: 11 | F19: 13 | H19: 7 | J19: =AVERAGE(E19,MAX(F19:G19),MAX(H19:I19)) -> 10.333333 | K19: =IF(J19>=10,"TRANSITA","N/TRANSITA") -> TRANSITA | L19: 20 | M19: 20 | O19: 12 | Q19: =AVERAGE(L19,MAX(M19:N19),MAX(O19:P19)) -> 17.333333 | R19: =IF(Q19>=10,"TRANSITA","N/TRANSITA") -> TRANSITA | X19: =AVERAGE(S19,MAX(T19:U19),MAX(V19:W19)) -> 0 | Y19: =SUM(J19,Q19,X19)/3 -> 9.2222222 | Z19: =IF(Y19>=10,"TRANSITA","N/TRANSITA") -> N/TRANSITA
B20: 12 | C20: Arinalda De Canatividade Prata Bungo | E20: 14 | F20: 20 | H20: 15 | J20: =AVERAGE(E20,MAX(F20:G20),MAX(H20:I20)) -> 16.333333 | K20: =IF(J20>=10,"TRANSITA","N/TRANSITA") -> TRANSITA | L20: 20 | M20: 20 | O20: 18 | Q20: =AVERAGE(L20,MAX(M20:N20),MAX(O20:P20)) -> 19.333333 | R20: =IF(Q20>=10,"TRANSITA","N/TRANSITA") -> TRANSITA | X20: =AVERAGE(S20,MAX(T20:U20),MAX(V20:W20)) -> 0 | Y20: =SUM(J20,Q20,X20)/3 -> 11.888889 | Z20: =IF(Y20>=10,"TRANSITA","N/TRANSITA") -> TRANSITA
B21: 13 | C21: Basílio Araújo Simba Mabiala | E21: 14 | F21: 19 | H21: 18 | J21: =AVERAGE(E21,MAX(F21:G21),MAX(H21:I21)) -> 17 | K21: =IF(J21>=10,"TRANSITA","N/TRANSITA") -> TRANSITA | L21: 20 | M21: 20 | O21: 18 | Q21: =AVERAGE(L21,MAX(M21:N21),MAX(O21:P21)) -> 19.333333 | R21: =IF(Q21>=10,"TRANSITA","N/TRANSITA") -> TRANSITA | X21: =AVERAGE(S21,MAX(T21:U21),MAX(V21:W21)) -> 0 | Y21: =SUM(J21,Q21,X21)/3 -> 12.111111 | Z21: =IF(Y21>=10,"TRANSITA","N/TRANSITA") -> TRANSITA
B22: 14 | C22: Carlota Mbungo Conde | E22: 6 | F22: 4 | H22: 5 | J22: =AVERAGE(E22,MAX(F22:G22),MAX(H22:I22)) -> 5 | K22: =IF(J22>=10,"TRANSITA","N/TRANSITA") -> N/TRANSITA | L22: 10 | M22: 20 | O22: 6 | Q22: =AVERAGE(L22,MAX(M22:N22),MAX(O22:P22)) -> 12 | R22: =IF(Q22>=10,"TRANSITA","N/TRANSITA") -> TRANSITA | X22: =AVERAGE(S22,MAX(T22:U22),MAX(V22:W22)) -> 0 | Y22: =SUM(J22,Q22,X22)/3 -> 5.6666667 | Z22: =IF(Y22>=10,"TRANSITA","N/TRANSITA") -> N/TRANSITA
