Workbook

Sheet EDITAL - 10ª CFB-UNICA (I TRIM)
A1: COMPLEXO ESCOLAR PRIVADO JOMORAIS
C3: Visto
C4: Director do Complexo
C6: GABRIEL PRÓSPERO MABIALA
A7: Ano Lectivo: 2025-2026 10ª Classe Turma: Única Sala: C5 Período: Matinal I Trimestre
A8: CURSO: CIÊNCIAS FÍSICAS E BIOLÓGICAS
A9: N◦ | B9: Nº MATRI | C9: NOME COMPLETO | D9: DISCIPLINAS | M9: Observação | N9: MÉDIA | P9: DADOS ESTATÍSTICOS
D10: L.Port. | E10: Inglês | F10: Mat. | G10: Infor. | H10: Ed. Fis. | I10: Fís. | J10: Qca | K10: Biol. | L10: Emp. | O10: Género | P10: MATRICULADOS | R10: TRANSITA | T10: N/TRANSITA | V10: Desistido/a
A11: 1 | B11: 4562 | C11: Adelina Malonda Poba | D11: =SUM('10ªCFB-U-L PORT'!H9) -> 10 | E11: =SUM('10ªCFB-U-INGLES'!H9) -> 12.5 | F11: =SUM('10ªCFB-U-MAT'!H9) -> 13 | G11: =SUM('10ªCFB-U-INFOR'!H9) -> 14.5 | H11: =SUM('10ªCFB-U-ED. FIS'!H9) -> 16 | I11: =SUM('10ªCFB-U-FIS'!H9) -> 9 | J11: =SUM('10ªCFB-U-QCA'!H9) -> 10 | K11: =SUM('10ªCFB-U-BIOL'!H9) -> 12.5 | L11: =SUM('10ªCFB-U-EMPREEND'!H9) -> 14.25 | M11: N/TRANSITA | N11: =AVERAGE(D11:L11) -> 12.416667 | O11: F | P11: M | Q11: F | R11: M | S11: F | T11: M | U11: F | V11: M | W11: F
A12: 2 | B12: 4637 | C12: Adelina Marques Zau | D12: =SUM('10ªCFB-U-L PORT'!H10) -> 11 | E12: =SUM('10ªCFB-U-INGLES'!H10) -> 12 | F12: =SUM('10ªCFB-U-MAT'!H10) -> 6.5 | G12: =SUM('10ªCFB-U-INFOR'!H10) -> 12.5 | H12: =SUM('10ªCFB-U-ED. FIS'!H10) -> 12 | I12: =SUM('10ªCFB-U-FIS'!H10) -> 10.25 | J12: =SUM('10ªCFB-U-QCA'!H10) -> 10 | K12: =SUM('10ªCFB-U-BIOL'!H10) -> 10.5 | L12: =SUM('10ªCFB-U-EMPREEND'!H10) -> 13.75 | M12: N/TRANSITA | N12: =AVERAGE(D12:L12) -> 10.944444 | O12: F | P12: =COUNTIF(O11:O73,"M") -> 11 | Q12: =COUNTIF(O11:O73,"F") -> 52 | R12: =COUNTIFS(M11:M73,"Transita",O11:O73,"M") -> 3 | S12: =COUNTIFS(M11:M73,"Transita",O11:O73,"F") -> 7 | T12: =COUNTIFS(M11:M73,"N/Transita",O11:O73,"M") -> 7 | U12: =COUNTIFS(M11:M73,"N/Transita",O11:O73,"F") -> 33 | V12: =COUNTIFS(M11:M73,"DESISTIDO",O11:O73,"M") -> 1 | W12: =COUNTIFS(M11:M73,"DESISTIDA",O11:O73,"F") -> 12
A13: 3 | B13: 4538 | C13: Albertina Eduardo Macosso | D13: =SUM('10ªCFB-U-L PORT'!H11) -> 12.75 | E13: =SUM('10ªCFB-U-INGLES'!H11) -> 15 | F13: =SUM('10ªCFB-U-MAT'!H11) -> 13.5 | G13: =SUM('10ªCFB-U-INFOR'!H11) -> 11.5 | H13: =SUM('10ªCFB-U-ED. FIS'!H11) -> 17 | I13: =SUM('10ªCFB-U-FIS'!H11) -> 12 | J13: =SUM('10ªCFB-U-QCA'!H11) -> 10 | K13: =SUM('10ªCFB-U-BIOL'!H11) -> 17.5 | L13: =SUM('10ªCFB-U-EMPREEND'!H11) -> 10 | M13: TRANSITA | N13: =AVERAGE(D13:L13) -> 13.25 | O13: M | P13: =SUM(P12:Q12) -> 63 | R13: =SUM(R11:S12) -> 10 | T13: =SUM(T11:U12) -> 40 | V13: =SUM(V11:W12) -> 13
A14: 4 | B14: 4146 | C14: Albertina Muanda Salvador Biala | D14: =SUM('10ªCFB-U-L PORT'!H12) -> 6.25 | E14: =SUM('10ªCFB-U-INGLES'!H12) -> 7.5 | F14: =SUM('10ªCFB-U-MAT'!H12) -> 5.5 | G14: =SUM('10ªCFB-U-INFOR'!H12) -> 7.75 | H14: =SUM('10ªCFB-U-ED. FIS'!H12) -> 15 | I14: =SUM('10ªCFB-U-FIS'!H12) -> 5.25 | J14: =SUM('10ªCFB-U-QCA'!H12) -> 15 | K14: =SUM('10ªCFB-U-BIOL'!H12) -> 8 | L14: =SUM('10ªCFB-U-EMPREEND'!H12) -> 5.5 | M14: N/TRANSITA | N14: =AVERAGE(D14:L14) -> 8.4166667 | O14: F
A15: 5 | B15: 4651 | C15: Alberto Pucuta Luemba Mambuco | D15: =SUM('10ªCFB-U-L PORT'!H13) -> 19 | E15: =SUM('10ªCFB-U-INGLES'!H13) -> 19 | F15: =SUM('10ªCFB-U-MAT'!H13) -> 20 | G15: =SUM('10ªCFB-U-INFOR'!H13) -> 20 | H15: =SUM('10ªCFB-U-ED. FIS'!H13) -> 17 | I15: =SUM('10ªCFB-U-FIS'!H13) -> 15.5 | J15: =SUM('10ªCFB-U-QCA'!H13) -> 18 | K15: =SUM('10ªCFB-U-BIOL'!H13) -> 18.5 | L15: =SUM('10ªCFB-U-EMPREEND'!H13) -> 15.25 | M15: TRANSITA | N15: =AVERAGE(D15:L15) -> 18.027778 | O15: F
A16: 6 | B16: 4553 | C16: Alexandre Coto Ndombe Puati | D16: =SUM('10ªCFB-U-L PORT'!H14) -> 11 | E16: =SUM('10ªCFB-U-INGLES'!H14) -> 15 | F16: =SUM('10ªCFB-U-MAT'!H14) -> 11.5 | G16: =SUM('10ªCFB-U-INFOR'!H14) -> 10 | H16: =SUM('10ªCFB-U-ED. FIS'!H14) -> 8 | I16: =SUM('10ªCFB-U-FIS'!H14) -> 6.75 | J16: =SUM('10ªCFB-U-QCA'!H14) -> 10 | K16: =SUM('10ªCFB-U-BIOL'!H14) -> 10 | L16: =SUM('10ªCFB-U-EMPREEND'!H14) -> 5.5 | M16: N/TRANSITA | N16: =AVERAGE(D16:L16) -> 9.75 | O16: M | Q16: MÁXIMA | R16: =MAX(N11:N74) -> 18.027778
A17: 7 | B17: 2450 | C17: Alice Isabel Maria Muginga | D17: =SUM('10ªCFB-U-L PORT'!H15) -> 6.5 | E17: =SUM('10ªCFB-U-INGLES'!H15) -> 9.5 | F17: =SUM('10ªCFB-U-MAT'!H15) -> 13 | G17: =SUM('10ªCFB-U-INFOR'!H15) -> 6.75 | H17: =SUM('10ªCFB-U-ED. FIS'!H15) -> 8 | I17: =SUM('10ªCFB-U-FIS'!H15) -> 11.5 | J17: =SUM('10ªCFB-U-QCA'!H15) -> 9 | K17: =SUM('10ªCFB-U-BIOL'!H15) -> 9 | L17: =SUM('10ªCFB-U-EMPREEND'!H15) -> 8.25 | M17: N/TRANSITA | N17: =AVERAGE(D17:L17) -> 9.0555556 | O17: F
A18: 8 | B18: 4580 | C18: Angelica Celina Domingos | D18: =SUM('10ªCFB-U-L PORT'!H16) -> 8.5 | E18: =SUM('10ªCFB-U-INGLES'!H16) -> 11.5 | F18: =SUM('10ªCFB-U-MAT'!H16) -> 7 | G18: =SUM('10ªCFB-U-INFOR'!H16) -> 8 | H18: =SUM('10ªCFB-U-ED. FIS'!H16) -> 14 | I18: =SUM('10ªCFB-U-FIS'!H16) -> 10.5 | J18: =SUM('10ªCFB-U-QCA'!H16) -> 9 | K18: =SUM('10ªCFB-U-BIOL'!H16) -> 9 | L18: =SUM('10ªCFB-U-EMPREEND'!H16) -> 12 | M18: N/TRANSITA | N18: =AVERAGE(D18:L18) -> 9.9444444 | O18: F | Q18: NOME DO/A ALUNO/A | T18: Madalena Simba Mavinga Maciala
A19: 9 | B19: 4605 | C19: António Diela | D19: =SUM('10ªCFB-U-L PORT'!H17) -> 8.75 | E19: =SUM('10ªCFB-U-INGLES'!H17) -> 14.5 | F19: =SUM('10ªCFB-U-MAT'!H17) -> 13.5 | G19: =SUM('10ªCFB-U-INFOR'!H17) -> 11.25 | H19: =SUM('10ªCFB-U-ED. FIS'!H17) -> 15 | I19: =SUM('10ªCFB-U-FIS'!H17) -> 8 | J19: =SUM('10ªCFB-U-QCA'!H17) -> 10 | K19: =SUM('10ªCFB-U-BIOL'!H17) -> 15 | L19: =SUM('10ªCFB-U-EMPREEND'!H17) -> 11.25 | M19: N/TRANSITA | N19: =AVERAGE(D19:L19) -> 11.916667 | O19: M | Q19: IDADE: | R19: 12
A20: 10 | B20: 4295 | C20: António Ngimbi Capita | D20: =SUM('10ªCFB-U-L PORT'!H18) -> 0 | E20: =SUM('10ªCFB-U-INGLES'!H18) -> 8.5 | F20: =SUM('10ªCFB-U-MAT'!H18) -> 4 | G20: =SUM('10ªCFB-U-INFOR'!H18) -> 10 | H20: =SUM('10ªCFB-U-ED. FIS'!H18) -> 0 | I20: =SUM('10ªCFB-U-FIS'!H18) -> 3.75 | J20: =SUM('10ªCFB-U-QCA'!H18) -> 9 | K20: =SUM('10ªCFB-U-BIOL'!H18) -> 5 | L20: =SUM('10ªCFB-U-EMPREEND'!H18) -> 5.5 | M20: N/TRANSITA | N20: =AVERAGE(D20:L20) -> 5.0833333 | O20: M | R20: ANOS
A21: 11 | B21: 4594 | C21: Bernicia Mussitu | D21: =SUM('10ªCFB-U-L PORT'!H19) -> 0 | E21: =SUM('10ªCFB-U-INGLES'!H19) -> 0 | F21: =SUM('10ªCFB-U-MAT'!H19) -> 0 | G21: =SUM('10ªCFB-U-INFOR'!H19) -> 0 | H21: =SUM('10ªCFB-U-ED. FIS'!H19) -> 0 | I21: =SUM('10ªCFB-U-FIS'!H19) -> 0 | J21: =SUM('10ªCFB-U-QCA'!H19) -> 5 | K21: =SUM('10ªCFB-U-BIOL'!H19) -> 0 | L21: =SUM('10ªCFB-U-EMPREEND'!H19) -> 0 | M21: DESISTIDA | N21: =AVERAGE(D21:L21) -> 0.55555556 | O21: F
A22: 12 | B22: 4566 | C22: Candida Da Silva Sambo | D22: =SUM('10ªCFB-U-L PORT'!H20) -> 14.5 | E22: =SUM('10ªCFB-U-INGLES'!H20) -> 15.5 | F22: =SUM('10ªCFB-U-MAT'!H20) -> 12.5 | G22: =SUM('10ªCFB-U-INFOR'!H20) -> 12.4 | H22: =SUM('10ªCFB-U-ED. FIS'!H20) -> 15 | I22: =SUM('10ªCFB-U-FIS'!H20) -> 13.25 | J22: =SUM('10ªCFB-U-QCA'!H20) -> 12 | K22: =SUM('10ªCFB-U-BIOL'!H20) -> 15 | L22: =SUM('10ªCFB-U-EMPREEND'!H20) -> 12.5 | M22: TRANSITA | N22: =AVERAGE(D22:L22) -> 13.627778 | O22: F
A23: 13 | B23: 4667 | C23: Catarina Kiaba Maluta | D23: =SUM('10ªCFB-U-L PORT'!H21) -> 0 | E23: =SUM('10ªCFB-U-INGLES'!H21) -> 0 | F23: =SUM('10ªCFB-U-MAT'!H21) -> 0 | G23: =SUM('10ªCFB-U-INFOR'!H21) -> 5 | H23: =SUM('10ªCFB-U-ED. FIS'!H21) -> 0 | I23: =SUM('10ªCFB-U-FIS'!H21) -> 0 | J23: =SUM('10ªCFB-U-QCA'!H21) -> 5 | K23: =SUM('10ªCFB-U-BIOL'!H21) -> 0 | L23: =SUM('10ªCFB-U-EMPREEND'!H21) -> 0 | M23: DESISTIDA | N23: =AVERAGE(D23:L23) -> 1.1111111 | O23: F
A24: 14 | B24: 3964 | C24: Cristiana Jemina Macanda | D24: =SUM('10ªCFB-U-L PORT'!H22) -> 0 | E24: =SUM('10ªCFB-U-INGLES'!H22) -> 0 | F24: =SUM('10ªCFB-U-MAT'!H22) -> 0 | G24: =SUM('10ªCFB-U-INFOR'!H22) -> 0 | H24: =SUM('10ªCFB-U-ED. FIS'!H22) -> 0 | I24: =SUM('10ªCFB-U-FIS'!H22) -> 0 | J24: =SUM('10ªCFB-U-QCA'!H22) -> 5 | K24: =SUM('10ªCFB-U-BIOL'!H22) -> 0 | L24: =SUM('10ªCFB-U-EMPREEND'!H22) -> 0 | M24: DESISTIDA | N24: =AVERAGE(D24:L24) -> 0.55555556 | O24: F
A25: 15 | B25: 4593 | C25: Debora Antonio Bumba Bilongo | D25: =SUM('10ªCFB-U-L PORT'!H23) -> 13.5 | E25: =SUM('10ªCFB-U-INGLES'!H23) -> 14.5 | F25: =SUM('10ªCFB-U-MAT'!H23) -> 16.5 | G25: =SUM('10ªCFB-U-INFOR'!H23) -> 16.5 | H25: =SUM('10ªCFB-U-ED. FIS'!H23) -> 16 | I25: =SUM('10ªCFB-U-FIS'!H23) -> 11.25 | J25: =SUM('10ªCFB-U-QCA'!H23) -> 14 | K25: =SUM('10ªCFB-U-BIOL'!H23) -> 18 | L25: =SUM('10ªCFB-U-EMPREEND'!H23) -> 14.25 | M25: TRANSITA | N25: =AVERAGE(D25:L25) -> 14.944444 | O25: F
A26: 16 | B26: 4577 | C26: Elisa Do Nascimento Cumbo | D26: =SUM('10ªCFB-U-L PORT'!H24) -> 12.5 | E26: =SUM('10ªCFB-U-INGLES'!H24) -> 13.5 | F26: =SUM('10ªCFB-U-MAT'!H24) -> 10 | G26: =SUM('10ªCFB-U-INFOR'!H24) -> 12.55 | H26: =SUM('10ªCFB-U-ED. FIS'!H24) -> 16 | I26: =SUM('10ªCFB-U-FIS'!H24) -> 10.75 | J26: =SUM('10ªCFB-U-QCA'!H24) -> 12.5 | K26: =SUM('10ªCFB-U-BIOL'!H24) -> 16 | L26: =SUM('10ªCFB-U-EMPREEND'!H24) -> 15 | M26: TRANSITA | N26: =AVERAGE(D26:L26) -> 13.2 | O26: M
A27: 17 | B27: 4584 | C27: Elizabeth Nsuami Casimiro | D27: =SUM('10ªCFB-U-L PORT'!H25) -> 10 | E27: =SUM('10ªCFB-U-INGLES'!H25) -> 11.5 | F27: =SUM('10ªCFB-U-MAT'!H25) -> 14 | G27: =SUM('10ªCFB-U-INFOR'!H25) -> 10.5 | H27: =SUM('10ªCFB-U-ED. FIS'!H25) -> 14 | I27: =SUM('10ªCFB-U-FIS'!H25) -> 8 | J27: =SUM('10ªCFB-U-QCA'!H25) -> 10 | K27: =SUM('10ªCFB-U-BIOL'!H25) -> 14.5 | L27: =SUM('10ªCFB-U-EMPREEND'!H25) -> 10.5 | M27: N/TRANSITA | N27: =AVERAGE(D27:L27) -> 11.444444 | O27: F
A28: 18 | B28: 4590 | C28: Elizabeth Simba Mbonzo | D28: =SUM('10ªCFB-U-L PORT'!H26) -> 0 | E28: =SUM('10ªCFB-U-INGLES'!H26) -> 10.5 | F28: =SUM('10ªCFB-U-MAT'!H26) -> 5.5 | G28: =SUM('10ªCFB-U-INFOR'!H26) -> 0 | H28: =SUM('10ªCFB-U-ED. FIS'!H26) -> 15 | I28: =SUM('10ªCFB-U-FIS'!H26) -> 0 | J28: =SUM('10ªCFB-U-QCA'!H26) -> 0 | K28: =SUM('10ªCFB-U-BIOL'!H26) -> 0 | L28: =SUM('10ªCFB-U-EMPREEND'!H26) -> 0 | M28: N/TRANSITA | N28: =AVERAGE(D28:L28) -> 3.4444444 | O28: F
A29: 19 | B29: 4546 | C29: Ermelinda Chibinda Paulino | D29: =SUM('10ªCFB-U-L PORT'!H27) -> 0 | E29: =SUM('10ªCFB-U-INGLES'!H27) -> 0 | F29: =SUM('10ªCFB-U-MAT'!H27) -> 0 | G29: =SUM('10ªCFB-U-INFOR'!H27) -> 0 | H29: =SUM('10ªCFB-U-ED. FIS'!H27) -> 0 | I29: =SUM('10ªCFB-U-FIS'!H27) -> 11.5 | J29: =SUM('10ªCFB-U-QCA'!H27) -> 5 | K29: =SUM('10ªCFB-U-BIOL'!H27) -> 0 | L29: =SUM('10ªCFB-U-EMPREEND'!H27) -> 0 | M29: N/TRANSITA | N29: =AVERAGE(D29:L29) -> 1.8333333 | O29: F
A30: 20 | B30: 4631 | C30: Esperança Monteiro Ernesto | D30: =SUM('10ªCFB-U-L PORT'!H28) -> 11.75 | E30: =SUM('10ªCFB-U-INGLES'!H28) -> 15 | F30: =SUM('10ªCFB-U-MAT'!H28) -> 12 | G30: =SUM('10ªCFB-U-INFOR'!H28) -> 13.9 | H30: =SUM('10ªCFB-U-ED. FIS'!H28) -> 14 | I30: =SUM('10ªCFB-U-FIS'!H28) -> 14 | J30: =SUM('10ªCFB-U-QCA'!H28) -> 10.5 | K30: =SUM('10ªCFB-U-BIOL'!H28) -> 12.5 | L30: =SUM('10ªCFB-U-EMPREEND'!H28) -> 15.75 | M30: TRANSITA | N30: =AVERAGE(D30:L30) -> 13.266667 | O30: F
A31: 21 | B31: 2387 | C31: Eulália Simba Pedro Claver | D31: =SUM('10ªCFB-U-L PORT'!H29) -> 12.25 | E31: =SUM('10ªCFB-U-INGLES'!H29) -> 13 | F31: =SUM('10ªCFB-U-MAT'!H29) -> 6.5 | G31: =SUM('10ªCFB-U-INFOR'!H29) -> 7 | H31: =SUM('10ªCFB-U-ED. FIS'!H29) -> 16 | I31: =SUM('10ªCFB-U-FIS'!H29) -> 7.5 | J31: =SUM('10ªCFB-U-QCA'!H29) -> 9 | K31: =SUM('10ªCFB-U-BIOL'!H29) -> 5 | L31: =SUM('10ªCFB-U-EMPREEND'!H29) -> 2.5 | M31: N/TRANSITA | N31: =AVERAGE(D31:L31) -> 8.75 | O31: F
A32: 22 | B32: 4613 | C32: Filipina Bambi | D32: =SUM('10ªCFB-U-L PORT'!H30) -> 8.75 | E32: =SUM('10ªCFB-U-INGLES'!H30) -> 11 | F32: =SUM('10ªCFB-U-MAT'!H30) -> 5.5 | G32: =SUM('10ªCFB-U-INFOR'!H30) -> 13.5 | H32: =SUM('10ªCFB-U-ED. FIS'!H30) -> 15 | I32: =SUM('10ªCFB-U-FIS'!H30) -> 8.75 | J32: =SUM('10ªCFB-U-QCA'!H30) -> 10 | K32: =SUM('10ªCFB-U-BIOL'!H30) -> 12 | L32: =SUM('10ªCFB-U-EMPREEND'!H30) -> 9.5 | M32: N/TRANSITA | N32: =AVERAGE(D32:L32) -> 10.444444 | O32: F
... A73: 63 | B73: 4556 | C73: Zolina Massiala Cumba | D73: =SUM('10ªCFB-U-L PORT'!H71) -> 16.75 | E73: =SUM('10ªCFB-U-INGLES'!H71) -> 16.5 | F73: =SUM('10ªCFB-U-MAT'!H71) -> 8 | G73: =SUM('10ªCFB-U-INFOR'!H71) -> 12.75 | H73: =SUM('10ªCFB-U-ED. FIS'!H71) -> 15 | I73: =SUM('10ªCFB-U-FIS'!H71) -> 11.5 | J73: =SUM('10ªCFB-U-QCA'!H71) -> 11 | K73: =SUM('10ªCFB-U-BIOL'!H71) -> 14 | L73: =SUM('10ªCFB-U-EMPREEND'!H71) -> 15 | M73: N/TRANSITA | N73: =AVERAGE(D73:L73) -> 13.388889 | O73: F
A75: COMPLEXO ESCOLAR PRIVADO JOMORAIS, 8 de dezembro de 2025.-
A78: A Directora de Turma | K78: O Subdirector Pedagógico
A79: ______________________________ | K79: _____________________________
A80: ALICE DEOLINDA CHIAZI | K80: ALBERTO SASSA TATI

Sheet EDITAL - 10ª CFB-UNICA II TRIM
A1: COMPLEXO ESCOLAR PRIVADO JOMORAIS
C3: Visto
C4: Director do Complexo
C6: GABRIEL PRÓSPERO MABIALA
A7: Ano Lectivo: 2025-2026 10ª Classe Turma: Única Sala: C5 Período: Matinal II Trimestre
A8: CURSO: CIÊNCIAS FÍSICAS E BIOLÓGICAS
A9: N◦ | B9: Nº MATRI | C9: NOME COMPLETO | D9: DISCIPLINAS | M9: Observação | N9: MÉDIA | P9: DADOS ESTATÍSTICOS
D10: L.Port. | E10: Inglês | F10: Mat. | G10: Infor. | H10: Ed. Fis. | I10: Fís. | J10: Qca | K10: Biol. | L10: Emp. | O10: Género | P10: MATRICULADOS | R10: TRANSITA | T10: N/TRANSITA | V10: Desistido/a
A11: 1 | B11: 4562 | C11: Adelina Malonda Poba | D11: =SUM('10ªCFB-U-L PORT'!M9) -> 10 | E11: =SUM('10ªCFB-U-INGLES'!M9) -> 14 | F11: =SUM('10ªCFB-U-MAT'!M9) -> 13 | G11: =SUM('10ªCFB-U-INFOR'!M9) -> 16.25 | H11: =SUM('10ªCFB-U-ED. FIS'!M9) -> 15 | I11: =SUM('10ªCFB-U-FIS'!M9) -> 10 | J11: =SUM('10ªCFB-U-QCA'!M9) -> 13.5 | K11: =SUM('10ªCFB-U-BIOL'!M9) -> 16.5 | L11: =SUM('10ªCFB-U-EMPREEND'!M9) -> 7.5 | M11: N/TRANSITA | N11: =AVERAGE(D11:L11) -> 12.861111 | O11: F | P11: M | Q11: F | R11: M | S11: F | T11: M | U11: F | V11: M | W11: F
A12: 2 | B12: 4637 | C12: Adelina Marques Zau | D12: =SUM('10ªCFB-U-L PORT'!M10) -> 11 | E12: =SUM('10ªCFB-U-INGLES'!M10) -> 11 | F12: =SUM('10ªCFB-U-MAT'!M10) -> 13.5 | G12: =SUM('10ªCFB-U-INFOR'!M10) -> 11 | H12: =SUM('10ªCFB-U-ED. FIS'!M10) -> 0 | I12: =SUM('10ªCFB-U-FIS'!M10) -> 7.75 | J12: =SUM('10ªCFB-U-QCA'!M10) -> 5.5 | K12: =SUM('10ªCFB-U-BIOL'!M10) -> 15 | L12: =SUM('10ªCFB-U-EMPREEND'!M10) -> 8.5 | M12: N/TRANSITA | N12: =AVERAGE(D12:L12) -> 9.25 | O12: F | P12: =COUNTIF(O11:O73,"M") -> 11 | Q12: =COUNTIF(O11:O73,"F") -> 52 | R12: =COUNTIFS(M11:M73,"Transita",O11:O73,"M") -> 0 | S12: =COUNTIFS(M11:M73,"Transita",O11:O73,"F") -> 1 | T12: =COUNTIFS(M11:M73,"N/Transita",O11:O73,"M") -> 8 | U12: =COUNTIFS(M11:M73,"N/Transita",O11:O73,"F") -> 28 | V12: =COUNTIFS(M11:M73,"DESISTIDO",O11:O73,"M") -> 3 | W12: =COUNTIFS(M11:M73,"DESISTIDA",O11:O73,"F") -> 23
A13: 3 | B13: 4538 | C13: Albertina Eduardo Macosso | D13: =SUM('10ªCFB-U-L PORT'!M11) -> 10 | E13: =SUM('10ªCFB-U-INGLES'!M11) -> 11 | F13: =SUM('10ªCFB-U-MAT'!M11) -> 10 | G13: =SUM('10ªCFB-U-INFOR'!M11) -> 13 | H13: =SUM('10ªCFB-U-ED. FIS'!M11) -> 16 | I13: =SUM('10ªCFB-U-FIS'!M11) -> 7.75 | J13: =SUM('10ªCFB-U-QCA'!M11) -> 11.75 | K13: =SUM('10ªCFB-U-BIOL'!M11) -> 12 | L13: =SUM('10ªCFB-U-EMPREEND'!M11) -> 11.5 | M13: N/TRANSITA | N13: =AVERAGE(D13:L13) -> 11.444444 | O13: M | P13: =SUM(P12:Q12) -> 63 | R13: =SUM(R11:S12) -> 1 | T13: =SUM(T11:U12) -> 36 | V13: =SUM(V11:W12) -> 26
A14: 4 | B14: 4146 | C14: Albertina Muanda Salvador Biala | D14: =SUM('10ªCFB-U-L PORT'!M12) -> 0 | E14: =SUM('10ªCFB-U-INGLES'!M12) -> 0 | F14: =SUM('10ªCFB-U-MAT'!M12) -> 0 | G14: =SUM('10ªCFB-U-INFOR'!M12) -> 0 | H14: =SUM('10ªCFB-U-ED. FIS'!M12) -> 0 | I14: =SUM('10ªCFB-U-FIS'!M12) -> 0 | J14: =SUM('10ªCFB-U-QCA'!M12) -> 0 | K14: =SUM('10ªCFB-U-BIOL'!M12) -> 0 | L14: =SUM('10ªCFB-U-EMPREEND'!M12) -> 2 | M14: DESISTIDA | N14: =AVERAGE(D14:L14) -> 0.22222222 | O14: F
A15: 5 | B15: 4651 | C15: Alberto Pucuta Luemba Mambuco | D15: =SUM('10ªCFB-U-L PORT'!M13) -> 15 | E15: =SUM('10ªCFB-U-INGLES'!M13) -> 20 | F15: =SUM('10ªCFB-U-MAT'!M13) -> 19 | G15: =SUM('10ªCFB-U-INFOR'!M13) -> 19.25 | H15: =SUM('10ªCFB-U-ED. FIS'!M13) -> 5 | I15: =SUM('10ªCFB-U-FIS'!M13) -> 18 | J15: =SUM('10ªCFB-U-QCA'!M13) -> 15.5 | K15: =SUM('10ªCFB-U-BIOL'!M13) -> 15 | L15: =SUM('10ªCFB-U-EMPREEND'!M13) -> 12.5 | M15: N/TRANSITA | N15: =AVERAGE(D15:L15) -> 15.472222 | O15: F
A16: 6 | B16: 4553 | C16: Alexandre Coto Ndombe Puati | D16: =SUM('10ªCFB-U-L PORT'!M14) -> 5 | E16: =SUM('10ªCFB-U-INGLES'!M14) -> 4 | F16: =SUM('10ªCFB-U-MAT'!M14) -> 11.5 | G16: =SUM('10ªCFB-U-INFOR'!M14) -> 7.5 | H16: =SUM('10ªCFB-U-ED. FIS'!M14) -> 0 | I16: =SUM('10ªCFB-U-FIS'!M14) -> 3.5 | J16: =SUM('10ªCFB-U-QCA'!M14) -> 0 | K16: =SUM('10ªCFB-U-BIOL'!M14) -> 6.5 | L16: =SUM('10ªCFB-U-EMPREEND'!M14) -> 6.5 | M16: N/TRANSITA | N16: =AVERAGE(D16:L16) -> 4.9444444 | O16: M | Q16: MÁXIMA | R16: =MAX(N11:N74) -> 15.472222
A17: 7 | B17: 2450 | C17: Alice Isabel Maria Muginga | D17: =SUM('10ªCFB-U-L PORT'!M15) -> 0 | E17: =SUM('10ªCFB-U-INGLES'!M15) -> 0 | F17: =SUM('10ªCFB-U-MAT'!M15) -> 4 | G17: =SUM('10ªCFB-U-INFOR'!M15) -> 0 | H17: =SUM('10ªCFB-U-ED. FIS'!M15) -> 0 | I17: =SUM('10ªCFB-U-FIS'!M15) -> 0 | J17: =SUM('10ªCFB-U-QCA'!M15) -> 0 | K17: =SUM('10ªCFB-U-BIOL'!M15) -> 0 | L17: =SUM('10ªCFB-U-EMPREEND'!M15) -> 2 | M17: DESISTIDA | N17: =AVERAGE(D17:L17) -> 0.66666667 | O17: F
A18: 8 | B18: 4580 | C18: Angelica Celina Domingos | D18: =SUM('10ªCFB-U-L PORT'!M16) -> 11 | E18: =SUM('10ªCFB-U-INGLES'!M16) -> 12 | F18: =SUM('10ªCFB-U-MAT'!M16) -> 12.5 | G18: =SUM('10ªCFB-U-INFOR'!M16) -> 12.5 | H18: =SUM('10ªCFB-U-ED. FIS'!M16) -> 0 | I18: =SUM('10ªCFB-U-FIS'!M16) -> 5.5 | J18: =SUM('10ªCFB-U-QCA'!M16) -> 9 | K18: =SUM('10ªCFB-U-BIOL'!M16) -> 12 | L18: =SUM('10ªCFB-U-EMPREEND'!M16) -> 10 | M18: N/TRANSITA | N18: =AVERAGE(D18:L18) -> 9.3888889 | O18: F | Q18: NOME DO/A ALUNO/A | T18: Madalena Simba Mavinga Maciala
A19: 9 | B19: 4605 | C19: António Diela | D19: =SUM('10ªCFB-U-L PORT'!M17) -> 10.25 | E19: =SUM('10ªCFB-U-INGLES'!M17) -> 10.5 | F19: =SUM('10ªCFB-U-MAT'!M17) -> 14 | G19: =SUM('10ªCFB-U-INFOR'!M17) -> 9.25 | H19: =SUM('10ªCFB-U-ED. FIS'!M17) -> 10 | I19: =SUM('10ªCFB-U-FIS'!M17) -> 8 | J19: =SUM('10ªCFB-U-QCA'!M17) -> 10.5 | K19: =SUM('10ªCFB-U-BIOL'!M17) -> 9 | L19: =SUM('10ªCFB-U-EMPREEND'!M17) -> 8.5 | M19: N/TRANSITA | N19: =AVERAGE(D19:L19) -> 10 | O19: M | Q19: IDADE: | R19: 12
A20: 10 | B20: 4295 | C20: António Ngimbi Capita | D20: =SUM('10ªCFB-U-L PORT'!M18) -> 6.5 | E20: =SUM('10ªCFB-U-INGLES'!M18) -> 6 | F20: =SUM('10ªCFB-U-MAT'!M18) -> 11 | G20: =SUM('10ªCFB-U-INFOR'!M18) -> 8.5 | H20: =SUM('10ªCFB-U-ED. FIS'!M18) -> 0 | I20: =SUM('10ªCFB-U-FIS'!M18) -> 10 | J20: =SUM('10ªCFB-U-QCA'!M18) -> 8.5 | K20: =SUM('10ªCFB-U-BIOL'!M18) -> 11 | L20: =SUM('10ªCFB-U-EMPREEND'!M18) -> 9 | M20: N/TRANSITA | N20: =AVERAGE(D20:L20) -> 7.8333333 | O20: M | R20: ANOS
A21: 11 | B21: 4594 | C21: Bernicia Mussitu | D21: =SUM('10ªCFB-U-L PORT'!M19) -> 0 | E21: =SUM('10ªCFB-U-INGLES'!M19) -> 0 | F21: =SUM('10ªCFB-U-MAT'!M19) -> 0 | G21: =SUM('10ªCFB-U-INFOR'!M19) -> 0 | H21: =SUM('10ªCFB-U-ED. FIS'!M19) -> 0 | I21: =SUM('10ªCFB-U-FIS'!M19) -> 0 | J21: =SUM('10ªCFB-U-QCA'!M19) -> 0 | K21: =SUM('10ªCFB-U-BIOL'!M19) -> 0 | L21: =SUM('10ªCFB-U-EMPREEND'!M19) -> 2 | M21: DESISTIDA | N21: =AVERAGE(D21:L21) -> 0.22222222 | O21: F
A22: 12 | B22: 4566 | C22: Candida Da Silva Sambo | D22: =SUM('10ªCFB-U-L PORT'!M20) -> 11 | E22: =SUM('10ªCFB-U-INGLES'!M20) -> 14 | F22: =SUM('10ªCFB-U-MAT'!M20) -> 13 | G22: =SUM('10ªCFB-U-INFOR'!M20) -> 18.75 | H22: =SUM('10ªCFB-U-ED. FIS'!M20) -> 0 | I22: =SUM('10ªCFB-U-FIS'!M20) -> 10 | J22: =SUM('10ªCFB-U-QCA'!M20) -> 9.5 | K22: =SUM('10ªCFB-U-BIOL'!M20) -> 15 | L22: =SUM('10ªCFB-U-EMPREEND'!M20) -> 12 | M22: N/TRANSITA | N22: =AVERAGE(D22:L22) -> 11.472222 | O22: F
A23: 13 | B23: 4667 | C23: Catarina Kiaba Maluta | D23: =SUM('10ªCFB-U-L PORT'!M21) -> 0 | E23: =SUM('10ªCFB-U-INGLES'!M21) -> 0 | F23: =SUM('10ªCFB-U-MAT'!M21) -> 0 | G23: =SUM('10ªCFB-U-INFOR'!M21) -> 0 | H23: =SUM('10ªCFB-U-ED. FIS'!M21) -> 0 | I23: =SUM('10ªCFB-U-FIS'!M21) -> 0 | J23: =SUM('10ªCFB-U-QCA'!M21) -> 0 | K23: =SUM('10ªCFB-U-BIOL'!M21) -> 0 | L23: =SUM('10ªCFB-U-EMPREEND'!M21) -> 2 | M23: DESISTIDA | N23: =AVERAGE(D23:L23) -> 0.22222222 | O23: F
A24: 14 | B24: 3964 | C24: Cristiana Jemina Macanda | D24: =SUM('10ªCFB-U-L PORT'!M22) -> 0 | E24: =SUM('10ªCFB-U-INGLES'!M22) -> 0 | F24: =SUM('10ªCFB-U-MAT'!M22) -> 0 | G24: =SUM('10ªCFB-U-INFOR'!M22) -> 0 | H24: =SUM('10ªCFB-U-ED. FIS'!M22) -> 0 | I24: =SUM('10ªCFB-U-FIS'!M22) -> 0 | J24: =SUM('10ªCFB-U-QCA'!M22) -> 0 | K24: =SUM('10ªCFB-U-BIOL'!M22) -> 0 | L24: =SUM('10ªCFB-U-EMPREEND'!M22) -> 2 | M24: DESISTIDA | N24: =AVERAGE(D24:L24) -> 0.22222222 | O24: F
A25: 15 | B25: 4593 | C25: Debora Antonio Bumba Bilongo | D25: =SUM('10ªCFB-U-L PORT'!M23) -> 8 | E25: =SUM('10ªCFB-U-INGLES'!M23) -> 13.5 | F25: =SUM('10ªCFB-U-MAT'!M23) -> 14.5 | G25: =SUM('10ªCFB-U-INFOR'!M23) -> 18.75 | H25: =SUM('10ªCFB-U-ED. FIS'!M23) -> 5 | I25: =SUM('10ªCFB-U-FIS'!M23) -> 11 | J25: =SUM('10ªCFB-U-QCA'!M23) -> 12.25 | K25: =SUM('10ªCFB-U-BIOL'!M23) -> 13 | L25: =SUM('10ªCFB-U-EMPREEND'!M23) -> 10.5 | M25: N/TRANSITA | N25: =AVERAGE(D25:L25) -> 11.833333 | O25: F
A26: 16 | B26: 4577 | C26: Elisa Do Nascimento Cumbo | D26: =SUM('10ªCFB-U-L PORT'!M24) -> 10 | E26: =SUM('10ªCFB-U-INGLES'!M24) -> 14.5 | F26: =SUM('10ªCFB-U-MAT'!M24) -> 14.5 | G26: =SUM('10ªCFB-U-INFOR'!M24) -> 17.75 | H26: =SUM('10ªCFB-U-ED. FIS'!M24) -> 0 | I26: =SUM('10ªCFB-U-FIS'!M24) -> 10.25 | J26: =SUM('10ªCFB-U-QCA'!M24) -> 11.5 | K26: =SUM('10ªCFB-U-BIOL'!M24) -> 11 | L26: =SUM('10ªCFB-U-EMPREEND'!M24) -> 13 | M26: N/TRANSITA | N26: =AVERAGE(D26:L26) -> 11.388889 | O26: M
A27: 17 | B27: 4584 | C27: Elizabeth Nsuami Casimiro | D27: =SUM('10ªCFB-U-L PORT'!M25) -> 8 | E27: =SUM('10ªCFB-U-INGLES'!M25) -> 9 | F27: =SUM('10ªCFB-U-MAT'!M25) -> 11.5 | G27: =SUM('10ªCFB-U-INFOR'!M25) -> 10 | H27: =SUM('10ªCFB-U-ED. FIS'!M25) -> 0 | I27: =SUM('10ªCFB-U-FIS'!M25) -> 6.25 | J27: =SUM('10ªCFB-U-QCA'!M25) -> 0 | K27: =SUM('10ªCFB-U-BIOL'!M25) -> 10 | L27: =SUM('10ªCFB-U-EMPREEND'!M25) -> 5.5 | M27: N/TRANSITA | N27: =AVERAGE(D27:L27) -> 6.6944444 | O27: F
A28: 18 | B28: 4590 | C28: Elizabeth Simba Mbonzo | D28: =SUM('10ªCFB-U-L PORT'!M26) -> 11.25 | E28: =SUM('10ªCFB-U-INGLES'!M26) -> 5.5 | F28: =SUM('10ªCFB-U-MAT'!M26) -> 12 | G28: =SUM('10ªCFB-U-INFOR'!M26) -> 5.5 | H28: =SUM('10ªCFB-U-ED. FIS'!M26) -> 15 | I28: =SUM('10ªCFB-U-FIS'!M26) -> 10 | J28: =SUM('10ªCFB-U-QCA'!M26) -> 8.5 | K28: =SUM('10ªCFB-U-BIOL'!M26) -> 14 | L28: =SUM('10ªCFB-U-EMPREEND'!M26) -> 9.5 | M28: N/TRANSITA | N28: =AVERAGE(D28:L28) -> 10.138889 | O28: F
A29: 19 | B29: 4546 | C29: Ermelinda Chibinda Paulino | D29: =SUM('10ªCFB-U-L PORT'!M27) -> 0 | E29: =SUM('10ªCFB-U-INGLES'!M27) -> 0 | F29: =SUM('10ªCFB-U-MAT'!M27) -> 0 | G29: =SUM('10ªCFB-U-INFOR'!M27) -> 0 | H29: =SUM('10ªCFB-U-ED. FIS'!M27) -> 0 | I29: =SUM('10ªCFB-U-FIS'!M27) -> 0 | J29: =SUM('10ªCFB-U-QCA'!M27) -> 0 | K29: =SUM('10ªCFB-U-BIOL'!M27) -> 0 | L29: =SUM('10ªCFB-U-EMPREEND'!M27) -> 2 | M29: DESISTIDA | N29: =AVERAGE(D29:L29) -> 0.22222222 | O29: F
A30: 20 | B30: 4631 | C30: Esperança Monteiro Ernesto | D30: =SUM('10ªCFB-U-L PORT'!M28) -> 10.5 | E30: =SUM('10ªCFB-U-INGLES'!M28) -> 8 | F30: =SUM('10ªCFB-U-MAT'!M28) -> 12 | G30: =SUM('10ªCFB-U-INFOR'!M28) -> 14.25 | H30: =SUM('10ªCFB-U-ED. FIS'!M28) -> 0 | I30: =SUM('10ªCFB-U-FIS'!M28) -> 6 | J30: =SUM('10ªCFB-U-QCA'!M28) -> 10.5 | K30: =SUM('10ªCFB-U-BIOL'!M28) -> 16 | L30: =SUM('10ªCFB-U-EMPREEND'!M28) -> 7 | M30: N/TRANSITA | N30: =AVERAGE(D30:L30) -> 9.3611111 | O30: F
A31: 21 | B31: 2387 | C31: Eulália Simba Pedro Claver | D31: =SUM('10ªCFB-U-L PORT'!M29) -> 0 | E31: =SUM('10ªCFB-U-INGLES'!M29) -> 0 | F31: =SUM('10ªCFB-U-MAT'!M29) -> 5 | G31: =SUM('10ªCFB-U-INFOR'!M29) -> 0 | H31: =SUM('10ªCFB-U-ED. FIS'!M29) -> 0 | I31: =SUM('10ªCFB-U-FIS'!M29) -> 0 | J31: =SUM('10ªCFB-U-QCA'!M29) -> 0 | K31: =SUM('10ªCFB-U-BIOL'!M29) -> 0 | L31: =SUM('10ªCFB-U-EMPREEND'!M29) -> 2 | M31: DESISTIDA | N31: =AVERAGE(D31:L31) -> 0.77777778 | O31: F
A32: 22 | B32: 4613 | C32: Filipina Bambi | D32: =SUM('10ªCFB-U-L PORT'!M30) -> 9 | E32: =SUM('10ªCFB-U-INGLES'!M30) -> 13.5 | F32: =SUM('10ªCFB-U-MAT'!M30) -> 11 | G32: =SUM('10ªCFB-U-INFOR'!M30) -> 8.75 | H32: =SUM('10ªCFB-U-ED. FIS'!M30) -> 0 | I32: =SUM('10ªCFB-U-FIS'!M30) -> 8.75 | J32: =SUM('10ªCFB-U-QCA'!M30) -> 12 | K32: =SUM('10ªCFB-U-BIOL'!M30) -> 8.5 | L32: =SUM('10ªCFB-U-EMPREEND'!M30) -> 7.5 | M32: N/TRANSITA | N32: =AVERAGE(D32:L32) -> 8.7777778 | O32: F
... A73: 63 | B73: 4556 | C73: Zolina Massiala Cumba | D73: =SUM('10ªCFB-U-L PORT'!M71) -> 0 | E73: =SUM('10ªCFB-U-INGLES'!M71) -> 0 | F73: =SUM('10ªCFB-U-MAT'!M71) -> 0 | G73: =SUM('10ªCFB-U-INFOR'!M71) -> 0 | H73: =SUM('10ªCFB-U-ED. FIS'!M71) -> 0 | I73: =SUM('10ªCFB-U-FIS'!M71) -> 0 | J73: =SUM('10ªCFB-U-QCA'!M71) -> 0 | K73: =SUM('10ªCFB-U-BIOL'!M71) -> 6.5 | L73: =SUM('10ªCFB-U-EMPREEND'!M71) -> 2 | M73: DESISTIDA | N73: =AVERAGE(D73:L73) -> 0.94444444 | O73: F
A75: COMPLEXO ESCOLAR PRIVADO JOMORAIS, 27 de março de 2026.-
A78: A Directora de Turma | K78: O Subdirector Pedagógico
A79: ______________________________ | K79: _____________________________
A80: ALICE DEOLINDA CHIAZI | K80: ALBERTO SASSA TATI

Sheet 10ªCFB-U-L PORT
A1: COMPLEXO ESCOLAR PRIVADO JOMORAIS
B4: Classe: 10ª | I4: Disciplina: Língua Portuguesa | P4: Ano Lectivo:2025/2026
B5: Período: Matinal | I5: Turma: Única | N5: Curso: Ciências Físicas e Biológicas
B6: MINI-PAUTA - I Ciclo do Ensino Secundário Geral
B7: Nº | C7: Nome do (a) Aluno (a) | D7: FALTAS | E7: Avaliações/I Trimestre | I7: OBS | J7: Avaliações/II Trimestre | N7: OBS | O7: Avaliações/IIITrimestre | S7: MFD | T7: OBS
D8: J/I | E8: MAC | F8: NPT | G8: NPR2 | H8: MT1 | J8: MAC | K8: NPT | L8: NPR2 | M8: MT2 | O8: MAC | P8: NPT | Q8: NPR2 | R8: MT3
B9: 1 | C9: Adelina Malonda Poba | E9: 14 | F9: 6 | H9: =AVERAGE(E9,MAX(F9:G9)) -> 10 | I9: =IF(H9>=10,"TRANSITA","N/TRANSITA") -> TRANSITA | J9: 14 | K9: 6 | M9: =AVERAGE(J9,MAX(K9:L9)) -> 10 | N9: =IF(M9>=10,"TRANSITA","N/TRANSITA") -> TRANSITA | R9: =AVERAGE(O9,MAX(P9:Q9)) -> 0 | S9: =SUM(H9,M9,R9)/3 -> 6.6666667 | T9: =IF(S9>=10,"TRANSITA","N/TRANSITA") -> N/TRANSITA
B10: 2 | C10: Adelina Marques Zau | E10: 13 | F10: 9 | H10: =AVERAGE(E10,MAX(F10:G10)) -> 11 | I10: =IF(H10>=10,"TRANSITA","N/TRANSITA") -> TRANSITA | J10: 13.5 | K10: 8.5 | M10: =AVERAGE(J10,MAX(K10:L10)) -> 11 | N10: =IF(M10>=10,"TRANSITA","N/TRANSITA") -> TRANSITA | R10: =AVERAGE(O10,MAX(P10:Q10)) -> 0 | S10: =SUM(H10,M10,R10)/3 -> 7.3333333 | T10: =IF(S10>=10,"TRANSITA","N/TRANSITA") -> N/TRANSITA
B11: 3 | C11: Albertina Eduardo Macosso | E11: 13 | F11: 12.5 | H11: =AVERAGE(E11,MAX(F11:G11)) -> 12.75 | I11: =IF(H11>=10,"TRANSITA","N/TRANSITA") -> TRANSITA | J11: 13.5 | K11: 6.5 | M11: =AVERAGE(J11,MAX(K11:L11)) -> 10 | N11: =IF(M11>=10,"TRANSITA","N/TRANSITA") -> TRANSITA | R11: =AVERAGE(O11,MAX(P11:Q11)) -> 0 | S11: =SUM(H11,M11,R11)/3 -> 7.5833333 | T11: =IF(S11>=10,"TRANSITA","N/TRANSITA") -> N/TRANSITA
B12: 4 | C12: Albertina Muanda Salvador Biala | E12: 12 | F12: 0.5 | H12: =AVERAGE(E12,MAX(F12:G12)) -> 6.25 | I12: =IF(H12>=10,"TRANSITA","N/TRANSITA") -> N/TRANSITA | M12: =AVERAGE(J12,MAX(K12:L12)) -> 0 | N12: =IF(M12>=10,"TRANSITA","N/TRANSITA") -> N/TRANSITA | R12: =AVERAGE(O12,MAX(P12:Q12)) -> 0 | S12: =SUM(H12,M12,R12)/3 -> 2.0833333 | T12: =IF(S12>=10,"TRANSITA","N/TRANSITA") -> N/TRANSITA
B13: 5 | C13: Albeto Pucuta Luemba Mambuco | E13: 19 | F13: 19 | H13: =AVERAGE(E13,MAX(F13:G13)) -> 19 | I13: =IF(H13>=10,"TRANSITA","N/TRANSITA") -> TRANSITA | J13: 18 | K13: 12 | M13: =AVERAGE(J13,MAX(K13:L13)) -> 15 | N13: =IF(M13>=10,"TRANSITA","N/TRANSITA") -> TRANSITA | R13: =AVERAGE(O13,MAX(P13:Q13)) -> 0 | S13: =SUM(H13,M13,R13)/3 -> 11.333333 | T13: =IF(S13>=10,"TRANSITA","N/TRANSITA") -> TRANSITA
B14: 6 | C14: Alexandre Coto Ndombe Puati | E14: 12 | F14: 10 | H14: =AVERAGE(E14,MAX(F14:G14)) -> 11 | I14: =IF(H14>=10,"TRANSITA","N/TRANSITA") -> TRANSITA | K14: 5 | M14: =AVERAGE(J14,MAX(K14:L14)) -> 5 | N14: =IF(M14>=10,"TRANSITA","N/TRANSITA") -> N/TRANSITA | R14: =AVERAGE(O14,MAX(P14:Q14)) -> 0 | S14: =SUM(H14,M14,R14)/3 -> 5.3333333 | T14: =IF(S14>=10,"TRANSITA","N/TRANSITA") -> N/TRANSITA
B15: 7 | C15: Alice Isabel Maria Muginga | F15: 6.5 | H15: =AVERAGE(E15,MAX(F15:G15)) -> 6.5 | I15: =IF(H15>=10,"TRANSITA","N/TRANSITA") -> N/TRANSITA | M15: =AVERAGE(J15,MAX(K15:L15)) -> 0 | N15: =IF(M15>=10,"TRANSITA","N/TRANSITA") -> N/TRANSITA | R15: =AVERAGE(O15,MAX(P15:Q15)) -> 0 | S15: =SUM(H15,M15,R15)/3 -> 2.1666667 | T15: =IF(S15>=10,"TRANSITA","N/TRANSITA") -> N/TRANSITA
B16: 8 | C16: Angelica Celina Domingos | E16: 12 | F16: 5 | H16: =AVERAGE(E16,MAX(F16:G16)) -> 8.5 | I16: =IF(H16>=10,"TRANSITA","N/TRANSITA") -> N/TRANSITA | J16: 14 | K16: 8 | M16: =AVERAGE(J16,MAX(K16:L16)) -> 11 | N16: =IF(M16>=10,"TRANSITA","N/TRANSITA") -> TRANSITA | R16: =AVERAGE(O16,MAX(P16:Q16)) -> 0 | S16: =SUM(H16,M16,R16)/3 -> 6.5 | T16: =IF(S16>=10,"TRANSITA","N/TRANSITA") -> N/TRANSITA
B17: 9 | C17: António Diela | E17: 13 | F17: 4.5 | H17: =AVERAGE(E17,MAX(F17:G17)) -> 8.75 | I17: =IF(H17>=10,"TRANSITA","N/TRANSITA") -> N/TRANSITA | J17: 12.5 | K17: 8 | M17: =AVERAGE(J17,MAX(K17:L17)) -> 10.25 | N17: =IF(M17>=10,"TRANSITA","N/TRANSITA") -> TRANSITA | R17: =AVERAGE(O17,MAX(P17:Q17)) -> 0 | S17: =SUM(H17,M17,R17)/3 -> 6.3333333 | T17: =IF(S17>=10,"TRANSITA","N/TRANSITA") -> N/TRANSITA
B18: 10 | C18: António Ngimbi Capita | H18: =AVERAGE(E18,MAX(F18:G18)) -> 0 | I18: =IF(H18>=10,"TRANSITA","N/TRANSITA") -> N/TRANSITA | J18: 10 | K18: 3 | M18: =AVERAGE(J18,MAX(K18:L18)) -> 6.5 | N18: =IF(M18>=10,"TRANSITA","N/TRANSITA") -> N/TRANSITA | R18: =AVERAGE(O18,MAX(P18:Q18)) -> 0 | S18: =SUM(H18,M18,R18)/3 -> 2.1666667 | T18: =IF(S18>=10,"TRANSITA","N/TRANSITA") -> N/TRANSITA
B19: 11 | C19: Bernicia Mussitu | H19: =AVERAGE(E19,MAX(F19:G19)) -> 0 | I19: =IF(H19>=10,"TRANSITA","N/TRANSITA") -> N/TRANSITA | M19: =AVERAGE(J19,MAX(K19:L19)) -> 0 | N19: =IF(M19>=10,"TRANSITA","N/TRANSITA") -> N/TRANSITA | R19: =AVERAGE(O19,MAX(P19:Q19)) -> 0 | S19: =SUM(H19,M19,R19)/3 -> 0 | T19: =IF(S19>=10,"TRANSITA","N/TRANSITA") -> N/TRANSITA
B20: 12 | C20: Candida Da Silva Sambo | E20: 14 | F20: 15 | H20: =AVERAGE(E20,MAX(F20:G20)) -> 14.5 | I20: =IF(H20>=10,"TRANSITA","N/TRANSITA") -> TRANSITA | J20: 13.5 | K20: 8.5 | M20: =AVERAGE(J20,MAX(K20:L20)) -> 11 | N20: =IF(M20>=10,"TRANSITA","N/TRANSITA") -> TRANSITA | R20: =AVERAGE(O20,MAX(P20:Q20)) -> 0 | S20: =SUM(H20,M20,R20)/3 -> 8.5 | T20: =IF(S20>=10,"TRANSITA","N/TRANSITA") -> N/TRANSITA
B21: 13 | C21: Catarina Kiaba Maluta | H21: =AVERAGE(E21,MAX(F21:G21)) -> 0 | I21: =IF(H21>=10,"TRANSITA","N/TRANSITA") -> N/TRANSITA | M21: =AVERAGE(J21,MAX(K21:L21)) -> 0 | N21: =IF(M21>=10,"TRANSITA","N/TRANSITA") -> N/TRANSITA | R21: =AVERAGE(O21,MAX(P21:Q21)) -> 0 | S21: =SUM(H21,M21,R21)/3 -> 0 | T21: =IF(S21>=10,"TRANSITA","N/TRANSITA") -> N/TRANSITA
B22: 14 | C22: Cristiana Jemina Macanda | H22: =AVERAGE(E22,MAX(F22:G22)) -> 0 | I22: =IF(H22>=10,"TRANSITA","N/TRANSITA") -> N/TRANSITA | M22: =AVERAGE(J22,MAX(K22:L22)) -> 0 | N22: =IF(M22>=10,"TRANSITA","N/TRANSITA") -> N/TRANSITA | R22: =AVERAGE(O22,MAX(P22:Q22)) -> 0 | S22: =SUM(H22,M22,R22)/3 -> 0 | T22: =IF(S22>=10,"TRANSITA","N/TRANSITA") -> N/TRANSITA
B23: 15 | C23: Debora Antonio Bumba Bilongo | E23: 14 | F23: 13 | H23: =AVERAGE(E23,MAX(F23:G23)) -> 13.5 | I23: =IF(H23>=10,"TRANSITA","N/TRANSITA") -> TRANSITA | J23: 13 | K23: 3 | M23: =AVERAGE(J23,MAX(K23:L23)) -> 8 | N23: =IF(M23>=10,"TRANSITA","N/TRANSITA") -> N/TRANSITA | R23: =AVERAGE(O23,MAX(P23:Q23)) -> 0 | S23: =SUM(H23,M23,R23)/3 -> 7.1666667 | T23: =IF(S23>=10,"TRANSITA","N/TRANSITA") -> N/TRANSITA
B24: 16 | C24: Elisa Do Nascimento Cumbo | E24: 13 | F24: 12 | H24: =AVERAGE(E24,MAX(F24:G24)) -> 12.5 | I24: =IF(H24>=10,"TRANSITA","N/TRANSITA") -> TRANSITA | J24: 14 | K24: 6 | M24: =AVERAGE(J24,MAX(K24:L24)) -> 10 | N24: =IF(M24>=10,"TRANSITA","N/TRANSITA") -> TRANSITA | R24: =AVERAGE(O24,MAX(P24:Q24)) -> 0 | S24: =SUM(H24,M24,R24)/3 -> 7.5 | T24: =IF(S24>=10,"TRANSITA","N/TRANSITA") -> N/TRANSITA
B25: 17 | C25: Elizabeth Nsuami Casimiro | E25: 13 | F25: 7 | H25: =AVERAGE(E25,MAX(F25:G25)) -> 10 | I25: =IF(H25>=10,"TRANSITA","N/TRANSITA") -> TRANSITA | J25: 12.5 | K25: 3.5 | M25: =AVERAGE(J25,MAX(K25:L25)) -> 8 | N25: =IF(M25>=10,"TRANSITA","N/TRANSITA") -> N/TRANSITA | R25: =AVERAGE(O25,MAX(P25:Q25)) -> 0 | S25: =SUM(H25,M25,R25)/3 -> 6 | T25: =IF(S25>=10,"TRANSITA","N/TRANSITA") -> N/TRANSITA
B26: 18 | C26: Elizabeth Simba Mbonzo | H26: =AVERAGE(E26,MAX(F26:G26)) -> 0 | I26: =IF(H26>=10,"TRANSITA","N/TRANSITA") -> N/TRANSITA | J26: 12 | K26: 10.5 | M26: =AVERAGE(J26,MAX(K26:L26)) -> 11.25 | N26: =IF(M26>=10,"TRANSITA","N/TRANSITA") -> TRANSITA | R26: =AVERAGE(O26,MAX(P26:Q26)) -> 0 | S26: =SUM(H26,M26,R26)/3 -> 3.75 | T26: =IF(S26>=10,"TRANSITA","N/TRANSITA") -> N/TRANSITA
B27: 19 | C27: Ermelinda Chibinda Paulino | H27: =AVERAGE(E27,MAX(F27:G27)) -> 0 | I27: =IF(H27>=10,"TRANSITA","N/TRANSITA") -> N/TRANSITA | M27: =AVERAGE(J27,MAX(K27:L27)) -> 0 | N27: =IF(M27>=10,"TRANSITA","N/TRANSITA") -> N/TRANSITA | R27: =AVERAGE(O27,MAX(P27:Q27)) -> 0 | S27: =SUM(H27,M27,R27)/3 -> 0 | T27: =IF(S27>=10,"TRANSITA","N/TRANSITA") -> N/TRANSITA
B28: 20 | C28: Esperança Monteiro Ernesto | E28: 13 | F28: 10.5 | H28: =AVERAGE(E28,MAX(F28:G28)) -> 11.75 | I28: =IF(H28>=10,"TRANSITA","N/TRANSITA") -> TRANSITA | J28: 13 | K28: 8 | M28: =AVERAGE(J28,MAX(K28:L28)) -> 10.5 | N28: =IF(M28>=10,"TRANSITA","N/TRANSITA") -> TRANSITA | R28: =AVERAGE(O28,MAX(P28:Q28)) -> 0 | S28: =SUM(H28,M28,R28)/3 -> 7.4166667 | T28: =IF(S28>=10,"TRANSITA","N/TRANSITA") -> N/TRANSITA
B29: 21 | C29: Eulália Simba Pedro Claver | E29: 13 | F29: 11.5 | H29: =AVERAGE(E29,MAX(F29:G29)) -> 12.25 | I29: =IF(H29>=10,"TRANSITA","N/TRANSITA") -> TRANSITA | M29: =AVERAGE(J29,MAX(K29:L29)) -> 0 | N29: =IF(M29>=10,"TRANSITA","N/TRANSITA") -> N/TRANSITA | R29: =AVERAGE(O29,MAX(P29:Q29)) -> 0 | S29: =SUM(H29,M29,R29)/3 -> 4.0833333 | T29: =IF(S29>=10,"TRANSITA","N/TRANSITA") -> N/TRANSITA
B30: 22 | C30: Filipina Bambi | E30: 12 | F30: 5.5 | H30: =AVERAGE(E30,MAX(F30:G30)) -> 8.75 | I30: =IF(H30>=10,"TRANSITA","N/TRANSITA") -> N/TRANSITA | J30: 13 | K30: 5 | M30: =AVERAGE(J30,MAX(K30:L30)) -> 9 | N30: =IF(M30>=10,"TRANSITA","N/TRANSITA") -> N/TRANSITA | R30: =AVERAGE(O30,MAX(P30:Q30)) -> 0 | S30: =SUM(H30,M30,R30)/3 -> 5.9166667 | T30: =IF(S30>=10,"TRANSITA","N/TRANSITA") -> N/TRANSITA
B31: 23 | C31: Filomena Chicaia Poba | E31: 11 | F31: 9 | H31: =AVERAGE(E31,MAX(F31:G31)) -> 10 | I31: =IF(H31>=10,"TRANSITA","N/TRANSITA") -> TRANSITA | K31: 3.5 | M31: =AVERAGE(J31,MAX(K31:L31)) -> 3.5 | N31: =IF(M31>=10,"TRANSITA","N/TRANSITA") -> N/TRANSITA | R31: =AVERAGE(O31,MAX(P31:Q31)) -> 0 | S31: =SUM(H31,M31,R31)/3 -> 4.5 | T31: =IF(S31>=10,"TRANSITA","N/TRANSITA") -> N/TRANSITA
B32: 24 | C32: Francisca Simba Sibua | H32: =AVERAGE(E32,MAX(F32:G32)) -> 0 | I32: =IF(H32>=10,"TRANSITA","N/TRANSITA") -> N/TRANSITA | M32: =AVERAGE(J32,MAX(K32:L32)) -> 0 | N32: =IF(M32>=10,"TRANSITA","N/TRANSITA") -> N/TRANSITA | R32: =AVERAGE(O32,MAX(P32:Q32)) -> 0 | S32: =SUM(H32,M32,R32)/3 -> 0 | T32: =IF(S32>=10,"TRANSITA","N/TRANSITA") -> N/TRANSITA
B33: 25 | C33: Gandira De Fatima Gomes | H33: =AVERAGE(E33,MAX(F33:G33)) -> 0 | I33: =IF(H33>=10,"TRANSITA","N/TRANSITA") -> N/TRANSITA | J33: 12 | K33: 6 | M33: =AVERAGE(J33,MAX(K33:L33)) -> 9 | N33: =IF(M33>=10,"TRANSITA","N/TRANSITA") -> N/TRANSITA | R33: =AVERAGE(O33,MAX(P33:Q33)) -> 0 | S33: =SUM(H33,M33,R33)/3 -> 3 | T33: =IF(S33>=10,"TRANSITA","N/TRANSITA") -> N/TRANSITA
B34: 26 | C34: Germénia Gertrudes Bato | H34: =AVERAGE(E34,MAX(F34:G34)) -> 0 | I34: =IF(H34>=10,"TRANSITA","N/TRANSITA") -> N/TRANSITA | M34: =AVERAGE(J34,MAX(K34:L34)) -> 0 | N34: =IF(M34>=10,"TRANSITA","N/TRANSITA") -> N/TRANSITA | R34: =AVERAGE(O34,MAX(P34:Q34)) -> 0 | S34: =SUM(H34,M34,R34)/3 -> 0 | T34: =IF(S34>=10,"TRANSITA","N/TRANSITA") -> N/TRANSITA
B35: 27 | C35: Graça das Dores Isiala Goiaba | H35: =AVERAGE(E35,MAX(F35:G35)) -> 0 | I35: =IF(H35>=10,"TRANSITA","N/TRANSITA") -> N/TRANSITA | M35: =AVERAGE(J35,MAX(K35:L35)) -> 0 | N35: =IF(M35>=10,"TRANSITA","N/TRANSITA") -> N/TRANSITA | R35: =AVERAGE(O35,MAX(P35:Q35)) -> 0 | S35: =SUM(H35,M35,R35)/3 -> 0 | T35: =IF(S35>=10,"TRANSITA","N/TRANSITA") -> N/TRANSITA
B36: 28 | C36: Helena De Fátima Sango Mabiala | H36: =AVERAGE(E36,MAX(F36:G36)) -> 0 | I36: =IF(H36>=10,"TRANSITA","N/TRANSITA") -> N/TRANSITA | M36: =AVERAGE(J36,MAX(K36:L36)) -> 0 | N36: =IF(M36>=10,"TRANSITA","N/TRANSITA") -> N/TRANSITA | R36: =AVERAGE(O36,MAX(P36:Q36)) -> 0 | S36: =SUM(H36,M36,R36)/3 -> 0 | T36: =IF(S36>=10,"TRANSITA","N/TRANSITA") -> N/TRANSITA
B37: 29 | C37: Helena Mavinga | E37: 13 | F37: 10 | H37: =AVERAGE(E37,MAX(F37:G37)) -> 11.5 | I37: =IF(H37>=10,"TRANSITA","N/TRANSITA") -> TRANSITA | J37: 14 | K37: 7 | M37: =AVERAGE(J37,MAX(K37:L37)) -> 10.5 | N37: =IF(M37>=10,"TRANSITA","N/TRANSITA") -> TRANSITA | R37: =AVERAGE(O37,MAX(P37:Q37)) -> 0 | S37: =SUM(H37,M37,R37)/3 -> 7.3333333 | T37: =IF(S37>=10,"TRANSITA","N/TRANSITA") -> N/TRANSITA
B38: 30 | C38: Hornorina Pemba Binda Sunda | H38: =AVERAGE(E38,MAX(F38:G38)) -> 0 | I38: =IF(H38>=10,"TRANSITA","N/TRANSITA") -> N/TRANSITA | M38: =AVERAGE(J38,MAX(K38:L38)) -> 0 | N38: =IF(M38>=10,"TRANSITA","N/TRANSITA") -> N/TRANSITA | R38: =AVERAGE(O38,MAX(P38:Q38)) -> 0 | S38: =SUM(H38,M38,R38)/3 -> 0 | T38: =IF(S38>=10,"TRANSITA","N/TRANSITA") -> N/TRANSITA
B39: 31 | C39: Imaculada Lelo Lufumba | H39: =AVERAGE(E39,MAX(F39:G39)) -> 0 | I39: =IF(H39>=10,"TRANSITA","N/TRANSITA") -> N/TRANSITA | M39: =AVERAGE(J39,MAX(K39:L39)) -> 0 | N39: =IF(M39>=10,"TRANSITA","N/TRANSITA") -> N/TRANSITA | R39: =AVERAGE(O39,MAX(P39:Q39)) -> 0 | S39: =SUM(H39,M39,R39)/3 -> 0 | T39: =IF(S39>=10,"TRANSITA","N/TRANSITA") -> N/TRANSITA
B40: 32 | C40: Isabel Ernesto Zovo Lourdes | E40: 10 | F40: 6 | H40: =AVERAGE(E40,MAX(F40:G40)) -> 8 | I40: =IF(H40>=10,"TRANSITA","N/TRANSITA") -> N/TRANSITA | K40: 2.5 | M40: =AVERAGE(J40,MAX(K40:L40)) -> 2.5 | N40: =IF(M40>=10,"TRANSITA","N/TRANSITA") -> N/TRANSITA | R40: =AVERAGE(O40,MAX(P40:Q40)) -> 0 | S40: =SUM(H40,M40,R40)/3 -> 3.5 | T40: =IF(S40>=10,"TRANSITA","N/TRANSITA") -> N/TRANSITA
B41: 33 | C41: Jaquelina Kibinda Chicai Suami | E41: 15 | F41: 15 | H41: =AVERAGE(E41,MAX(F41:G41)) -> 15 | I41: =IF(H41>=10,"TRANSITA","N/TRANSITA") -> TRANSITA | J41: 15 | K41: 9 | M41: =AVERAGE(J41,MAX(K41:L41)) -> 12 | N41: =IF(M41>=10,"TRANSITA","N/TRANSITA") -> TRANSITA | R41: =AVERAGE(O41,MAX(P41:Q41)) -> 0 | S41: =SUM(H41,M41,R41)/3 -> 9 | T41: =IF(S41>=10,"TRANSITA","N/TRANSITA") -> N/TRANSITA
B42: 34 | C42: Joana Mabiala Simba | H42: =AVERAGE(E42,MAX(F42:G42)) -> 0 | I42: =IF(H42>=10,"TRANSITA","N/TRANSITA") -> N/TRANSITA | M42: =AVERAGE(J42,MAX(K42:L42)) -> 0 | N42: =IF(M42>=10,"TRANSITA","N/TRANSITA") -> N/TRANSITA | R42: =AVERAGE(O42,MAX(P42:Q42)) -> 0 | S42: =SUM(H42,M42,R42)/3 -> 0 | T42: =IF(S42>=10,"TRANSITA","N/TRANSITA") -> N/TRANSITA
...

Sheet 10ªCFB-U-INGLES
A1: COMPLEXO ESCOLAR PRIVADO JOMORAIS
B4: Classe: 10ª | I4: Disciplina: Língua Inglesa | P4: Ano Lectivo:2025/2026
B5: Período: Matinal | I5: Turma: Única | N5: Curso: Ciências Físicas e Biológicas
B6: MINI-PAUTA - I Ciclo do Ensino Secundário Geral
B7: Nº | C7: Nome do (a) Aluno (a) | D7: FALTAS | E7: Avaliações/I Trimestre | I7: OBS | J7: Avaliações/II Trimestre | N7: OBS | O7: Avaliações/IIITrimestre | S7: MFD | T7: OBS
D8: J/I | E8: MAC | F8: NPT | G8: NPR2 | H8: MT1 | J8: MAC | K8: NPT | L8: NPR2 | M8: MT2 | O8: MAC | P8: NPT | Q8: NPR2 | R8: MT3
B9: 1 | C9: Adelina Malonda Poba | E9: 12 | F9: 13 | H9: =AVERAGE(E9,MAX(F9:G9)) -> 12.5 | I9: =IF(H9>=10,"TRANSITA","N/TRANSITA") -> TRANSITA | J9: 14 | K9: 14 | M9: =AVERAGE(J9,MAX(K9:L9)) -> 14 | N9: =IF(M9>=10,"TRANSITA","N/TRANSITA") -> TRANSITA | R9: =AVERAGE(O9,MAX(P9:Q9)) -> 0 | S9: =SUM(H9,M9,R9)/3 -> 8.8333333 | T9: =IF(S9>=10,"TRANSITA","N/TRANSITA") -> N/TRANSITA
B10: 2 | C10: Adelina Marques Zau | E10: 14 | F10: 10 | H10: =AVERAGE(E10,MAX(F10:G10)) -> 12 | I10: =IF(H10>=10,"TRANSITA","N/TRANSITA") -> TRANSITA | J10: 12 | K10: 10 | M10: =AVERAGE(J10,MAX(K10:L10)) -> 11 | N10: =IF(M10>=10,"TRANSITA","N/TRANSITA") -> TRANSITA | R10: =AVERAGE(O10,MAX(P10:Q10)) -> 0 | S10: =SUM(H10,M10,R10)/3 -> 7.6666667 | T10: =IF(S10>=10,"TRANSITA","N/TRANSITA") -> N/TRANSITA
B11: 3 | C11: Albertina Eduardo Macosso | E11: 15 | F11: 15 | H11: =AVERAGE(E11,MAX(F11:G11)) -> 15 | I11: =IF(H11>=10,"TRANSITA","N/TRANSITA") -> TRANSITA | J11: 10 | K11: 12 | M11: =AVERAGE(J11,MAX(K11:L11)) -> 11 | N11: =IF(M11>=10,"TRANSITA","N/TRANSITA") -> TRANSITA | R11: =AVERAGE(O11,MAX(P11:Q11)) -> 0 | S11: =SUM(H11,M11,R11)/3 -> 8.6666667 | T11: =IF(S11>=10,"TRANSITA","N/TRANSITA") -> N/TRANSITA
B12: 4 | C12: Albertina Muanda Salvador Biala | E12: 12 | F12: 3 | H12: =AVERAGE(E12,MAX(F12:G12)) -> 7.5 | I12: =IF(H12>=10,"TRANSITA","N/TRANSITA") -> N/TRANSITA | M12: =AVERAGE(J12,MAX(K12:L12)) -> 0 | N12: =IF(M12>=10,"TRANSITA","N/TRANSITA") -> N/TRANSITA | R12: =AVERAGE(O12,MAX(P12:Q12)) -> 0 | S12: =SUM(H12,M12,R12)/3 -> 2.5 | T12: =IF(S12>=10,"TRANSITA","N/TRANSITA") -> N/TRANSITA
B13: 5 | C13: Albeto Pucuta Luemba Mambuco | E13: 19 | F13: 19 | H13: =AVERAGE(E13,MAX(F13:G13)) -> 19 | I13: =IF(H13>=10,"TRANSITA","N/TRANSITA") -> TRANSITA | J13: 20 | K13: 20 | M13: =AVERAGE(J13,MAX(K13:L13)) -> 20 | N13: =IF(M13>=10,"TRANSITA","N/TRANSITA") -> TRANSITA | R13: =AVERAGE(O13,MAX(P13:Q13)) -> 0 | S13: =SUM(H13,M13,R13)/3 -> 13 | T13: =IF(S13>=10,"TRANSITA","N/TRANSITA") -> TRANSITA
B14: 6 | C14: Alexandre Coto Ndombe Puati | E14: 14 | F14: 16 | H14: =AVERAGE(E14,MAX(F14:G14)) -> 15 | I14: =IF(H14>=10,"TRANSITA","N/TRANSITA") -> TRANSITA | J14: 2 | K14: 6 | M14: =AVERAGE(J14,MAX(K14:L14)) -> 4 | N14: =IF(M14>=10,"TRANSITA","N/TRANSITA") -> N/TRANSITA | R14: =AVERAGE(O14,MAX(P14:Q14)) -> 0 | S14: =SUM(H14,M14,R14)/3 -> 6.3333333 | T14: =IF(S14>=10,"TRANSITA","N/TRANSITA") -> N/TRANSITA
B15: 7 | C15: Alice Isabel Maria Muginga | E15: 12 | F15: 7 | H15: =AVERAGE(E15,MAX(F15:G15)) -> 9.5 | I15: =IF(H15>=10,"TRANSITA","N/TRANSITA") -> N/TRANSITA | M15: =AVERAGE(J15,MAX(K15:L15)) -> 0 | N15: =IF(M15>=10,"TRANSITA","N/TRANSITA") -> N/TRANSITA | R15: =AVERAGE(O15,MAX(P15:Q15)) -> 0 | S15: =SUM(H15,M15,R15)/3 -> 3.1666667 | T15: =IF(S15>=10,"TRANSITA","N/TRANSITA") -> N/TRANSITA
B16: 8 | C16: Angelica Celina Domingos | E16: 11 | F16: 12 | H16: =AVERAGE(E16,MAX(F16:G16)) -> 11.5 | I16: =IF(H16>=10,"TRANSITA","N/TRANSITA") -> TRANSITA | J16: 12 | K16: 12 | M16: =AVERAGE(J16,MAX(K16:L16)) -> 12 | N16: =IF(M16>=10,"TRANSITA","N/TRANSITA") -> TRANSITA | R16: =AVERAGE(O16,MAX(P16:Q16)) -> 0 | S16: =SUM(H16,M16,R16)/3 -> 7.8333333 | T16: =IF(S16>=10,"TRANSITA","N/TRANSITA") -> N/TRANSITA
B17: 9 | C17: António Diela | E17: 13 | F17: 16 | H17: =AVERAGE(E17,MAX(F17:G17)) -> 14.5 | I17: =IF(H17>=10,"TRANSITA","N/TRANSITA") -> TRANSITA | J17: 8 | K17: 13 | M17: =AVERAGE(J17,MAX(K17:L17)) -> 10.5 | N17: =IF(M17>=10,"TRANSITA","N/TRANSITA") -> TRANSITA | R17: =AVERAGE(O17,MAX(P17:Q17)) -> 0 | S17: =SUM(H17,M17,R17)/3 -> 8.3333333 | T17: =IF(S17>=10,"TRANSITA","N/TRANSITA") -> N/TRANSITA
B18: 10 | C18: António Ngimbi Capita | E18: 6 | F18: 11 | H18: =AVERAGE(E18,MAX(F18:G18)) -> 8.5 | I18: =IF(H18>=10,"TRANSITA","N/TRANSITA") -> N/TRANSITA | J18: 12 | M18: =AVERAGE(J18,MAX(K18:L18)) -> 6 | N18: =IF(M18>=10,"TRANSITA","N/TRANSITA") -> N/TRANSITA | R18: =AVERAGE(O18,MAX(P18:Q18)) -> 0 | S18: =SUM(H18,M18,R18)/3 -> 4.8333333 | T18: =IF(S18>=10,"TRANSITA","N/TRANSITA") -> N/TRANSITA
B19: 11 | C19: Bernicia Mussitu | H19: =AVERAGE(E19,MAX(F19:G19)) -> 0 | I19: =IF(H19>=10,"TRANSITA","N/TRANSITA") -> N/TRANSITA | M19: =AVERAGE(J19,MAX(K19:L19)) -> 0 | N19: =IF(M19>=10,"TRANSITA","N/TRANSITA") -> N/TRANSITA | R19: =AVERAGE(O19,MAX(P19:Q19)) -> 0 | S19: =SUM(H19,M19,R19)/3 -> 0 | T19: =IF(S19>=10,"TRANSITA","N/TRANSITA") -> N/TRANSITA
B20: 12 | C20: Candida Da Silva Sambo | E20: 14 | F20: 17 | H20: =AVERAGE(E20,MAX(F20:G20)) -> 15.5 | I20: =IF(H20>=10,"TRANSITA","N/TRANSITA") -> TRANSITA | J20: 14 | K20: 14 | M20: =AVERAGE(J20,MAX(K20:L20)) -> 14 | N20: =IF(M20>=10,"TRANSITA","N/TRANSITA") -> TRANSITA | R20: =AVERAGE(O20,MAX(P20:Q20)) -> 0 | S20: =SUM(H20,M20,R20)/3 -> 9.8333333 | T20: =IF(S20>=10,"TRANSITA","N/TRANSITA") -> N/TRANSITA
B21: 13 | C21: Catarina Kiaba Maluta | H21: =AVERAGE(E21,MAX(F21:G21)) -> 0 | I21: =IF(H21>=10,"TRANSITA","N/TRANSITA") -> N/TRANSITA | M21: =AVERAGE(J21,MAX(K21:L21)) -> 0 | N21: =IF(M21>=10,"TRANSITA","N/TRANSITA") -> N/TRANSITA | R21: =AVERAGE(O21,MAX(P21:Q21)) -> 0 | S21: =SUM(H21,M21,R21)/3 -> 0 | T21: =IF(S21>=10,"TRANSITA","N/TRANSITA") -> N/TRANSITA
B22: 14 | C22: Cristiana Jemina Macanda | H22: =AVERAGE(E22,MAX(F22:G22)) -> 0 | I22: =IF(H22>=10,"TRANSITA","N/TRANSITA") -> N/TRANSITA | M22: =AVERAGE(J22,MAX(K22:L22)) -> 0 | N22: =IF(M22>=10,"TRANSITA","N/TRANSITA") -> N/TRANSITA | R22: =AVERAGE(O22,MAX(P22:Q22)) -> 0 | S22: =SUM(H22,M22,R22)/3 -> 0 | T22: =IF(S22>=10,"TRANSITA","N/TRANSITA") -> N/TRANSITA
B23: 15 | C23: Debora Antonio Bumba Bilongo | E23: 15 | F23: 14 | H23: =AVERAGE(E23,MAX(F23:G23)) -> 14.5 | I23: =IF(H23>=10,"TRANSITA","N/TRANSITA") -> TRANSITA | J23: 15 | K23: 12 | M23: =AVERAGE(J23,MAX(K23:L23)) -> 13.5 | N23: =IF(M23>=10,"TRANSITA","N/TRANSITA") -> TRANSITA | R23: =AVERAGE(O23,MAX(P23:Q23)) -> 0 | S23: =SUM(H23,M23,R23)/3 -> 9.3333333 | T23: =IF(S23>=10,"TRANSITA","N/TRANSITA") -> N/TRANSITA
B24: 16 | C24: Elisa Do Nascimento Cumbo | E24: 15 | F24: 12 | H24: =AVERAGE(E24,MAX(F24:G24)) -> 13.5 | I24: =IF(H24>=10,"TRANSITA","N/TRANSITA") -> TRANSITA | J24: 15 | K24: 14 | M24: =AVERAGE(J24,MAX(K24:L24)) -> 14.5 | N24: =IF(M24>=10,"TRANSITA","N/TRANSITA") -> TRANSITA | R24: =AVERAGE(O24,MAX(P24:Q24)) -> 0 | S24: =SUM(H24,M24,R24)/3 -> 9.3333333 | T24: =IF(S24>=10,"TRANSITA","N/TRANSITA") -> N/TRANSITA
B25: 17 | C25: Elizabeth Nsuami Casimiro | E25: 14 | F25: 9 | H25: =AVERAGE(E25,MAX(F25:G25)) -> 11.5 | I25: =IF(H25>=10,"TRANSITA","N/TRANSITA") -> TRANSITA | J25: 10 | K25: 8 | M25: =AVERAGE(J25,MAX(K25:L25)) -> 9 | N25: =IF(M25>=10,"TRANSITA","N/TRANSITA") -> N/TRANSITA | R25: =AVERAGE(O25,MAX(P25:Q25)) -> 0 | S25: =SUM(H25,M25,R25)/3 -> 6.8333333 | T25: =IF(S25>=10,"TRANSITA","N/TRANSITA") -> N/TRANSITA
B26: 18 | C26: Elizabeth Simba Mbonzo | E26: 7 | F26: 14 | H26: =AVERAGE(E26,MAX(F26:G26)) -> 10.5 | I26: =IF(H26>=10,"TRANSITA","N/TRANSITA") -> TRANSITA | J26: 11 | K26: 0 | M26: =AVERAGE(J26,MAX(K26:L26)) -> 5.5 | N26: =IF(M26>=10,"TRANSITA","N/TRANSITA") -> N/TRANSITA | R26: =AVERAGE(O26,MAX(P26:Q26)) -> 0 | S26: =SUM(H26,M26,R26)/3 -> 5.3333333 | T26: =IF(S26>=10,"TRANSITA","N/TRANSITA") -> N/TRANSITA
B27: 19 | C27: Ermelinda Chibinda Paulino | H27: =AVERAGE(E27,MAX(F27:G27)) -> 0 | I27: =IF(H27>=10,"TRANSITA","N/TRANSITA") -> N/TRANSITA | M27: =AVERAGE(J27,MAX(K27:L27)) -> 0 | N27: =IF(M27>=10,"TRANSITA","N/TRANSITA") -> N/TRANSITA | R27: =AVERAGE(O27,MAX(P27:Q27)) -> 0 | S27: =SUM(H27,M27,R27)/3 -> 0 | T27: =IF(S27>=10,"TRANSITA","N/TRANSITA") -> N/TRANSITA
B28: 20 | C28: Esperança Monteiro Ernesto | E28: 14 | F28: 16 | H28: =AVERAGE(E28,MAX(F28:G28)) -> 15 | I28: =IF(H28>=10,"TRANSITA","N/TRANSITA") -> TRANSITA | J28: 10 | K28: 6 | M28: =AVERAGE(J28,MAX(K28:L28)) -> 8 | N28: =IF(M28>=10,"TRANSITA","N/TRANSITA") -> N/TRANSITA | R28: =AVERAGE(O28,MAX(P28:Q28)) -> 0 | S28: =SUM(H28,M28,R28)/3 -> 7.6666667 | T28: =IF(S28>=10,"TRANSITA","N/TRANSITA") -> N/TRANSITA
B29: 21 | C29: Eulália Simba Pedro Claver | E29: 14 | F29: 12 | H29: =AVERAGE(E29,MAX(F29:G29)) -> 13 | I29: =IF(H29>=10,"TRANSITA","N/TRANSITA") -> TRANSITA | M29: =AVERAGE(J29,MAX(K29:L29)) -> 0 | N29: =IF(M29>=10,"TRANSITA","N/TRANSITA") -> N/TRANSITA | R29: =AVERAGE(O29,MAX(P29:Q29)) -> 0 | S29: =SUM(H29,M29,R29)/3 -> 4.3333333 | T29: =IF(S29>=10,"TRANSITA","N/TRANSITA") -> N/TRANSITA
B30: 22 | C30: Filipina Bambi | E30: 12 | F30: 10 | H30: =AVERAGE(E30,MAX(F30:G30)) -> 11 | I30: =IF(H30>=10,"TRANSITA","N/TRANSITA") -> TRANSITA | J30: 13 | K30: 14 | M30: =AVERAGE(J30,MAX(K30:L30)) -> 13.5 | N30: =IF(M30>=10,"TRANSITA","N/TRANSITA") -> TRANSITA | R30: =AVERAGE(O30,MAX(P30:Q30)) -> 0 | S30: =SUM(H30,M30,R30)/3 -> 8.1666667 | T30: =IF(S30>=10,"TRANSITA","N/TRANSITA") -> N/TRANSITA
B31: 23 | C31: Filomena Chicaia Poba | E31: 6 | F31: 9 | H31: =AVERAGE(E31,MAX(F31:G31)) -> 7.5 | I31: =IF(H31>=10,"TRANSITA","N/TRANSITA") -> N/TRANSITA | J31: 2 | K31: 12 | M31: =AVERAGE(J31,MAX(K31:L31)) -> 7 | N31: =IF(M31>=10,"TRANSITA","N/TRANSITA") -> N/TRANSITA | R31: =AVERAGE(O31,MAX(P31:Q31)) -> 0 | S31: =SUM(H31,M31,R31)/3 -> 4.8333333 | T31: =IF(S31>=10,"TRANSITA","N/TRANSITA") -> N/TRANSITA
B32: 24 | C32: Francisca Simba Sibua | H32: =AVERAGE(E32,MAX(F32:G32)) -> 0 | I32: =IF(H32>=10,"TRANSITA","N/TRANSITA") -> N/TRANSITA | M32: =AVERAGE(J32,MAX(K32:L32)) -> 0 | N32: =IF(M32>=10,"TRANSITA","N/TRANSITA") -> N/TRANSITA | R32: =AVERAGE(O32,MAX(P32:Q32)) -> 0 | S32: =SUM(H32,M32,R32)/3 -> 0 | T32: =IF(S32>=10,"TRANSITA","N/TRANSITA") -> N/TRANSITA
B33: 25 | C33: Gandira De Fatima Gomes | E33: 8 | F33: 11 | H33: =AVERAGE(E33,MAX(F33:G33)) -> 9.5 | I33: =IF(H33>=10,"TRANSITA","N/TRANSITA") -> N/TRANSITA | J33: 12 | K33: 12 | M33: =AVERAGE(J33,MAX(K33:L33)) -> 12 | N33: =IF(M33>=10,"TRANSITA","N/TRANSITA") -> TRANSITA | R33: =AVERAGE(O33,MAX(P33:Q33)) -> 0 | S33: =SUM(H33,M33,R33)/3 -> 7.1666667 | T33: =IF(S33>=10,"TRANSITA","N/TRANSITA") -> N/TRANSITA
B34: 26 | C34: Germénia Gertrudes Bato | H34: =AVERAGE(E34,MAX(F34:G34)) -> 0 | I34: =IF(H34>=10,"TRANSITA","N/TRANSITA") -> N/TRANSITA | M34: =AVERAGE(J34,MAX(K34:L34)) -> 0 | N34: =IF(M34>=10,"TRANSITA","N/TRANSITA") -> N/TRANSITA | R34: =AVERAGE(O34,MAX(P34:Q34)) -> 0 | S34: =SUM(H34,M34,R34)/3 -> 0 | T34: =IF(S34>=10,"TRANSITA","N/TRANSITA") -> N/TRANSITA
B35: 27 | C35: Graça das Dores Isiala Goiaba | H35: =AVERAGE(E35,MAX(F35:G35)) -> 0 | I35: =IF(H35>=10,"TRANSITA","N/TRANSITA") -> N/TRANSITA | M35: =AVERAGE(J35,MAX(K35:L35)) -> 0 | N35: =IF(M35>=10,"TRANSITA","N/TRANSITA") -> N/TRANSITA | R35: =AVERAGE(O35,MAX(P35:Q35)) -> 0 | S35: =SUM(H35,M35,R35)/3 -> 0 | T35: =IF(S35>=10,"TRANSITA","N/TRANSITA") -> N/TRANSITA
B36: 28 | C36: Helena De Fátima Sango Mabiala | E36: 8 | F36: 11 | H36: =AVERAGE(E36,MAX(F36:G36)) -> 9.5 | I36: =IF(H36>=10,"TRANSITA","N/TRANSITA") -> N/TRANSITA | J36: 4 | M36: =AVERAGE(J36,MAX(K36:L36)) -> 2 | N36: =IF(M36>=10,"TRANSITA","N/TRANSITA") -> N/TRANSITA | R36: =AVERAGE(O36,MAX(P36:Q36)) -> 0 | S36: =SUM(H36,M36,R36)/3 -> 3.8333333 | T36: =IF(S36>=10,"TRANSITA","N/TRANSITA") -> N/TRANSITA
B37: 29 | C37: Helena Mavinga | E37: 12 | F37: 14 | H37: =AVERAGE(E37,MAX(F37:G37)) -> 13 | I37: =IF(H37>=10,"TRANSITA","N/TRANSITA") -> TRANSITA | J37: 10 | K37: 6 | M37: =AVERAGE(J37,MAX(K37:L37)) -> 8 | N37: =IF(M37>=10,"TRANSITA","N/TRANSITA") -> N/TRANSITA | R37: =AVERAGE(O37,MAX(P37:Q37)) -> 0 | S37: =SUM(H37,M37,R37)/3 -> 7 | T37: =IF(S37>=10,"TRANSITA","N/TRANSITA") -> N/TRANSITA
B38: 30 | C38: Hornorina Pemba Binda Sunda | H38: =AVERAGE(E38,MAX(F38:G38)) -> 0 | I38: =IF(H38>=10,"TRANSITA","N/TRANSITA") -> N/TRANSITA | M38: =AVERAGE(J38,MAX(K38:L38)) -> 0 | N38: =IF(M38>=10,"TRANSITA","N/TRANSITA") -> N/TRANSITA | R38: =AVERAGE(O38,MAX(P38:Q38)) -> 0 | S38: =SUM(H38,M38,R38)/3 -> 0 | T38: =IF(S38>=10,"TRANSITA","N/TRANSITA") -> N/TRANSITA
B39: 31 | C39: Imaculada Lelo Lufumba | H39: =AVERAGE(E39,MAX(F39:G39)) -> 0 | I39: =IF(H39>=10,"TRANSITA","N/TRANSITA") -> N/TRANSITA | M39: =AVERAGE(J39,MAX(K39:L39)) -> 0 | N39: =IF(M39>=10,"TRANSITA","N/TRANSITA") -> N/TRANSITA | R39: =AVERAGE(O39,MAX(P39:Q39)) -> 0 | S39: =SUM(H39,M39,R39)/3 -> 0 | T39: =IF(S39>=10,"TRANSITA","N/TRANSITA") -> N/TRANSITA
B40: 32 | C40: Isabel Ernesto Zovo Lourdes | E40: 6 | F40: 0 | H40: =AVERAGE(E40,MAX(F40:G40)) -> 3 | I40: =IF(H40>=10,"TRANSITA","N/TRANSITA") -> N/TRANSITA | J40: 2 | K40: 11 | M40: =AVERAGE(J40,MAX(K40:L40)) -> 6.5 | N40: =IF(M40>=10,"TRANSITA","N/TRANSITA") -> N/TRANSITA | R40: =AVERAGE(O40,MAX(P40:Q40)) -> 0 | S40: =SUM(H40,M40,R40)/3 -> 3.1666667 | T40: =IF(S40>=10,"TRANSITA","N/TRANSITA") -> N/TRANSITA
B41: 33 | C41: Jaquelina Kibinda Chicai Suami | E41: 16 | F41: 17 | H41: =AVERAGE(E41,MAX(F41:G41)) -> 16.5 | I41: =IF(H41>=10,"TRANSITA","N/TRANSITA") -> TRANSITA | J41: 16 | K41: 15 | M41: =AVERAGE(J41,MAX(K41:L41)) -> 15.5 | N41: =IF(M41>=10,"TRANSITA","N/TRANSITA") -> TRANSITA | R41: =AVERAGE(O41,MAX(P41:Q41)) -> 0 | S41: =SUM(H41,M41,R41)/3 -> 10.666667 | T41: =IF(S41>=10,"TRANSITA","N/TRANSITA") -> TRANSITA
B42: 34 | C42: Joana Mabiala Simba | H42: =AVERAGE(E42,MAX(F42:G42)) -> 0 | I42: =IF(H42>=10,"TRANSITA","N/TRANSITA") -> N/TRANSITA | M42: =AVERAGE(J42,MAX(K42:L42)) -> 0 | N42: =IF(M42>=10,"TRANSITA","N/TRANSITA") -> N/TRANSITA | R42: =AVERAGE(O42,MAX(P42:Q42)) -> 0 | S42: =SUM(H42,M42,R42)/3 -> 0 | T42: =IF(S42>=10,"TRANSITA","N/TRANSITA") -> N/TRANSITA
...

Sheet 10ªCFB-U-MAT
A1: COMPLEXO ESCOLAR PRIVADO JOMORAIS
B4: Classe: 10ª | I4: Disciplina: Matemática | P4: Ano Lectivo:2025/2026
B5: Período: Matinal | I5: Turma: Única | N5: Curso: Ciências Físicas e Biológicas
B6: MINI-PAUTA - I Ciclo do Ensino Secundário Geral
B7: Nº | C7: Nome do (a) Aluno (a) | D7: FALTAS | E7: Avaliações/I Trimestre | I7: OBS | J7: Avaliações/II Trimestre | N7: OBS | O7: Avaliações/IIITrimestre | S7: MFD | T7: OBS
D8: J/I | E8: MAC | F8: NPT | G8: NPR2 | H8: MT1 | J8: MAC | K8: NPT | L8: NPR2 | M8: MT2 | O8: MAC | P8: NPT | Q8: NPR2 | R8: MT3
B9: 1 | C9: Adelina Malonda Poba | E9: 16 | F9: 3 | G9: 10 | H9: =AVERAGE(E9,MAX(F9:G9)) -> 13 | I9: =IF(H9>=10,"TRANSITA","N/TRANSITA") -> TRANSITA | J9: 13 | K9: 13 | M9: =AVERAGE(J9,MAX(K9:L9)) -> 13 | N9: =IF(M9>=10,"TRANSITA","N/TRANSITA") -> TRANSITA | R9: =AVERAGE(O9,MAX(P9:Q9)) -> 0 | S9: =SUM(H9,M9,R9)/3 -> 8.6666667 | T9: =IF(S9>=10,"TRANSITA","N/TRANSITA") -> N/TRANSITA
B10: 2 | C10: Adelina Marques Zau | E10: 13 | H10: =AVERAGE(E10,MAX(F10:G10)) -> 6.5 | I10: =IF(H10>=10,"TRANSITA","N/TRANSITA") -> N/TRANSITA | J10: 12 | K10: 15 | M10: =AVERAGE(J10,MAX(K10:L10)) -> 13.5 | N10: =IF(M10>=10,"TRANSITA","N/TRANSITA") -> TRANSITA | R10: =AVERAGE(O10,MAX(P10:Q10)) -> 0 | S10: =SUM(H10,M10,R10)/3 -> 6.6666667 | T10: =IF(S10>=10,"TRANSITA","N/TRANSITA") -> N/TRANSITA
B11: 3 | C11: Albertina Eduardo Macosso | E11: 17 | F11: 10 | H11: =AVERAGE(E11,MAX(F11:G11)) -> 13.5 | I11: =IF(H11>=10,"TRANSITA","N/TRANSITA") -> TRANSITA | J11: 10 | K11: 10 | M11: =AVERAGE(J11,MAX(K11:L11)) -> 10 | N11: =IF(M11>=10,"TRANSITA","N/TRANSITA") -> TRANSITA | R11: =AVERAGE(O11,MAX(P11:Q11)) -> 0 | S11: =SUM(H11,M11,R11)/3 -> 7.8333333 | T11: =IF(S11>=10,"TRANSITA","N/TRANSITA") -> N/TRANSITA
B12: 4 | C12: Albertina Muanda Salvador Biala | E12: 11 | H12: =AVERAGE(E12,MAX(F12:G12)) -> 5.5 | I12: =IF(H12>=10,"TRANSITA","N/TRANSITA") -> N/TRANSITA | M12: =AVERAGE(J12,MAX(K12:L12)) -> 0 | N12: =IF(M12>=10,"TRANSITA","N/TRANSITA") -> N/TRANSITA | R12: =AVERAGE(O12,MAX(P12:Q12)) -> 0 | S12: =SUM(H12,M12,R12)/3 -> 1.8333333 | T12: =IF(S12>=10,"TRANSITA","N/TRANSITA") -> N/TRANSITA
B13: 5 | C13: Albeto Pucuta Luemba Mambuco | E13: 20 | F13: 20 | H13: =AVERAGE(E13,MAX(F13:G13)) -> 20 | I13: =IF(H13>=10,"TRANSITA","N/TRANSITA") -> TRANSITA | J13: 18 | K13: 20 | M13: =AVERAGE(J13,MAX(K13:L13)) -> 19 | N13: =IF(M13>=10,"TRANSITA","N/TRANSITA") -> TRANSITA | R13: =AVERAGE(O13,MAX(P13:Q13)) -> 0 | S13: =SUM(H13,M13,R13)/3 -> 13 | T13: =IF(S13>=10,"TRANSITA","N/TRANSITA") -> TRANSITA
B14: 6 | C14: Alexandre Coto Ndombe Puati | E14: 13 | F14: 10 | H14: =AVERAGE(E14,MAX(F14:G14)) -> 11.5 | I14: =IF(H14>=10,"TRANSITA","N/TRANSITA") -> TRANSITA | J14: 8 | K14: 15 | M14: =AVERAGE(J14,MAX(K14:L14)) -> 11.5 | N14: =IF(M14>=10,"TRANSITA","N/TRANSITA") -> TRANSITA | R14: =AVERAGE(O14,MAX(P14:Q14)) -> 0 | S14: =SUM(H14,M14,R14)/3 -> 7.6666667 | T14: =IF(S14>=10,"TRANSITA","N/TRANSITA") -> N/TRANSITA
B15: 7 | C15: Alice Isabel Maria Muginga | E15: 14 | F15: 12 | H15: =AVERAGE(E15,MAX(F15:G15)) -> 13 | I15: =IF(H15>=10,"TRANSITA","N/TRANSITA") -> TRANSITA | J15: 8 | M15: =AVERAGE(J15,MAX(K15:L15)) -> 4 | N15: =IF(M15>=10,"TRANSITA","N/TRANSITA") -> N/TRANSITA | R15: =AVERAGE(O15,MAX(P15:Q15)) -> 0 | S15: =SUM(H15,M15,R15)/3 -> 5.6666667 | T15: =IF(S15>=10,"TRANSITA","N/TRANSITA") -> N/TRANSITA
B16: 8 | C16: Angelica Celina Domingos | E16: 14 | H16: =AVERAGE(E16,MAX(F16:G16)) -> 7 | I16: =IF(H16>=10,"TRANSITA","N/TRANSITA") -> N/TRANSITA | J16: 8 | K16: 17 | M16: =AVERAGE(J16,MAX(K16:L16)) -> 12.5 | N16: =IF(M16>=10,"TRANSITA","N/TRANSITA") -> TRANSITA | R16: =AVERAGE(O16,MAX(P16:Q16)) -> 0 | S16: =SUM(H16,M16,R16)/3 -> 6.5 | T16: =IF(S16>=10,"TRANSITA","N/TRANSITA") -> N/TRANSITA
B17: 9 | C17: António Diela | E17: 15 | F17: 12 | H17: =AVERAGE(E17,MAX(F17:G17)) -> 13.5 | I17: =IF(H17>=10,"TRANSITA","N/TRANSITA") -> TRANSITA | J17: 13 | K17: 15 | M17: =AVERAGE(J17,MAX(K17:L17)) -> 14 | N17: =IF(M17>=10,"TRANSITA","N/TRANSITA") -> TRANSITA | R17: =AVERAGE(O17,MAX(P17:Q17)) -> 0 | S17: =SUM(H17,M17,R17)/3 -> 9.1666667 | T17: =IF(S17>=10,"TRANSITA","N/TRANSITA") -> N/TRANSITA
B18: 10 | C18: António Ngimbi Capita | E18: 8 | H18: =AVERAGE(E18,MAX(F18:G18)) -> 4 | I18: =IF(H18>=10,"TRANSITA","N/TRANSITA") -> N/TRANSITA | J18: 10 | K18: 12 | M18: =AVERAGE(J18,MAX(K18:L18)) -> 11 | N18: =IF(M18>=10,"TRANSITA","N/TRANSITA") -> TRANSITA | R18: =AVERAGE(O18,MAX(P18:Q18)) -> 0 | S18: =SUM(H18,M18,R18)/3 -> 5 | T18: =IF(S18>=10,"TRANSITA","N/TRANSITA") -> N/TRANSITA
B19: 11 | C19: Bernicia Mussitu | H19: =AVERAGE(E19,MAX(F19:G19)) -> 0 | I19: =IF(H19>=10,"TRANSITA","N/TRANSITA") -> N/TRANSITA | M19: =AVERAGE(J19,MAX(K19:L19)) -> 0 | N19: =IF(M19>=10,"TRANSITA","N/TRANSITA") -> N/TRANSITA | R19: =AVERAGE(O19,MAX(P19:Q19)) -> 0 | S19: =SUM(H19,M19,R19)/3 -> 0 | T19: =IF(S19>=10,"TRANSITA","N/TRANSITA") -> N/TRANSITA
B20: 12 | C20: Candida Da Silva Sambo | E20: 14 | F20: 11 | H20: =AVERAGE(E20,MAX(F20:G20)) -> 12.5 | I20: =IF(H20>=10,"TRANSITA","N/TRANSITA") -> TRANSITA | J20: 10 | K20: 16 | M20: =AVERAGE(J20,MAX(K20:L20)) -> 13 | N20: =IF(M20>=10,"TRANSITA","N/TRANSITA") -> TRANSITA | R20: =AVERAGE(O20,MAX(P20:Q20)) -> 0 | S20: =SUM(H20,M20,R20)/3 -> 8.5 | T20: =IF(S20>=10,"TRANSITA","N/TRANSITA") -> N/TRANSITA
B21: 13 | C21: Catarina Kiaba Maluta | H21: =AVERAGE(E21,MAX(F21:G21)) -> 0 | I21: =IF(H21>=10,"TRANSITA","N/TRANSITA") -> N/TRANSITA | M21: =AVERAGE(J21,MAX(K21:L21)) -> 0 | N21: =IF(M21>=10,"TRANSITA","N/TRANSITA") -> N/TRANSITA | R21: =AVERAGE(O21,MAX(P21:Q21)) -> 0 | S21: =SUM(H21,M21,R21)/3 -> 0 | T21: =IF(S21>=10,"TRANSITA","N/TRANSITA") -> N/TRANSITA
B22: 14 | C22: Cristiana Jemina Macanda | H22: =AVERAGE(E22,MAX(F22:G22)) -> 0 | I22: =IF(H22>=10,"TRANSITA","N/TRANSITA") -> N/TRANSITA | M22: =AVERAGE(J22,MAX(K22:L22)) -> 0 | N22: =IF(M22>=10,"TRANSITA","N/TRANSITA") -> N/TRANSITA | R22: =AVERAGE(O22,MAX(P22:Q22)) -> 0 | S22: =SUM(H22,M22,R22)/3 -> 0 | T22: =IF(S22>=10,"TRANSITA","N/TRANSITA") -> N/TRANSITA
B23: 15 | C23: Debora Antonio Bumba Bilongo | E23: 17 | F23: 16 | H23: =AVERAGE(E23,MAX(F23:G23)) -> 16.5 | I23: =IF(H23>=10,"TRANSITA","N/TRANSITA") -> TRANSITA | J23: 13 | K23: 16 | M23: =AVERAGE(J23,MAX(K23:L23)) -> 14.5 | N23: =IF(M23>=10,"TRANSITA","N/TRANSITA") -> TRANSITA | R23: =AVERAGE(O23,MAX(P23:Q23)) -> 0 | S23: =SUM(H23,M23,R23)/3 -> 10.333333 | T23: =IF(S23>=10,"TRANSITA","N/TRANSITA") -> TRANSITA
B24: 16 | C24: Elisa Do Nascimento Cumbo | E24: 14 | F24: 6 | H24: =AVERAGE(E24,MAX(F24:G24)) -> 10 | I24: =IF(H24>=10,"TRANSITA","N/TRANSITA") -> TRANSITA | J24: 13 | K24: 16 | M24: =AVERAGE(J24,MAX(K24:L24)) -> 14.5 | N24: =IF(M24>=10,"TRANSITA","N/TRANSITA") -> TRANSITA | R24: =AVERAGE(O24,MAX(P24:Q24)) -> 0 | S24: =SUM(H24,M24,R24)/3 -> 8.1666667 | T24: =IF(S24>=10,"TRANSITA","N/TRANSITA") -> N/TRANSITA
