Workbook

Sheet 1ºT-11ª-FAR-UNICA-PAUTA
A1: INSTITUTO TÉCNICO PRIVADO DE SAÚDE JOMORAIS
B7: PAUTA DE APROVEITAMENTO ESCOLAR
C8: ÁREA DE FORMAÇÃO: SAÚDE
H9: 11ª CLASSE | M9: CURSO: FARMÁCIA | AC9: PERÍODO: VESPERTNO
B10: O Director do Instituto | AD10: 1º TRIMESTRE | AH10: MF: | AI10: =SUM(AI12,AI11) -> 55
B11: ________________________________________ | H11: TURMA: | J11: ÚNICA | AH11: M | AI11: =COUNTIF(AV17:AV71,"M") -> 12 | AR11: 46003
B12: GABRIEL PRÓSPERO MABIALA | Z12: ANO LECTIVO: 2025/2026 | AH12: F | AI12: =COUNTIF(AV17:AV71,"F") -> 43
B13: DATA______/______/2025
B14: Nº | C14: Nº PROC | D14: NOME | E14: DISCIPLINA A REPETIR | F14: L. Port | I14: Mat. | L14: Biologia | O14: Inglês | R14: Patologia | U14: Micoparasit. | X14: Farmacologia | AA14: Farmacog. | AD14: TPM | AG14: Qca Org. | AJ14: Ed. Física | AM14: Botânica | AP14: A.F.H | AS14: OBS | AT14: MÉDIA | AU14: Idade | AV14: Género | AW14: DADOS ESTATÍSTICOS
F15: FALTAS | H15: MT1º | I15: FALTAS | K15: MT1º | L15: FALTAS | N15: MT1º | O15: FALTAS | Q15: MT1º | R15: FALTAS | T15: MT1º | U15: FALTAS | W15: MT1º | X15: FALTAS | Z15: MT1º | AA15: FALTAS | AC15: MT1º | AD15: FALTAS | AF15: MT1º | AG15: FALTAS | AI15: MT1º | AJ15: FALTAS | AL15: MT1º | AM15: FALTAS | AO15: MT1º | AP15: FALTAS | AR15: MT1º | AW15: MATRICULADOS | AY15: TRANSITA | BA15: N/TRANSITA | BC15: Desistido/a
F16: J | G16: I | I16: J | J16: I | L16: J | M16: I | O16: J | P16: I | R16: J | S16: I | U16: J | V16: I | X16: J | Y16: I | AA16: J | AB16: I | AD16: J | AE16: I | AG16: J | AH16: I | AJ16: J | AK16: I | AM16: J | AN16: I | AP16: J | AQ16: I | AW16: M | AX16: F | AY16: M | AZ16: F | BA16: M | BB16: F | BC16: M | BD16: F
B17: 1 | C17: 4068 | D17: Alice Cungi Alfredo | H17: =SUM('11CL-FAR-L PORT'!J9) -> 9.3333333 | K17: =SUM('11CL-FAR-MAT'!J9) -> 6.6666667 | N17: =SUM('11CL-FAR-BIOL'!J9) -> 11.666667 | Q17: =SUM('11CL-FAR-INGLES'!J9) -> 8 | T17: =SUM('11CL-FAR-PATOL'!J9) -> 3 | W17: =SUM('11CL-FAR-MPARASITOL'!J9) -> 1.1666667 | Z17: =SUM('11CL-FAR-FARMACOL'!J9) -> 8.6666667 | AC17: =SUM('11CL-FAR-FARMACOG'!J9) -> 7.8333333 | AF17: =SUM('11CL-FAR-TPM'!J9) -> 10 | AI17: =SUM('11CL-FAR-QCA ORG.'!J9) -> 9.3333333 | AL17: =SUM('11CL-FAR-ED. FIS'!J9) -> 12 | AO17: =SUM('11CL-FAR-BOTANICA'!J9) -> 8 | AR17: =SUM('11CL-FAR-AFH'!J9) -> 8.3333333 | AS17: N/TRANSITA | AT17: =AVERAGE(H17:AR17) -> 8 | AU17: 22 | AV17: F | AW17: =COUNTIF(AV17:AV71,"M") -> 12 | AX17: =COUNTIF(AV17:AV71,"F") -> 43 | AY17: =COUNTIFS(AS17:AS71,"Transita",AV17:AV71,"M") -> 1 | AZ17: =COUNTIFS(AS17:AS71,"Transita",AV17:AV71,"F") -> 2 | BA17: =COUNTIFS(AS17:AS71,"N/Transita",AV17:AV71,"M") -> 11 | BB17: =COUNTIFS(AS17:AS71,"N/Transita",AV17:AV71,"F") -> 37 | BC17: =COUNTIFS(AS17:AS71,"DESISTIDO",AV17:AV71,"M") -> 0 | BD17: =COUNTIFS(AS17:AS71,"DESISTIDA",AV17:AV71,"F") -> 4
B18: 2 | C18: 3983 | D18: Amélia Mauricio Macaia | H18: =SUM('11CL-FAR-L PORT'!J10) -> 9.8333333 | K18: =SUM('11CL-FAR-MAT'!J10) -> 7.8333333 | N18: =SUM('11CL-FAR-BIOL'!J10) -> 11.666667 | Q18: =SUM('11CL-FAR-INGLES'!J10) -> 13.333333 | T18: =SUM('11CL-FAR-PATOL'!J10) -> 11 | W18: =SUM('11CL-FAR-MPARASITOL'!J10) -> 9.6666667 | Z18: =SUM('11CL-FAR-FARMACOL'!J10) -> 10.666667 | AC18: =SUM('11CL-FAR-FARMACOG'!J10) -> 12 | AF18: =SUM('11CL-FAR-TPM'!J10) -> 11.333333 | AI18: =SUM('11CL-FAR-QCA ORG.'!J10) -> 9.8333333 | AL18: =SUM('11CL-FAR-ED. FIS'!J10) -> 15 | AO18: =SUM('11CL-FAR-BOTANICA'!J10) -> 8.8333333 | AR18: =SUM('11CL-FAR-AFH'!J10) -> 16.333333 | AS18: N/TRANSITA | AT18: =AVERAGE(H18:AR18) -> 11.333333 | AU18: 18 | AV18: F | AW18: =SUM(AW17:AX17) -> 55 | AY18: =SUM(AY16:AZ17) -> 3 | BA18: =SUM(BA16:BB17) -> 48 | BC18: =SUM(BC16:BD17) -> 4
B19: 3 | C19: 4163 | D19: Angelina Umba Esperança Luyeye | H19: =SUM('11CL-FAR-L PORT'!J11) -> 11.333333 | K19: =SUM('11CL-FAR-MAT'!J11) -> 12.5 | N19: =SUM('11CL-FAR-BIOL'!J11) -> 10.333333 | Q19: =SUM('11CL-FAR-INGLES'!J11) -> 12.333333 | T19: =SUM('11CL-FAR-PATOL'!J11) -> 12.666667 | W19: =SUM('11CL-FAR-MPARASITOL'!J11) -> 9 | Z19: =SUM('11CL-FAR-FARMACOL'!J11) -> 14 | AC19: =SUM('11CL-FAR-FARMACOG'!J11) -> 9.3333333 | AF19: =SUM('11CL-FAR-TPM'!J11) -> 7 | AI19: =SUM('11CL-FAR-QCA ORG.'!J11) -> 11.333333 | AL19: =SUM('11CL-FAR-ED. FIS'!J11) -> 14 | AO19: =SUM('11CL-FAR-BOTANICA'!J11) -> 9 | AR19: =SUM('11CL-FAR-AFH'!J11) -> 8.1666667 | AS19: N/TRANSITA | AT19: =AVERAGE(H19:AR19) -> 10.846154 | AU19: 20 | AV19: F
B20: 4 | C20: 3939 | D20: Armindo Maciala Mendes | H20: =SUM('11CL-FAR-L PORT'!J12) -> 16.666667 | K20: =SUM('11CL-FAR-MAT'!J12) -> 20 | N20: =SUM('11CL-FAR-BIOL'!J12) -> 17.333333 | Q20: =SUM('11CL-FAR-INGLES'!J12) -> 19 | T20: =SUM('11CL-FAR-PATOL'!J12) -> 14.666667 | W20: =SUM('11CL-FAR-MPARASITOL'!J12) -> 12 | Z20: =SUM('11CL-FAR-FARMACOL'!J12) -> 14 | AC20: =SUM('11CL-FAR-FARMACOG'!J12) -> 10 | AF20: =SUM('11CL-FAR-TPM'!J12) -> 15 | AI20: =SUM('11CL-FAR-QCA ORG.'!J12) -> 16.666667 | AL20: =SUM('11CL-FAR-ED. FIS'!J12) -> 17 | AO20: =SUM('11CL-FAR-BOTANICA'!J12) -> 16.5 | AR20: =SUM('11CL-FAR-AFH'!J12) -> 17.666667 | AS20: TRANSITA | AT20: =AVERAGE(H20:AR20) -> 15.884615 | AU20: 20 | AV20: M
B21: 5 | C21: 3461 | D21: Beatriz Lelo Nombo | H21: =SUM('11CL-FAR-L PORT'!J13) -> 15.666667 | K21: =SUM('11CL-FAR-MAT'!J13) -> 6 | N21: =SUM('11CL-FAR-BIOL'!J13) -> 15.333333 | Q21: =SUM('11CL-FAR-INGLES'!J13) -> 16.666667 | T21: =SUM('11CL-FAR-PATOL'!J13) -> 16.666667 | W21: =SUM('11CL-FAR-MPARASITOL'!J13) -> 10 | Z21: =SUM('11CL-FAR-FARMACOL'!J13) -> 15.333333 | AC21: =SUM('11CL-FAR-FARMACOG'!J13) -> 15.333333 | AF21: =SUM('11CL-FAR-TPM'!J13) -> 16 | AI21: =SUM('11CL-FAR-QCA ORG.'!J13) -> 15.666667 | AL21: =SUM('11CL-FAR-ED. FIS'!J13) -> 15 | AO21: =SUM('11CL-FAR-BOTANICA'!J13) -> 14.5 | AR21: =SUM('11CL-FAR-AFH'!J13) -> 14.833333 | AS21: N/TRANSITA | AT21: =AVERAGE(H21:AR21) -> 14.384615 | AU21: 17 | AV21: F
B22: 6 | C22: 4030 | D22: Carolina Zuzi Nhimi | H22: =SUM('11CL-FAR-L PORT'!J14) -> 13.333333 | K22: =SUM('11CL-FAR-MAT'!J14) -> 13.333333 | N22: =SUM('11CL-FAR-BIOL'!J14) -> 8.3333333 | Q22: =SUM('11CL-FAR-INGLES'!J14) -> 12 | T22: =SUM('11CL-FAR-PATOL'!J14) -> 9.8333333 | W22: =SUM('11CL-FAR-MPARASITOL'!J14) -> 3.6666667 | Z22: =SUM('11CL-FAR-FARMACOL'!J14) -> 12.666667 | AC22: =SUM('11CL-FAR-FARMACOG'!J14) -> 10 | AF22: =SUM('11CL-FAR-TPM'!J14) -> 13.666667 | AI22: =SUM('11CL-FAR-QCA ORG.'!J14) -> 13.333333 | AL22: =SUM('11CL-FAR-ED. FIS'!J14) -> 13 | AO22: =SUM('11CL-FAR-BOTANICA'!J14) -> 11.666667 | AR22: =SUM('11CL-FAR-AFH'!J14) -> 16.5 | AS22: N/TRANSITA | AT22: =AVERAGE(H22:AR22) -> 11.641026 | AU22: 20 | AV22: F
B23: 7 | C23: 3086 | D23: Catarina Simba Buela | H23: =SUM('11CL-FAR-L PORT'!J15) -> 9 | K23: =SUM('11CL-FAR-MAT'!J15) -> 17.666667 | N23: =SUM('11CL-FAR-BIOL'!J15) -> 12.666667 | Q23: =SUM('11CL-FAR-INGLES'!J15) -> 12 | T23: =SUM('11CL-FAR-PATOL'!J15) -> 11.666667 | W23: =SUM('11CL-FAR-MPARASITOL'!J15) -> 9.3333333 | Z23: =SUM('11CL-FAR-FARMACOL'!J15) -> 11 | AC23: =SUM('11CL-FAR-FARMACOG'!J15) -> 9 | AF23: =SUM('11CL-FAR-TPM'!J15) -> 9.6666667 | AI23: =SUM('11CL-FAR-QCA ORG.'!J15) -> 9 | AL23: =SUM('11CL-FAR-ED. FIS'!J15) -> 13 | AO23: =SUM('11CL-FAR-BOTANICA'!J15) -> 12 | AR23: =SUM('11CL-FAR-AFH'!J15) -> 11.166667 | AS23: N/TRANSITA | AT23: =AVERAGE(H23:AR23) -> 11.320513 | AU23: 29 | AV23: F
B24: 8 | C24: 4117 | D24: Cecília Suami Lando Massiala | H24: =SUM('11CL-FAR-L PORT'!J16) -> 5.8333333 | K24: =SUM('11CL-FAR-MAT'!J16) -> 8 | N24: =SUM('11CL-FAR-BIOL'!J16) -> 9 | Q24: =SUM('11CL-FAR-INGLES'!J16) -> 11.666667 | T24: =SUM('11CL-FAR-PATOL'!J16) -> 1.6666667 | W24: =SUM('11CL-FAR-MPARASITOL'!J16) -> 2.1666667 | Z24: =SUM('11CL-FAR-FARMACOL'!J16) -> 9.6666667 | AC24: =SUM('11CL-FAR-FARMACOG'!J16) -> 10 | AF24: =SUM('11CL-FAR-TPM'!J16) -> 9.3333333 | AI24: =SUM('11CL-FAR-QCA ORG.'!J16) -> 5.8333333 | AL24: =SUM('11CL-FAR-ED. FIS'!J16) -> 15 | AO24: =SUM('11CL-FAR-BOTANICA'!J16) -> 7.5 | AR24: =SUM('11CL-FAR-AFH'!J16) -> 9 | AS24: N/TRANSITA | AT24: =AVERAGE(H24:AR24) -> 8.0512821 | AU24: 21 | AV24: M
B25: 9 | C25: 4080 | D25: Clara Sungo Buati Chiânica | H25: =SUM('11CL-FAR-L PORT'!J17) -> 13.666667 | K25: =SUM('11CL-FAR-MAT'!J17) -> 17 | N25: =SUM('11CL-FAR-BIOL'!J17) -> 12.333333 | Q25: =SUM('11CL-FAR-INGLES'!J17) -> 15.333333 | T25: =SUM('11CL-FAR-PATOL'!J17) -> 11.666667 | W25: =SUM('11CL-FAR-MPARASITOL'!J17) -> 10.666667 | Z25: =SUM('11CL-FAR-FARMACOL'!J17) -> 11.5 | AC25: =SUM('11CL-FAR-FARMACOG'!J17) -> 10.333333 | AF25: =SUM('11CL-FAR-TPM'!J17) -> 9 | AI25: =SUM('11CL-FAR-QCA ORG.'!J17) -> 13.666667 | AL25: =SUM('11CL-FAR-ED. FIS'!J17) -> 14 | AO25: =SUM('11CL-FAR-BOTANICA'!J17) -> 13.833333 | AR25: =SUM('11CL-FAR-AFH'!J17) -> 10.166667 | AS25: N/TRANSITA | AT25: =AVERAGE(H25:AR25) -> 12.551282 | AU25: 19 | AV25: F
B26: 10 | C26: 3986 | D26: Clementina Paca V. Guimbi | H26: =SUM('11CL-FAR-L PORT'!J18) -> 10.5 | K26: =SUM('11CL-FAR-MAT'!J18) -> 8.6666667 | N26: =SUM('11CL-FAR-BIOL'!J18) -> 10.333333 | Q26: =SUM('11CL-FAR-INGLES'!J18) -> 4.6666667 | T26: =SUM('11CL-FAR-PATOL'!J18) -> 4.6666667 | W26: =SUM('11CL-FAR-MPARASITOL'!J18) -> 2.5 | Z26: =SUM('11CL-FAR-FARMACOL'!J18) -> 9.6666667 | AC26: =SUM('11CL-FAR-FARMACOG'!J18) -> 9.3333333 | AF26: =SUM('11CL-FAR-TPM'!J18) -> 8 | AI26: =SUM('11CL-FAR-QCA ORG.'!J18) -> 10.5 | AL26: =SUM('11CL-FAR-ED. FIS'!J18) -> 10 | AO26: =SUM('11CL-FAR-BOTANICA'!J18) -> 2 | AR26: =SUM('11CL-FAR-AFH'!J18) -> 7.5 | AS26: N/TRANSITA | AT26: =AVERAGE(H26:AR26) -> 7.5641026 | AU26: 19 | AV26: F
B27: 11 | C27: 4094 | D27: Cleúsia Da Conceição Mboco Kilombo | H27: =SUM('11CL-FAR-L PORT'!J19) -> 6.6666667 | K27: =SUM('11CL-FAR-MAT'!J19) -> 7.6666667 | N27: =SUM('11CL-FAR-BIOL'!J19) -> 11 | Q27: =SUM('11CL-FAR-INGLES'!J19) -> 10.333333 | T27: =SUM('11CL-FAR-PATOL'!J19) -> 3.8333333 | W27: =SUM('11CL-FAR-MPARASITOL'!J19) -> 4.5 | Z27: =SUM('11CL-FAR-FARMACOL'!J19) -> 11.166667 | AC27: =SUM('11CL-FAR-FARMACOG'!J19) -> 10 | AF27: =SUM('11CL-FAR-TPM'!J19) -> 0 | AI27: =SUM('11CL-FAR-QCA ORG.'!J19) -> 6.6666667 | AL27: =SUM('11CL-FAR-ED. FIS'!J19) -> 10 | AO27: =SUM('11CL-FAR-BOTANICA'!J19) -> 4.6666667 | AR27: =SUM('11CL-FAR-AFH'!J19) -> 11.5 | AS27: N/TRANSITA | AT27: =AVERAGE(H27:AR27) -> 7.5384615 | AU27: 19 | AV27: F
B28: 12 | C28: 4175 | D28: Damália Isaias Bumba | H28: =SUM('11CL-FAR-L PORT'!J20) -> 13 | K28: =SUM('11CL-FAR-MAT'!J20) -> 14.833333 | N28: =SUM('11CL-FAR-BIOL'!J20) -> 9.6666667 | Q28: =SUM('11CL-FAR-INGLES'!J20) -> 13 | T28: =SUM('11CL-FAR-PATOL'!J20) -> 14.5 | W28: =SUM('11CL-FAR-MPARASITOL'!J20) -> 10.333333 | Z28: =SUM('11CL-FAR-FARMACOL'!J20) -> 13 | AC28: =SUM('11CL-FAR-FARMACOG'!J20) -> 12.5 | AF28: =SUM('11CL-FAR-TPM'!J20) -> 8.6666667 | AI28: =SUM('11CL-FAR-QCA ORG.'!J20) -> 13 | AL28: =SUM('11CL-FAR-ED. FIS'!J20) -> 11 | AO28: =SUM('11CL-FAR-BOTANICA'!J20) -> 10.666667 | AR28: =SUM('11CL-FAR-AFH'!J20) -> 10.833333 | AS28: N/TRANSITA | AT28: =AVERAGE(H28:AR28) -> 11.923077 | AU28: 22 | AV28: F
B29: 13 | C29: 2532 | D29: Divina Pemba Dembe | H29: =SUM('11CL-FAR-L PORT'!J21) -> 11.5 | K29: =SUM('11CL-FAR-MAT'!J21) -> 14.666667 | N29: =SUM('11CL-FAR-BIOL'!J21) -> 10.333333 | Q29: =SUM('11CL-FAR-INGLES'!J21) -> 15.333333 | T29: =SUM('11CL-FAR-PATOL'!J21) -> 14.166667 | W29: =SUM('11CL-FAR-MPARASITOL'!J21) -> 12.333333 | Z29: =SUM('11CL-FAR-FARMACOL'!J21) -> 13.666667 | AC29: =SUM('11CL-FAR-FARMACOG'!J21) -> 11 | AF29: =SUM('11CL-FAR-TPM'!J21) -> 10 | AI29: =SUM('11CL-FAR-QCA ORG.'!J21) -> 11.5 | AL29: =SUM('11CL-FAR-ED. FIS'!J21) -> 14 | AO29: =SUM('11CL-FAR-BOTANICA'!J21) -> 13.833333 | AR29: =SUM('11CL-FAR-AFH'!J21) -> 12 | AS29: N/TRANSITA | AT29: =AVERAGE(H29:AR29) -> 12.641026 | AU29: 19 | AV29: F
B30: 14 | C30: 3737 | D30: Emíliana Pemba Baza Jonace | H30: =SUM('11CL-FAR-L PORT'!J22) -> 12.333333 | K30: =SUM('11CL-FAR-MAT'!J22) -> 8 | N30: =SUM('11CL-FAR-BIOL'!J22) -> 13.666667 | Q30: =SUM('11CL-FAR-INGLES'!J22) -> 18.666667 | T30: =SUM('11CL-FAR-PATOL'!J22) -> 16.333333 | W30: =SUM('11CL-FAR-MPARASITOL'!J22) -> 8.6666667 | Z30: =SUM('11CL-FAR-FARMACOL'!J22) -> 0 | AC30: =SUM('11CL-FAR-FARMACOG'!J22) -> 12 | AF30: =SUM('11CL-FAR-TPM'!J22) -> 14.333333 | AI30: =SUM('11CL-FAR-QCA ORG.'!J22) -> 12.333333 | AL30: =SUM('11CL-FAR-ED. FIS'!J22) -> 16 | AO30: =SUM('11CL-FAR-BOTANICA'!J22) -> 11.666667 | AR30: =SUM('11CL-FAR-AFH'!J22) -> 14.333333 | AS30: N/TRANSITA | AT30: =AVERAGE(H30:AR30) -> 12.179487 | AU30: 17 | AV30: F
... B65: 49 | C65: 4044 | D65: Rosangela Andreia Pedro Brás Tati | H65: =SUM('11CL-FAR-L PORT'!J57) -> 15.166667 | K65: =SUM('11CL-FAR-MAT'!J57) -> 11.666667 | N65: =SUM('11CL-FAR-BIOL'!J57) -> 14.666667 | Q65: =SUM('11CL-FAR-INGLES'!J57) -> 20 | T65: =SUM('11CL-FAR-PATOL'!J57) -> 16.833333 | W65: =SUM('11CL-FAR-MPARASITOL'!J57) -> 10.833333 | Z65: =SUM('11CL-FAR-FARMACOL'!J57) -> 13.333333 | AC65: =SUM('11CL-FAR-FARMACOG'!J57) -> 13.5 | AF65: =SUM('11CL-FAR-TPM'!J57) -> 15 | AI65: =SUM('11CL-FAR-QCA ORG.'!J57) -> 15.166667 | AL65: =SUM('11CL-FAR-ED. FIS'!J57) -> 15 | AO65: =SUM('11CL-FAR-BOTANICA'!J57) -> 15.666667 | AR65: =SUM('11CL-FAR-AFH'!J57) -> 15.166667 | AS65: TRANSITA | AT65: =AVERAGE(H65:AR65) -> 14.769231 | AU65: 17 | AV65: F
B66: 50 | C66: 3263 | D66: Simélia Milando Pungui | H66: =SUM('11CL-FAR-L PORT'!J58) -> 0 | K66: =SUM('11CL-FAR-MAT'!J58) -> 0 | N66: =SUM('11CL-FAR-BIOL'!J58) -> 0 | Q66: =SUM('11CL-FAR-INGLES'!J58) -> 0 | T66: =SUM('11CL-FAR-PATOL'!J58) -> 0 | W66: =SUM('11CL-FAR-MPARASITOL'!J58) -> 0 | Z66: =SUM('11CL-FAR-FARMACOL'!J58) -> 0 | AC66: =SUM('11CL-FAR-FARMACOG'!J58) -> 0 | AF66: =SUM('11CL-FAR-TPM'!J58) -> 0 | AI66: =SUM('11CL-FAR-QCA ORG.'!J58) -> 0 | AL66: =SUM('11CL-FAR-ED. FIS'!J58) -> 10 | AO66: =SUM('11CL-FAR-BOTANICA'!J58) -> 0 | AR66: =SUM('11CL-FAR-AFH'!J58) -> 10 | AS66: DESISTIDA | AT66: =AVERAGE(H66:AR66) -> 1.5384615 | AU66: 27 | AV66: F | AX66: MÁXIMA | AY66: =MAX(AT17:AT71) -> 15.884615
B67: 51 | C67: 3610 | D67: Teresa Ndonda Costa | H67: =SUM('11CL-FAR-L PORT'!J59) -> 10.333333 | K67: =SUM('11CL-FAR-MAT'!J59) -> 10.666667 | N67: =SUM('11CL-FAR-BIOL'!J59) -> 8.6666667 | Q67: =SUM('11CL-FAR-INGLES'!J59) -> 13 | T67: =SUM('11CL-FAR-PATOL'!J59) -> 5.8333333 | W67: =SUM('11CL-FAR-MPARASITOL'!J59) -> 4 | Z67: =SUM('11CL-FAR-FARMACOL'!J59) -> 10 | AC67: =SUM('11CL-FAR-FARMACOG'!J59) -> 9.3333333 | AF67: =SUM('11CL-FAR-TPM'!J59) -> 9.3333333 | AI67: =SUM('11CL-FAR-QCA ORG.'!J59) -> 10.333333 | AL67: =SUM('11CL-FAR-ED. FIS'!J59) -> 14 | AO67: =SUM('11CL-FAR-BOTANICA'!J59) -> 2 | AR67: =SUM('11CL-FAR-AFH'!J59) -> 10 | AS67: N/TRANSITA | AT67: =AVERAGE(H67:AR67) -> 9.0384615 | AU67: 17 | AV67: F
B68: 52 | C68: 3451 | D68: Teresa Tchiânica Londa Futi | H68: =SUM('11CL-FAR-L PORT'!J60) -> 12.5 | K68: =SUM('11CL-FAR-MAT'!J60) -> 12.333333 | N68: =SUM('11CL-FAR-BIOL'!J60) -> 10.666667 | Q68: =SUM('11CL-FAR-INGLES'!J60) -> 15 | T68: =SUM('11CL-FAR-PATOL'!J60) -> 12 | W68: =SUM('11CL-FAR-MPARASITOL'!J60) -> 11.333333 | Z68: =SUM('11CL-FAR-FARMACOL'!J60) -> 12 | AC68: =SUM('11CL-FAR-FARMACOG'!J60) -> 12.333333 | AF68: =SUM('11CL-FAR-TPM'!J60) -> 8.3333333 | AI68: =SUM('11CL-FAR-QCA ORG.'!J60) -> 12.5 | AL68: =SUM('11CL-FAR-ED. FIS'!J60) -> 15 | AO68: =SUM('11CL-FAR-BOTANICA'!J60) -> 9.3333333 | AR68: =SUM('11CL-FAR-AFH'!J60) -> 11.5 | AS68: N/TRANSITA | AT68: =AVERAGE(H68:AR68) -> 11.910256 | AU68: 21 | AV68: F | AX68: NOME DO/A ALUNO/A
B69: 53 | C69: 3185 | D69: Tiago Nguala Puna Vela | H69: =SUM('11CL-FAR-L PORT'!J61) -> 12 | K69: =SUM('11CL-FAR-MAT'!J61) -> 18.5 | N69: =SUM('11CL-FAR-BIOL'!J61) -> 10.666667 | Q69: =SUM('11CL-FAR-INGLES'!J61) -> 17.666667 | T69: =SUM('11CL-FAR-PATOL'!J61) -> 17 | W69: =SUM('11CL-FAR-MPARASITOL'!J61) -> 8.6666667 | Z69: =SUM('11CL-FAR-FARMACOL'!J61) -> 13.666667 | AC69: =SUM('11CL-FAR-FARMACOG'!J61) -> 13 | AF69: =SUM('11CL-FAR-TPM'!J61) -> 16.666667 | AI69: =SUM('11CL-FAR-QCA ORG.'!J61) -> 12 | AL69: =SUM('11CL-FAR-ED. FIS'!J61) -> 16.333333 | AO69: =SUM('11CL-FAR-BOTANICA'!J61) -> 16.833333 | AR69: =SUM('11CL-FAR-AFH'!J61) -> 17.666667 | AS69: N/TRANSITA | AT69: =AVERAGE(H69:AR69) -> 14.666667 | AU69: 20 | AV69: M | AX69: IDADE:
B70: 54 | C70: 4132 | D70: Virgínia Béua Bachi | H70: =SUM('11CL-FAR-L PORT'!J62) -> 8.6666667 | K70: =SUM('11CL-FAR-MAT'!J62) -> 7.5 | N70: =SUM('11CL-FAR-BIOL'!J62) -> 11 | Q70: =SUM('11CL-FAR-INGLES'!J62) -> 17.333333 | T70: =SUM('11CL-FAR-PATOL'!J62) -> 10.666667 | W70: =SUM('11CL-FAR-MPARASITOL'!J62) -> 9.1666667 | Z70: =SUM('11CL-FAR-FARMACOL'!J62) -> 12 | AC70: =SUM('11CL-FAR-FARMACOG'!J62) -> 12.166667 | AF70: =SUM('11CL-FAR-TPM'!J62) -> 9 | AI70: =SUM('11CL-FAR-QCA ORG.'!J62) -> 8.6666667 | AL70: =SUM('11CL-FAR-ED. FIS'!J62) -> 14 | AO70: =SUM('11CL-FAR-BOTANICA'!J62) -> 11 | AR70: =SUM('11CL-FAR-AFH'!J62) -> 14.833333 | AS70: N/TRANSITA | AT70: =AVERAGE(H70:AR70) -> 11.230769 | AU70: 21 | AV70: F
B71: 55 | C71: 2941 | D71: Zacarias Bungo Nguimbi | H71: =SUM('11CL-FAR-L PORT'!J63) -> 11.5 | K71: =SUM('11CL-FAR-MAT'!J63) -> 11.166667 | N71: =SUM('11CL-FAR-BIOL'!J63) -> 11.333333 | Q71: =SUM('11CL-FAR-INGLES'!J63) -> 12.333333 | T71: =SUM('11CL-FAR-PATOL'!J63) -> 12 | W71: =SUM('11CL-FAR-MPARASITOL'!J63) -> 8.1666667 | Z71: =SUM('11CL-FAR-FARMACOL'!J63) -> 9.6666667 | AC71: =SUM('11CL-FAR-FARMACOG'!J63) -> 9.6666667 | AF71: =SUM('11CL-FAR-TPM'!J63) -> 10 | AI71: =SUM('11CL-FAR-QCA ORG.'!J63) -> 11.5 | AL71: =SUM('11CL-FAR-ED. FIS'!J63) -> 14 | AO71: =SUM('11CL-FAR-BOTANICA'!J63) -> 12.333333 | AR71: =SUM('11CL-FAR-AFH'!J63) -> 11.666667 | AS71: N/TRANSITA | AT71: =AVERAGE(H71:AR71) -> 11.179487 | AU71: 19 | AV71: M
B72: DATA DO CONSELHO DE TURMA______/______/2025
B74: ODirector de Turma | X74: O Subdirector Pedagógico
B75: _____________________________________
B76: SAMUEL BERNUÁRIO CALINHA | X76: ALBERTO SASSA TATI

Sheet 2ºT-11ª-FAR-UNICA-PAUTA
A1: INSTITUTO TÉCNICO PRIVADO DE SAÚDE JOMORAIS
B7: PAUTA DE APROVEITAMENTO ESCOLAR
C8: ÁREA DE FORMAÇÃO: SAÚDE
H9: 11ª CLASSE | M9: CURSO: FARMÁCIA | AC9: PERÍODO: VESPERTNO
B10: O Director do Instituto | AD10: 2º TRIMESTRE | AH10: MF: | AI10: =SUM(AI12,AI11) -> 55
B11: ________________________________________ | H11: TURMA: | J11: ÚNICA | AH11: M | AI11: =COUNTIF(AV17:AV71,"M") -> 12 | AR11: 46118
B12: GABRIEL PRÓSPERO MABIALA | Z12: ANO LECTIVO: 2025/2026 | AH12: F | AI12: =COUNTIF(AV17:AV71,"F") -> 43
B13: DATA______/______/2025
B14: Nº | C14: Nº PROC | D14: NOME | E14: DISCIPLINA A REPETIR | F14: L. Port | I14: Mat. | L14: Biologia | O14: Inglês | R14: Patologia | U14: Micoparasit. | X14: Farmacologia | AA14: Farmacog. | AD14: TPM | AG14: Qca Org. | AJ14: Ed. Física | AM14: Botânica | AP14: A.F.H | AS14: OBS | AT14: MÉDIA | AU14: Idade | AV14: Género | AW14: DADOS ESTATÍSTICOS
F15: FALTAS | H15: MT2º | I15: FALTAS | K15: MT2º | L15: FALTAS | N15: MT2º | O15: FALTAS | Q15: MT2º | R15: FALTAS | T15: MT2º | U15: FALTAS | W15: MT2º | X15: FALTAS | Z15: MT2º | AA15: FALTAS | AC15: MT2º | AD15: FALTAS | AF15: MT2º | AG15: FALTAS | AI15: MT2º | AJ15: FALTAS | AL15: MT2º | AM15: FALTAS | AO15: MT2º | AP15: FALTAS | AR15: MT2º | AW15: MATRICULADOS | AY15: TRANSITA | BA15: N/TRANSITA | BC15: Desistido/a
F16: J | G16: I | I16: J | J16: I | L16: J | M16: I | O16: J | P16: I | R16: J | S16: I | U16: J | V16: I | X16: J | Y16: I | AA16: J | AB16: I | AD16: J | AE16: I | AG16: J | AH16: I | AJ16: J | AK16: I | AM16: J | AN16: I | AP16: J | AQ16: I | AW16: M | AX16: F | AY16: M | AZ16: F | BA16: M | BB16: F | BC16: M | BD16: F
B17: 1 | C17: 4068 | D17: Alice Cungi Alfredo | H17: =SUM('11CL-FAR-L PORT'!Q9) -> 7.1666667 | K17: =SUM('11CL-FAR-MAT'!Q9) -> 6.6666667 | N17: =SUM('11CL-FAR-BIOL'!Q9) -> 7.3333333 | Q17: =SUM('11CL-FAR-INGLES'!Q9) -> 8.6666667 | T17: =SUM('11CL-FAR-PATOL'!Q9) -> 5.5 | W17: =SUM('11CL-FAR-MPARASITOL'!Q9) -> 6.5 | Z17: =SUM('11CL-FAR-FARMACOL'!Q9) -> 8.1666667 | AC17: =SUM('11CL-FAR-FARMACOG'!Q9) -> 6.6666667 | AF17: =SUM('11CL-FAR-TPM'!Q9) -> 5 | AI17: =SUM('11CL-FAR-QCA ORG.'!Q9) -> 7.1666667 | AL17: =SUM('11CL-FAR-ED. FIS'!Q9) -> 13 | AO17: =SUM('11CL-FAR-BOTANICA'!Q9) -> 9.5 | AR17: =SUM('11CL-FAR-AFH'!Q9) -> 10.666667 | AS17: N/TRANSITA | AT17: =AVERAGE(H17:AR17) -> 7.8461538 | AU17: 22 | AV17: F | AW17: =COUNTIF(AV17:AV71,"M") -> 12 | AX17: =COUNTIF(AV17:AV71,"F") -> 43 | AY17: =COUNTIFS(AS17:AS71,"Transita",AV17:AV71,"M") -> 0 | AZ17: =COUNTIFS(AS17:AS71,"Transita",AV17:AV71,"F") -> 2 | BA17: =COUNTIFS(AS17:AS71,"N/Transita",AV17:AV71,"M") -> 12 | BB17: =COUNTIFS(AS17:AS71,"N/Transita",AV17:AV71,"F") -> 35 | BC17: =COUNTIFS(AS17:AS71,"DESISTIDO",AV17:AV71,"M") -> 0 | BD17: =COUNTIFS(AS17:AS71,"DESISTIDA",AV17:AV71,"F") -> 6
B18: 2 | C18: 3983 | D18: Amélia Mauricio Macaia | H18: =SUM('11CL-FAR-L PORT'!Q10) -> 8.3333333 | K18: =SUM('11CL-FAR-MAT'!Q10) -> 8.1666667 | N18: =SUM('11CL-FAR-BIOL'!Q10) -> 13 | Q18: =SUM('11CL-FAR-INGLES'!Q10) -> 12.333333 | T18: =SUM('11CL-FAR-PATOL'!Q10) -> 5.3333333 | W18: =SUM('11CL-FAR-MPARASITOL'!Q10) -> 2.8333333 | Z18: =SUM('11CL-FAR-FARMACOL'!Q10) -> 7.5 | AC18: =SUM('11CL-FAR-FARMACOG'!Q10) -> 10.333333 | AF18: =SUM('11CL-FAR-TPM'!Q10) -> 12.333333 | AI18: =SUM('11CL-FAR-QCA ORG.'!Q10) -> 8.3333333 | AL18: =SUM('11CL-FAR-ED. FIS'!Q10) -> 3.3333333 | AO18: =SUM('11CL-FAR-BOTANICA'!Q10) -> 10.5 | AR18: =SUM('11CL-FAR-AFH'!Q10) -> 13.333333 | AS18: N/TRANSITA | AT18: =AVERAGE(H18:AR18) -> 8.8974359 | AU18: 18 | AV18: F | AW18: =SUM(AW17:AX17) -> 55 | AY18: =SUM(AY16:AZ17) -> 2 | BA18: =SUM(BA16:BB17) -> 47 | BC18: =SUM(BC16:BD17) -> 6
B19: 3 | C19: 4163 | D19: Angelina Umba Esperança Luyeye | H19: =SUM('11CL-FAR-L PORT'!Q11) -> 9.5 | K19: =SUM('11CL-FAR-MAT'!Q11) -> 7.6666667 | N19: =SUM('11CL-FAR-BIOL'!Q11) -> 10.666667 | Q19: =SUM('11CL-FAR-INGLES'!Q11) -> 12.666667 | T19: =SUM('11CL-FAR-PATOL'!Q11) -> 11.333333 | W19: =SUM('11CL-FAR-MPARASITOL'!Q11) -> 11.666667 | Z19: =SUM('11CL-FAR-FARMACOL'!Q11) -> 10 | AC19: =SUM('11CL-FAR-FARMACOG'!Q11) -> 7.8333333 | AF19: =SUM('11CL-FAR-TPM'!Q11) -> 10.666667 | AI19: =SUM('11CL-FAR-QCA ORG.'!Q11) -> 9.5 | AL19: =SUM('11CL-FAR-ED. FIS'!Q11) -> 14 | AO19: =SUM('11CL-FAR-BOTANICA'!Q11) -> 11.5 | AR19: =SUM('11CL-FAR-AFH'!Q11) -> 10.666667 | AS19: N/TRANSITA | AT19: =AVERAGE(H19:AR19) -> 10.589744 | AU19: 20 | AV19: F
B20: 4 | C20: 3939 | D20: Armindo Maciala Mendes | H20: =SUM('11CL-FAR-L PORT'!Q12) -> 12.5 | K20: =SUM('11CL-FAR-MAT'!Q12) -> 15 | N20: =SUM('11CL-FAR-BIOL'!Q12) -> 14.666667 | Q20: =SUM('11CL-FAR-INGLES'!Q12) -> 16 | T20: =SUM('11CL-FAR-PATOL'!Q12) -> 11.666667 | W20: =SUM('11CL-FAR-MPARASITOL'!Q12) -> 10.333333 | Z20: =SUM('11CL-FAR-FARMACOL'!Q12) -> 12.833333 | AC20: =SUM('11CL-FAR-FARMACOG'!Q12) -> 9.3333333 | AF20: =SUM('11CL-FAR-TPM'!Q12) -> 15 | AI20: =SUM('11CL-FAR-QCA ORG.'!Q12) -> 12.5 | AL20: =SUM('11CL-FAR-ED. FIS'!Q12) -> 18 | AO20: =SUM('11CL-FAR-BOTANICA'!Q12) -> 14.5 | AR20: =SUM('11CL-FAR-AFH'!Q12) -> 13.666667 | AS20: N/TRANSITA | AT20: =AVERAGE(H20:AR20) -> 13.538462 | AU20: 20 | AV20: M
B21: 5 | C21: 3461 | D21: Beatriz Lelo Nombo | H21: =SUM('11CL-FAR-L PORT'!Q13) -> 7.3333333 | K21: =SUM('11CL-FAR-MAT'!Q13) -> 13.333333 | N21: =SUM('11CL-FAR-BIOL'!Q13) -> 16 | Q21: =SUM('11CL-FAR-INGLES'!Q13) -> 18 | T21: =SUM('11CL-FAR-PATOL'!Q13) -> 10 | W21: =SUM('11CL-FAR-MPARASITOL'!Q13) -> 10 | Z21: =SUM('11CL-FAR-FARMACOL'!Q13) -> 12.166667 | AC21: =SUM('11CL-FAR-FARMACOG'!Q13) -> 15 | AF21: =SUM('11CL-FAR-TPM'!Q13) -> 16 | AI21: =SUM('11CL-FAR-QCA ORG.'!Q13) -> 7.3333333 | AL21: =SUM('11CL-FAR-ED. FIS'!Q13) -> 10 | AO21: =SUM('11CL-FAR-BOTANICA'!Q13) -> 13.666667 | AR21: =SUM('11CL-FAR-AFH'!Q13) -> 12.666667 | AS21: N/TRANSITA | AT21: =AVERAGE(H21:AR21) -> 12.423077 | AU21: 17 | AV21: F
B22: 6 | C22: 4030 | D22: Carolina Zuzi Nhimi | H22: =SUM('11CL-FAR-L PORT'!Q14) -> 8.8333333 | K22: =SUM('11CL-FAR-MAT'!Q14) -> 10.166667 | N22: =SUM('11CL-FAR-BIOL'!Q14) -> 10.333333 | Q22: =SUM('11CL-FAR-INGLES'!Q14) -> 11.666667 | T22: =SUM('11CL-FAR-PATOL'!Q14) -> 9 | W22: =SUM('11CL-FAR-MPARASITOL'!Q14) -> 5.3333333 | Z22: =SUM('11CL-FAR-FARMACOL'!Q14) -> 10.166667 | AC22: =SUM('11CL-FAR-FARMACOG'!Q14) -> 10.666667 | AF22: =SUM('11CL-FAR-TPM'!Q14) -> 13.333333 | AI22: =SUM('11CL-FAR-QCA ORG.'!Q14) -> 8.8333333 | AL22: =SUM('11CL-FAR-ED. FIS'!Q14) -> 15 | AO22: =SUM('11CL-FAR-BOTANICA'!Q14) -> 12 | AR22: =SUM('11CL-FAR-AFH'!Q14) -> 11.666667 | AS22: N/TRANSITA | AT22: =AVERAGE(H22:AR22) -> 10.538462 | AU22: 20 | AV22: F
B23: 7 | C23: 3086 | D23: Catarina Simba Buela | H23: =SUM('11CL-FAR-L PORT'!Q15) -> 7 | K23: =SUM('11CL-FAR-MAT'!Q15) -> 7.3333333 | N23: =SUM('11CL-FAR-BIOL'!Q15) -> 10.666667 | Q23: =SUM('11CL-FAR-INGLES'!Q15) -> 17 | T23: =SUM('11CL-FAR-PATOL'!Q15) -> 11.333333 | W23: =SUM('11CL-FAR-MPARASITOL'!Q15) -> 11.166667 | Z23: =SUM('11CL-FAR-FARMACOL'!Q15) -> 9.5 | AC23: =SUM('11CL-FAR-FARMACOG'!Q15) -> 11 | AF23: =SUM('11CL-FAR-TPM'!Q15) -> 9 | AI23: =SUM('11CL-FAR-QCA ORG.'!Q15) -> 7 | AL23: =SUM('11CL-FAR-ED. FIS'!Q15) -> 15 | AO23: =SUM('11CL-FAR-BOTANICA'!Q15) -> 10.666667 | AR23: =SUM('11CL-FAR-AFH'!Q15) -> 11.333333 | AS23: N/TRANSITA | AT23: =AVERAGE(H23:AR23) -> 10.615385 | AU23: 29 | AV23: F
B24: 8 | C24: 4117 | D24: Cecília Suami Lando Massiala | H24: =SUM('11CL-FAR-L PORT'!Q16) -> 5.6666667 | K24: =SUM('11CL-FAR-MAT'!Q16) -> 7.3333333 | N24: =SUM('11CL-FAR-BIOL'!Q16) -> 7.6666667 | Q24: =SUM('11CL-FAR-INGLES'!Q16) -> 12.666667 | T24: =SUM('11CL-FAR-PATOL'!Q16) -> 5.6666667 | W24: =SUM('11CL-FAR-MPARASITOL'!Q16) -> 5.8333333 | Z24: =SUM('11CL-FAR-FARMACOL'!Q16) -> 7.6666667 | AC24: =SUM('11CL-FAR-FARMACOG'!Q16) -> 6.6666667 | AF24: =SUM('11CL-FAR-TPM'!Q16) -> 7 | AI24: =SUM('11CL-FAR-QCA ORG.'!Q16) -> 5.6666667 | AL24: =SUM('11CL-FAR-ED. FIS'!Q16) -> 10 | AO24: =SUM('11CL-FAR-BOTANICA'!Q16) -> 7.3333333 | AR24: =SUM('11CL-FAR-AFH'!Q16) -> 11 | AS24: N/TRANSITA | AT24: =AVERAGE(H24:AR24) -> 7.7051282 | AU24: 21 | AV24: M
B25: 9 | C25: 4080 | D25: Clara Sungo Buati Chiânica | H25: =SUM('11CL-FAR-L PORT'!Q17) -> 8.6666667 | K25: =SUM('11CL-FAR-MAT'!Q17) -> 8.3333333 | N25: =SUM('11CL-FAR-BIOL'!Q17) -> 12.666667 | Q25: =SUM('11CL-FAR-INGLES'!Q17) -> 16.666667 | T25: =SUM('11CL-FAR-PATOL'!Q17) -> 11.5 | W25: =SUM('11CL-FAR-MPARASITOL'!Q17) -> 4.3333333 | Z25: =SUM('11CL-FAR-FARMACOL'!Q17) -> 7.5 | AC25: =SUM('11CL-FAR-FARMACOG'!Q17) -> 9.3333333 | AF25: =SUM('11CL-FAR-TPM'!Q17) -> 9.3333333 | AI25: =SUM('11CL-FAR-QCA ORG.'!Q17) -> 8.6666667 | AL25: =SUM('11CL-FAR-ED. FIS'!Q17) -> 7 | AO25: =SUM('11CL-FAR-BOTANICA'!Q17) -> 10 | AR25: =SUM('11CL-FAR-AFH'!Q17) -> 11 | AS25: N/TRANSITA | AT25: =AVERAGE(H25:AR25) -> 9.6153846 | AU25: 19 | AV25: F
B26: 10 | C26: 3986 | D26: Clementina Paca V. Guimbi | H26: =SUM('11CL-FAR-L PORT'!Q18) -> 6 | K26: =SUM('11CL-FAR-MAT'!Q18) -> 6.3333333 | N26: =SUM('11CL-FAR-BIOL'!Q18) -> 9.3333333 | Q26: =SUM('11CL-FAR-INGLES'!Q18) -> 11.666667 | T26: =SUM('11CL-FAR-PATOL'!Q18) -> 6.6666667 | W26: =SUM('11CL-FAR-MPARASITOL'!Q18) -> 10 | Z26: =SUM('11CL-FAR-FARMACOL'!Q18) -> 0 | AC26: =SUM('11CL-FAR-FARMACOG'!Q18) -> 7 | AF26: =SUM('11CL-FAR-TPM'!Q18) -> 5.6666667 | AI26: =SUM('11CL-FAR-QCA ORG.'!Q18) -> 6 | AL26: =SUM('11CL-FAR-ED. FIS'!Q18) -> 15.666667 | AO26: =SUM('11CL-FAR-BOTANICA'!Q18) -> 5.3333333 | AR26: =SUM('11CL-FAR-AFH'!Q18) -> 10 | AS26: N/TRANSITA | AT26: =AVERAGE(H26:AR26) -> 7.6666667 | AU26: 19 | AV26: F
B27: 11 | C27: 4094 | D27: Cleúsia Da Conceição Mboco Kilombo | H27: =SUM('11CL-FAR-L PORT'!Q19) -> 7 | K27: =SUM('11CL-FAR-MAT'!Q19) -> 7.8333333 | N27: =SUM('11CL-FAR-BIOL'!Q19) -> 10.666667 | Q27: =SUM('11CL-FAR-INGLES'!Q19) -> 12.666667 | T27: =SUM('11CL-FAR-PATOL'!Q19) -> 11.333333 | W27: =SUM('11CL-FAR-MPARASITOL'!Q19) -> 9 | Z27: =SUM('11CL-FAR-FARMACOL'!Q19) -> 9.1666667 | AC27: =SUM('11CL-FAR-FARMACOG'!Q19) -> 7.6666667 | AF27: =SUM('11CL-FAR-TPM'!Q19) -> 10.666667 | AI27: =SUM('11CL-FAR-QCA ORG.'!Q19) -> 7 | AL27: =SUM('11CL-FAR-ED. FIS'!Q19) -> 13 | AO27: =SUM('11CL-FAR-BOTANICA'!Q19) -> 4 | AR27: =SUM('11CL-FAR-AFH'!Q19) -> 12.333333 | AS27: N/TRANSITA | AT27: =AVERAGE(H27:AR27) -> 9.4102564 | AU27: 19 | AV27: F
B28: 12 | C28: 4175 | D28: Damália Isaias Bumba | H28: =SUM('11CL-FAR-L PORT'!Q20) -> 9.3333333 | K28: =SUM('11CL-FAR-MAT'!Q20) -> 7.6666667 | N28: =SUM('11CL-FAR-BIOL'!Q20) -> 10.666667 | Q28: =SUM('11CL-FAR-INGLES'!Q20) -> 13.333333 | T28: =SUM('11CL-FAR-PATOL'!Q20) -> 11.333333 | W28: =SUM('11CL-FAR-MPARASITOL'!Q20) -> 11.333333 | Z28: =SUM('11CL-FAR-FARMACOL'!Q20) -> 9.5 | AC28: =SUM('11CL-FAR-FARMACOG'!Q20) -> 10.833333 | AF28: =SUM('11CL-FAR-TPM'!Q20) -> 12 | AI28: =SUM('11CL-FAR-QCA ORG.'!Q20) -> 9.3333333 | AL28: =SUM('11CL-FAR-ED. FIS'!Q20) -> 11 | AO28: =SUM('11CL-FAR-BOTANICA'!Q20) -> 11 | AR28: =SUM('11CL-FAR-AFH'!Q20) -> 12 | AS28: N/TRANSITA | AT28: =AVERAGE(H28:AR28) -> 10.717949 | AU28: 22 | AV28: F
B29: 13 | C29: 2532 | D29: Divina Pemba Dembe | H29: =SUM('11CL-FAR-L PORT'!Q21) -> 8.6666667 | K29: =SUM('11CL-FAR-MAT'!Q21) -> 8.3333333 | N29: =SUM('11CL-FAR-BIOL'!Q21) -> 13.666667 | Q29: =SUM('11CL-FAR-INGLES'!Q21) -> 16.666667 | T29: =SUM('11CL-FAR-PATOL'!Q21) -> 10 | W29: =SUM('11CL-FAR-MPARASITOL'!Q21) -> 10 | Z29: =SUM('11CL-FAR-FARMACOL'!Q21) -> 8.8333333 | AC29: =SUM('11CL-FAR-FARMACOG'!Q21) -> 11.333333 | AF29: =SUM('11CL-FAR-TPM'!Q21) -> 11 | AI29: =SUM('11CL-FAR-QCA ORG.'!Q21) -> 8.6666667 | AL29: =SUM('11CL-FAR-ED. FIS'!Q21) -> 12 | AO29: =SUM('11CL-FAR-BOTANICA'!Q21) -> 7 | AR29: =SUM('11CL-FAR-AFH'!Q21) -> 12 | AS29: N/TRANSITA | AT29: =AVERAGE(H29:AR29) -> 10.628205 | AU29: 19 | AV29: F
B30: 14 | C30: 3737 | D30: Emíliana Pemba Baza Jonace | H30: =SUM('11CL-FAR-L PORT'!Q22) -> 10.5 | K30: =SUM('11CL-FAR-MAT'!Q22) -> 9.1666667 | N30: =SUM('11CL-FAR-BIOL'!Q22) -> 13.333333 | Q30: =SUM('11CL-FAR-INGLES'!Q22) -> 19.333333 | T30: =SUM('11CL-FAR-PATOL'!Q22) -> 8.8333333 | W30: =SUM('11CL-FAR-MPARASITOL'!Q22) -> 5.5 | Z30: =SUM('11CL-FAR-FARMACOL'!Q22) -> 0 | AC30: =SUM('11CL-FAR-FARMACOG'!Q22) -> 11.333333 | AF30: =SUM('11CL-FAR-TPM'!Q22) -> 10 | AI30: =SUM('11CL-FAR-QCA ORG.'!Q22) -> 10.5 | AL30: =SUM('11CL-FAR-ED. FIS'!Q22) -> 16 | AO30: =SUM('11CL-FAR-BOTANICA'!Q22) -> 14 | AR30: =SUM('11CL-FAR-AFH'!Q22) -> 15.666667 | AS30: N/TRANSITA | AT30: =AVERAGE(H30:AR30) -> 11.089744 | AU30: 17 | AV30: F
... B65: 49 | C65: 4044 | D65: Rosangela Andreia Pedro Brás Tati | H65: =SUM('11CL-FAR-L PORT'!Q57) -> 10.166667 | K65: =SUM('11CL-FAR-MAT'!Q57) -> 16.333333 | N65: =SUM('11CL-FAR-BIOL'!Q57) -> 17.666667 | Q65: =SUM('11CL-FAR-INGLES'!Q57) -> 19.666667 | T65: =SUM('11CL-FAR-PATOL'!Q57) -> 11.333333 | W65: =SUM('11CL-FAR-MPARASITOL'!Q57) -> 11.833333 | Z65: =SUM('11CL-FAR-FARMACOL'!Q57) -> 10.333333 | AC65: =SUM('11CL-FAR-FARMACOG'!Q57) -> 14 | AF65: =SUM('11CL-FAR-TPM'!Q57) -> 14 | AI65: =SUM('11CL-FAR-QCA ORG.'!Q57) -> 10.166667 | AL65: =SUM('11CL-FAR-ED. FIS'!Q57) -> 13 | AO65: =SUM('11CL-FAR-BOTANICA'!Q57) -> 14.833333 | AR65: =SUM('11CL-FAR-AFH'!Q57) -> 12.666667 | AS65: TRANSITA | AT65: =AVERAGE(H65:AR65) -> 13.538462 | AU65: 17 | AV65: F
B66: 50 | C66: 3263 | D66: Simélia Milando Pungui | H66: =SUM('11CL-FAR-L PORT'!Q58) -> 0 | K66: =SUM('11CL-FAR-MAT'!Q58) -> 0 | N66: =SUM('11CL-FAR-BIOL'!Q58) -> 0 | Q66: =SUM('11CL-FAR-INGLES'!Q58) -> 0 | T66: =SUM('11CL-FAR-PATOL'!Q58) -> 0 | W66: =SUM('11CL-FAR-MPARASITOL'!Q58) -> 0 | Z66: =SUM('11CL-FAR-FARMACOL'!Q58) -> 0 | AC66: =SUM('11CL-FAR-FARMACOG'!Q58) -> 0 | AF66: =SUM('11CL-FAR-TPM'!Q58) -> 0 | AI66: =SUM('11CL-FAR-QCA ORG.'!Q58) -> 0 | AL66: =SUM('11CL-FAR-ED. FIS'!Q58) -> 0 | AO66: =SUM('11CL-FAR-BOTANICA'!Q58) -> 0 | AR66: =SUM('11CL-FAR-AFH'!Q58) -> 12.666667 | AS66: DESISTIDA | AT66: =AVERAGE(H66:AR66) -> 0.97435897 | AU66: 27 | AV66: F | AX66: MÁXIMA | AY66: =MAX(AT17:AT71) -> 14.782051
B67: 51 | C67: 3610 | D67: Teresa Ndonda Costa | H67: =SUM('11CL-FAR-L PORT'!Q59) -> 6.3333333 | K67: =SUM('11CL-FAR-MAT'!Q59) -> 6 | N67: =SUM('11CL-FAR-BIOL'!Q59) -> 8.6666667 | Q67: =SUM('11CL-FAR-INGLES'!Q59) -> 8.6666667 | T67: =SUM('11CL-FAR-PATOL'!Q59) -> 8.3333333 | W67: =SUM('11CL-FAR-MPARASITOL'!Q59) -> 6.6666667 | Z67: =SUM('11CL-FAR-FARMACOL'!Q59) -> 6.8333333 | AC67: =SUM('11CL-FAR-FARMACOG'!Q59) -> 8 | AF67: =SUM('11CL-FAR-TPM'!Q59) -> 5.3333333 | AI67: =SUM('11CL-FAR-QCA ORG.'!Q59) -> 6.3333333 | AL67: =SUM('11CL-FAR-ED. FIS'!Q59) -> 7 | AO67: =SUM('11CL-FAR-BOTANICA'!Q59) -> 8.1666667 | AR67: =SUM('11CL-FAR-AFH'!Q59) -> 9 | AS67: N/TRANSITA | AT67: =AVERAGE(H67:AR67) -> 7.3333333 | AU67: 17 | AV67: F
B68: 52 | C68: 3451 | D68: Teresa Tchiânica Londa Futi | H68: =SUM('11CL-FAR-L PORT'!Q60) -> 6.1666667 | K68: =SUM('11CL-FAR-MAT'!Q60) -> 8.5 | N68: =SUM('11CL-FAR-BIOL'!Q60) -> 13 | Q68: =SUM('11CL-FAR-INGLES'!Q60) -> 16.666667 | T68: =SUM('11CL-FAR-PATOL'!Q60) -> 5.6666667 | W68: =SUM('11CL-FAR-MPARASITOL'!Q60) -> 5 | Z68: =SUM('11CL-FAR-FARMACOL'!Q60) -> 7.8333333 | AC68: =SUM('11CL-FAR-FARMACOG'!Q60) -> 12 | AF68: =SUM('11CL-FAR-TPM'!Q60) -> 9 | AI68: =SUM('11CL-FAR-QCA ORG.'!Q60) -> 6.1666667 | AL68: =SUM('11CL-FAR-ED. FIS'!Q60) -> 10 | AO68: =SUM('11CL-FAR-BOTANICA'!Q60) -> 10.666667 | AR68: =SUM('11CL-FAR-AFH'!Q60) -> 10.333333 | AS68: N/TRANSITA | AT68: =AVERAGE(H68:AR68) -> 9.3076923 | AU68: 21 | AV68: F | AX68: NOME DO/A ALUNO/A
B69: 53 | C69: 3185 | D69: Tiago Nguala Puna Vela | H69: =SUM('11CL-FAR-L PORT'!Q61) -> 9.3333333 | K69: =SUM('11CL-FAR-MAT'!Q61) -> 15.666667 | N69: =SUM('11CL-FAR-BIOL'!Q61) -> 11.666667 | Q69: =SUM('11CL-FAR-INGLES'!Q61) -> 18.666667 | T69: =SUM('11CL-FAR-PATOL'!Q61) -> 10.333333 | W69: =SUM('11CL-FAR-MPARASITOL'!Q61) -> 8.6666667 | Z69: =SUM('11CL-FAR-FARMACOL'!Q61) -> 12 | AC69: =SUM('11CL-FAR-FARMACOG'!Q61) -> 10.333333 | AF69: =SUM('11CL-FAR-TPM'!Q61) -> 13 | AI69: =SUM('11CL-FAR-QCA ORG.'!Q61) -> 9.3333333 | AL69: =SUM('11CL-FAR-ED. FIS'!Q61) -> 14 | AO69: =SUM('11CL-FAR-BOTANICA'!Q61) -> 10.5 | AR69: =SUM('11CL-FAR-AFH'!Q61) -> 18 | AS69: N/TRANSITA | AT69: =AVERAGE(H69:AR69) -> 12.423077 | AU69: 20 | AV69: M | AX69: IDADE:
B70: 54 | C70: 4132 | D70: Virgínia Béua Bachi | H70: =SUM('11CL-FAR-L PORT'!Q62) -> 8.1666667 | K70: =SUM('11CL-FAR-MAT'!Q62) -> 11 | N70: =SUM('11CL-FAR-BIOL'!Q62) -> 13.333333 | Q70: =SUM('11CL-FAR-INGLES'!Q62) -> 15.666667 | T70: =SUM('11CL-FAR-PATOL'!Q62) -> 11.5 | W70: =SUM('11CL-FAR-MPARASITOL'!Q62) -> 6.8333333 | Z70: =SUM('11CL-FAR-FARMACOL'!Q62) -> 7.3333333 | AC70: =SUM('11CL-FAR-FARMACOG'!Q62) -> 10.666667 | AF70: =SUM('11CL-FAR-TPM'!Q62) -> 11.333333 | AI70: =SUM('11CL-FAR-QCA ORG.'!Q62) -> 8.1666667 | AL70: =SUM('11CL-FAR-ED. FIS'!Q62) -> 12.666667 | AO70: =SUM('11CL-FAR-BOTANICA'!Q62) -> 11.5 | AR70: =SUM('11CL-FAR-AFH'!Q62) -> 11 | AS70: N/TRANSITA | AT70: =AVERAGE(H70:AR70) -> 10.705128 | AU70: 21 | AV70: F
B71: 55 | C71: 2941 | D71: Zacarias Bungo Nguimbi | H71: =SUM('11CL-FAR-L PORT'!Q63) -> 9.6666667 | K71: =SUM('11CL-FAR-MAT'!Q63) -> 6.6666667 | N71: =SUM('11CL-FAR-BIOL'!Q63) -> 10.333333 | Q71: =SUM('11CL-FAR-INGLES'!Q63) -> 15.333333 | T71: =SUM('11CL-FAR-PATOL'!Q63) -> 13.333333 | W71: =SUM('11CL-FAR-MPARASITOL'!Q63) -> 11 | Z71: =SUM('11CL-FAR-FARMACOL'!Q63) -> 7.5 | AC71: =SUM('11CL-FAR-FARMACOG'!Q63) -> 6.6666667 | AF71: =SUM('11CL-FAR-TPM'!Q63) -> 8.3333333 | AI71: =SUM('11CL-FAR-QCA ORG.'!Q63) -> 9.6666667 | AL71: =SUM('11CL-FAR-ED. FIS'!Q63) -> 10 | AO71: =SUM('11CL-FAR-BOTANICA'!Q63) -> 7.8333333 | AR71: =SUM('11CL-FAR-AFH'!Q63) -> 13 | AS71: N/TRANSITA | AT71: =AVERAGE(H71:AR71) -> 9.9487179 | AU71: 19 | AV71: M
B72: DATA DO CONSELHO DE TURMA______/______/2025
B74: ODirector de Turma | X74: O Subdirector Pedagógico
B75: _____________________________________
B76: SAMUEL BERNUÁRIO CALINHA | X76: ALBERTO SASSA TATI

Sheet 11CL-FAR-L PORT
A1: INSTITUTO TÉCNICP PRIVADO DE SAÚDE JOMORAIS
I3: DATA: 12/12/2025
B4: Classe: 11ª | E4: Disciplina: Língua Portuguesa | V4: Ano Lectivo:2025/2026
B5: Período: Vespertino | E5: Turma: Única | X5: Curso: FARMÁCIA
B6: MINI-PAUTA - TÉCNICO DE SAÚDE
B7: Nº | C7: Nome do (a) Aluno (a) | D7: FALTAS | E7: Avaliações/I Trimestre | K7: OBS | L7: Avaliações/II Trimestre | R7: OBS | S7: Avaliações/IIITrimestre | Y7: MFD | Z7: OBS | AA7: M | AB7: F | AC7: TRANSITA | AD7: N/TRANSITA | AE7: E.E.F
D8: J/I | E8: MAC | F8: NPP | G8: NPR1 | H8: NPT | I8: NPR2 | J8: MT1 | L8: MAC | M8: NPP | N8: NPR1 | O8: NPT | P8: NPR2 | Q8: MT2 | S8: MAC | T8: NPP | U8: NPR1 | V8: NPT | W8: NPR2 | X8: MT3 | AA8: =COUNTIF(Z9:Z69,"M") -> 0 | AB8: =COUNTIF(Z9:Z69,"F") -> 0 | AC8: =COUNTIF(Z9:Z69,"TRANSITA") -> 0 | AD8: =COUNTIF(Z9:Z69,"N/TRANSITA") -> 55 | AE8: =COUNTIF(Z9:Z69,"E.E.F") -> 0
B9: 1 | C9: Alice Cungi Alfredo | E9: 13.5 | F9: 10 | H9: 4.5 | J9: =AVERAGE(E9,MAX(F9:G9),MAX(H9:I9)) -> 9.3333333 | K9: =IF(J9>=10,"TRANSITA","N/TRANSITA") -> N/TRANSITA | L9: 10 | M9: 8 | O9: 3.5 | Q9: =AVERAGE(L9,MAX(M9:N9),MAX(O9:P9)) -> 7.1666667 | R9: =IF(Q9>=10,"TRANSITA","N/TRANSITA") -> N/TRANSITA | X9: =AVERAGE(S9,MAX(T9:U9),MAX(V9:W9)) -> 0 | Y9: =SUM(J9,Q9,X9)/3 -> 5.5 | Z9: =IF(Y9>=10,"TRANSITA","N/TRANSITA") -> N/TRANSITA
B10: 2 | C10: Amélia Mauricio Macaia | E10: 13.5 | F10: 10 | H10: 6 | J10: =AVERAGE(E10,MAX(F10:G10),MAX(H10:I10)) -> 9.8333333 | K10: =IF(J10>=10,"TRANSITA","N/TRANSITA") -> N/TRANSITA | L10: 10 | M10: 9 | O10: 6 | Q10: =AVERAGE(L10,MAX(M10:N10),MAX(O10:P10)) -> 8.3333333 | R10: =IF(Q10>=10,"TRANSITA","N/TRANSITA") -> N/TRANSITA | X10: =AVERAGE(S10,MAX(T10:U10),MAX(V10:W10)) -> 0 | Y10: =SUM(J10,Q10,X10)/3 -> 6.0555556 | Z10: =IF(Y10>=10,"TRANSITA","N/TRANSITA") -> N/TRANSITA | AA10: =SUM(AA8:AB9) -> 0
B11: 3 | C11: Angelina Umba Esperança Luyeye | E11: 14.5 | F11: 10 | H11: 9.5 | J11: =AVERAGE(E11,MAX(F11:G11),MAX(H11:I11)) -> 11.333333 | K11: =IF(J11>=10,"TRANSITA","N/TRANSITA") -> TRANSITA | L11: 10 | M11: 10 | O11: 8.5 | Q11: =AVERAGE(L11,MAX(M11:N11),MAX(O11:P11)) -> 9.5 | R11: =IF(Q11>=10,"TRANSITA","N/TRANSITA") -> N/TRANSITA | X11: =AVERAGE(S11,MAX(T11:U11),MAX(V11:W11)) -> 0 | Y11: =SUM(J11,Q11,X11)/3 -> 6.9444444 | Z11: =IF(Y11>=10,"TRANSITA","N/TRANSITA") -> N/TRANSITA
B12: 4 | C12: Armindo Maciala Mendes | E12: 17 | F12: 18 | H12: 15 | J12: =AVERAGE(E12,MAX(F12:G12),MAX(H12:I12)) -> 16.666667 | K12: =IF(J12>=10,"TRANSITA","N/TRANSITA") -> TRANSITA | L12: 10 | M12: 14 | O12: 13.5 | Q12: =AVERAGE(L12,MAX(M12:N12),MAX(O12:P12)) -> 12.5 | R12: =IF(Q12>=10,"TRANSITA","N/TRANSITA") -> TRANSITA | X12: =AVERAGE(S12,MAX(T12:U12),MAX(V12:W12)) -> 0 | Y12: =SUM(J12,Q12,X12)/3 -> 9.7222222 | Z12: =IF(Y12>=10,"TRANSITA","N/TRANSITA") -> N/TRANSITA
B13: 5 | C13: Beatriz Lelo Nombo | E13: 17 | F13: 18 | H13: 12 | J13: =AVERAGE(E13,MAX(F13:G13),MAX(H13:I13)) -> 15.666667 | K13: =IF(J13>=10,"TRANSITA","N/TRANSITA") -> TRANSITA | L13: 10 | O13: 12 | Q13: =AVERAGE(L13,MAX(M13:N13),MAX(O13:P13)) -> 7.3333333 | R13: =IF(Q13>=10,"TRANSITA","N/TRANSITA") -> N/TRANSITA | X13: =AVERAGE(S13,MAX(T13:U13),MAX(V13:W13)) -> 0 | Y13: =SUM(J13,Q13,X13)/3 -> 7.6666667 | Z13: =IF(Y13>=10,"TRANSITA","N/TRANSITA") -> N/TRANSITA
B14: 6 | C14: Carolina Zuzi Nhimi | E14: 10 | F14: 16 | H14: 14 | J14: =AVERAGE(E14,MAX(F14:G14),MAX(H14:I14)) -> 13.333333 | K14: =IF(J14>=10,"TRANSITA","N/TRANSITA") -> TRANSITA | L14: 10 | M14: 12 | O14: 4.5 | Q14: =AVERAGE(L14,MAX(M14:N14),MAX(O14:P14)) -> 8.8333333 | R14: =IF(Q14>=10,"TRANSITA","N/TRANSITA") -> N/TRANSITA | X14: =AVERAGE(S14,MAX(T14:U14),MAX(V14:W14)) -> 0 | Y14: =SUM(J14,Q14,X14)/3 -> 7.3888889 | Z14: =IF(Y14>=10,"TRANSITA","N/TRANSITA") -> N/TRANSITA
B15: 7 | C15: Catarina Simba Buela | E15: 10 | F15: 10 | H15: 7 | J15: =AVERAGE(E15,MAX(F15:G15),MAX(H15:I15)) -> 9 | K15: =IF(J15>=10,"TRANSITA","N/TRANSITA") -> N/TRANSITA | L15: 10 | M15: 7 | O15: 4 | Q15: =AVERAGE(L15,MAX(M15:N15),MAX(O15:P15)) -> 7 | R15: =IF(Q15>=10,"TRANSITA","N/TRANSITA") -> N/TRANSITA | X15: =AVERAGE(S15,MAX(T15:U15),MAX(V15:W15)) -> 0 | Y15: =SUM(J15,Q15,X15)/3 -> 5.3333333 | Z15: =IF(Y15>=10,"TRANSITA","N/TRANSITA") -> N/TRANSITA
B16: 8 | C16: Cecília Suami Lando Massiala | E16: 13.5 | H16: 4 | J16: =AVERAGE(E16,MAX(F16:G16),MAX(H16:I16)) -> 5.8333333 | K16: =IF(J16>=10,"TRANSITA","N/TRANSITA") -> N/TRANSITA | L16: 10 | M16: 7 | Q16: =AVERAGE(L16,MAX(M16:N16),MAX(O16:P16)) -> 5.6666667 | R16: =IF(Q16>=10,"TRANSITA","N/TRANSITA") -> N/TRANSITA | X16: =AVERAGE(S16,MAX(T16:U16),MAX(V16:W16)) -> 0 | Y16: =SUM(J16,Q16,X16)/3 -> 3.8333333 | Z16: =IF(Y16>=10,"TRANSITA","N/TRANSITA") -> N/TRANSITA
B17: 9 | C17: Clara Sungo Buati Chiânica | E17: 15 | F17: 17 | H17: 9 | J17: =AVERAGE(E17,MAX(F17:G17),MAX(H17:I17)) -> 13.666667 | K17: =IF(J17>=10,"TRANSITA","N/TRANSITA") -> TRANSITA | L17: 10 | M17: 6.5 | O17: 9.5 | Q17: =AVERAGE(L17,MAX(M17:N17),MAX(O17:P17)) -> 8.6666667 | R17: =IF(Q17>=10,"TRANSITA","N/TRANSITA") -> N/TRANSITA | X17: =AVERAGE(S17,MAX(T17:U17),MAX(V17:W17)) -> 0 | Y17: =SUM(J17,Q17,X17)/3 -> 7.4444444 | Z17: =IF(Y17>=10,"TRANSITA","N/TRANSITA") -> N/TRANSITA
B18: 10 | C18: Clementina Paca V. Guimbi | E18: 13 | F18: 10 | H18: 8.5 | J18: =AVERAGE(E18,MAX(F18:G18),MAX(H18:I18)) -> 10.5 | K18: =IF(J18>=10,"TRANSITA","N/TRANSITA") -> TRANSITA | L18: 10 | M18: 8 | Q18: =AVERAGE(L18,MAX(M18:N18),MAX(O18:P18)) -> 6 | R18: =IF(Q18>=10,"TRANSITA","N/TRANSITA") -> N/TRANSITA | X18: =AVERAGE(S18,MAX(T18:U18),MAX(V18:W18)) -> 0 | Y18: =SUM(J18,Q18,X18)/3 -> 5.5 | Z18: =IF(Y18>=10,"TRANSITA","N/TRANSITA") -> N/TRANSITA
B19: 11 | C19: Cleúsia Da Conceição Mboco Kilombo | E19: 13 | H19: 7 | J19: =AVERAGE(E19,MAX(F19:G19),MAX(H19:I19)) -> 6.6666667 | K19: =IF(J19>=10,"TRANSITA","N/TRANSITA") -> N/TRANSITA | L19: 10 | M19: 11 | Q19: =AVERAGE(L19,MAX(M19:N19),MAX(O19:P19)) -> 7 | R19: =IF(Q19>=10,"TRANSITA","N/TRANSITA") -> N/TRANSITA | X19: =AVERAGE(S19,MAX(T19:U19),MAX(V19:W19)) -> 0 | Y19: =SUM(J19,Q19,X19)/3 -> 4.5555556 | Z19: =IF(Y19>=10,"TRANSITA","N/TRANSITA") -> N/TRANSITA
B20: 12 | C20: Damália Isaias Bumba | E20: 14 | F20: 16 | H20: 9 | J20: =AVERAGE(E20,MAX(F20:G20),MAX(H20:I20)) -> 13 | K20: =IF(J20>=10,"TRANSITA","N/TRANSITA") -> TRANSITA | L20: 10 | M20: 10 | O20: 8 | Q20: =AVERAGE(L20,MAX(M20:N20),MAX(O20:P20)) -> 9.3333333 | R20: =IF(Q20>=10,"TRANSITA","N/TRANSITA") -> N/TRANSITA | X20: =AVERAGE(S20,MAX(T20:U20),MAX(V20:W20)) -> 0 | Y20: =SUM(J20,Q20,X20)/3 -> 7.4444444 | Z20: =IF(Y20>=10,"TRANSITA","N/TRANSITA") -> N/TRANSITA
B21: 13 | C21: Divina Pemba Dembe | E21: 14 | F21: 13.5 | H21: 7 | J21: =AVERAGE(E21,MAX(F21:G21),MAX(H21:I21)) -> 11.5 | K21: =IF(J21>=10,"TRANSITA","N/TRANSITA") -> TRANSITA | L21: 10 | M21: 9 | O21: 7 | Q21: =AVERAGE(L21,MAX(M21:N21),MAX(O21:P21)) -> 8.6666667 | R21: =IF(Q21>=10,"TRANSITA","N/TRANSITA") -> N/TRANSITA | X21: =AVERAGE(S21,MAX(T21:U21),MAX(V21:W21)) -> 0 | Y21: =SUM(J21,Q21,X21)/3 -> 6.7222222 | Z21: =IF(Y21>=10,"TRANSITA","N/TRANSITA") -> N/TRANSITA
B22: 14 | C22: Emíliana Pemba Baza Jonace | E22: 13.5 | F22: 16 | H22: 7.5 | J22: =AVERAGE(E22,MAX(F22:G22),MAX(H22:I22)) -> 12.333333 | K22: =IF(J22>=10,"TRANSITA","N/TRANSITA") -> TRANSITA | L22: 10 | M22: 12 | O22: 9.5 | Q22: =AVERAGE(L22,MAX(M22:N22),MAX(O22:P22)) -> 10.5 | R22: =IF(Q22>=10,"TRANSITA","N/TRANSITA") -> TRANSITA | X22: =AVERAGE(S22,MAX(T22:U22),MAX(V22:W22)) -> 0 | Y22: =SUM(J22,Q22,X22)/3 -> 7.6111111 | Z22: =IF(Y22>=10,"TRANSITA","N/TRANSITA") -> N/TRANSITA
B23: 15 | C23: Esmênia Constância Pedro Mendes | E23: 14 | F23: 10 | H23: 13 | J23: =AVERAGE(E23,MAX(F23:G23),MAX(H23:I23)) -> 12.333333 | K23: =IF(J23>=10,"TRANSITA","N/TRANSITA") -> TRANSITA | L23: 10 | M23: 12 | O23: 10 | Q23: =AVERAGE(L23,MAX(M23:N23),MAX(O23:P23)) -> 10.666667 | R23: =IF(Q23>=10,"TRANSITA","N/TRANSITA") -> TRANSITA | X23: =AVERAGE(S23,MAX(T23:U23),MAX(V23:W23)) -> 0 | Y23: =SUM(J23,Q23,X23)/3 -> 7.6666667 | Z23: =IF(Y23>=10,"TRANSITA","N/TRANSITA") -> N/TRANSITA
B24: 16 | C24: Esperança Muanda | E24: 13.5 | F24: 17 | H24: 10 | J24: =AVERAGE(E24,MAX(F24:G24),MAX(H24:I24)) -> 13.5 | K24: =IF(J24>=10,"TRANSITA","N/TRANSITA") -> TRANSITA | L24: 10 | M24: 12 | O24: 6.5 | Q24: =AVERAGE(L24,MAX(M24:N24),MAX(O24:P24)) -> 9.5 | R24: =IF(Q24>=10,"TRANSITA","N/TRANSITA") -> N/TRANSITA | X24: =AVERAGE(S24,MAX(T24:U24),MAX(V24:W24)) -> 0 | Y24: =SUM(J24,Q24,X24)/3 -> 7.6666667 | Z24: =IF(Y24>=10,"TRANSITA","N/TRANSITA") -> N/TRANSITA
B25: 17 | C25: Esperança Velância Gomes | E25: 13.5 | F25: 11.5 | H25: 10 | J25: =AVERAGE(E25,MAX(F25:G25),MAX(H25:I25)) -> 11.666667 | K25: =IF(J25>=10,"TRANSITA","N/TRANSITA") -> TRANSITA | L25: 10 | M25: 5 | O25: 3 | Q25: =AVERAGE(L25,MAX(M25:N25),MAX(O25:P25)) -> 6 | R25: =IF(Q25>=10,"TRANSITA","N/TRANSITA") -> N/TRANSITA | X25: =AVERAGE(S25,MAX(T25:U25),MAX(V25:W25)) -> 0 | Y25: =SUM(J25,Q25,X25)/3 -> 5.8888889 | Z25: =IF(Y25>=10,"TRANSITA","N/TRANSITA") -> N/TRANSITA
B26: 18 | C26: Eunice Domingas Umbar | E26: 15 | F26: 17 | H26: 13.5 | J26: =AVERAGE(E26,MAX(F26:G26),MAX(H26:I26)) -> 15.166667 | K26: =IF(J26>=10,"TRANSITA","N/TRANSITA") -> TRANSITA | L26: 12 | M26: 12 | O26: 7 | Q26: =AVERAGE(L26,MAX(M26:N26),MAX(O26:P26)) -> 10.333333 | R26: =IF(Q26>=10,"TRANSITA","N/TRANSITA") -> TRANSITA | X26: =AVERAGE(S26,MAX(T26:U26),MAX(V26:W26)) -> 0 | Y26: =SUM(J26,Q26,X26)/3 -> 8.5 | Z26: =IF(Y26>=10,"TRANSITA","N/TRANSITA") -> N/TRANSITA
B27: 19 | C27: Faustino Cardoso | E27: 14 | F27: 13.5 | H27: 7.5 | J27: =AVERAGE(E27,MAX(F27:G27),MAX(H27:I27)) -> 11.666667 | K27: =IF(J27>=10,"TRANSITA","N/TRANSITA") -> TRANSITA | L27: 10 | M27: 8 | O27: 10.5 | Q27: =AVERAGE(L27,MAX(M27:N27),MAX(O27:P27)) -> 9.5 | R27: =IF(Q27>=10,"TRANSITA","N/TRANSITA") -> N/TRANSITA | X27: =AVERAGE(S27,MAX(T27:U27),MAX(V27:W27)) -> 0 | Y27: =SUM(J27,Q27,X27)/3 -> 7.0555556 | Z27: =IF(Y27>=10,"TRANSITA","N/TRANSITA") -> N/TRANSITA
B28: 20 | C28: Felicidade Buzi Guerra | E28: 13.5 | F28: 10 | H28: 8.25 | J28: =AVERAGE(E28,MAX(F28:G28),MAX(H28:I28)) -> 10.583333 | K28: =IF(J28>=10,"TRANSITA","N/TRANSITA") -> TRANSITA | Q28: =AVERAGE(L28,MAX(M28:N28),MAX(O28:P28)) -> 0 | R28: =IF(Q28>=10,"TRANSITA","N/TRANSITA") -> N/TRANSITA | X28: =AVERAGE(S28,MAX(T28:U28),MAX(V28:W28)) -> 0 | Y28: =SUM(J28,Q28,X28)/3 -> 3.5277778 | Z28: =IF(Y28>=10,"TRANSITA","N/TRANSITA") -> N/TRANSITA
B29: 21 | C29: Filipe Binjunga Futi | E29: 14 | F29: 12 | H29: 8 | J29: =AVERAGE(E29,MAX(F29:G29),MAX(H29:I29)) -> 11.333333 | K29: =IF(J29>=10,"TRANSITA","N/TRANSITA") -> TRANSITA | O29: 8.5 | Q29: =AVERAGE(L29,MAX(M29:N29),MAX(O29:P29)) -> 4.25 | R29: =IF(Q29>=10,"TRANSITA","N/TRANSITA") -> N/TRANSITA | X29: =AVERAGE(S29,MAX(T29:U29),MAX(V29:W29)) -> 0 | Y29: =SUM(J29,Q29,X29)/3 -> 5.1944444 | Z29: =IF(Y29>=10,"TRANSITA","N/TRANSITA") -> N/TRANSITA
B30: 22 | C30: Graça Tucola Mavungo | E30: 14 | F30: 16 | H30: 11 | J30: =AVERAGE(E30,MAX(F30:G30),MAX(H30:I30)) -> 13.666667 | K30: =IF(J30>=10,"TRANSITA","N/TRANSITA") -> TRANSITA | L30: 10 | M30: 12 | O30: 10.5 | Q30: =AVERAGE(L30,MAX(M30:N30),MAX(O30:P30)) -> 10.833333 | R30: =IF(Q30>=10,"TRANSITA","N/TRANSITA") -> TRANSITA | X30: =AVERAGE(S30,MAX(T30:U30),MAX(V30:W30)) -> 0 | Y30: =SUM(J30,Q30,X30)/3 -> 8.1666667 | Z30: =IF(Y30>=10,"TRANSITA","N/TRANSITA") -> N/TRANSITA
B31: 23 | C31: Helena Ernestina Pemba Cole | E31: 13 | F31: 10 | J31: =AVERAGE(E31,MAX(F31:G31),MAX(H31:I31)) -> 7.6666667 | K31: =IF(J31>=10,"TRANSITA","N/TRANSITA") -> N/TRANSITA | M31: 8 | O31: 5 | Q31: =AVERAGE(L31,MAX(M31:N31),MAX(O31:P31)) -> 6.5 | R31: =IF(Q31>=10,"TRANSITA","N/TRANSITA") -> N/TRANSITA | X31: =AVERAGE(S31,MAX(T31:U31),MAX(V31:W31)) -> 0 | Y31: =SUM(J31,Q31,X31)/3 -> 4.7222222 | Z31: =IF(Y31>=10,"TRANSITA","N/TRANSITA") -> N/TRANSITA
B32: 24 | C32: Imaculada Da Conceiãção Cungi Zau | E32: 13.5 | F32: 10 | H32: 7 | J32: =AVERAGE(E32,MAX(F32:G32),MAX(H32:I32)) -> 10.166667 | K32: =IF(J32>=10,"TRANSITA","N/TRANSITA") -> TRANSITA | L32: 10 | M32: 5 | O32: 5.5 | Q32: =AVERAGE(L32,MAX(M32:N32),MAX(O32:P32)) -> 6.8333333 | R32: =IF(Q32>=10,"TRANSITA","N/TRANSITA") -> N/TRANSITA | X32: =AVERAGE(S32,MAX(T32:U32),MAX(V32:W32)) -> 0 | Y32: =SUM(J32,Q32,X32)/3 -> 5.6666667 | Z32: =IF(Y32>=10,"TRANSITA","N/TRANSITA") -> N/TRANSITA
B33: 25 | C33: Isabel Buanga Lelo Mendes | E33: 13 | F33: 18 | H33: 6 | J33: =AVERAGE(E33,MAX(F33:G33),MAX(H33:I33)) -> 12.333333 | K33: =IF(J33>=10,"TRANSITA","N/TRANSITA") -> TRANSITA | L33: 10 | M33: 10 | O33: 8.5 | Q33: =AVERAGE(L33,MAX(M33:N33),MAX(O33:P33)) -> 9.5 | R33: =IF(Q33>=10,"TRANSITA","N/TRANSITA") -> N/TRANSITA | X33: =AVERAGE(S33,MAX(T33:U33),MAX(V33:W33)) -> 0 | Y33: =SUM(J33,Q33,X33)/3 -> 7.2777778 | Z33: =IF(Y33>=10,"TRANSITA","N/TRANSITA") -> N/TRANSITA
B34: 26 | C34: Isabel Domingas Futi | E34: 15 | F34: 16 | H34: 13.75 | J34: =AVERAGE(E34,MAX(F34:G34),MAX(H34:I34)) -> 14.916667 | K34: =IF(J34>=10,"TRANSITA","N/TRANSITA") -> TRANSITA | L34: 10 | M34: 10 | O34: 11.5 | Q34: =AVERAGE(L34,MAX(M34:N34),MAX(O34:P34)) -> 10.5 | R34: =IF(Q34>=10,"TRANSITA","N/TRANSITA") -> TRANSITA | X34: =AVERAGE(S34,MAX(T34:U34),MAX(V34:W34)) -> 0 | Y34: =SUM(J34,Q34,X34)/3 -> 8.4722222 | Z34: =IF(Y34>=10,"TRANSITA","N/TRANSITA") -> N/TRANSITA
B35: 27 | C35: Joana Bizi Muanda Bungo | E35: 14 | F35: 10 | H35: 6.25 | J35: =AVERAGE(E35,MAX(F35:G35),MAX(H35:I35)) -> 10.083333 | K35: =IF(J35>=10,"TRANSITA","N/TRANSITA") -> TRANSITA | Q35: =AVERAGE(L35,MAX(M35:N35),MAX(O35:P35)) -> 0 | R35: =IF(Q35>=10,"TRANSITA","N/TRANSITA") -> N/TRANSITA | X35: =AVERAGE(S35,MAX(T35:U35),MAX(V35:W35)) -> 0 | Y35: =SUM(J35,Q35,X35)/3 -> 3.3611111 | Z35: =IF(Y35>=10,"TRANSITA","N/TRANSITA") -> N/TRANSITA
B36: 28 | C36: Jaquelina Malonda Muanda Mbumba | E36: 14 | F36: 9 | H36: 5 | J36: =AVERAGE(E36,MAX(F36:G36),MAX(H36:I36)) -> 9.3333333 | K36: =IF(J36>=10,"TRANSITA","N/TRANSITA") -> N/TRANSITA | L36: 10 | M36: 8 | O36: 1.5 | Q36: =AVERAGE(L36,MAX(M36:N36),MAX(O36:P36)) -> 6.5 | R36: =IF(Q36>=10,"TRANSITA","N/TRANSITA") -> N/TRANSITA | X36: =AVERAGE(S36,MAX(T36:U36),MAX(V36:W36)) -> 0 | Y36: =SUM(J36,Q36,X36)/3 -> 5.2777778 | Z36: =IF(Y36>=10,"TRANSITA","N/TRANSITA") -> N/TRANSITA
B37: 29 | C37: José Mavungo Dungi | E37: 15 | F37: 15 | H37: 11.5 | J37: =AVERAGE(E37,MAX(F37:G37),MAX(H37:I37)) -> 13.833333 | K37: =IF(J37>=10,"TRANSITA","N/TRANSITA") -> TRANSITA | L37: 10 | M37: 10 | O37: 12.5 | Q37: =AVERAGE(L37,MAX(M37:N37),MAX(O37:P37)) -> 10.833333 | R37: =IF(Q37>=10,"TRANSITA","N/TRANSITA") -> TRANSITA | X37: =AVERAGE(S37,MAX(T37:U37),MAX(V37:W37)) -> 0 | Y37: =SUM(J37,Q37,X37)/3 -> 8.2222222 | Z37: =IF(Y37>=10,"TRANSITA","N/TRANSITA") -> N/TRANSITA
B38: 30 | C38: Jose Nhimi Cesse | E38: 14.5 | F38: 10 | H38: 11.5 | J38: =AVERAGE(E38,MAX(F38:G38),MAX(H38:I38)) -> 12 | K38: =IF(J38>=10,"TRANSITA","N/TRANSITA") -> TRANSITA | L38: 10 | M38: 8 | O38: 3.5 | Q38: =AVERAGE(L38,MAX(M38:N38),MAX(O38:P38)) -> 7.1666667 | R38: =IF(Q38>=10,"TRANSITA","N/TRANSITA") -> N/TRANSITA | X38: =AVERAGE(S38,MAX(T38:U38),MAX(V38:W38)) -> 0 | Y38: =SUM(J38,Q38,X38)/3 -> 6.3888889 | Z38: =IF(Y38>=10,"TRANSITA","N/TRANSITA") -> N/TRANSITA
B39: 31 | C39: Josefina Milonge Poba Ndoqui | E39: 12 | F39: 9 | H39: 6 | J39: =AVERAGE(E39,MAX(F39:G39),MAX(H39:I39)) -> 9 | K39: =IF(J39>=10,"TRANSITA","N/TRANSITA") -> N/TRANSITA | L39: 10 | M39: 7 | O39: 2.5 | Q39: =AVERAGE(L39,MAX(M39:N39),MAX(O39:P39)) -> 6.5 | R39: =IF(Q39>=10,"TRANSITA","N/TRANSITA") -> N/TRANSITA | X39: =AVERAGE(S39,MAX(T39:U39),MAX(V39:W39)) -> 0 | Y39: =SUM(J39,Q39,X39)/3 -> 5.1666667 | Z39: =IF(Y39>=10,"TRANSITA","N/TRANSITA") -> N/TRANSITA
B40: 32 | C40: Lídia Pemba Muel | E40: 13 | F40: 11 | H40: 10 | J40: =AVERAGE(E40,MAX(F40:G40),MAX(H40:I40)) -> 11.333333 | K40: =IF(J40>=10,"TRANSITA","N/TRANSITA") -> TRANSITA | L40: 10 | M40: 7.5 | O40: 6 | Q40: =AVERAGE(L40,MAX(M40:N40),MAX(O40:P40)) -> 7.8333333 | R40: =IF(Q40>=10,"TRANSITA","N/TRANSITA") -> N/TRANSITA | X40: =AVERAGE(S40,MAX(T40:U40),MAX(V40:W40)) -> 0 | Y40: =SUM(J40,Q40,X40)/3 -> 6.3888889 | Z40: =IF(Y40>=10,"TRANSITA","N/TRANSITA") -> N/TRANSITA
B41: 33 | C41: Lino Futi Dinis | H41: 10 | J41: =AVERAGE(E41,MAX(F41:G41),MAX(H41:I41)) -> 5 | K41: =IF(J41>=10,"TRANSITA","N/TRANSITA") -> N/TRANSITA | L41: 10 | M41: 6.5 | O41: 8.5 | Q41: =AVERAGE(L41,MAX(M41:N41),MAX(O41:P41)) -> 8.3333333 | R41: =IF(Q41>=10,"TRANSITA","N/TRANSITA") -> N/TRANSITA | X41: =AVERAGE(S41,MAX(T41:U41),MAX(V41:W41)) -> 0 | Y41: =SUM(J41,Q41,X41)/3 -> 4.4444444 | Z41: =IF(Y41>=10,"TRANSITA","N/TRANSITA") -> N/TRANSITA
...

Sheet 11CL-FAR-MAT
A1: INSTITUTO TÉCNICP PRIVADO DE SAÚDE JOMORAIS
I3: DATA: 12/12/2025
B4: Classe: 11ª | I4: Disciplina: Matemática | V4: Ano Lectivo:2025/2026
B5: Período: Vespertino | I5: Turma: Única | X5: Curso: FARMÁCIA
B6: MINI-PAUTA - TÉCNICO DE SAÚDE
B7: Nº | C7: Nome do (a) Aluno (a) | D7: FALTAS | E7: Avaliações/I Trimestre | K7: OBS | L7: Avaliações/II Trimestre | R7: OBS | S7: Avaliações/IIITrimestre | Y7: MFD | Z7: OBS | AA7: M | AB7: F | AC7: TRANSITA | AD7: N/TRANSITA | AE7: E.E.F
D8: J/I | E8: MAC | F8: NPP | G8: NPR1 | H8: NPT | I8: NPR2 | J8: MT1 | L8: MAC | M8: NPP | N8: NPR1 | O8: NPT | P8: NPR2 | Q8: MT2 | S8: MAC | T8: NPP | U8: NPR1 | V8: NPT | W8: NPR2 | X8: MT3 | AA8: =COUNTIF(Z9:Z69,"M") -> 0 | AB8: =COUNTIF(Z9:Z69,"F") -> 0 | AC8: =COUNTIF(Z9:Z69,"TRANSITA") -> 5 | AD8: =COUNTIF(Z9:Z69,"N/TRANSITA") -> 50 | AE8: =COUNTIF(Z9:Z69,"E.E.F") -> 0
B9: 1 | C9: Alice Cungi Alfredo | E9: 8 | F9: 2 | H9: 10 | J9: =AVERAGE(E9,MAX(F9:G9),MAX(H9:I9)) -> 6.6666667 | K9: =IF(J9>=10,"TRANSITA","N/TRANSITA") -> N/TRANSITA | L9: 12 | M9: 6 | O9: 2 | Q9: =AVERAGE(L9,MAX(M9:N9),MAX(O9:P9)) -> 6.6666667 | R9: =IF(Q9>=10,"TRANSITA","N/TRANSITA") -> N/TRANSITA | X9: =AVERAGE(S9,MAX(T9:U9),MAX(V9:W9)) -> 0 | Y9: =SUM(J9,Q9,X9)/3 -> 4.4444444 | Z9: =IF(Y9>=10,"TRANSITA","N/TRANSITA") -> N/TRANSITA
B10: 2 | C10: Amélia Mauricio Macaia | E10: 12 | F10: 10.5 | H10: 1 | J10: =AVERAGE(E10,MAX(F10:G10),MAX(H10:I10)) -> 7.8333333 | K10: =IF(J10>=10,"TRANSITA","N/TRANSITA") -> N/TRANSITA | L10: 13 | M10: 5 | O10: 6.5 | Q10: =AVERAGE(L10,MAX(M10:N10),MAX(O10:P10)) -> 8.1666667 | R10: =IF(Q10>=10,"TRANSITA","N/TRANSITA") -> N/TRANSITA | X10: =AVERAGE(S10,MAX(T10:U10),MAX(V10:W10)) -> 0 | Y10: =SUM(J10,Q10,X10)/3 -> 5.3333333 | Z10: =IF(Y10>=10,"TRANSITA","N/TRANSITA") -> N/TRANSITA | AA10: =SUM(AA8:AB9) -> 0
B11: 3 | C11: Angelina Umba Esperança Luyeye | E11: 16 | F11: 18.5 | H11: 3 | J11: =AVERAGE(E11,MAX(F11:G11),MAX(H11:I11)) -> 12.5 | K11: =IF(J11>=10,"TRANSITA","N/TRANSITA") -> TRANSITA | L11: 13 | M11: 8 | O11: 2 | Q11: =AVERAGE(L11,MAX(M11:N11),MAX(O11:P11)) -> 7.6666667 | R11: =IF(Q11>=10,"TRANSITA","N/TRANSITA") -> N/TRANSITA | X11: =AVERAGE(S11,MAX(T11:U11),MAX(V11:W11)) -> 0 | Y11: =SUM(J11,Q11,X11)/3 -> 6.7222222 | Z11: =IF(Y11>=10,"TRANSITA","N/TRANSITA") -> N/TRANSITA
B12: 4 | C12: Armindo Maciala Mendes | E12: 20 | F12: 20 | H12: 20 | J12: =AVERAGE(E12,MAX(F12:G12),MAX(H12:I12)) -> 20 | K12: =IF(J12>=10,"TRANSITA","N/TRANSITA") -> TRANSITA | L12: 20 | M12: 10 | O12: 15 | Q12: =AVERAGE(L12,MAX(M12:N12),MAX(O12:P12)) -> 15 | R12: =IF(Q12>=10,"TRANSITA","N/TRANSITA") -> TRANSITA | X12: =AVERAGE(S12,MAX(T12:U12),MAX(V12:W12)) -> 0 | Y12: =SUM(J12,Q12,X12)/3 -> 11.666667 | Z12: =IF(Y12>=10,"TRANSITA","N/TRANSITA") -> TRANSITA
B13: 5 | C13: Beatriz Lelo Nombo | E13: 10 | H13: 8 | J13: =AVERAGE(E13,MAX(F13:G13),MAX(H13:I13)) -> 6 | K13: =IF(J13>=10,"TRANSITA","N/TRANSITA") -> N/TRANSITA | L13: 15 | M13: 15 | O13: 10 | Q13: =AVERAGE(L13,MAX(M13:N13),MAX(O13:P13)) -> 13.333333 | R13: =IF(Q13>=10,"TRANSITA","N/TRANSITA") -> TRANSITA | X13: =AVERAGE(S13,MAX(T13:U13),MAX(V13:W13)) -> 0 | Y13: =SUM(J13,Q13,X13)/3 -> 6.4444444 | Z13: =IF(Y13>=10,"TRANSITA","N/TRANSITA") -> N/TRANSITA
B14: 6 | C14: Carolina Zuzi Nhimi | E14: 16 | F14: 19 | H14: 5 | J14: =AVERAGE(E14,MAX(F14:G14),MAX(H14:I14)) -> 13.333333 | K14: =IF(J14>=10,"TRANSITA","N/TRANSITA") -> TRANSITA | L14: 14 | M14: 5 | O14: 11.5 | Q14: =AVERAGE(L14,MAX(M14:N14),MAX(O14:P14)) -> 10.166667 | R14: =IF(Q14>=10,"TRANSITA","N/TRANSITA") -> TRANSITA | X14: =AVERAGE(S14,MAX(T14:U14),MAX(V14:W14)) -> 0 | Y14: =SUM(J14,Q14,X14)/3 -> 7.8333333 | Z14: =IF(Y14>=10,"TRANSITA","N/TRANSITA") -> N/TRANSITA
B15: 7 | C15: Catarina Simba Buela | E15: 18 | F15: 19 | H15: 16 | J15: =AVERAGE(E15,MAX(F15:G15),MAX(H15:I15)) -> 17.666667 | K15: =IF(J15>=10,"TRANSITA","N/TRANSITA") -> TRANSITA | L15: 12 | M15: 8 | O15: 2 | Q15: =AVERAGE(L15,MAX(M15:N15),MAX(O15:P15)) -> 7.3333333 | R15: =IF(Q15>=10,"TRANSITA","N/TRANSITA") -> N/TRANSITA | X15: =AVERAGE(S15,MAX(T15:U15),MAX(V15:W15)) -> 0 | Y15: =SUM(J15,Q15,X15)/3 -> 8.3333333 | Z15: =IF(Y15>=10,"TRANSITA","N/TRANSITA") -> N/TRANSITA
B16: 8 | C16: Cecília Suami Lando Massiala | E16: 12 | F16: 2 | H16: 10 | J16: =AVERAGE(E16,MAX(F16:G16),MAX(H16:I16)) -> 8 | K16: =IF(J16>=10,"TRANSITA","N/TRANSITA") -> N/TRANSITA | L16: 13 | M16: 7 | O16: 2 | Q16: =AVERAGE(L16,MAX(M16:N16),MAX(O16:P16)) -> 7.3333333 | R16: =IF(Q16>=10,"TRANSITA","N/TRANSITA") -> N/TRANSITA | X16: =AVERAGE(S16,MAX(T16:U16),MAX(V16:W16)) -> 0 | Y16: =SUM(J16,Q16,X16)/3 -> 5.1111111 | Z16: =IF(Y16>=10,"TRANSITA","N/TRANSITA") -> N/TRANSITA
B17: 9 | C17: Clara Sungo Buati Chiânica | E17: 18 | F17: 18 | H17: 15 | J17: =AVERAGE(E17,MAX(F17:G17),MAX(H17:I17)) -> 17 | K17: =IF(J17>=10,"TRANSITA","N/TRANSITA") -> TRANSITA | L17: 14 | M17: 6 | O17: 5 | Q17: =AVERAGE(L17,MAX(M17:N17),MAX(O17:P17)) -> 8.3333333 | R17: =IF(Q17>=10,"TRANSITA","N/TRANSITA") -> N/TRANSITA | X17: =AVERAGE(S17,MAX(T17:U17),MAX(V17:W17)) -> 0 | Y17: =SUM(J17,Q17,X17)/3 -> 8.4444444 | Z17: =IF(Y17>=10,"TRANSITA","N/TRANSITA") -> N/TRANSITA
B18: 10 | C18: Clementina Paca V. Guimbi | E18: 14 | F18: 5.5 | H18: 6.5 | J18: =AVERAGE(E18,MAX(F18:G18),MAX(H18:I18)) -> 8.6666667 | K18: =IF(J18>=10,"TRANSITA","N/TRANSITA") -> N/TRANSITA | L18: 12 | M18: 5 | O18: 2 | Q18: =AVERAGE(L18,MAX(M18:N18),MAX(O18:P18)) -> 6.3333333 | R18: =IF(Q18>=10,"TRANSITA","N/TRANSITA") -> N/TRANSITA | X18: =AVERAGE(S18,MAX(T18:U18),MAX(V18:W18)) -> 0 | Y18: =SUM(J18,Q18,X18)/3 -> 5 | Z18: =IF(Y18>=10,"TRANSITA","N/TRANSITA") -> N/TRANSITA
B19: 11 | C19: Cleúsia Da Conceição Mboco Kilombo | E19: 12 | F19: 9 | H19: 2 | J19: =AVERAGE(E19,MAX(F19:G19),MAX(H19:I19)) -> 7.6666667 | K19: =IF(J19>=10,"TRANSITA","N/TRANSITA") -> N/TRANSITA | L19: 13 | M19: 7 | O19: 3.5 | Q19: =AVERAGE(L19,MAX(M19:N19),MAX(O19:P19)) -> 7.8333333 | R19: =IF(Q19>=10,"TRANSITA","N/TRANSITA") -> N/TRANSITA | X19: =AVERAGE(S19,MAX(T19:U19),MAX(V19:W19)) -> 0 | Y19: =SUM(J19,Q19,X19)/3 -> 5.1666667 | Z19: =IF(Y19>=10,"TRANSITA","N/TRANSITA") -> N/TRANSITA
B20: 12 | C20: Damália Isaias Bumba | E20: 16 | F20: 18 | H20: 10.5 | J20: =AVERAGE(E20,MAX(F20:G20),MAX(H20:I20)) -> 14.833333 | K20: =IF(J20>=10,"TRANSITA","N/TRANSITA") -> TRANSITA | L20: 13 | M20: 8 | O20: 2 | Q20: =AVERAGE(L20,MAX(M20:N20),MAX(O20:P20)) -> 7.6666667 | R20: =IF(Q20>=10,"TRANSITA","N/TRANSITA") -> N/TRANSITA | X20: =AVERAGE(S20,MAX(T20:U20),MAX(V20:W20)) -> 0 | Y20: =SUM(J20,Q20,X20)/3 -> 7.5 | Z20: =IF(Y20>=10,"TRANSITA","N/TRANSITA") -> N/TRANSITA
B21: 13 | C21: Divina Pemba Dembe | E21: 16 | F21: 19.5 | H21: 8.5 | J21: =AVERAGE(E21,MAX(F21:G21),MAX(H21:I21)) -> 14.666667 | K21: =IF(J21>=10,"TRANSITA","N/TRANSITA") -> TRANSITA | L21: 12 | M21: 8 | O21: 5 | Q21: =AVERAGE(L21,MAX(M21:N21),MAX(O21:P21)) -> 8.3333333 | R21: =IF(Q21>=10,"TRANSITA","N/TRANSITA") -> N/TRANSITA | X21: =AVERAGE(S21,MAX(T21:U21),MAX(V21:W21)) -> 0 | Y21: =SUM(J21,Q21,X21)/3 -> 7.6666667 | Z21: =IF(Y21>=10,"TRANSITA","N/TRANSITA") -> N/TRANSITA
B22: 14 | C22: Emíliana Pemba Baza Jonace | E22: 12 | F22: 6 | H22: 6 | J22: =AVERAGE(E22,MAX(F22:G22),MAX(H22:I22)) -> 8 | K22: =IF(J22>=10,"TRANSITA","N/TRANSITA") -> N/TRANSITA | L22: 13 | M22: 9 | O22: 5.5 | Q22: =AVERAGE(L22,MAX(M22:N22),MAX(O22:P22)) -> 9.1666667 | R22: =IF(Q22>=10,"TRANSITA","N/TRANSITA") -> N/TRANSITA | X22: =AVERAGE(S22,MAX(T22:U22),MAX(V22:W22)) -> 0 | Y22: =SUM(J22,Q22,X22)/3 -> 5.7222222 | Z22: =IF(Y22>=10,"TRANSITA","N/TRANSITA") -> N/TRANSITA
B23: 15 | C23: Esmênia Constância Pedro Mendes | E23: 16 | F23: 4 | H23: 10 | J23: =AVERAGE(E23,MAX(F23:G23),MAX(H23:I23)) -> 10 | K23: =IF(J23>=10,"TRANSITA","N/TRANSITA") -> TRANSITA | L23: 14 | M23: 7 | O23: 2 | Q23: =AVERAGE(L23,MAX(M23:N23),MAX(O23:P23)) -> 7.6666667 | R23: =IF(Q23>=10,"TRANSITA","N/TRANSITA") -> N/TRANSITA | X23: =AVERAGE(S23,MAX(T23:U23),MAX(V23:W23)) -> 0 | Y23: =SUM(J23,Q23,X23)/3 -> 5.8888889 | Z23: =IF(Y23>=10,"TRANSITA","N/TRANSITA") -> N/TRANSITA
