Workbook

Sheet EDITAL - 10ª CEJ-UNICA (I TRIM)
A1: COMPLEXO ESCOLAR PRIVADO JOMORAIS
C3: Visto
C4: Director do Complexo
C6: GABRIEL PRÓSPERO MABIALA
A8: Ano Lectivo: 2025-2026 10ª Classe Turma: A Sala: B1 Período: Vespertino I Trimestre
A9: CURSO: CIÊNCIAS ECONÓMICO-JURÍDICAS
A10: N◦ | B10: Nº MATRI | C10: NOME COMPLETO | D10: DISCIPLINAS | N10: Observação | O10: MÉDIA | Q10: DADOS ESTATÍSTICOS
D11: L.Port. | E11: Inglês | F11: Mat. | G11: Infor. | H11: Ed. Fis. | I11: Int. Dto | J11: Int. Eco | K11: Hist. | L11: Geo. | M11: Emp. | P11: Género | Q11: MATRICULADOS | S11: TRANSITA | U11: N/TRANSITA | W11: Desistido/a
A12: 1 | B12: 4570 | C12: Albertina Futi Mavungo | D12: =SUM('10ªCEJ-U-L PORT'!H9) -> 11.25 | E12: =SUM('10ªCEJ-U-INGLES'!H9) -> 4 | F12: =SUM('10ªCEJ-U-MAT'!H9) -> 10.25 | G12: =SUM('10ªCEJ-U-INFOR'!H9) -> 15.5 | H12: =SUM('10ªCEJ-U-ED. FIS'!H9) -> 14 | I12: =SUM('10ªCEJ-U-INT. DTO'!H9) -> 9.5 | J12: =SUM('10ªCEJ-U-INT. ECO'!H9) -> 17 | K12: =SUM('10ªCEJ-U-HIST.'!H9) -> 14.5 | L12: =SUM('10ªCEJ-U-GEO'!H9) -> 16.5 | M12: =SUM('10ªCEJ-U-EMPREEND'!H9) -> 17 | N12: N/TRANSITA | O12: =AVERAGE(D12:M12) -> 12.95 | P12: F | Q12: M | R12: F | S12: M | T12: F | U12: M | V12: F | W12: M | X12: F
A13: 2 | B13: 306 | C13: António Chimpanzo Inocêncio | D13: =SUM('10ªCEJ-U-L PORT'!H10) -> 8.75 | E13: =SUM('10ªCEJ-U-INGLES'!H10) -> 4.5 | F13: =SUM('10ªCEJ-U-MAT'!H10) -> 0 | G13: =SUM('10ªCEJ-U-INFOR'!H10) -> 0 | H13: =SUM('10ªCEJ-U-ED. FIS'!H10) -> 0 | I13: =SUM('10ªCEJ-U-INT. DTO'!H10) -> 6.5 | J13: =SUM('10ªCEJ-U-INT. ECO'!H10) -> 9 | K13: =SUM('10ªCEJ-U-HIST.'!H10) -> 4.5 | L13: =SUM('10ªCEJ-U-GEO'!H10) -> 6.5 | M13: =SUM('10ªCEJ-U-EMPREEND'!H10) -> 0 | N13: N/TRANSITA | O13: =AVERAGE(D13:M13) -> 3.975 | P13: M | Q13: =COUNTIF(P12:P49,"M") -> 17 | R13: =COUNTIF(P12:P49,"F") -> 21 | S13: =COUNTIFS(N12:N49,"Transita",P12:P49,"M") -> 1 | T13: =COUNTIFS(N12:N49,"Transita",P12:P49,"F") -> 2 | U13: =COUNTIFS(N12:N49,"N/Transita",P12:P49,"M") -> 11 | V13: =COUNTIFS(N12:N49,"N/Transita",P12:P49,"F") -> 16 | W13: =COUNTIFS(N12:N49,"DESISTIDO",P12:P49,"M") -> 5 | X13: =COUNTIFS(N12:N49,"DESISTIDA",P12:P49,"F") -> 3
A14: 3 | B14: 4536 | C14: Augusto Mbungo Lando Barros | D14: =SUM('10ªCEJ-U-L PORT'!H11) -> 0 | E14: =SUM('10ªCEJ-U-INGLES'!H11) -> 0 | F14: =SUM('10ªCEJ-U-MAT'!H11) -> 0 | G14: =SUM('10ªCEJ-U-INFOR'!H11) -> 0 | H14: =SUM('10ªCEJ-U-ED. FIS'!H11) -> 0 | I14: =SUM('10ªCEJ-U-INT. DTO'!H11) -> 0 | J14: =SUM('10ªCEJ-U-INT. ECO'!H11) -> 0 | K14: =SUM('10ªCEJ-U-HIST.'!H11) -> 0 | L14: =SUM('10ªCEJ-U-GEO'!H11) -> 0 | M14: =SUM('10ªCEJ-U-EMPREEND'!H11) -> 0 | N14: DESISTIDO | O14: =AVERAGE(D14:M14) -> 0 | P14: M | Q14: =SUM(Q13:R13) -> 38 | S14: =SUM(S12:T13) -> 3 | U14: =SUM(U12:V13) -> 27 | W14: =SUM(W12:X13) -> 8
A15: 4 | B15: 4534 | C15: Chianica Bete Quende | D15: =SUM('10ªCEJ-U-L PORT'!H12) -> 10.5 | E15: =SUM('10ªCEJ-U-INGLES'!H12) -> 11 | F15: =SUM('10ªCEJ-U-MAT'!H12) -> 7 | G15: =SUM('10ªCEJ-U-INFOR'!H12) -> 11 | H15: =SUM('10ªCEJ-U-ED. FIS'!H12) -> 15 | I15: =SUM('10ªCEJ-U-INT. DTO'!H12) -> 0 | J15: =SUM('10ªCEJ-U-INT. ECO'!H12) -> 15.5 | K15: =SUM('10ªCEJ-U-HIST.'!H12) -> 13 | L15: =SUM('10ªCEJ-U-GEO'!H12) -> 12.5 | M15: =SUM('10ªCEJ-U-EMPREEND'!H12) -> 8.5 | N15: N/TRANSITA | O15: =AVERAGE(D15:M15) -> 10.4 | P15: F
A16: 5 | B16: 4748 | C16: Claudete Vuângela | D16: =SUM('10ªCEJ-U-L PORT'!H13) -> 8.5 | E16: =SUM('10ªCEJ-U-INGLES'!H13) -> 2 | F16: =SUM('10ªCEJ-U-MAT'!H13) -> 5 | G16: =SUM('10ªCEJ-U-INFOR'!H13) -> 10.75 | H16: =SUM('10ªCEJ-U-ED. FIS'!H13) -> 0 | I16: =SUM('10ªCEJ-U-INT. DTO'!H13) -> 0 | J16: =SUM('10ªCEJ-U-INT. ECO'!H13) -> 14.5 | K16: =SUM('10ªCEJ-U-HIST.'!H13) -> 9 | L16: =SUM('10ªCEJ-U-GEO'!H13) -> 10 | M16: =SUM('10ªCEJ-U-EMPREEND'!H13) -> 13 | N16: N/TRANSITA | O16: =AVERAGE(D16:M16) -> 7.275 | P16: F
A17: 6 | B17: 4587 | C17: Cristina Massanga Vubo | D17: =SUM('10ªCEJ-U-L PORT'!H14) -> 7.25 | E17: =SUM('10ªCEJ-U-INGLES'!H14) -> 0 | F17: =SUM('10ªCEJ-U-MAT'!H14) -> 0 | G17: =SUM('10ªCEJ-U-INFOR'!H14) -> 10.5 | H17: =SUM('10ªCEJ-U-ED. FIS'!H14) -> 10 | I17: =SUM('10ªCEJ-U-INT. DTO'!H14) -> 0 | J17: =SUM('10ªCEJ-U-INT. ECO'!H14) -> 8 | K17: =SUM('10ªCEJ-U-HIST.'!H14) -> 11 | L17: =SUM('10ªCEJ-U-GEO'!H14) -> 10 | M17: =SUM('10ªCEJ-U-EMPREEND'!H14) -> 10.5 | N17: N/TRANSITA | O17: =AVERAGE(D17:M17) -> 6.725 | P17: F | R17: MÁXIMA | S17: =MAX(O12:O50) -> 15.95
A18: 7 | B18: 3480 | C18: Dalmácia Carlota Quitunga | D18: =SUM('10ªCEJ-U-L PORT'!H15) -> 13 | E18: =SUM('10ªCEJ-U-INGLES'!H15) -> 13.5 | F18: =SUM('10ªCEJ-U-MAT'!H15) -> 13 | G18: =SUM('10ªCEJ-U-INFOR'!H15) -> 14 | H18: =SUM('10ªCEJ-U-ED. FIS'!H15) -> 17 | I18: =SUM('10ªCEJ-U-INT. DTO'!H15) -> 9.5 | J18: =SUM('10ªCEJ-U-INT. ECO'!H15) -> 15.5 | K18: =SUM('10ªCEJ-U-HIST.'!H15) -> 15.5 | L18: =SUM('10ªCEJ-U-GEO'!H15) -> 16 | M18: =SUM('10ªCEJ-U-EMPREEND'!H15) -> 17 | N18: TRANSITA | O18: =AVERAGE(D18:M18) -> 14.4 | P18: F
A19: 8 | B19: 4752 | C19: Daniela Teresa Elias Pinto | D19: =SUM('10ªCEJ-U-L PORT'!H16) -> 8.25 | E19: =SUM('10ªCEJ-U-INGLES'!H16) -> 3 | F19: =SUM('10ªCEJ-U-MAT'!H16) -> 5.5 | G19: =SUM('10ªCEJ-U-INFOR'!H16) -> 7.75 | H19: =SUM('10ªCEJ-U-ED. FIS'!H16) -> 15 | I19: =SUM('10ªCEJ-U-INT. DTO'!H16) -> 11 | J19: =SUM('10ªCEJ-U-INT. ECO'!H16) -> 18 | K19: =SUM('10ªCEJ-U-HIST.'!H16) -> 12.5 | L19: =SUM('10ªCEJ-U-GEO'!H16) -> 9 | M19: =SUM('10ªCEJ-U-EMPREEND'!H16) -> 11.5 | N19: N/TRANSITA | O19: =AVERAGE(D19:M19) -> 10.15 | P19: F | R19: NOME DO/A ALUNO/A | U19: Madalena Simba Mavinga Maciala
A20: 9 | B20: 4640 | C20: Delfina Goma Nsoki | D20: =SUM('10ªCEJ-U-L PORT'!H17) -> 14 | E20: =SUM('10ªCEJ-U-INGLES'!H17) -> 10.5 | F20: =SUM('10ªCEJ-U-MAT'!H17) -> 12.5 | G20: =SUM('10ªCEJ-U-INFOR'!H17) -> 15 | H20: =SUM('10ªCEJ-U-ED. FIS'!H17) -> 16 | I20: =SUM('10ªCEJ-U-INT. DTO'!H17) -> 0 | J20: =SUM('10ªCEJ-U-INT. ECO'!H17) -> 11.5 | K20: =SUM('10ªCEJ-U-HIST.'!H17) -> 17 | L20: =SUM('10ªCEJ-U-GEO'!H17) -> 14.5 | M20: =SUM('10ªCEJ-U-EMPREEND'!H17) -> 16.5 | N20: N/TRANSITA | O20: =AVERAGE(D20:M20) -> 12.75 | P20: F | R20: IDADE: | S20: 12
A21: 10 | B21: 4777 | C21: Deolinda Ngueve Waia | D21: =SUM('10ªCEJ-U-L PORT'!H18) -> 9.25 | E21: =SUM('10ªCEJ-U-INGLES'!H18) -> 0 | F21: =SUM('10ªCEJ-U-MAT'!H18) -> 0 | G21: =SUM('10ªCEJ-U-INFOR'!H18) -> 6.75 | H21: =SUM('10ªCEJ-U-ED. FIS'!H18) -> 10 | I21: =SUM('10ªCEJ-U-INT. DTO'!H18) -> 9 | J21: =SUM('10ªCEJ-U-INT. ECO'!H18) -> 11 | K21: =SUM('10ªCEJ-U-HIST.'!H18) -> 7 | L21: =SUM('10ªCEJ-U-GEO'!H18) -> 8.5 | M21: =SUM('10ªCEJ-U-EMPREEND'!H18) -> 5 | N21: N/TRANSITA | O21: =AVERAGE(D21:M21) -> 6.65 | P21: F | S21: ANOS
A22: 11 | B22: 3207 | C22: Estanislau Massiala Roque | D22: =SUM('10ªCEJ-U-L PORT'!H19) -> 0 | E22: =SUM('10ªCEJ-U-INGLES'!H19) -> 0 | F22: =SUM('10ªCEJ-U-MAT'!H19) -> 0 | G22: =SUM('10ªCEJ-U-INFOR'!H19) -> 0 | H22: =SUM('10ªCEJ-U-ED. FIS'!H19) -> 0 | I22: =SUM('10ªCEJ-U-INT. DTO'!H19) -> 0 | J22: =SUM('10ªCEJ-U-INT. ECO'!H19) -> 0 | K22: =SUM('10ªCEJ-U-HIST.'!H19) -> 0 | L22: =SUM('10ªCEJ-U-GEO'!H19) -> 0 | M22: =SUM('10ªCEJ-U-EMPREEND'!H19) -> 0 | N22: DESISTIDO | O22: =AVERAGE(D22:M22) -> 0 | P22: M
A23: 12 | B23: 4716 | C23: Estrela Teta Lumbauziládio | D23: =SUM('10ªCEJ-U-L PORT'!H20) -> 8.5 | E23: =SUM('10ªCEJ-U-INGLES'!H20) -> 14 | F23: =SUM('10ªCEJ-U-MAT'!H20) -> 5.5 | G23: =SUM('10ªCEJ-U-INFOR'!H20) -> 8.5 | H23: =SUM('10ªCEJ-U-ED. FIS'!H20) -> 15 | I23: =SUM('10ªCEJ-U-INT. DTO'!H20) -> 10 | J23: =SUM('10ªCEJ-U-INT. ECO'!H20) -> 14.5 | K23: =SUM('10ªCEJ-U-HIST.'!H20) -> 7 | L23: =SUM('10ªCEJ-U-GEO'!H20) -> 8.5 | M23: =SUM('10ªCEJ-U-EMPREEND'!H20) -> 8 | N23: N/TRANSITA | O23: =AVERAGE(D23:M23) -> 9.95 | P23: M
A24: 13 | B24: 4625 | C24: Gertrudes De Jesus Pucuta Melo | D24: =SUM('10ªCEJ-U-L PORT'!H21) -> 0 | E24: =SUM('10ªCEJ-U-INGLES'!H21) -> 0 | F24: =SUM('10ªCEJ-U-MAT'!H21) -> 0 | G24: =SUM('10ªCEJ-U-INFOR'!H21) -> 0 | H24: =SUM('10ªCEJ-U-ED. FIS'!H21) -> 0 | I24: =SUM('10ªCEJ-U-INT. DTO'!H21) -> 0 | J24: =SUM('10ªCEJ-U-INT. ECO'!H21) -> 0 | K24: =SUM('10ªCEJ-U-HIST.'!H21) -> 0 | L24: =SUM('10ªCEJ-U-GEO'!H21) -> 0 | M24: =SUM('10ªCEJ-U-EMPREEND'!H21) -> 0 | N24: DESISTIDA | O24: =AVERAGE(D24:M24) -> 0 | P24: F
A25: 14 | B25: 4552 | C25: Guiomar Isabel Malonda André | D25: =SUM('10ªCEJ-U-L PORT'!H22) -> 11 | E25: =SUM('10ªCEJ-U-INGLES'!H22) -> 11.5 | F25: =SUM('10ªCEJ-U-MAT'!H22) -> 10.25 | G25: =SUM('10ªCEJ-U-INFOR'!H22) -> 15 | H25: =SUM('10ªCEJ-U-ED. FIS'!H22) -> 17 | I25: =SUM('10ªCEJ-U-INT. DTO'!H22) -> 10.5 | J25: =SUM('10ªCEJ-U-INT. ECO'!H22) -> 15.5 | K25: =SUM('10ªCEJ-U-HIST.'!H22) -> 15.5 | L25: =SUM('10ªCEJ-U-GEO'!H22) -> 13 | M25: =SUM('10ªCEJ-U-EMPREEND'!H22) -> 16.5 | N25: TRANSITA | O25: =AVERAGE(D25:M25) -> 13.575 | P25: F
A26: 15 | B26: 4720 | C26: Filomena de Fátima Goma Monteiro | D26: =SUM('10ªCEJ-U-L PORT'!H23) -> 7.5 | E26: =SUM('10ªCEJ-U-INGLES'!H23) -> 0 | F26: =SUM('10ªCEJ-U-MAT'!H23) -> 5.5 | G26: =SUM('10ªCEJ-U-INFOR'!H23) -> 0 | H26: =SUM('10ªCEJ-U-ED. FIS'!H23) -> 10 | I26: =SUM('10ªCEJ-U-INT. DTO'!H23) -> 9.5 | J26: =SUM('10ªCEJ-U-INT. ECO'!H23) -> 0 | K26: =SUM('10ªCEJ-U-HIST.'!H23) -> 12.5 | L26: =SUM('10ªCEJ-U-GEO'!H23) -> 10 | M26: =SUM('10ªCEJ-U-EMPREEND'!H23) -> 8.5 | N26: N/TRANSITA | O26: =AVERAGE(D26:M26) -> 6.35 | P26: F
A27: 16 | B27: 4747 | C27: Francisco Chocolate Chinene | D27: =SUM('10ªCEJ-U-L PORT'!H24) -> 7.5 | E27: =SUM('10ªCEJ-U-INGLES'!H24) -> 12 | F27: =SUM('10ªCEJ-U-MAT'!H24) -> 0 | G27: =SUM('10ªCEJ-U-INFOR'!H24) -> 9.5 | H27: =SUM('10ªCEJ-U-ED. FIS'!H24) -> 8 | I27: =SUM('10ªCEJ-U-INT. DTO'!H24) -> 0 | J27: =SUM('10ªCEJ-U-INT. ECO'!H24) -> 12 | K27: =SUM('10ªCEJ-U-HIST.'!H24) -> 8.5 | L27: =SUM('10ªCEJ-U-GEO'!H24) -> 11 | M27: =SUM('10ªCEJ-U-EMPREEND'!H24) -> 9.5 | N27: N/TRANSITA | O27: =AVERAGE(D27:M27) -> 7.8 | P27: M
A28: 17 | B28: 4635 | C28: Isabel Mavinga Chiana Chocolate | D28: =SUM('10ªCEJ-U-L PORT'!H25) -> 8 | E28: =SUM('10ªCEJ-U-INGLES'!H25) -> 0 | F28: =SUM('10ªCEJ-U-MAT'!H25) -> 0 | G28: =SUM('10ªCEJ-U-INFOR'!H25) -> 0 | H28: =SUM('10ªCEJ-U-ED. FIS'!H25) -> 0 | I28: =SUM('10ªCEJ-U-INT. DTO'!H25) -> 0 | J28: =SUM('10ªCEJ-U-INT. ECO'!H25) -> 0 | K28: =SUM('10ªCEJ-U-HIST.'!H25) -> 0 | L28: =SUM('10ªCEJ-U-GEO'!H25) -> 0 | M28: =SUM('10ªCEJ-U-EMPREEND'!H25) -> 0 | N28: DESISTIDA | O28: =AVERAGE(D28:M28) -> 0.8 | P28: F
A29: 18 | B29: 4738 | C29: Jacinto Luciano | D29: =SUM('10ªCEJ-U-L PORT'!H26) -> 7.25 | E29: =SUM('10ªCEJ-U-INGLES'!H26) -> 11.5 | F29: =SUM('10ªCEJ-U-MAT'!H26) -> 5 | G29: =SUM('10ªCEJ-U-INFOR'!H26) -> 9 | H29: =SUM('10ªCEJ-U-ED. FIS'!H26) -> 12 | I29: =SUM('10ªCEJ-U-INT. DTO'!H26) -> 10 | J29: =SUM('10ªCEJ-U-INT. ECO'!H26) -> 9.5 | K29: =SUM('10ªCEJ-U-HIST.'!H26) -> 7 | L29: =SUM('10ªCEJ-U-GEO'!H26) -> 14.5 | M29: =SUM('10ªCEJ-U-EMPREEND'!H26) -> 11 | N29: N/TRANSITA | O29: =AVERAGE(D29:M29) -> 9.675 | P29: M
A30: 19 | B30: 4757 | C30: Joana Suzana Felismina | D30: =SUM('10ªCEJ-U-L PORT'!H27) -> 0 | E30: =SUM('10ªCEJ-U-INGLES'!H27) -> 0 | F30: =SUM('10ªCEJ-U-MAT'!H27) -> 0 | G30: =SUM('10ªCEJ-U-INFOR'!H27) -> 5 | H30: =SUM('10ªCEJ-U-ED. FIS'!H27) -> 8 | I30: =SUM('10ªCEJ-U-INT. DTO'!H27) -> 0 | J30: =SUM('10ªCEJ-U-INT. ECO'!H27) -> 0 | K30: =SUM('10ªCEJ-U-HIST.'!H27) -> 0 | L30: =SUM('10ªCEJ-U-GEO'!H27) -> 0 | M30: =SUM('10ªCEJ-U-EMPREEND'!H27) -> 5 | N30: N/TRANSITA | O30: =AVERAGE(D30:M30) -> 1.8 | P30: F
A31: 20 | B31: 3797 | C31: João Maria Sambo | D31: =SUM('10ªCEJ-U-L PORT'!H28) -> 9.25 | E31: =SUM('10ªCEJ-U-INGLES'!H28) -> 3 | F31: =SUM('10ªCEJ-U-MAT'!H28) -> 0 | G31: =SUM('10ªCEJ-U-INFOR'!H28) -> 12.75 | H31: =SUM('10ªCEJ-U-ED. FIS'!H28) -> 13 | I31: =SUM('10ªCEJ-U-INT. DTO'!H28) -> 9 | J31: =SUM('10ªCEJ-U-INT. ECO'!H28) -> 12 | K31: =SUM('10ªCEJ-U-HIST.'!H28) -> 6 | L31: =SUM('10ªCEJ-U-GEO'!H28) -> 10 | M31: =SUM('10ªCEJ-U-EMPREEND'!H28) -> 6.5 | N31: N/TRANSITA | O31: =AVERAGE(D31:M31) -> 8.15 | P31: M
A32: 21 | B32: 4673 | C32: Joaquim Osvaldo Deca Ngaca | D32: =SUM('10ªCEJ-U-L PORT'!H29) -> 12 | E32: =SUM('10ªCEJ-U-INGLES'!H29) -> 14.5 | F32: =SUM('10ªCEJ-U-MAT'!H29) -> 11.5 | G32: =SUM('10ªCEJ-U-INFOR'!H29) -> 9.75 | H32: =SUM('10ªCEJ-U-ED. FIS'!H29) -> 0 | I32: =SUM('10ªCEJ-U-INT. DTO'!H29) -> 9 | J32: =SUM('10ªCEJ-U-INT. ECO'!H29) -> 16 | K32: =SUM('10ªCEJ-U-HIST.'!H29) -> 11.5 | L32: =SUM('10ªCEJ-U-GEO'!H29) -> 14 | M32: =SUM('10ªCEJ-U-EMPREEND'!H29) -> 12.5 | N32: N/TRANSITA | O32: =AVERAGE(D32:M32) -> 11.075 | P32: M
A33: 22 | B33: 4729 | C33: Josefina Lembe Zau Futi | D33: =SUM('10ªCEJ-U-L PORT'!H30) -> 0 | E33: =SUM('10ªCEJ-U-INGLES'!H30) -> 0 | F33: =SUM('10ªCEJ-U-MAT'!H30) -> 6.5 | G33: =SUM('10ªCEJ-U-INFOR'!H30) -> 5 | H33: =SUM('10ªCEJ-U-ED. FIS'!H30) -> 8 | I33: =SUM('10ªCEJ-U-INT. DTO'!H30) -> 0 | J33: =SUM('10ªCEJ-U-INT. ECO'!H30) -> 15.5 | K33: =SUM('10ªCEJ-U-HIST.'!H30) -> 12.5 | L33: =SUM('10ªCEJ-U-GEO'!H30) -> 6.5 | M33: =SUM('10ªCEJ-U-EMPREEND'!H30) -> 6 | N33: N/TRANSITA | O33: =AVERAGE(D33:M33) -> 6 | P33: F
... A49: 38 | B49: 4680 | C49: Zeferino D. Cambimbi Candongo | D49: =SUM('10ªCEJ-U-L PORT'!H46) -> 0 | E49: =SUM('10ªCEJ-U-INGLES'!H46) -> 0 | F49: =SUM('10ªCEJ-U-MAT'!H46) -> 0 | G49: =SUM('10ªCEJ-U-INFOR'!H46) -> 0 | H49: =SUM('10ªCEJ-U-ED. FIS'!H46) -> 0 | I49: =SUM('10ªCEJ-U-INT. DTO'!H46) -> 0 | J49: =SUM('10ªCEJ-U-INT. ECO'!H46) -> 0 | K49: =SUM('10ªCEJ-U-HIST.'!H46) -> 0 | L49: =SUM('10ªCEJ-U-GEO'!H46) -> 0 | M49: =SUM('10ªCEJ-U-EMPREEND'!H46) -> 0 | N49: DESISTIDO | O49: =AVERAGE(D49:M49) -> 0 | P49: M
A52: COMPLEXO ESCOLAR PRIVADO JOMORAIS, 8 de dezembro de 2025.-
A55: O Director de Turma | L55: O Subdirector Pedagógico
A56: ___________________________ | L56: _____________________________
A57: ANASTÁSIO ZOVO NZUZI | L57: ALBERTO SASSA TATI

Sheet EDITAL - 10ª CEJ-UNICA II TRIM
A1: COMPLEXO ESCOLAR PRIVADO JOMORAIS
C3: Visto
C4: Director do Complexo
C6: GABRIEL PRÓSPERO MABIALA
A8: Ano Lectivo: 2025-2026 10ª Classe Turma: A Sala: B1 Período: Vespertino II Trimestre
A9: CURSO: CIÊNCIAS ECONÓMICO-JURÍDICAS
A10: N◦ | B10: Nº MATRI | C10: NOME COMPLETO | D10: DISCIPLINAS | N10: Observação | O10: MÉDIA | Q10: DADOS ESTATÍSTICOS
D11: L.Port. | E11: Inglês | F11: Mat. | G11: Infor. | H11: Ed. Fis. | I11: Int. Dto | J11: Int. Eco | K11: Hist. | L11: Geo. | M11: Emp. | P11: Género | Q11: MATRICULADOS | S11: TRANSITA | U11: N/TRANSITA | W11: Desistido/a
A12: 1 | B12: 4570 | C12: Albertina Futi Mavungo | D12: =SUM('10ªCEJ-U-L PORT'!M9) -> 13 | E12: =SUM('10ªCEJ-U-INGLES'!M9) -> 17.5 | F12: =SUM('10ªCEJ-U-MAT'!M9) -> 12 | G12: =SUM('10ªCEJ-U-INFOR'!M9) -> 13.5 | H12: =SUM('10ªCEJ-U-ED. FIS'!M9) -> 7 | I12: =SUM('10ªCEJ-U-INT. DTO'!M9) -> 11 | J12: =SUM('10ªCEJ-U-INT. ECO'!M9) -> 13 | K12: =SUM('10ªCEJ-U-HIST.'!M9) -> 15 | L12: =SUM('10ªCEJ-U-GEO'!M9) -> 16.5 | M12: =SUM('10ªCEJ-U-EMPREEND'!M9) -> 14 | N12: N/TRANSITA | O12: =AVERAGE(D12:M12) -> 13.25 | P12: F | Q12: M | R12: F | S12: M | T12: F | U12: M | V12: F | W12: M | X12: F
A13: 2 | B13: 306 | C13: António Chimpanzo Inocêncio | D13: =SUM('10ªCEJ-U-L PORT'!M10) -> 5.75 | E13: =SUM('10ªCEJ-U-INGLES'!M10) -> 9.5 | F13: =SUM('10ªCEJ-U-MAT'!M10) -> 12 | G13: =SUM('10ªCEJ-U-INFOR'!M10) -> 4.5 | H13: =SUM('10ªCEJ-U-ED. FIS'!M10) -> 0 | I13: =SUM('10ªCEJ-U-INT. DTO'!M10) -> 0 | J13: =SUM('10ªCEJ-U-INT. ECO'!M10) -> 10 | K13: =SUM('10ªCEJ-U-HIST.'!M10) -> 5 | L13: =SUM('10ªCEJ-U-GEO'!M10) -> 6.25 | M13: =SUM('10ªCEJ-U-EMPREEND'!M10) -> 2.5 | N13: N/TRANSITA | O13: =AVERAGE(D13:M13) -> 5.55 | P13: M | Q13: =COUNTIF(P12:P49,"M") -> 16 | R13: =COUNTIF(P12:P49,"F") -> 22 | S13: =COUNTIFS(N12:N49,"Transita",P12:P49,"M") -> 1 | T13: =COUNTIFS(N12:N49,"Transita",P12:P49,"F") -> 2 | U13: =COUNTIFS(N12:N49,"N/Transita",P12:P49,"M") -> 8 | V13: =COUNTIFS(N12:N49,"N/Transita",P12:P49,"F") -> 13 | W13: =COUNTIFS(N12:N49,"DESISTIDO",P12:P49,"M") -> 7 | X13: =COUNTIFS(N12:N49,"DESISTIDA",P12:P49,"F") -> 7
A14: 3 | B14: 4536 | C14: Augusto Mbungo Lando Barros | D14: =SUM('10ªCEJ-U-L PORT'!M11) -> 0 | E14: =SUM('10ªCEJ-U-INGLES'!M11) -> 0 | F14: =SUM('10ªCEJ-U-MAT'!M11) -> 12 | G14: =SUM('10ªCEJ-U-INFOR'!M11) -> 0 | H14: =SUM('10ªCEJ-U-ED. FIS'!M11) -> 0 | I14: =SUM('10ªCEJ-U-INT. DTO'!M11) -> 0 | J14: =SUM('10ªCEJ-U-INT. ECO'!M11) -> 0 | K14: =SUM('10ªCEJ-U-HIST.'!M11) -> 0 | L14: =SUM('10ªCEJ-U-GEO'!M11) -> 0 | M14: =SUM('10ªCEJ-U-EMPREEND'!M11) -> 0 | N14: DESISTIDO | O14: =AVERAGE(D14:M14) -> 1.2 | P14: M | Q14: =SUM(Q13:R13) -> 38 | S14: =SUM(S12:T13) -> 3 | U14: =SUM(U12:V13) -> 21 | W14: =SUM(W12:X13) -> 14
A15: 4 | B15: 4534 | C15: Chianica Bete Quende | D15: =SUM('10ªCEJ-U-L PORT'!M12) -> 6.25 | E15: =SUM('10ªCEJ-U-INGLES'!M12) -> 10 | F15: =SUM('10ªCEJ-U-MAT'!M12) -> 12 | G15: =SUM('10ªCEJ-U-INFOR'!M12) -> 8 | H15: =SUM('10ªCEJ-U-ED. FIS'!M12) -> 10 | I15: =SUM('10ªCEJ-U-INT. DTO'!M12) -> 10 | J15: =SUM('10ªCEJ-U-INT. ECO'!M12) -> 15 | K15: =SUM('10ªCEJ-U-HIST.'!M12) -> 12 | L15: =SUM('10ªCEJ-U-GEO'!M12) -> 3 | M15: =SUM('10ªCEJ-U-EMPREEND'!M12) -> 10 | N15: N/TRANSITA | O15: =AVERAGE(D15:M15) -> 9.625 | P15: F
A16: 5 | B16: 4748 | C16: Claudete Vuângela | D16: =SUM('10ªCEJ-U-L PORT'!M13) -> 6.75 | E16: =SUM('10ªCEJ-U-INGLES'!M13) -> 8 | F16: =SUM('10ªCEJ-U-MAT'!M13) -> 12 | G16: =SUM('10ªCEJ-U-INFOR'!M13) -> 9.25 | H16: =SUM('10ªCEJ-U-ED. FIS'!M13) -> 0 | I16: =SUM('10ªCEJ-U-INT. DTO'!M13) -> 7 | J16: =SUM('10ªCEJ-U-INT. ECO'!M13) -> 10.5 | K16: =SUM('10ªCEJ-U-HIST.'!M13) -> 8 | L16: =SUM('10ªCEJ-U-GEO'!M13) -> 9 | M16: =SUM('10ªCEJ-U-EMPREEND'!M13) -> 10 | N16: N/TRANSITA | O16: =AVERAGE(D16:M16) -> 8.05 | P16: F
A17: 6 | B17: 4587 | C17: Cristina Massanga Vubo | D17: =SUM('10ªCEJ-U-L PORT'!M14) -> 3 | E17: =SUM('10ªCEJ-U-INGLES'!M14) -> 8 | F17: =SUM('10ªCEJ-U-MAT'!M14) -> 12 | G17: =SUM('10ªCEJ-U-INFOR'!M14) -> 2.75 | H17: =SUM('10ªCEJ-U-ED. FIS'!M14) -> 0 | I17: =SUM('10ªCEJ-U-INT. DTO'!M14) -> 10 | J17: =SUM('10ªCEJ-U-INT. ECO'!M14) -> 8 | K17: =SUM('10ªCEJ-U-HIST.'!M14) -> 8 | L17: =SUM('10ªCEJ-U-GEO'!M14) -> 10 | M17: =SUM('10ªCEJ-U-EMPREEND'!M14) -> 10 | N17: N/TRANSITA | O17: =AVERAGE(D17:M17) -> 7.175 | P17: F | R17: MÁXIMA | S17: =MAX(O12:O50) -> 15.3
A18: 7 | B18: 3480 | C18: Dalmácia Carlota Quitunga | D18: =SUM('10ªCEJ-U-L PORT'!M15) -> 11.75 | E18: =SUM('10ªCEJ-U-INGLES'!M15) -> 15 | F18: =SUM('10ªCEJ-U-MAT'!M15) -> 12 | G18: =SUM('10ªCEJ-U-INFOR'!M15) -> 13.75 | H18: =SUM('10ªCEJ-U-ED. FIS'!M15) -> 18 | I18: =SUM('10ªCEJ-U-INT. DTO'!M15) -> 10.5 | J18: =SUM('10ªCEJ-U-INT. ECO'!M15) -> 17.25 | K18: =SUM('10ªCEJ-U-HIST.'!M15) -> 15 | L18: =SUM('10ªCEJ-U-GEO'!M15) -> 17.5 | M18: =SUM('10ªCEJ-U-EMPREEND'!M15) -> 14.25 | N18: TRANSITA | O18: =AVERAGE(D18:M18) -> 14.5 | P18: F
A19: 8 | B19: 4752 | C19: Daniela Teresa Elias Pinto | D19: =SUM('10ªCEJ-U-L PORT'!M16) -> 6 | E19: =SUM('10ªCEJ-U-INGLES'!M16) -> 10.5 | F19: =SUM('10ªCEJ-U-MAT'!M16) -> 12 | G19: =SUM('10ªCEJ-U-INFOR'!M16) -> 3.25 | H19: =SUM('10ªCEJ-U-ED. FIS'!M16) -> 0 | I19: =SUM('10ªCEJ-U-INT. DTO'!M16) -> 9.5 | J19: =SUM('10ªCEJ-U-INT. ECO'!M16) -> 12.5 | K19: =SUM('10ªCEJ-U-HIST.'!M16) -> 11 | L19: =SUM('10ªCEJ-U-GEO'!M16) -> 8 | M19: =SUM('10ªCEJ-U-EMPREEND'!M16) -> 10 | N19: N/TRANSITA | O19: =AVERAGE(D19:M19) -> 8.275 | P19: F | R19: NOME DO/A ALUNO/A | U19: Madalena Simba Mavinga Maciala
A20: 9 | B20: 4640 | C20: Delfina Goma Nsoki | D20: =SUM('10ªCEJ-U-L PORT'!M17) -> 10.25 | E20: =SUM('10ªCEJ-U-INGLES'!M17) -> 14.5 | F20: =SUM('10ªCEJ-U-MAT'!M17) -> 12 | G20: =SUM('10ªCEJ-U-INFOR'!M17) -> 9.25 | H20: =SUM('10ªCEJ-U-ED. FIS'!M17) -> 14 | I20: =SUM('10ªCEJ-U-INT. DTO'!M17) -> 12.5 | J20: =SUM('10ªCEJ-U-INT. ECO'!M17) -> 11 | K20: =SUM('10ªCEJ-U-HIST.'!M17) -> 12.5 | L20: =SUM('10ªCEJ-U-GEO'!M17) -> 10.5 | M20: =SUM('10ªCEJ-U-EMPREEND'!M17) -> 11 | N20: N/TRANSITA | O20: =AVERAGE(D20:M20) -> 11.75 | P20: F | R20: IDADE: | S20: 12
A21: 10 | B21: 4777 | C21: Deolinda Ngueve Waia | D21: =SUM('10ªCEJ-U-L PORT'!M18) -> 3.25 | E21: =SUM('10ªCEJ-U-INGLES'!M18) -> 4 | F21: =SUM('10ªCEJ-U-MAT'!M18) -> 12 | G21: =SUM('10ªCEJ-U-INFOR'!M18) -> 3.5 | H21: =SUM('10ªCEJ-U-ED. FIS'!M18) -> 0 | I21: =SUM('10ªCEJ-U-INT. DTO'!M18) -> 9.5 | J21: =SUM('10ªCEJ-U-INT. ECO'!M18) -> 10 | K21: =SUM('10ªCEJ-U-HIST.'!M18) -> 10.75 | L21: =SUM('10ªCEJ-U-GEO'!M18) -> 1 | M21: =SUM('10ªCEJ-U-EMPREEND'!M18) -> 2.5 | N21: N/TRANSITA | O21: =AVERAGE(D21:M21) -> 5.65 | P21: F | S21: ANOS
A22: 11 | B22: 3207 | C22: Estanislau Massiala Roque | D22: =SUM('10ªCEJ-U-L PORT'!M19) -> 0 | E22: =SUM('10ªCEJ-U-INGLES'!M19) -> 0 | F22: =SUM('10ªCEJ-U-MAT'!M19) -> 12 | G22: =SUM('10ªCEJ-U-INFOR'!M19) -> 0 | H22: =SUM('10ªCEJ-U-ED. FIS'!M19) -> 0 | I22: =SUM('10ªCEJ-U-INT. DTO'!M19) -> 0 | J22: =SUM('10ªCEJ-U-INT. ECO'!M19) -> 0 | K22: =SUM('10ªCEJ-U-HIST.'!M19) -> 0 | L22: =SUM('10ªCEJ-U-GEO'!M19) -> 0 | M22: =SUM('10ªCEJ-U-EMPREEND'!M19) -> 0 | N22: DESISTIDO | O22: =AVERAGE(D22:M22) -> 1.2 | P22: M
A23: 12 | B23: 4716 | C23: Estrela Teta Lumbauziládio | D23: =SUM('10ªCEJ-U-L PORT'!M20) -> 5 | E23: =SUM('10ªCEJ-U-INGLES'!M20) -> 3 | F23: =SUM('10ªCEJ-U-MAT'!M20) -> 12 | G23: =SUM('10ªCEJ-U-INFOR'!M20) -> 0 | H23: =SUM('10ªCEJ-U-ED. FIS'!M20) -> 0 | I23: =SUM('10ªCEJ-U-INT. DTO'!M20) -> 0 | J23: =SUM('10ªCEJ-U-INT. ECO'!M20) -> 0 | K23: =SUM('10ªCEJ-U-HIST.'!M20) -> 0 | L23: =SUM('10ªCEJ-U-GEO'!M20) -> 0 | M23: =SUM('10ªCEJ-U-EMPREEND'!M20) -> 0 | N23: DESISTIDA | O23: =AVERAGE(D23:M23) -> 2 | P23: F
A24: 13 | B24: 4625 | C24: Gertrudes De Jesus Pucuta Melo | D24: =SUM('10ªCEJ-U-L PORT'!M21) -> 0 | E24: =SUM('10ªCEJ-U-INGLES'!M21) -> 0 | F24: =SUM('10ªCEJ-U-MAT'!M21) -> 12 | G24: =SUM('10ªCEJ-U-INFOR'!M21) -> 0 | H24: =SUM('10ªCEJ-U-ED. FIS'!M21) -> 0 | I24: =SUM('10ªCEJ-U-INT. DTO'!M21) -> 0 | J24: =SUM('10ªCEJ-U-INT. ECO'!M21) -> 0 | K24: =SUM('10ªCEJ-U-HIST.'!M21) -> 0 | L24: =SUM('10ªCEJ-U-GEO'!M21) -> 0 | M24: =SUM('10ªCEJ-U-EMPREEND'!M21) -> 0 | N24: DESISTIDA | O24: =AVERAGE(D24:M24) -> 1.2 | P24: F
A25: 14 | B25: 4552 | C25: Guiomar Isabel Malonda André | D25: =SUM('10ªCEJ-U-L PORT'!M22) -> 7.25 | E25: =SUM('10ªCEJ-U-INGLES'!M22) -> 14.5 | F25: =SUM('10ªCEJ-U-MAT'!M22) -> 12 | G25: =SUM('10ªCEJ-U-INFOR'!M22) -> 9.5 | H25: =SUM('10ªCEJ-U-ED. FIS'!M22) -> 7 | I25: =SUM('10ªCEJ-U-INT. DTO'!M22) -> 10 | J25: =SUM('10ªCEJ-U-INT. ECO'!M22) -> 15 | K25: =SUM('10ªCEJ-U-HIST.'!M22) -> 8.5 | L25: =SUM('10ªCEJ-U-GEO'!M22) -> 9 | M25: =SUM('10ªCEJ-U-EMPREEND'!M22) -> 11.5 | N25: N/TRANSITA | O25: =AVERAGE(D25:M25) -> 10.425 | P25: F
A26: 15 | B26: 4720 | C26: Filomena de Fátima Goma Monteiro | D26: =SUM('10ªCEJ-U-L PORT'!M23) -> 5.5 | E26: =SUM('10ªCEJ-U-INGLES'!M23) -> 7 | F26: =SUM('10ªCEJ-U-MAT'!M23) -> 12 | G26: =SUM('10ªCEJ-U-INFOR'!M23) -> 3.75 | H26: =SUM('10ªCEJ-U-ED. FIS'!M23) -> 0 | I26: =SUM('10ªCEJ-U-INT. DTO'!M23) -> 8.5 | J26: =SUM('10ªCEJ-U-INT. ECO'!M23) -> 7.5 | K26: =SUM('10ªCEJ-U-HIST.'!M23) -> 10 | L26: =SUM('10ªCEJ-U-GEO'!M23) -> 6.25 | M26: =SUM('10ªCEJ-U-EMPREEND'!M23) -> 2.5 | N26: N/TRANSITA | O26: =AVERAGE(D26:M26) -> 6.3 | P26: F
A27: 16 | B27: 4747 | C27: Francisco Chocolate Chinene | D27: =SUM('10ªCEJ-U-L PORT'!M24) -> 6.75 | E27: =SUM('10ªCEJ-U-INGLES'!M24) -> 9.5 | F27: =SUM('10ªCEJ-U-MAT'!M24) -> 12 | G27: =SUM('10ªCEJ-U-INFOR'!M24) -> 7.25 | H27: =SUM('10ªCEJ-U-ED. FIS'!M24) -> 0 | I27: =SUM('10ªCEJ-U-INT. DTO'!M24) -> 0 | J27: =SUM('10ªCEJ-U-INT. ECO'!M24) -> 10 | K27: =SUM('10ªCEJ-U-HIST.'!M24) -> 10.5 | L27: =SUM('10ªCEJ-U-GEO'!M24) -> 6 | M27: =SUM('10ªCEJ-U-EMPREEND'!M24) -> 2.5 | N27: N/TRANSITA | O27: =AVERAGE(D27:M27) -> 6.45 | P27: M
A28: 17 | B28: 4635 | C28: Isabel Mavinga Chiana Chocolate | D28: =SUM('10ªCEJ-U-L PORT'!M25) -> 0 | E28: =SUM('10ªCEJ-U-INGLES'!M25) -> 0 | F28: =SUM('10ªCEJ-U-MAT'!M25) -> 12 | G28: =SUM('10ªCEJ-U-INFOR'!M25) -> 0 | H28: =SUM('10ªCEJ-U-ED. FIS'!M25) -> 0 | I28: =SUM('10ªCEJ-U-INT. DTO'!M25) -> 0 | J28: =SUM('10ªCEJ-U-INT. ECO'!M25) -> 0 | K28: =SUM('10ªCEJ-U-HIST.'!M25) -> 0 | L28: =SUM('10ªCEJ-U-GEO'!M25) -> 0 | M28: =SUM('10ªCEJ-U-EMPREEND'!M25) -> 0 | N28: DESISTIDA | O28: =AVERAGE(D28:M28) -> 1.2 | P28: F
A29: 18 | B29: 4738 | C29: Jacinto Luciano | D29: =SUM('10ªCEJ-U-L PORT'!M26) -> 7.75 | E29: =SUM('10ªCEJ-U-INGLES'!M26) -> 11 | F29: =SUM('10ªCEJ-U-MAT'!M26) -> 12 | G29: =SUM('10ªCEJ-U-INFOR'!M26) -> 0.25 | H29: =SUM('10ªCEJ-U-ED. FIS'!M26) -> 0 | I29: =SUM('10ªCEJ-U-INT. DTO'!M26) -> 0 | J29: =SUM('10ªCEJ-U-INT. ECO'!M26) -> 10 | K29: =SUM('10ªCEJ-U-HIST.'!M26) -> 7.5 | L29: =SUM('10ªCEJ-U-GEO'!M26) -> 8 | M29: =SUM('10ªCEJ-U-EMPREEND'!M26) -> 2.5 | N29: N/TRANSITA | O29: =AVERAGE(D29:M29) -> 5.9 | P29: M
A30: 19 | B30: 4757 | C30: Joana Suzana Felismina | D30: =SUM('10ªCEJ-U-L PORT'!M27) -> 0 | E30: =SUM('10ªCEJ-U-INGLES'!M27) -> 0 | F30: =SUM('10ªCEJ-U-MAT'!M27) -> 12 | G30: =SUM('10ªCEJ-U-INFOR'!M27) -> 0 | H30: =SUM('10ªCEJ-U-ED. FIS'!M27) -> 0 | I30: =SUM('10ªCEJ-U-INT. DTO'!M27) -> 0 | J30: =SUM('10ªCEJ-U-INT. ECO'!M27) -> 0 | K30: =SUM('10ªCEJ-U-HIST.'!M27) -> 0 | L30: =SUM('10ªCEJ-U-GEO'!M27) -> 0 | M30: =SUM('10ªCEJ-U-EMPREEND'!M27) -> 0 | N30: DESISTIDA | O30: =AVERAGE(D30:M30) -> 1.2 | P30: F
A31: 20 | B31: 3797 | C31: João Maria Sambo | D31: =SUM('10ªCEJ-U-L PORT'!M28) -> 1 | E31: =SUM('10ªCEJ-U-INGLES'!M28) -> 0 | F31: =SUM('10ªCEJ-U-MAT'!M28) -> 12 | G31: =SUM('10ªCEJ-U-INFOR'!M28) -> 0 | H31: =SUM('10ªCEJ-U-ED. FIS'!M28) -> 0 | I31: =SUM('10ªCEJ-U-INT. DTO'!M28) -> 0 | J31: =SUM('10ªCEJ-U-INT. ECO'!M28) -> 5 | K31: =SUM('10ªCEJ-U-HIST.'!M28) -> 0 | L31: =SUM('10ªCEJ-U-GEO'!M28) -> 0 | M31: =SUM('10ªCEJ-U-EMPREEND'!M28) -> 0 | N31: DESISTIDO | O31: =AVERAGE(D31:M31) -> 1.8 | P31: M
A32: 21 | B32: 4673 | C32: Joaquim Osvaldo Deca Ngaca | D32: =SUM('10ªCEJ-U-L PORT'!M29) -> 8.5 | E32: =SUM('10ªCEJ-U-INGLES'!M29) -> 8 | F32: =SUM('10ªCEJ-U-MAT'!M29) -> 12 | G32: =SUM('10ªCEJ-U-INFOR'!M29) -> 4.5 | H32: =SUM('10ªCEJ-U-ED. FIS'!M29) -> 0 | I32: =SUM('10ªCEJ-U-INT. DTO'!M29) -> 10 | J32: =SUM('10ªCEJ-U-INT. ECO'!M29) -> 5 | K32: =SUM('10ªCEJ-U-HIST.'!M29) -> 10 | L32: =SUM('10ªCEJ-U-GEO'!M29) -> 2 | M32: =SUM('10ªCEJ-U-EMPREEND'!M29) -> 10 | N32: N/TRANSITA | O32: =AVERAGE(D32:M32) -> 7 | P32: M
A33: 22 | B33: 4729 | C33: Josefina Lembe Zau Futi | D33: =SUM('10ªCEJ-U-L PORT'!M30) -> 0 | E33: =SUM('10ªCEJ-U-INGLES'!M30) -> 0 | F33: =SUM('10ªCEJ-U-MAT'!M30) -> 12 | G33: =SUM('10ªCEJ-U-INFOR'!M30) -> 0 | H33: =SUM('10ªCEJ-U-ED. FIS'!M30) -> 0 | I33: =SUM('10ªCEJ-U-INT. DTO'!M30) -> 0 | J33: =SUM('10ªCEJ-U-INT. ECO'!M30) -> 0 | K33: =SUM('10ªCEJ-U-HIST.'!M30) -> 0 | L33: =SUM('10ªCEJ-U-GEO'!M30) -> 0 | M33: =SUM('10ªCEJ-U-EMPREEND'!M30) -> 0 | N33: DESISTIDA | O33: =AVERAGE(D33:M33) -> 1.2 | P33: F
... A49: 38 | B49: 4680 | C49: Zeferino D. Cambimbi Candongo | D49: =SUM('10ªCEJ-U-L PORT'!M46) -> 0 | E49: =SUM('10ªCEJ-U-INGLES'!M46) -> 0 | F49: =SUM('10ªCEJ-U-MAT'!M46) -> 12 | G49: =SUM('10ªCEJ-U-INFOR'!M46) -> 0 | H49: =SUM('10ªCEJ-U-ED. FIS'!M46) -> 0 | I49: =SUM('10ªCEJ-U-INT. DTO'!M46) -> 0 | J49: =SUM('10ªCEJ-U-INT. ECO'!M46) -> 0 | K49: =SUM('10ªCEJ-U-HIST.'!M46) -> 0 | L49: =SUM('10ªCEJ-U-GEO'!M46) -> 0 | M49: =SUM('10ªCEJ-U-EMPREEND'!M46) -> 0 | N49: DESISTIDO | O49: =AVERAGE(D49:M49) -> 1.2 | P49: M
A52: COMPLEXO ESCOLAR PRIVADO JOMORAIS, 27 de março de 2026.-
A55: O Director de Turma | L55: O Subdirector Pedagógico
A56: ___________________________ | L56: _____________________________
A57: ANASTÁSIO ZOVO NZUZI | L57: ALBERTO SASSA TATI

Sheet 10ªCEJ-U-L PORT
A1: COMPLEXO ESCOLAR PRIVADO JOMORAIS
B4: Classe: 10ª | I4: Disciplina: Língua Portuguesa | P4: Ano Lectivo:2025/2026
B5: Período: Vespertino | I5: Turma: Única | N5: Curso: Ciências Económico-jurídicas
B6: MINI-PAUTA - I Ciclo do Ensino Secundário Geral
B7: Nº | C7: Nome do (a) Aluno (a) | D7: FALTAS | E7: Avaliações/I Trimestre | I7: OBS | J7: Avaliações/II Trimestre | N7: OBS | O7: Avaliações/IIITrimestre | S7: MFD | T7: OBS
D8: J/I | E8: MAC | F8: NPT | G8: NPR2 | H8: MT1 | J8: MAC | K8: NPT | L8: NPR2 | M8: MT2 | O8: MAC | P8: NPT | Q8: NPR2 | R8: MT3
B9: 1 | C9: Albertina Futi Mavungo | E9: 13 | F9: 9.5 | H9: =AVERAGE(E9,MAX(F9:G9)) -> 11.25 | I9: =IF(H9>=10,"TRANSITA","N/TRANSITA") -> TRANSITA | J9: 14 | K9: 12 | M9: =AVERAGE(J9,MAX(K9:L9)) -> 13 | N9: =IF(M9>=10,"TRANSITA","N/TRANSITA") -> TRANSITA | R9: =AVERAGE(O9,MAX(P9:Q9)) -> 0 | S9: =SUM(H9,M9,R9)/3 -> 8.0833333 | T9: =IF(S9>=10,"TRANSITA","N/TRANSITA") -> N/TRANSITA
B10: 2 | C10: António Chimpanzo Inocêncio | E10: 13 | F10: 4.5 | H10: =AVERAGE(E10,MAX(F10:G10)) -> 8.75 | I10: =IF(H10>=10,"TRANSITA","N/TRANSITA") -> N/TRANSITA | J10: 10 | K10: 1.5 | M10: =AVERAGE(J10,MAX(K10:L10)) -> 5.75 | N10: =IF(M10>=10,"TRANSITA","N/TRANSITA") -> N/TRANSITA | R10: =AVERAGE(O10,MAX(P10:Q10)) -> 0 | S10: =SUM(H10,M10,R10)/3 -> 4.8333333 | T10: =IF(S10>=10,"TRANSITA","N/TRANSITA") -> N/TRANSITA
B11: 3 | C11: Augusto Mbungo Lando Barros | H11: =AVERAGE(E11,MAX(F11:G11)) -> 0 | I11: =IF(H11>=10,"TRANSITA","N/TRANSITA") -> N/TRANSITA | M11: =AVERAGE(J11,MAX(K11:L11)) -> 0 | N11: =IF(M11>=10,"TRANSITA","N/TRANSITA") -> N/TRANSITA | R11: =AVERAGE(O11,MAX(P11:Q11)) -> 0 | S11: =SUM(H11,M11,R11)/3 -> 0 | T11: =IF(S11>=10,"TRANSITA","N/TRANSITA") -> N/TRANSITA
B12: 4 | C12: Chianica Bete Quende | E12: 13 | F12: 8 | H12: =AVERAGE(E12,MAX(F12:G12)) -> 10.5 | I12: =IF(H12>=10,"TRANSITA","N/TRANSITA") -> TRANSITA | J12: 10 | K12: 2.5 | M12: =AVERAGE(J12,MAX(K12:L12)) -> 6.25 | N12: =IF(M12>=10,"TRANSITA","N/TRANSITA") -> N/TRANSITA | R12: =AVERAGE(O12,MAX(P12:Q12)) -> 0 | S12: =SUM(H12,M12,R12)/3 -> 5.5833333 | T12: =IF(S12>=10,"TRANSITA","N/TRANSITA") -> N/TRANSITA
B13: 5 | C13: Claudete Vuângela | E13: 12 | F13: 5 | H13: =AVERAGE(E13,MAX(F13:G13)) -> 8.5 | I13: =IF(H13>=10,"TRANSITA","N/TRANSITA") -> N/TRANSITA | J13: 10 | K13: 3.5 | M13: =AVERAGE(J13,MAX(K13:L13)) -> 6.75 | N13: =IF(M13>=10,"TRANSITA","N/TRANSITA") -> N/TRANSITA | R13: =AVERAGE(O13,MAX(P13:Q13)) -> 0 | S13: =SUM(H13,M13,R13)/3 -> 5.0833333 | T13: =IF(S13>=10,"TRANSITA","N/TRANSITA") -> N/TRANSITA
B14: 6 | C14: Cristina Massanga Vubo | E14: 12 | F14: 2.5 | H14: =AVERAGE(E14,MAX(F14:G14)) -> 7.25 | I14: =IF(H14>=10,"TRANSITA","N/TRANSITA") -> N/TRANSITA | J14: 3 | K14: 3 | M14: =AVERAGE(J14,MAX(K14:L14)) -> 3 | N14: =IF(M14>=10,"TRANSITA","N/TRANSITA") -> N/TRANSITA | R14: =AVERAGE(O14,MAX(P14:Q14)) -> 0 | S14: =SUM(H14,M14,R14)/3 -> 3.4166667 | T14: =IF(S14>=10,"TRANSITA","N/TRANSITA") -> N/TRANSITA
B15: 7 | C15: Dalmácia Carlota Quitunga | E15: 16 | F15: 10 | H15: =AVERAGE(E15,MAX(F15:G15)) -> 13 | I15: =IF(H15>=10,"TRANSITA","N/TRANSITA") -> TRANSITA | J15: 13 | K15: 10.5 | M15: =AVERAGE(J15,MAX(K15:L15)) -> 11.75 | N15: =IF(M15>=10,"TRANSITA","N/TRANSITA") -> TRANSITA | R15: =AVERAGE(O15,MAX(P15:Q15)) -> 0 | S15: =SUM(H15,M15,R15)/3 -> 8.25 | T15: =IF(S15>=10,"TRANSITA","N/TRANSITA") -> N/TRANSITA
B16: 8 | C16: Daniela Teresa Elias Pinto | E16: 13.5 | F16: 3 | H16: =AVERAGE(E16,MAX(F16:G16)) -> 8.25 | I16: =IF(H16>=10,"TRANSITA","N/TRANSITA") -> N/TRANSITA | J16: 10 | K16: 2 | M16: =AVERAGE(J16,MAX(K16:L16)) -> 6 | N16: =IF(M16>=10,"TRANSITA","N/TRANSITA") -> N/TRANSITA | R16: =AVERAGE(O16,MAX(P16:Q16)) -> 0 | S16: =SUM(H16,M16,R16)/3 -> 4.75 | T16: =IF(S16>=10,"TRANSITA","N/TRANSITA") -> N/TRANSITA
B17: 9 | C17: Delfina Goma Nsoki | E17: 16 | F17: 12 | H17: =AVERAGE(E17,MAX(F17:G17)) -> 14 | I17: =IF(H17>=10,"TRANSITA","N/TRANSITA") -> TRANSITA | J17: 12 | K17: 8.5 | M17: =AVERAGE(J17,MAX(K17:L17)) -> 10.25 | N17: =IF(M17>=10,"TRANSITA","N/TRANSITA") -> TRANSITA | R17: =AVERAGE(O17,MAX(P17:Q17)) -> 0 | S17: =SUM(H17,M17,R17)/3 -> 8.0833333 | T17: =IF(S17>=10,"TRANSITA","N/TRANSITA") -> N/TRANSITA
B18: 10 | C18: Deolinda Ngueve Waia | E18: 13 | F18: 5.5 | H18: =AVERAGE(E18,MAX(F18:G18)) -> 9.25 | I18: =IF(H18>=10,"TRANSITA","N/TRANSITA") -> N/TRANSITA | J18: 4 | K18: 2.5 | M18: =AVERAGE(J18,MAX(K18:L18)) -> 3.25 | N18: =IF(M18>=10,"TRANSITA","N/TRANSITA") -> N/TRANSITA | R18: =AVERAGE(O18,MAX(P18:Q18)) -> 0 | S18: =SUM(H18,M18,R18)/3 -> 4.1666667 | T18: =IF(S18>=10,"TRANSITA","N/TRANSITA") -> N/TRANSITA
B19: 11 | C19: Estanislau Massiala Roque | H19: =AVERAGE(E19,MAX(F19:G19)) -> 0 | I19: =IF(H19>=10,"TRANSITA","N/TRANSITA") -> N/TRANSITA | M19: =AVERAGE(J19,MAX(K19:L19)) -> 0 | N19: =IF(M19>=10,"TRANSITA","N/TRANSITA") -> N/TRANSITA | R19: =AVERAGE(O19,MAX(P19:Q19)) -> 0 | S19: =SUM(H19,M19,R19)/3 -> 0 | T19: =IF(S19>=10,"TRANSITA","N/TRANSITA") -> N/TRANSITA
B20: 12 | C20: Estrela Teta Lumbauziládio | E20: 12 | F20: 5 | H20: =AVERAGE(E20,MAX(F20:G20)) -> 8.5 | I20: =IF(H20>=10,"TRANSITA","N/TRANSITA") -> N/TRANSITA | J20: 10 | M20: =AVERAGE(J20,MAX(K20:L20)) -> 5 | N20: =IF(M20>=10,"TRANSITA","N/TRANSITA") -> N/TRANSITA | R20: =AVERAGE(O20,MAX(P20:Q20)) -> 0 | S20: =SUM(H20,M20,R20)/3 -> 4.5 | T20: =IF(S20>=10,"TRANSITA","N/TRANSITA") -> N/TRANSITA
B21: 13 | C21: Gertrudes De Jesus Pucuta Melo | H21: =AVERAGE(E21,MAX(F21:G21)) -> 0 | I21: =IF(H21>=10,"TRANSITA","N/TRANSITA") -> N/TRANSITA | M21: =AVERAGE(J21,MAX(K21:L21)) -> 0 | N21: =IF(M21>=10,"TRANSITA","N/TRANSITA") -> N/TRANSITA | R21: =AVERAGE(O21,MAX(P21:Q21)) -> 0 | S21: =SUM(H21,M21,R21)/3 -> 0 | T21: =IF(S21>=10,"TRANSITA","N/TRANSITA") -> N/TRANSITA
B22: 14 | C22: Guiomar Isabel Malonda André | E22: 16 | F22: 6 | H22: =AVERAGE(E22,MAX(F22:G22)) -> 11 | I22: =IF(H22>=10,"TRANSITA","N/TRANSITA") -> TRANSITA | J22: 12 | K22: 2.5 | M22: =AVERAGE(J22,MAX(K22:L22)) -> 7.25 | N22: =IF(M22>=10,"TRANSITA","N/TRANSITA") -> N/TRANSITA | R22: =AVERAGE(O22,MAX(P22:Q22)) -> 0 | S22: =SUM(H22,M22,R22)/3 -> 6.0833333 | T22: =IF(S22>=10,"TRANSITA","N/TRANSITA") -> N/TRANSITA
B23: 15 | C23: Filomena de Fátima Goma Monteiro | E23: 12 | F23: 3 | H23: =AVERAGE(E23,MAX(F23:G23)) -> 7.5 | I23: =IF(H23>=10,"TRANSITA","N/TRANSITA") -> N/TRANSITA | J23: 10 | K23: 1 | M23: =AVERAGE(J23,MAX(K23:L23)) -> 5.5 | N23: =IF(M23>=10,"TRANSITA","N/TRANSITA") -> N/TRANSITA | R23: =AVERAGE(O23,MAX(P23:Q23)) -> 0 | S23: =SUM(H23,M23,R23)/3 -> 4.3333333 | T23: =IF(S23>=10,"TRANSITA","N/TRANSITA") -> N/TRANSITA
B24: 16 | C24: Francisco Chocolate Chinene | E24: 12 | F24: 3 | H24: =AVERAGE(E24,MAX(F24:G24)) -> 7.5 | I24: =IF(H24>=10,"TRANSITA","N/TRANSITA") -> N/TRANSITA | J24: 10 | K24: 3.5 | M24: =AVERAGE(J24,MAX(K24:L24)) -> 6.75 | N24: =IF(M24>=10,"TRANSITA","N/TRANSITA") -> N/TRANSITA | R24: =AVERAGE(O24,MAX(P24:Q24)) -> 0 | S24: =SUM(H24,M24,R24)/3 -> 4.75 | T24: =IF(S24>=10,"TRANSITA","N/TRANSITA") -> N/TRANSITA
B25: 17 | C25: Isabel Mavinga Chiana Chocolate | E25: 16 | H25: =AVERAGE(E25,MAX(F25:G25)) -> 8 | I25: =IF(H25>=10,"TRANSITA","N/TRANSITA") -> N/TRANSITA | J25: 0 | M25: =AVERAGE(J25,MAX(K25:L25)) -> 0 | N25: =IF(M25>=10,"TRANSITA","N/TRANSITA") -> N/TRANSITA | R25: =AVERAGE(O25,MAX(P25:Q25)) -> 0 | S25: =SUM(H25,M25,R25)/3 -> 2.6666667 | T25: =IF(S25>=10,"TRANSITA","N/TRANSITA") -> N/TRANSITA
B26: 18 | C26: Jacinto Luciano | E26: 12 | F26: 2.5 | H26: =AVERAGE(E26,MAX(F26:G26)) -> 7.25 | I26: =IF(H26>=10,"TRANSITA","N/TRANSITA") -> N/TRANSITA | J26: 10 | K26: 5.5 | M26: =AVERAGE(J26,MAX(K26:L26)) -> 7.75 | N26: =IF(M26>=10,"TRANSITA","N/TRANSITA") -> N/TRANSITA | R26: =AVERAGE(O26,MAX(P26:Q26)) -> 0 | S26: =SUM(H26,M26,R26)/3 -> 5 | T26: =IF(S26>=10,"TRANSITA","N/TRANSITA") -> N/TRANSITA
B27: 19 | C27: Joana Suzana Felismina | H27: =AVERAGE(E27,MAX(F27:G27)) -> 0 | I27: =IF(H27>=10,"TRANSITA","N/TRANSITA") -> N/TRANSITA | M27: =AVERAGE(J27,MAX(K27:L27)) -> 0 | N27: =IF(M27>=10,"TRANSITA","N/TRANSITA") -> N/TRANSITA | R27: =AVERAGE(O27,MAX(P27:Q27)) -> 0 | S27: =SUM(H27,M27,R27)/3 -> 0 | T27: =IF(S27>=10,"TRANSITA","N/TRANSITA") -> N/TRANSITA
B28: 20 | C28: João Maria Sambo | E28: 13 | F28: 5.5 | H28: =AVERAGE(E28,MAX(F28:G28)) -> 9.25 | I28: =IF(H28>=10,"TRANSITA","N/TRANSITA") -> N/TRANSITA | J28: 2 | M28: =AVERAGE(J28,MAX(K28:L28)) -> 1 | N28: =IF(M28>=10,"TRANSITA","N/TRANSITA") -> N/TRANSITA | R28: =AVERAGE(O28,MAX(P28:Q28)) -> 0 | S28: =SUM(H28,M28,R28)/3 -> 3.4166667 | T28: =IF(S28>=10,"TRANSITA","N/TRANSITA") -> N/TRANSITA
B29: 21 | C29: Joaquim Osvaldo Deca Ngaca | E29: 16 | F29: 8 | H29: =AVERAGE(E29,MAX(F29:G29)) -> 12 | I29: =IF(H29>=10,"TRANSITA","N/TRANSITA") -> TRANSITA | J29: 10 | K29: 7 | M29: =AVERAGE(J29,MAX(K29:L29)) -> 8.5 | N29: =IF(M29>=10,"TRANSITA","N/TRANSITA") -> N/TRANSITA | R29: =AVERAGE(O29,MAX(P29:Q29)) -> 0 | S29: =SUM(H29,M29,R29)/3 -> 6.8333333 | T29: =IF(S29>=10,"TRANSITA","N/TRANSITA") -> N/TRANSITA
B30: 22 | C30: Josefina Lembe Zau Futi | H30: =AVERAGE(E30,MAX(F30:G30)) -> 0 | I30: =IF(H30>=10,"TRANSITA","N/TRANSITA") -> N/TRANSITA | M30: =AVERAGE(J30,MAX(K30:L30)) -> 0 | N30: =IF(M30>=10,"TRANSITA","N/TRANSITA") -> N/TRANSITA | R30: =AVERAGE(O30,MAX(P30:Q30)) -> 0 | S30: =SUM(H30,M30,R30)/3 -> 0 | T30: =IF(S30>=10,"TRANSITA","N/TRANSITA") -> N/TRANSITA
B31: 23 | C31: Lourdes Puati Issambo | E31: 16 | F31: 6.5 | H31: =AVERAGE(E31,MAX(F31:G31)) -> 11.25 | I31: =IF(H31>=10,"TRANSITA","N/TRANSITA") -> TRANSITA | J31: 10 | K31: 7 | M31: =AVERAGE(J31,MAX(K31:L31)) -> 8.5 | N31: =IF(M31>=10,"TRANSITA","N/TRANSITA") -> N/TRANSITA | R31: =AVERAGE(O31,MAX(P31:Q31)) -> 0 | S31: =SUM(H31,M31,R31)/3 -> 6.5833333 | T31: =IF(S31>=10,"TRANSITA","N/TRANSITA") -> N/TRANSITA
B32: 24 | C32: Luís Liberal Lemos Casimiro | E32: 16 | H32: =AVERAGE(E32,MAX(F32:G32)) -> 8 | I32: =IF(H32>=10,"TRANSITA","N/TRANSITA") -> N/TRANSITA | J32: 4 | M32: =AVERAGE(J32,MAX(K32:L32)) -> 2 | N32: =IF(M32>=10,"TRANSITA","N/TRANSITA") -> N/TRANSITA | R32: =AVERAGE(O32,MAX(P32:Q32)) -> 0 | S32: =SUM(H32,M32,R32)/3 -> 3.3333333 | T32: =IF(S32>=10,"TRANSITA","N/TRANSITA") -> N/TRANSITA
B33: 25 | C33: Marciano V. Shachilombe | H33: =AVERAGE(E33,MAX(F33:G33)) -> 0 | I33: =IF(H33>=10,"TRANSITA","N/TRANSITA") -> N/TRANSITA | M33: =AVERAGE(J33,MAX(K33:L33)) -> 0 | N33: =IF(M33>=10,"TRANSITA","N/TRANSITA") -> N/TRANSITA | R33: =AVERAGE(O33,MAX(P33:Q33)) -> 0 | S33: =SUM(H33,M33,R33)/3 -> 0 | T33: =IF(S33>=10,"TRANSITA","N/TRANSITA") -> N/TRANSITA
B34: 26 | C34: Maria Nsuami | E34: 16 | F34: 13 | H34: =AVERAGE(E34,MAX(F34:G34)) -> 14.5 | I34: =IF(H34>=10,"TRANSITA","N/TRANSITA") -> TRANSITA | J34: 16 | K34: 11 | M34: =AVERAGE(J34,MAX(K34:L34)) -> 13.5 | N34: =IF(M34>=10,"TRANSITA","N/TRANSITA") -> TRANSITA | R34: =AVERAGE(O34,MAX(P34:Q34)) -> 0 | S34: =SUM(H34,M34,R34)/3 -> 9.3333333 | T34: =IF(S34>=10,"TRANSITA","N/TRANSITA") -> N/TRANSITA
B35: 27 | C35: Maria Zinga Barros | E35: 13 | F35: 4 | H35: =AVERAGE(E35,MAX(F35:G35)) -> 8.5 | I35: =IF(H35>=10,"TRANSITA","N/TRANSITA") -> N/TRANSITA | J35: 1 | K35: 4 | M35: =AVERAGE(J35,MAX(K35:L35)) -> 2.5 | N35: =IF(M35>=10,"TRANSITA","N/TRANSITA") -> N/TRANSITA | R35: =AVERAGE(O35,MAX(P35:Q35)) -> 0 | S35: =SUM(H35,M35,R35)/3 -> 3.6666667 | T35: =IF(S35>=10,"TRANSITA","N/TRANSITA") -> N/TRANSITA
B36: 28 | C36: Mariana Cachala Muanda Calunga | E36: 10 | F36: 2.5 | H36: =AVERAGE(E36,MAX(F36:G36)) -> 6.25 | I36: =IF(H36>=10,"TRANSITA","N/TRANSITA") -> N/TRANSITA | M36: =AVERAGE(J36,MAX(K36:L36)) -> 0 | N36: =IF(M36>=10,"TRANSITA","N/TRANSITA") -> N/TRANSITA | R36: =AVERAGE(O36,MAX(P36:Q36)) -> 0 | S36: =SUM(H36,M36,R36)/3 -> 2.0833333 | T36: =IF(S36>=10,"TRANSITA","N/TRANSITA") -> N/TRANSITA
B37: 29 | C37: Miriame Puati Sumbo | H37: =AVERAGE(E37,MAX(F37:G37)) -> 0 | I37: =IF(H37>=10,"TRANSITA","N/TRANSITA") -> N/TRANSITA | J37: 3 | K37: 0.5 | M37: =AVERAGE(J37,MAX(K37:L37)) -> 1.75 | N37: =IF(M37>=10,"TRANSITA","N/TRANSITA") -> N/TRANSITA | R37: =AVERAGE(O37,MAX(P37:Q37)) -> 0 | S37: =SUM(H37,M37,R37)/3 -> 0.58333333 | T37: =IF(S37>=10,"TRANSITA","N/TRANSITA") -> N/TRANSITA
B38: 30 | C38: Odeth Nzuzi Chibinda Pambo | E38: 15 | F38: 12 | H38: =AVERAGE(E38,MAX(F38:G38)) -> 13.5 | I38: =IF(H38>=10,"TRANSITA","N/TRANSITA") -> TRANSITA | J38: 16 | K38: 12 | M38: =AVERAGE(J38,MAX(K38:L38)) -> 14 | N38: =IF(M38>=10,"TRANSITA","N/TRANSITA") -> TRANSITA | R38: =AVERAGE(O38,MAX(P38:Q38)) -> 0 | S38: =SUM(H38,M38,R38)/3 -> 9.1666667 | T38: =IF(S38>=10,"TRANSITA","N/TRANSITA") -> N/TRANSITA
B39: 31 | C39: Paulina Esperança Ntoni | E39: 14 | F39: 6 | H39: =AVERAGE(E39,MAX(F39:G39)) -> 10 | I39: =IF(H39>=10,"TRANSITA","N/TRANSITA") -> TRANSITA | J39: 4 | K39: 4 | M39: =AVERAGE(J39,MAX(K39:L39)) -> 4 | N39: =IF(M39>=10,"TRANSITA","N/TRANSITA") -> N/TRANSITA | R39: =AVERAGE(O39,MAX(P39:Q39)) -> 0 | S39: =SUM(H39,M39,R39)/3 -> 4.6666667 | T39: =IF(S39>=10,"TRANSITA","N/TRANSITA") -> N/TRANSITA
B40: 32 | C40: Paulo Cawalende Savicaia | H40: =AVERAGE(E40,MAX(F40:G40)) -> 0 | I40: =IF(H40>=10,"TRANSITA","N/TRANSITA") -> N/TRANSITA | J40: 3 | K40: 2 | M40: =AVERAGE(J40,MAX(K40:L40)) -> 2.5 | N40: =IF(M40>=10,"TRANSITA","N/TRANSITA") -> N/TRANSITA | R40: =AVERAGE(O40,MAX(P40:Q40)) -> 0 | S40: =SUM(H40,M40,R40)/3 -> 0.83333333 | T40: =IF(S40>=10,"TRANSITA","N/TRANSITA") -> N/TRANSITA
B41: 33 | C41: Regina De Fatima Mavungo Andre | H41: =AVERAGE(E41,MAX(F41:G41)) -> 0 | I41: =IF(H41>=10,"TRANSITA","N/TRANSITA") -> N/TRANSITA | M41: =AVERAGE(J41,MAX(K41:L41)) -> 0 | N41: =IF(M41>=10,"TRANSITA","N/TRANSITA") -> N/TRANSITA | R41: =AVERAGE(O41,MAX(P41:Q41)) -> 0 | S41: =SUM(H41,M41,R41)/3 -> 0 | T41: =IF(S41>=10,"TRANSITA","N/TRANSITA") -> N/TRANSITA
B42: 34 | C42: Ruth Lutete Mambuco | E42: 16 | F42: 2 | H42: =AVERAGE(E42,MAX(F42:G42)) -> 9 | I42: =IF(H42>=10,"TRANSITA","N/TRANSITA") -> N/TRANSITA | J42: 9 | K42: 1 | M42: =AVERAGE(J42,MAX(K42:L42)) -> 5 | N42: =IF(M42>=10,"TRANSITA","N/TRANSITA") -> N/TRANSITA | R42: =AVERAGE(O42,MAX(P42:Q42)) -> 0 | S42: =SUM(H42,M42,R42)/3 -> 4.6666667 | T42: =IF(S42>=10,"TRANSITA","N/TRANSITA") -> N/TRANSITA
...

Sheet 10ªCEJ-U-INGLES
A1: COMPLEXO ESCOLAR PRIVADO JOMORAIS
B4: Classe: 10ª | I4: Disciplina: Língua Inglesa | P4: Ano Lectivo:2025/2026
B5: Período: Vespertino | I5: Turma: Única | N5: Curso: Ciências Económico-jurídicas
B6: MINI-PAUTA - I Ciclo do Ensino Secundário Geral
B7: Nº | C7: Nome do (a) Aluno (a) | D7: FALTAS | E7: Avaliações/I Trimestre | I7: OBS | J7: Avaliações/II Trimestre | N7: OBS | O7: Avaliações/IIITrimestre | S7: MFD | T7: OBS
D8: J/I | E8: MAC | F8: NPT | G8: NPR2 | H8: MT1 | J8: MAC | K8: NPT | L8: NPR2 | M8: MT2 | O8: MAC | P8: NPT | Q8: NPR2 | R8: MT3
B9: 1 | C9: Albertina Futi Mavungo | E9: 0 | F9: 8 | H9: =AVERAGE(E9,MAX(F9:G9)) -> 4 | I9: =IF(H9>=10,"TRANSITA","N/TRANSITA") -> N/TRANSITA | J9: 20 | K9: 15 | M9: =AVERAGE(J9,MAX(K9:L9)) -> 17.5 | N9: =IF(M9>=10,"TRANSITA","N/TRANSITA") -> TRANSITA | R9: =AVERAGE(O9,MAX(P9:Q9)) -> 0 | S9: =SUM(H9,M9,R9)/3 -> 7.1666667 | T9: =IF(S9>=10,"TRANSITA","N/TRANSITA") -> N/TRANSITA
B10: 2 | C10: António Chimpanzo Inocêncio | E10: 0 | F10: 9 | H10: =AVERAGE(E10,MAX(F10:G10)) -> 4.5 | I10: =IF(H10>=10,"TRANSITA","N/TRANSITA") -> N/TRANSITA | J10: 10 | K10: 9 | M10: =AVERAGE(J10,MAX(K10:L10)) -> 9.5 | N10: =IF(M10>=10,"TRANSITA","N/TRANSITA") -> N/TRANSITA | R10: =AVERAGE(O10,MAX(P10:Q10)) -> 0 | S10: =SUM(H10,M10,R10)/3 -> 4.6666667 | T10: =IF(S10>=10,"TRANSITA","N/TRANSITA") -> N/TRANSITA
B11: 3 | C11: Augusto Mbungo Lando Barros | H11: =AVERAGE(E11,MAX(F11:G11)) -> 0 | I11: =IF(H11>=10,"TRANSITA","N/TRANSITA") -> N/TRANSITA | J11: 0 | M11: =AVERAGE(J11,MAX(K11:L11)) -> 0 | N11: =IF(M11>=10,"TRANSITA","N/TRANSITA") -> N/TRANSITA | R11: =AVERAGE(O11,MAX(P11:Q11)) -> 0 | S11: =SUM(H11,M11,R11)/3 -> 0 | T11: =IF(S11>=10,"TRANSITA","N/TRANSITA") -> N/TRANSITA
B12: 4 | C12: Chianica Bete Quende | E12: 10 | F12: 12 | H12: =AVERAGE(E12,MAX(F12:G12)) -> 11 | I12: =IF(H12>=10,"TRANSITA","N/TRANSITA") -> TRANSITA | J12: 10 | K12: 10 | M12: =AVERAGE(J12,MAX(K12:L12)) -> 10 | N12: =IF(M12>=10,"TRANSITA","N/TRANSITA") -> TRANSITA | R12: =AVERAGE(O12,MAX(P12:Q12)) -> 0 | S12: =SUM(H12,M12,R12)/3 -> 7 | T12: =IF(S12>=10,"TRANSITA","N/TRANSITA") -> N/TRANSITA
B13: 5 | C13: Claudete Vuângela | E13: 0 | F13: 4 | H13: =AVERAGE(E13,MAX(F13:G13)) -> 2 | I13: =IF(H13>=10,"TRANSITA","N/TRANSITA") -> N/TRANSITA | J13: 10 | K13: 6 | M13: =AVERAGE(J13,MAX(K13:L13)) -> 8 | N13: =IF(M13>=10,"TRANSITA","N/TRANSITA") -> N/TRANSITA | R13: =AVERAGE(O13,MAX(P13:Q13)) -> 0 | S13: =SUM(H13,M13,R13)/3 -> 3.3333333 | T13: =IF(S13>=10,"TRANSITA","N/TRANSITA") -> N/TRANSITA
B14: 6 | C14: Cristina Massanga Vubo | H14: =AVERAGE(E14,MAX(F14:G14)) -> 0 | I14: =IF(H14>=10,"TRANSITA","N/TRANSITA") -> N/TRANSITA | J14: 8 | K14: 8 | M14: =AVERAGE(J14,MAX(K14:L14)) -> 8 | N14: =IF(M14>=10,"TRANSITA","N/TRANSITA") -> N/TRANSITA | R14: =AVERAGE(O14,MAX(P14:Q14)) -> 0 | S14: =SUM(H14,M14,R14)/3 -> 2.6666667 | T14: =IF(S14>=10,"TRANSITA","N/TRANSITA") -> N/TRANSITA
B15: 7 | C15: Dalmácia Carlota Quitunga | E15: 15 | F15: 12 | H15: =AVERAGE(E15,MAX(F15:G15)) -> 13.5 | I15: =IF(H15>=10,"TRANSITA","N/TRANSITA") -> TRANSITA | J15: 20 | K15: 10 | M15: =AVERAGE(J15,MAX(K15:L15)) -> 15 | N15: =IF(M15>=10,"TRANSITA","N/TRANSITA") -> TRANSITA | R15: =AVERAGE(O15,MAX(P15:Q15)) -> 0 | S15: =SUM(H15,M15,R15)/3 -> 9.5 | T15: =IF(S15>=10,"TRANSITA","N/TRANSITA") -> N/TRANSITA
B16: 8 | C16: Daniela Teresa Elias Pinto | E16: 0 | F16: 6 | H16: =AVERAGE(E16,MAX(F16:G16)) -> 3 | I16: =IF(H16>=10,"TRANSITA","N/TRANSITA") -> N/TRANSITA | J16: 10 | K16: 11 | M16: =AVERAGE(J16,MAX(K16:L16)) -> 10.5 | N16: =IF(M16>=10,"TRANSITA","N/TRANSITA") -> TRANSITA | R16: =AVERAGE(O16,MAX(P16:Q16)) -> 0 | S16: =SUM(H16,M16,R16)/3 -> 4.5 | T16: =IF(S16>=10,"TRANSITA","N/TRANSITA") -> N/TRANSITA
B17: 9 | C17: Delfina Goma Nsoki | E17: 10 | F17: 11 | H17: =AVERAGE(E17,MAX(F17:G17)) -> 10.5 | I17: =IF(H17>=10,"TRANSITA","N/TRANSITA") -> TRANSITA | J17: 18 | K17: 11 | M17: =AVERAGE(J17,MAX(K17:L17)) -> 14.5 | N17: =IF(M17>=10,"TRANSITA","N/TRANSITA") -> TRANSITA | R17: =AVERAGE(O17,MAX(P17:Q17)) -> 0 | S17: =SUM(H17,M17,R17)/3 -> 8.3333333 | T17: =IF(S17>=10,"TRANSITA","N/TRANSITA") -> N/TRANSITA
B18: 10 | C18: Deolinda Ngueve Waia | E18: 0 | F18: 0 | H18: =AVERAGE(E18,MAX(F18:G18)) -> 0 | I18: =IF(H18>=10,"TRANSITA","N/TRANSITA") -> N/TRANSITA | J18: 0 | K18: 8 | M18: =AVERAGE(J18,MAX(K18:L18)) -> 4 | N18: =IF(M18>=10,"TRANSITA","N/TRANSITA") -> N/TRANSITA | R18: =AVERAGE(O18,MAX(P18:Q18)) -> 0 | S18: =SUM(H18,M18,R18)/3 -> 1.3333333 | T18: =IF(S18>=10,"TRANSITA","N/TRANSITA") -> N/TRANSITA
B19: 11 | C19: Estanislau Massiala Roque | H19: =AVERAGE(E19,MAX(F19:G19)) -> 0 | I19: =IF(H19>=10,"TRANSITA","N/TRANSITA") -> N/TRANSITA | J19: 0 | M19: =AVERAGE(J19,MAX(K19:L19)) -> 0 | N19: =IF(M19>=10,"TRANSITA","N/TRANSITA") -> N/TRANSITA | R19: =AVERAGE(O19,MAX(P19:Q19)) -> 0 | S19: =SUM(H19,M19,R19)/3 -> 0 | T19: =IF(S19>=10,"TRANSITA","N/TRANSITA") -> N/TRANSITA
B20: 12 | C20: Estrela Teta Lumbauziládio | E20: 17 | F20: 11 | H20: =AVERAGE(E20,MAX(F20:G20)) -> 14 | I20: =IF(H20>=10,"TRANSITA","N/TRANSITA") -> TRANSITA | J20: 6 | M20: =AVERAGE(J20,MAX(K20:L20)) -> 3 | N20: =IF(M20>=10,"TRANSITA","N/TRANSITA") -> N/TRANSITA | R20: =AVERAGE(O20,MAX(P20:Q20)) -> 0 | S20: =SUM(H20,M20,R20)/3 -> 5.6666667 | T20: =IF(S20>=10,"TRANSITA","N/TRANSITA") -> N/TRANSITA
B21: 13 | C21: Gertrudes De Jesus Pucuta Melo | H21: =AVERAGE(E21,MAX(F21:G21)) -> 0 | I21: =IF(H21>=10,"TRANSITA","N/TRANSITA") -> N/TRANSITA | J21: 0 | M21: =AVERAGE(J21,MAX(K21:L21)) -> 0 | N21: =IF(M21>=10,"TRANSITA","N/TRANSITA") -> N/TRANSITA | R21: =AVERAGE(O21,MAX(P21:Q21)) -> 0 | S21: =SUM(H21,M21,R21)/3 -> 0 | T21: =IF(S21>=10,"TRANSITA","N/TRANSITA") -> N/TRANSITA
B22: 14 | C22: Guiomar Isabel Malonda André | E22: 15 | F22: 8 | H22: =AVERAGE(E22,MAX(F22:G22)) -> 11.5 | I22: =IF(H22>=10,"TRANSITA","N/TRANSITA") -> TRANSITA | J22: 17 | K22: 12 | M22: =AVERAGE(J22,MAX(K22:L22)) -> 14.5 | N22: =IF(M22>=10,"TRANSITA","N/TRANSITA") -> TRANSITA | R22: =AVERAGE(O22,MAX(P22:Q22)) -> 0 | S22: =SUM(H22,M22,R22)/3 -> 8.6666667 | T22: =IF(S22>=10,"TRANSITA","N/TRANSITA") -> N/TRANSITA
B23: 15 | C23: Filomena de Fátima Goma Monteiro | H23: =AVERAGE(E23,MAX(F23:G23)) -> 0 | I23: =IF(H23>=10,"TRANSITA","N/TRANSITA") -> N/TRANSITA | J23: 6 | K23: 8 | M23: =AVERAGE(J23,MAX(K23:L23)) -> 7 | N23: =IF(M23>=10,"TRANSITA","N/TRANSITA") -> N/TRANSITA | R23: =AVERAGE(O23,MAX(P23:Q23)) -> 0 | S23: =SUM(H23,M23,R23)/3 -> 2.3333333 | T23: =IF(S23>=10,"TRANSITA","N/TRANSITA") -> N/TRANSITA
B24: 16 | C24: Francisco Chocolate Chinene | E24: 10 | F24: 14 | H24: =AVERAGE(E24,MAX(F24:G24)) -> 12 | I24: =IF(H24>=10,"TRANSITA","N/TRANSITA") -> TRANSITA | J24: 10 | K24: 9 | M24: =AVERAGE(J24,MAX(K24:L24)) -> 9.5 | N24: =IF(M24>=10,"TRANSITA","N/TRANSITA") -> N/TRANSITA | R24: =AVERAGE(O24,MAX(P24:Q24)) -> 0 | S24: =SUM(H24,M24,R24)/3 -> 7.1666667 | T24: =IF(S24>=10,"TRANSITA","N/TRANSITA") -> N/TRANSITA
B25: 17 | C25: Isabel Mavinga Chiana Chocolate | H25: =AVERAGE(E25,MAX(F25:G25)) -> 0 | I25: =IF(H25>=10,"TRANSITA","N/TRANSITA") -> N/TRANSITA | J25: 0 | M25: =AVERAGE(J25,MAX(K25:L25)) -> 0 | N25: =IF(M25>=10,"TRANSITA","N/TRANSITA") -> N/TRANSITA | R25: =AVERAGE(O25,MAX(P25:Q25)) -> 0 | S25: =SUM(H25,M25,R25)/3 -> 0 | T25: =IF(S25>=10,"TRANSITA","N/TRANSITA") -> N/TRANSITA
B26: 18 | C26: Jacinto Luciano | E26: 10 | F26: 13 | H26: =AVERAGE(E26,MAX(F26:G26)) -> 11.5 | I26: =IF(H26>=10,"TRANSITA","N/TRANSITA") -> TRANSITA | J26: 13 | K26: 9 | M26: =AVERAGE(J26,MAX(K26:L26)) -> 11 | N26: =IF(M26>=10,"TRANSITA","N/TRANSITA") -> TRANSITA | R26: =AVERAGE(O26,MAX(P26:Q26)) -> 0 | S26: =SUM(H26,M26,R26)/3 -> 7.5 | T26: =IF(S26>=10,"TRANSITA","N/TRANSITA") -> N/TRANSITA
B27: 19 | C27: Joana Suzana Felismina | H27: =AVERAGE(E27,MAX(F27:G27)) -> 0 | I27: =IF(H27>=10,"TRANSITA","N/TRANSITA") -> N/TRANSITA | J27: 0 | M27: =AVERAGE(J27,MAX(K27:L27)) -> 0 | N27: =IF(M27>=10,"TRANSITA","N/TRANSITA") -> N/TRANSITA | R27: =AVERAGE(O27,MAX(P27:Q27)) -> 0 | S27: =SUM(H27,M27,R27)/3 -> 0 | T27: =IF(S27>=10,"TRANSITA","N/TRANSITA") -> N/TRANSITA
B28: 20 | C28: João Maria Sambo | E28: 0 | F28: 6 | H28: =AVERAGE(E28,MAX(F28:G28)) -> 3 | I28: =IF(H28>=10,"TRANSITA","N/TRANSITA") -> N/TRANSITA | J28: 0 | M28: =AVERAGE(J28,MAX(K28:L28)) -> 0 | N28: =IF(M28>=10,"TRANSITA","N/TRANSITA") -> N/TRANSITA | R28: =AVERAGE(O28,MAX(P28:Q28)) -> 0 | S28: =SUM(H28,M28,R28)/3 -> 1 | T28: =IF(S28>=10,"TRANSITA","N/TRANSITA") -> N/TRANSITA
B29: 21 | C29: Joaquim Osvaldo Deca Ngaca | E29: 10 | F29: 19 | H29: =AVERAGE(E29,MAX(F29:G29)) -> 14.5 | I29: =IF(H29>=10,"TRANSITA","N/TRANSITA") -> TRANSITA | J29: 10 | K29: 6 | M29: =AVERAGE(J29,MAX(K29:L29)) -> 8 | N29: =IF(M29>=10,"TRANSITA","N/TRANSITA") -> N/TRANSITA | R29: =AVERAGE(O29,MAX(P29:Q29)) -> 0 | S29: =SUM(H29,M29,R29)/3 -> 7.5 | T29: =IF(S29>=10,"TRANSITA","N/TRANSITA") -> N/TRANSITA
B30: 22 | C30: Josefina Lembe Zau Futi | H30: =AVERAGE(E30,MAX(F30:G30)) -> 0 | I30: =IF(H30>=10,"TRANSITA","N/TRANSITA") -> N/TRANSITA | J30: 0 | M30: =AVERAGE(J30,MAX(K30:L30)) -> 0 | N30: =IF(M30>=10,"TRANSITA","N/TRANSITA") -> N/TRANSITA | R30: =AVERAGE(O30,MAX(P30:Q30)) -> 0 | S30: =SUM(H30,M30,R30)/3 -> 0 | T30: =IF(S30>=10,"TRANSITA","N/TRANSITA") -> N/TRANSITA
B31: 23 | C31: Lourdes Puati Issambo | E31: 10 | F31: 11 | H31: =AVERAGE(E31,MAX(F31:G31)) -> 10.5 | I31: =IF(H31>=10,"TRANSITA","N/TRANSITA") -> TRANSITA | J31: 19 | K31: 16 | M31: =AVERAGE(J31,MAX(K31:L31)) -> 17.5 | N31: =IF(M31>=10,"TRANSITA","N/TRANSITA") -> TRANSITA | R31: =AVERAGE(O31,MAX(P31:Q31)) -> 0 | S31: =SUM(H31,M31,R31)/3 -> 9.3333333 | T31: =IF(S31>=10,"TRANSITA","N/TRANSITA") -> N/TRANSITA
B32: 24 | C32: Luís Liberal Lemos Casimiro | H32: =AVERAGE(E32,MAX(F32:G32)) -> 0 | I32: =IF(H32>=10,"TRANSITA","N/TRANSITA") -> N/TRANSITA | J32: 0 | M32: =AVERAGE(J32,MAX(K32:L32)) -> 0 | N32: =IF(M32>=10,"TRANSITA","N/TRANSITA") -> N/TRANSITA | R32: =AVERAGE(O32,MAX(P32:Q32)) -> 0 | S32: =SUM(H32,M32,R32)/3 -> 0 | T32: =IF(S32>=10,"TRANSITA","N/TRANSITA") -> N/TRANSITA
B33: 25 | C33: Marciano V. Shachilombe | H33: =AVERAGE(E33,MAX(F33:G33)) -> 0 | I33: =IF(H33>=10,"TRANSITA","N/TRANSITA") -> N/TRANSITA | J33: 0 | M33: =AVERAGE(J33,MAX(K33:L33)) -> 0 | N33: =IF(M33>=10,"TRANSITA","N/TRANSITA") -> N/TRANSITA | R33: =AVERAGE(O33,MAX(P33:Q33)) -> 0 | S33: =SUM(H33,M33,R33)/3 -> 0 | T33: =IF(S33>=10,"TRANSITA","N/TRANSITA") -> N/TRANSITA
B34: 26 | C34: Maria Nsuami | E34: 15 | F34: 12 | H34: =AVERAGE(E34,MAX(F34:G34)) -> 13.5 | I34: =IF(H34>=10,"TRANSITA","N/TRANSITA") -> TRANSITA | J34: 20 | K34: 16 | M34: =AVERAGE(J34,MAX(K34:L34)) -> 18 | N34: =IF(M34>=10,"TRANSITA","N/TRANSITA") -> TRANSITA | R34: =AVERAGE(O34,MAX(P34:Q34)) -> 0 | S34: =SUM(H34,M34,R34)/3 -> 10.5 | T34: =IF(S34>=10,"TRANSITA","N/TRANSITA") -> TRANSITA
B35: 27 | C35: Maria Zinga Barros | H35: =AVERAGE(E35,MAX(F35:G35)) -> 0 | I35: =IF(H35>=10,"TRANSITA","N/TRANSITA") -> N/TRANSITA | J35: 6 | K35: 10 | M35: =AVERAGE(J35,MAX(K35:L35)) -> 8 | N35: =IF(M35>=10,"TRANSITA","N/TRANSITA") -> N/TRANSITA | R35: =AVERAGE(O35,MAX(P35:Q35)) -> 0 | S35: =SUM(H35,M35,R35)/3 -> 2.6666667 | T35: =IF(S35>=10,"TRANSITA","N/TRANSITA") -> N/TRANSITA
B36: 28 | C36: Mariana Cachala Muanda Calunga | H36: =AVERAGE(E36,MAX(F36:G36)) -> 0 | I36: =IF(H36>=10,"TRANSITA","N/TRANSITA") -> N/TRANSITA | J36: 0 | M36: =AVERAGE(J36,MAX(K36:L36)) -> 0 | N36: =IF(M36>=10,"TRANSITA","N/TRANSITA") -> N/TRANSITA | R36: =AVERAGE(O36,MAX(P36:Q36)) -> 0 | S36: =SUM(H36,M36,R36)/3 -> 0 | T36: =IF(S36>=10,"TRANSITA","N/TRANSITA") -> N/TRANSITA
B37: 29 | C37: Miriame Puati Sumbo | E37: 17 | F37: 10 | H37: =AVERAGE(E37,MAX(F37:G37)) -> 13.5 | I37: =IF(H37>=10,"TRANSITA","N/TRANSITA") -> TRANSITA | J37: 0 | K37: 8 | M37: =AVERAGE(J37,MAX(K37:L37)) -> 4 | N37: =IF(M37>=10,"TRANSITA","N/TRANSITA") -> N/TRANSITA | R37: =AVERAGE(O37,MAX(P37:Q37)) -> 0 | S37: =SUM(H37,M37,R37)/3 -> 5.8333333 | T37: =IF(S37>=10,"TRANSITA","N/TRANSITA") -> N/TRANSITA
B38: 30 | C38: Odeth Nzuzi Chibinda Pambo | E38: 15 | H38: =AVERAGE(E38,MAX(F38:G38)) -> 7.5 | I38: =IF(H38>=10,"TRANSITA","N/TRANSITA") -> N/TRANSITA | J38: 16 | K38: 10 | M38: =AVERAGE(J38,MAX(K38:L38)) -> 13 | N38: =IF(M38>=10,"TRANSITA","N/TRANSITA") -> TRANSITA | R38: =AVERAGE(O38,MAX(P38:Q38)) -> 0 | S38: =SUM(H38,M38,R38)/3 -> 6.8333333 | T38: =IF(S38>=10,"TRANSITA","N/TRANSITA") -> N/TRANSITA
B39: 31 | C39: Paulina Esperança Ntoni | E39: 15 | H39: =AVERAGE(E39,MAX(F39:G39)) -> 7.5 | I39: =IF(H39>=10,"TRANSITA","N/TRANSITA") -> N/TRANSITA | J39: 10 | K39: 8 | M39: =AVERAGE(J39,MAX(K39:L39)) -> 9 | N39: =IF(M39>=10,"TRANSITA","N/TRANSITA") -> N/TRANSITA | R39: =AVERAGE(O39,MAX(P39:Q39)) -> 0 | S39: =SUM(H39,M39,R39)/3 -> 5.5 | T39: =IF(S39>=10,"TRANSITA","N/TRANSITA") -> N/TRANSITA
B40: 32 | C40: Paulo Cawalende Savicaia | H40: =AVERAGE(E40,MAX(F40:G40)) -> 0 | I40: =IF(H40>=10,"TRANSITA","N/TRANSITA") -> N/TRANSITA | J40: 0 | M40: =AVERAGE(J40,MAX(K40:L40)) -> 0 | N40: =IF(M40>=10,"TRANSITA","N/TRANSITA") -> N/TRANSITA | R40: =AVERAGE(O40,MAX(P40:Q40)) -> 0 | S40: =SUM(H40,M40,R40)/3 -> 0 | T40: =IF(S40>=10,"TRANSITA","N/TRANSITA") -> N/TRANSITA
B41: 33 | C41: Regina De Fatima Mavungo Andre | H41: =AVERAGE(E41,MAX(F41:G41)) -> 0 | I41: =IF(H41>=10,"TRANSITA","N/TRANSITA") -> N/TRANSITA | J41: 0 | M41: =AVERAGE(J41,MAX(K41:L41)) -> 0 | N41: =IF(M41>=10,"TRANSITA","N/TRANSITA") -> N/TRANSITA | R41: =AVERAGE(O41,MAX(P41:Q41)) -> 0 | S41: =SUM(H41,M41,R41)/3 -> 0 | T41: =IF(S41>=10,"TRANSITA","N/TRANSITA") -> N/TRANSITA
B42: 34 | C42: Ruth Lutete Mambuco | E42: 10 | F42: 12 | H42: =AVERAGE(E42,MAX(F42:G42)) -> 11 | I42: =IF(H42>=10,"TRANSITA","N/TRANSITA") -> TRANSITA | J42: 6 | K42: 9 | M42: =AVERAGE(J42,MAX(K42:L42)) -> 7.5 | N42: =IF(M42>=10,"TRANSITA","N/TRANSITA") -> N/TRANSITA | R42: =AVERAGE(O42,MAX(P42:Q42)) -> 0 | S42: =SUM(H42,M42,R42)/3 -> 6.1666667 | T42: =IF(S42>=10,"TRANSITA","N/TRANSITA") -> N/TRANSITA
...

Sheet 10ªCEJ-U-MAT
A1: COMPLEXO ESCOLAR PRIVADO JOMORAIS
B4: Classe: 10ª | I4: Disciplina: Matemática | P4: Ano Lectivo:2025/2026
B5: Período: Vespertino | I5: Turma: Única | N5: Curso: Ciências Económico-jurídicas
B6: MINI-PAUTA - I Ciclo do Ensino Secundário Geral
B7: Nº | C7: Nome do (a) Aluno (a) | D7: FALTAS | E7: Avaliações/I Trimestre | I7: OBS | J7: Avaliações/II Trimestre | N7: OBS | O7: Avaliações/IIITrimestre | S7: MFD | T7: OBS
D8: J/I | E8: MAC | F8: NPT | G8: NPR2 | H8: MT1 | J8: MAC | K8: NPT | L8: NPR2 | M8: MT2 | O8: MAC | P8: NPT | Q8: NPR2 | R8: MT3
B9: 1 | C9: Albertina Futi Mavungo | E9: 13 | F9: 7.5 | H9: =AVERAGE(E9,MAX(F9:G9)) -> 10.25 | I9: =IF(H9>=10,"TRANSITA","N/TRANSITA") -> TRANSITA | J9: 12 | K9: 12 | M9: =AVERAGE(J9,MAX(K9:L9)) -> 12 | N9: =IF(M9>=10,"TRANSITA","N/TRANSITA") -> TRANSITA | R9: =AVERAGE(O9,MAX(P9:Q9)) -> 0 | S9: =SUM(H9,M9,R9)/3 -> 7.4166667 | T9: =IF(S9>=10,"TRANSITA","N/TRANSITA") -> N/TRANSITA
B10: 2 | C10: António Chimpanzo Inocêncio | H10: =AVERAGE(E10,MAX(F10:G10)) -> 0 | I10: =IF(H10>=10,"TRANSITA","N/TRANSITA") -> N/TRANSITA | J10: 12 | K10: 12 | M10: =AVERAGE(J10,MAX(K10:L10)) -> 12 | N10: =IF(M10>=10,"TRANSITA","N/TRANSITA") -> TRANSITA | R10: =AVERAGE(O10,MAX(P10:Q10)) -> 0 | S10: =SUM(H10,M10,R10)/3 -> 4 | T10: =IF(S10>=10,"TRANSITA","N/TRANSITA") -> N/TRANSITA
B11: 3 | C11: Augusto Mbungo Lando Barros | H11: =AVERAGE(E11,MAX(F11:G11)) -> 0 | I11: =IF(H11>=10,"TRANSITA","N/TRANSITA") -> N/TRANSITA | J11: 12 | K11: 12 | M11: =AVERAGE(J11,MAX(K11:L11)) -> 12 | N11: =IF(M11>=10,"TRANSITA","N/TRANSITA") -> TRANSITA | R11: =AVERAGE(O11,MAX(P11:Q11)) -> 0 | S11: =SUM(H11,M11,R11)/3 -> 4 | T11: =IF(S11>=10,"TRANSITA","N/TRANSITA") -> N/TRANSITA
B12: 4 | C12: Chianica Bete Quende | E12: 11 | F12: 3 | H12: =AVERAGE(E12,MAX(F12:G12)) -> 7 | I12: =IF(H12>=10,"TRANSITA","N/TRANSITA") -> N/TRANSITA | J12: 12 | K12: 12 | M12: =AVERAGE(J12,MAX(K12:L12)) -> 12 | N12: =IF(M12>=10,"TRANSITA","N/TRANSITA") -> TRANSITA | R12: =AVERAGE(O12,MAX(P12:Q12)) -> 0 | S12: =SUM(H12,M12,R12)/3 -> 6.3333333 | T12: =IF(S12>=10,"TRANSITA","N/TRANSITA") -> N/TRANSITA
B13: 5 | C13: Claudete Vuângela | E13: 10 | F13: 0 | H13: =AVERAGE(E13,MAX(F13:G13)) -> 5 | I13: =IF(H13>=10,"TRANSITA","N/TRANSITA") -> N/TRANSITA | J13: 12 | K13: 12 | M13: =AVERAGE(J13,MAX(K13:L13)) -> 12 | N13: =IF(M13>=10,"TRANSITA","N/TRANSITA") -> TRANSITA | R13: =AVERAGE(O13,MAX(P13:Q13)) -> 0 | S13: =SUM(H13,M13,R13)/3 -> 5.6666667 | T13: =IF(S13>=10,"TRANSITA","N/TRANSITA") -> N/TRANSITA
B14: 6 | C14: Cristina Massanga Vubo | H14: =AVERAGE(E14,MAX(F14:G14)) -> 0 | I14: =IF(H14>=10,"TRANSITA","N/TRANSITA") -> N/TRANSITA | J14: 12 | K14: 12 | M14: =AVERAGE(J14,MAX(K14:L14)) -> 12 | N14: =IF(M14>=10,"TRANSITA","N/TRANSITA") -> TRANSITA | R14: =AVERAGE(O14,MAX(P14:Q14)) -> 0 | S14: =SUM(H14,M14,R14)/3 -> 4 | T14: =IF(S14>=10,"TRANSITA","N/TRANSITA") -> N/TRANSITA
B15: 7 | C15: Dalmácia Carlota Quitunga | E15: 15 | F15: 11 | H15: =AVERAGE(E15,MAX(F15:G15)) -> 13 | I15: =IF(H15>=10,"TRANSITA","N/TRANSITA") -> TRANSITA | J15: 12 | K15: 12 | M15: =AVERAGE(J15,MAX(K15:L15)) -> 12 | N15: =IF(M15>=10,"TRANSITA","N/TRANSITA") -> TRANSITA | R15: =AVERAGE(O15,MAX(P15:Q15)) -> 0 | S15: =SUM(H15,M15,R15)/3 -> 8.3333333 | T15: =IF(S15>=10,"TRANSITA","N/TRANSITA") -> N/TRANSITA
B16: 8 | C16: Daniela Teresa Elias Pinto | E16: 10 | F16: 1 | H16: =AVERAGE(E16,MAX(F16:G16)) -> 5.5 | I16: =IF(H16>=10,"TRANSITA","N/TRANSITA") -> N/TRANSITA | J16: 12 | K16: 12 | M16: =AVERAGE(J16,MAX(K16:L16)) -> 12 | N16: =IF(M16>=10,"TRANSITA","N/TRANSITA") -> TRANSITA | R16: =AVERAGE(O16,MAX(P16:Q16)) -> 0 | S16: =SUM(H16,M16,R16)/3 -> 5.8333333 | T16: =IF(S16>=10,"TRANSITA","N/TRANSITA") -> N/TRANSITA
B17: 9 | C17: Delfina Goma Nsoki | E17: 14 | F17: 11 | H17: =AVERAGE(E17,MAX(F17:G17)) -> 12.5 | I17: =IF(H17>=10,"TRANSITA","N/TRANSITA") -> TRANSITA | J17: 12 | K17: 12 | M17: =AVERAGE(J17,MAX(K17:L17)) -> 12 | N17: =IF(M17>=10,"TRANSITA","N/TRANSITA") -> TRANSITA | R17: =AVERAGE(O17,MAX(P17:Q17)) -> 0 | S17: =SUM(H17,M17,R17)/3 -> 8.1666667 | T17: =IF(S17>=10,"TRANSITA","N/TRANSITA") -> N/TRANSITA
B18: 10 | C18: Deolinda Ngueve Waia | H18: =AVERAGE(E18,MAX(F18:G18)) -> 0 | I18: =IF(H18>=10,"TRANSITA","N/TRANSITA") -> N/TRANSITA | J18: 12 | K18: 12 | M18: =AVERAGE(J18,MAX(K18:L18)) -> 12 | N18: =IF(M18>=10,"TRANSITA","N/TRANSITA") -> TRANSITA | R18: =AVERAGE(O18,MAX(P18:Q18)) -> 0 | S18: =SUM(H18,M18,R18)/3 -> 4 | T18: =IF(S18>=10,"TRANSITA","N/TRANSITA") -> N/TRANSITA
B19: 11 | C19: Estanislau Massiala Roque | H19: =AVERAGE(E19,MAX(F19:G19)) -> 0 | I19: =IF(H19>=10,"TRANSITA","N/TRANSITA") -> N/TRANSITA | J19: 12 | K19: 12 | M19: =AVERAGE(J19,MAX(K19:L19)) -> 12 | N19: =IF(M19>=10,"TRANSITA","N/TRANSITA") -> TRANSITA | R19: =AVERAGE(O19,MAX(P19:Q19)) -> 0 | S19: =SUM(H19,M19,R19)/3 -> 4 | T19: =IF(S19>=10,"TRANSITA","N/TRANSITA") -> N/TRANSITA
